package com.mjr.extraplanets.world.features;

import java.util.Random;

import micdoodle8.mods.galacticraft.planets.mars.blocks.MarsBlocks;
import net.minecraft.init.Blocks;
import net.minecraft.world.World;
import net.minecraft.world.gen.feature.WorldGenerator;

import com.mjr.extraplanets.Config;
import com.mjr.extraplanets.blocks.ExtraPlanets_Blocks;
import com.mjr.extraplanets.util.WorldGenHelper;

public class WorldGenBigRedTree extends WorldGenerator {

	@Override
	public boolean generate(World world, Random rand, int x, int y, int z) {
		if (WorldGenHelper.checkValidSpawn(world, x, y, z, 10) == false)
			return false;
		else {
			if (Config.DEBUG_MODE)
				System.out.println("Spawning Big Red Tree at (x, y, z)" + x + " " + y + " " + z);
			generatreStructure(world, rand, x, y, z);
		}
		return true;
	}

	public boolean generatreStructure(World world, Random rand, int x, int y, int z) {
		world.setBlock(x + 5, y + 0, z + 4, ExtraPlanets_Blocks.kepler22bMapleLeaf, 1, 3);
		world.setBlock(x + 6, y + 0, z + 4, ExtraPlanets_Blocks.kepler22bMapleLeaf, 1, 3);
		world.setBlock(x + 7, y + 0, z + 4, ExtraPlanets_Blocks.kepler22bMapleLog, 1, 3);
		world.setBlock(x + 5, y + 0, z + 5, ExtraPlanets_Blocks.kepler22bMapleLeaf, 1, 3);
		world.setBlock(x + 6, y + 0, z + 5, ExtraPlanets_Blocks.kepler22bMapleLog, 1, 3);
		world.setBlock(x + 7, y + 0, z + 5, ExtraPlanets_Blocks.kepler22bMapleLog, 1, 3);
		world.setBlock(x + 8, y + 0, z + 5, ExtraPlanets_Blocks.kepler22bMapleLog, 1, 3);
		world.setBlock(x + 9, y + 0, z + 5, ExtraPlanets_Blocks.kepler22bMapleLeaf, 1, 3);
		world.setBlock(x + 4, y + 0, z + 6, ExtraPlanets_Blocks.kepler22bMapleLeaf, 1, 3);
		world.setBlock(x + 5, y + 0, z + 6, ExtraPlanets_Blocks.kepler22bMapleLog, 1, 3);
		world.setBlock(x + 6, y + 0, z + 6, ExtraPlanets_Blocks.kepler22bMapleLog, 1, 3);
		world.setBlock(x + 7, y + 0, z + 6, ExtraPlanets_Blocks.kepler22bMapleLog, 1, 3);
		world.setBlock(x + 8, y + 0, z + 6, ExtraPlanets_Blocks.kepler22bMapleLog, 1, 3);
		world.setBlock(x + 9, y + 0, z + 6, ExtraPlanets_Blocks.kepler22bMapleLog, 1, 3);
		world.setBlock(x + 10, y + 0, z + 6, ExtraPlanets_Blocks.kepler22bMapleLeaf, 1, 3);
		world.setBlock(x + 4, y + 0, z + 7, ExtraPlanets_Blocks.kepler22bMapleLog, 1, 3);
		world.setBlock(x + 5, y + 0, z + 7, ExtraPlanets_Blocks.kepler22bMapleLog, 1, 3);
		world.setBlock(x + 6, y + 0, z + 7, ExtraPlanets_Blocks.kepler22bMapleLog, 1, 3);
		world.setBlock(x + 7, y + 0, z + 7, ExtraPlanets_Blocks.kepler22bMapleLog, 1, 3);
		world.setBlock(x + 8, y + 0, z + 7, ExtraPlanets_Blocks.kepler22bMapleLog, 1, 3);
		world.setBlock(x + 9, y + 0, z + 7, ExtraPlanets_Blocks.kepler22bMapleLog, 1, 3);
		world.setBlock(x + 10, y + 0, z + 7, ExtraPlanets_Blocks.kepler22bMapleLog, 1, 3);
		world.setBlock(x + 4, y + 0, z + 8, ExtraPlanets_Blocks.kepler22bMapleLeaf, 1, 3);
		world.setBlock(x + 5, y + 0, z + 8, ExtraPlanets_Blocks.kepler22bMapleLog, 1, 3);
		world.setBlock(x + 6, y + 0, z + 8, ExtraPlanets_Blocks.kepler22bMapleLog, 1, 3);
		world.setBlock(x + 7, y + 0, z + 8, ExtraPlanets_Blocks.kepler22bMapleLog, 1, 3);
		world.setBlock(x + 8, y + 0, z + 8, ExtraPlanets_Blocks.kepler22bMapleLog, 1, 3);
		world.setBlock(x + 9, y + 0, z + 8, ExtraPlanets_Blocks.kepler22bMapleLog, 1, 3);
		world.setBlock(x + 10, y + 0, z + 8, ExtraPlanets_Blocks.kepler22bMapleLeaf, 1, 3);
		world.setBlock(x + 5, y + 0, z + 9, ExtraPlanets_Blocks.kepler22bMapleLeaf, 1, 3);
		world.setBlock(x + 6, y + 0, z + 9, ExtraPlanets_Blocks.kepler22bMapleLog, 1, 3);
		world.setBlock(x + 7, y + 0, z + 9, ExtraPlanets_Blocks.kepler22bMapleLog, 1, 3);
		world.setBlock(x + 8, y + 0, z + 9, ExtraPlanets_Blocks.kepler22bMapleLog, 1, 3);
		world.setBlock(x + 9, y + 0, z + 9, ExtraPlanets_Blocks.kepler22bMapleLeaf, 1, 3);
		world.setBlock(x + 10, y + 0, z + 9, ExtraPlanets_Blocks.kepler22bMapleLeaf, 1, 3);
		world.setBlock(x + 5, y + 0, z + 10, ExtraPlanets_Blocks.kepler22bMapleLeaf, 1, 3);
		world.setBlock(x + 6, y + 0, z + 10, ExtraPlanets_Blocks.kepler22bMapleLeaf, 1, 3);
		world.setBlock(x + 7, y + 0, z + 10, ExtraPlanets_Blocks.kepler22bMapleLog, 1, 3);
		world.setBlock(x + 8, y + 0, z + 10, ExtraPlanets_Blocks.kepler22bMapleLeaf, 1, 3);
		world.setBlock(x + 9, y + 0, z + 10, ExtraPlanets_Blocks.kepler22bMapleLeaf, 1, 3);
		world.setBlock(x + 5, y + 1, z + 5, ExtraPlanets_Blocks.kepler22bMapleLeaf, 1, 3);
		world.setBlock(x + 8, y + 1, z + 5, ExtraPlanets_Blocks.kepler22bMapleLeaf, 1, 3);
		world.setBlock(x + 9, y + 1, z + 5, ExtraPlanets_Blocks.kepler22bMapleLeaf, 1, 3);
		world.setBlock(x + 5, y + 1, z + 6, ExtraPlanets_Blocks.kepler22bMapleLeaf, 1, 3);
		world.setBlock(x + 6, y + 1, z + 6, ExtraPlanets_Blocks.kepler22bMapleLog, 1, 3);
		world.setBlock(x + 7, y + 1, z + 6, ExtraPlanets_Blocks.kepler22bMapleLog, 1, 3);
		world.setBlock(x + 8, y + 1, z + 6, ExtraPlanets_Blocks.kepler22bMapleLog, 1, 3);
		world.setBlock(x + 9, y + 1, z + 6, ExtraPlanets_Blocks.kepler22bMapleLeaf, 1, 3);
		world.setBlock(x + 6, y + 1, z + 7, ExtraPlanets_Blocks.kepler22bMapleLog, 1, 3);
		world.setBlock(x + 7, y + 1, z + 7, ExtraPlanets_Blocks.kepler22bMapleLog, 1, 3);
		world.setBlock(x + 8, y + 1, z + 7, ExtraPlanets_Blocks.kepler22bMapleLog, 1, 3);
		world.setBlock(x + 5, y + 1, z + 8, ExtraPlanets_Blocks.kepler22bMapleLeaf, 1, 3);
		world.setBlock(x + 6, y + 1, z + 8, ExtraPlanets_Blocks.kepler22bMapleLog, 1, 3);
		world.setBlock(x + 7, y + 1, z + 8, ExtraPlanets_Blocks.kepler22bMapleLog, 1, 3);
		world.setBlock(x + 8, y + 1, z + 8, ExtraPlanets_Blocks.kepler22bMapleLog, 1, 3);
		world.setBlock(x + 9, y + 1, z + 8, ExtraPlanets_Blocks.kepler22bMapleLeaf, 1, 3);
		world.setBlock(x + 5, y + 1, z + 9, ExtraPlanets_Blocks.kepler22bMapleLeaf, 1, 3);
		world.setBlock(x + 6, y + 1, z + 9, ExtraPlanets_Blocks.kepler22bMapleLeaf, 1, 3);
		world.setBlock(x + 8, y + 1, z + 9, ExtraPlanets_Blocks.kepler22bMapleLeaf, 1, 3);
		world.setBlock(x + 9, y + 1, z + 9, ExtraPlanets_Blocks.kepler22bMapleLeaf, 1, 3);
		world.setBlock(x + 6, y + 2, z + 5, MarsBlocks.vine, 2, 3);
		world.setBlock(x + 7, y + 2, z + 7, ExtraPlanets_Blocks.kepler22bMapleLog, 1, 3);
		world.setBlock(x + 8, y + 2, z + 9, MarsBlocks.vine, 2, 3);
		world.setBlock(x + 6, y + 3, z + 5, MarsBlocks.vine, 1, 3);
		world.setBlock(x + 6, y + 3, z + 6, MarsBlocks.vine, 2, 3);
		world.setBlock(x + 9, y + 3, z + 6, MarsBlocks.vine, 1, 3);
		world.setBlock(x + 7, y + 3, z + 7, ExtraPlanets_Blocks.kepler22bMapleLog, 1, 3);
		world.setBlock(x + 8, y + 3, z + 9, MarsBlocks.vine, 1, 3);
		world.setBlock(x + 6, y + 4, z + 5, MarsBlocks.vine, 0, 3);
		world.setBlock(x + 6, y + 4, z + 6, MarsBlocks.vine, 1, 3);
		world.setBlock(x + 9, y + 4, z + 6, MarsBlocks.vine, 0, 3);
		world.setBlock(x + 7, y + 4, z + 7, ExtraPlanets_Blocks.kepler22bMapleLog, 1, 3);
		world.setBlock(x + 8, y + 4, z + 9, MarsBlocks.vine, 0, 3);
		world.setBlock(x + 6, y + 5, z + 5, MarsBlocks.vine, 2, 3);
		world.setBlock(x + 6, y + 5, z + 6, MarsBlocks.vine, 0, 3);
		world.setBlock(x + 7, y + 5, z + 6, ExtraPlanets_Blocks.kepler22bMapleLeaf, 1, 3);
		world.setBlock(x + 9, y + 5, z + 6, MarsBlocks.vine, 2, 3);
		world.setBlock(x + 6, y + 5, z + 7, ExtraPlanets_Blocks.kepler22bMapleLeaf, 1, 3);
		world.setBlock(x + 7, y + 5, z + 7, ExtraPlanets_Blocks.kepler22bMapleLog, 1, 3);
		world.setBlock(x + 8, y + 5, z + 7, ExtraPlanets_Blocks.kepler22bMapleLeaf, 1, 3);
		world.setBlock(x + 7, y + 5, z + 8, ExtraPlanets_Blocks.kepler22bMapleLeaf, 1, 3);
		world.setBlock(x + 8, y + 5, z + 9, MarsBlocks.vine, 2, 3);
		world.setBlock(x + 6, y + 6, z + 5, MarsBlocks.vine, 1, 3);
		world.setBlock(x + 7, y + 6, z + 5, ExtraPlanets_Blocks.kepler22bMapleLeaf, 1, 3);
		world.setBlock(x + 6, y + 6, z + 6, ExtraPlanets_Blocks.kepler22bMapleLeaf, 1, 3);
		world.setBlock(x + 7, y + 6, z + 6, ExtraPlanets_Blocks.kepler22bMapleLeaf, 1, 3);
		world.setBlock(x + 8, y + 6, z + 6, ExtraPlanets_Blocks.kepler22bMapleLeaf, 1, 3);
		world.setBlock(x + 9, y + 6, z + 6, MarsBlocks.vine, 1, 3);
		world.setBlock(x + 5, y + 6, z + 7, ExtraPlanets_Blocks.kepler22bMapleLeaf, 1, 3);
		world.setBlock(x + 6, y + 6, z + 7, ExtraPlanets_Blocks.kepler22bMapleLeaf, 1, 3);
		world.setBlock(x + 7, y + 6, z + 7, ExtraPlanets_Blocks.kepler22bMapleLog, 1, 3);
		world.setBlock(x + 8, y + 6, z + 7, ExtraPlanets_Blocks.kepler22bMapleLeaf, 1, 3);
		world.setBlock(x + 9, y + 6, z + 7, ExtraPlanets_Blocks.kepler22bMapleLeaf, 1, 3);
		world.setBlock(x + 6, y + 6, z + 8, ExtraPlanets_Blocks.kepler22bMapleLeaf, 1, 3);
		world.setBlock(x + 7, y + 6, z + 8, ExtraPlanets_Blocks.kepler22bMapleLeaf, 1, 3);
		world.setBlock(x + 8, y + 6, z + 8, ExtraPlanets_Blocks.kepler22bMapleLeaf, 1, 3);
		world.setBlock(x + 7, y + 6, z + 9, ExtraPlanets_Blocks.kepler22bMapleLeaf, 1, 3);
		world.setBlock(x + 8, y + 6, z + 9, MarsBlocks.vine, 1, 3);
		world.setBlock(x + 6, y + 7, z + 5, MarsBlocks.vine, 0, 3);
		world.setBlock(x + 7, y + 7, z + 5, ExtraPlanets_Blocks.kepler22bMapleLeaf, 1, 3);
		world.setBlock(x + 6, y + 7, z + 6, ExtraPlanets_Blocks.kepler22bMapleLeaf, 1, 3);
		world.setBlock(x + 7, y + 7, z + 6, ExtraPlanets_Blocks.kepler22bMapleLeaf, 1, 3);
		world.setBlock(x + 8, y + 7, z + 6, ExtraPlanets_Blocks.kepler22bMapleLeaf, 1, 3);
		world.setBlock(x + 9, y + 7, z + 6, MarsBlocks.vine, 0, 3);
		world.setBlock(x + 5, y + 7, z + 7, ExtraPlanets_Blocks.kepler22bMapleLeaf, 1, 3);
		world.setBlock(x + 6, y + 7, z + 7, ExtraPlanets_Blocks.kepler22bMapleLeaf, 1, 3);
		world.setBlock(x + 7, y + 7, z + 7, ExtraPlanets_Blocks.kepler22bMapleLog, 1, 3);
		world.setBlock(x + 8, y + 7, z + 7, ExtraPlanets_Blocks.kepler22bMapleLeaf, 1, 3);
		world.setBlock(x + 9, y + 7, z + 7, ExtraPlanets_Blocks.kepler22bMapleLeaf, 1, 3);
		world.setBlock(x + 6, y + 7, z + 8, ExtraPlanets_Blocks.kepler22bMapleLeaf, 1, 3);
		world.setBlock(x + 7, y + 7, z + 8, ExtraPlanets_Blocks.kepler22bMapleLeaf, 1, 3);
		world.setBlock(x + 8, y + 7, z + 8, ExtraPlanets_Blocks.kepler22bMapleLeaf, 1, 3);
		world.setBlock(x + 7, y + 7, z + 9, ExtraPlanets_Blocks.kepler22bMapleLeaf, 1, 3);
		world.setBlock(x + 8, y + 7, z + 9, MarsBlocks.vine, 0, 3);
		world.setBlock(x + 6, y + 8, z + 3, ExtraPlanets_Blocks.kepler22bMapleLeaf, 1, 3);
		world.setBlock(x + 7, y + 8, z + 3, ExtraPlanets_Blocks.kepler22bMapleLeaf, 1, 3);
		world.setBlock(x + 8, y + 8, z + 3, ExtraPlanets_Blocks.kepler22bMapleLeaf, 1, 3);
		world.setBlock(x + 6, y + 8, z + 5, ExtraPlanets_Blocks.kepler22bMapleLeaf, 1, 3);
		world.setBlock(x + 7, y + 8, z + 5, ExtraPlanets_Blocks.kepler22bMapleLeaf, 1, 3);
		world.setBlock(x + 8, y + 8, z + 5, ExtraPlanets_Blocks.kepler22bMapleLeaf, 1, 3);
		world.setBlock(x + 3, y + 8, z + 6, ExtraPlanets_Blocks.kepler22bMapleLeaf, 1, 3);
		world.setBlock(x + 5, y + 8, z + 6, ExtraPlanets_Blocks.kepler22bMapleLeaf, 1, 3);
		world.setBlock(x + 6, y + 8, z + 6, ExtraPlanets_Blocks.kepler22bMapleLeaf, 1, 3);
		world.setBlock(x + 7, y + 8, z + 6, ExtraPlanets_Blocks.kepler22bMapleLeaf, 1, 3);
		world.setBlock(x + 8, y + 8, z + 6, ExtraPlanets_Blocks.kepler22bMapleLeaf, 1, 3);
		world.setBlock(x + 9, y + 8, z + 6, ExtraPlanets_Blocks.kepler22bMapleLeaf, 1, 3);
		world.setBlock(x + 11, y + 8, z + 6, ExtraPlanets_Blocks.kepler22bMapleLeaf, 1, 3);
		world.setBlock(x + 3, y + 8, z + 7, ExtraPlanets_Blocks.kepler22bMapleLeaf, 1, 3);
		world.setBlock(x + 5, y + 8, z + 7, ExtraPlanets_Blocks.kepler22bMapleLeaf, 1, 3);
		world.setBlock(x + 6, y + 8, z + 7, ExtraPlanets_Blocks.kepler22bMapleLeaf, 1, 3);
		world.setBlock(x + 7, y + 8, z + 7, ExtraPlanets_Blocks.kepler22bMapleLog, 1, 3);
		world.setBlock(x + 8, y + 8, z + 7, ExtraPlanets_Blocks.kepler22bMapleLeaf, 1, 3);
		world.setBlock(x + 9, y + 8, z + 7, ExtraPlanets_Blocks.kepler22bMapleLeaf, 1, 3);
		world.setBlock(x + 11, y + 8, z + 7, ExtraPlanets_Blocks.kepler22bMapleLeaf, 1, 3);
		world.setBlock(x + 3, y + 8, z + 8, ExtraPlanets_Blocks.kepler22bMapleLeaf, 1, 3);
		world.setBlock(x + 5, y + 8, z + 8, ExtraPlanets_Blocks.kepler22bMapleLeaf, 1, 3);
		world.setBlock(x + 6, y + 8, z + 8, ExtraPlanets_Blocks.kepler22bMapleLeaf, 1, 3);
		world.setBlock(x + 7, y + 8, z + 8, ExtraPlanets_Blocks.kepler22bMapleLeaf, 1, 3);
		world.setBlock(x + 8, y + 8, z + 8, ExtraPlanets_Blocks.kepler22bMapleLeaf, 1, 3);
		world.setBlock(x + 9, y + 8, z + 8, ExtraPlanets_Blocks.kepler22bMapleLeaf, 1, 3);
		world.setBlock(x + 11, y + 8, z + 8, ExtraPlanets_Blocks.kepler22bMapleLeaf, 1, 3);
		world.setBlock(x + 6, y + 8, z + 9, ExtraPlanets_Blocks.kepler22bMapleLeaf, 1, 3);
		world.setBlock(x + 7, y + 8, z + 9, ExtraPlanets_Blocks.kepler22bMapleLeaf, 1, 3);
		world.setBlock(x + 8, y + 8, z + 9, ExtraPlanets_Blocks.kepler22bMapleLeaf, 1, 3);
		world.setBlock(x + 6, y + 8, z + 11, ExtraPlanets_Blocks.kepler22bMapleLeaf, 1, 3);
		world.setBlock(x + 7, y + 8, z + 11, ExtraPlanets_Blocks.kepler22bMapleLeaf, 1, 3);
		world.setBlock(x + 8, y + 8, z + 11, ExtraPlanets_Blocks.kepler22bMapleLeaf, 1, 3);
		world.setBlock(x + 7, y + 9, z + 2, ExtraPlanets_Blocks.kepler22bMapleLeaf, 1, 3);
		world.setBlock(x + 6, y + 9, z + 3, ExtraPlanets_Blocks.kepler22bMapleLeaf, 1, 3);
		world.setBlock(x + 7, y + 9, z + 3, ExtraPlanets_Blocks.kepler22bMapleLog, 9, 3);
		world.setBlock(x + 8, y + 9, z + 3, ExtraPlanets_Blocks.kepler22bMapleLeaf, 1, 3);
		world.setBlock(x + 7, y + 9, z + 4, ExtraPlanets_Blocks.kepler22bMapleLog, 9, 3);
		world.setBlock(x + 6, y + 9, z + 5, ExtraPlanets_Blocks.kepler22bMapleLeaf, 1, 3);
		world.setBlock(x + 7, y + 9, z + 5, ExtraPlanets_Blocks.kepler22bMapleLog, 1, 3);
		world.setBlock(x + 8, y + 9, z + 5, ExtraPlanets_Blocks.kepler22bMapleLeaf, 1, 3);
		world.setBlock(x + 3, y + 9, z + 6, ExtraPlanets_Blocks.kepler22bMapleLeaf, 1, 3);
		world.setBlock(x + 5, y + 9, z + 6, ExtraPlanets_Blocks.kepler22bMapleLeaf, 1, 3);
		world.setBlock(x + 6, y + 9, z + 6, ExtraPlanets_Blocks.kepler22bMapleLeaf, 1, 3);
		world.setBlock(x + 7, y + 9, z + 6, ExtraPlanets_Blocks.kepler22bMapleLog, 1, 3);
		world.setBlock(x + 8, y + 9, z + 6, ExtraPlanets_Blocks.kepler22bMapleLeaf, 1, 3);
		world.setBlock(x + 9, y + 9, z + 6, ExtraPlanets_Blocks.kepler22bMapleLeaf, 1, 3);
		world.setBlock(x + 11, y + 9, z + 6, ExtraPlanets_Blocks.kepler22bMapleLeaf, 1, 3);
		world.setBlock(x + 2, y + 9, z + 7, ExtraPlanets_Blocks.kepler22bMapleLeaf, 1, 3);
		world.setBlock(x + 3, y + 9, z + 7, ExtraPlanets_Blocks.kepler22bMapleLog, 5, 3);
		world.setBlock(x + 4, y + 9, z + 7, ExtraPlanets_Blocks.kepler22bMapleLog, 5, 3);
		world.setBlock(x + 5, y + 9, z + 7, ExtraPlanets_Blocks.kepler22bMapleLog, 1, 3);
		world.setBlock(x + 6, y + 9, z + 7, ExtraPlanets_Blocks.kepler22bMapleLog, 1, 3);
		world.setBlock(x + 7, y + 9, z + 7, ExtraPlanets_Blocks.kepler22bMapleLog, 1, 3);
		world.setBlock(x + 8, y + 9, z + 7, ExtraPlanets_Blocks.kepler22bMapleLog, 1, 3);
		world.setBlock(x + 9, y + 9, z + 7, ExtraPlanets_Blocks.kepler22bMapleLog, 1, 3);
		world.setBlock(x + 10, y + 9, z + 7, ExtraPlanets_Blocks.kepler22bMapleLog, 5, 3);
		world.setBlock(x + 11, y + 9, z + 7, ExtraPlanets_Blocks.kepler22bMapleLog, 5, 3);
		world.setBlock(x + 12, y + 9, z + 7, ExtraPlanets_Blocks.kepler22bMapleLeaf, 1, 3);
		world.setBlock(x + 3, y + 9, z + 8, ExtraPlanets_Blocks.kepler22bMapleLeaf, 1, 3);
		world.setBlock(x + 5, y + 9, z + 8, ExtraPlanets_Blocks.kepler22bMapleLeaf, 1, 3);
		world.setBlock(x + 6, y + 9, z + 8, ExtraPlanets_Blocks.kepler22bMapleLeaf, 1, 3);
		world.setBlock(x + 7, y + 9, z + 8, ExtraPlanets_Blocks.kepler22bMapleLog, 1, 3);
		world.setBlock(x + 9, y + 9, z + 8, ExtraPlanets_Blocks.kepler22bMapleLeaf, 1, 3);
		world.setBlock(x + 11, y + 9, z + 8, ExtraPlanets_Blocks.kepler22bMapleLeaf, 1, 3);
		world.setBlock(x + 6, y + 9, z + 9, ExtraPlanets_Blocks.kepler22bMapleLeaf, 1, 3);
		world.setBlock(x + 7, y + 9, z + 9, ExtraPlanets_Blocks.kepler22bMapleLog, 1, 3);
		world.setBlock(x + 8, y + 9, z + 9, ExtraPlanets_Blocks.kepler22bMapleLeaf, 1, 3);
		world.setBlock(x + 7, y + 9, z + 10, ExtraPlanets_Blocks.kepler22bMapleLog, 9, 3);
		world.setBlock(x + 6, y + 9, z + 11, ExtraPlanets_Blocks.kepler22bMapleLeaf, 1, 3);
		world.setBlock(x + 7, y + 9, z + 11, ExtraPlanets_Blocks.kepler22bMapleLog, 9, 3);
		world.setBlock(x + 8, y + 9, z + 11, ExtraPlanets_Blocks.kepler22bMapleLeaf, 1, 3);
		world.setBlock(x + 7, y + 9, z + 12, ExtraPlanets_Blocks.kepler22bMapleLeaf, 1, 3);
		world.setBlock(x + 6, y + 10, z + 3, ExtraPlanets_Blocks.kepler22bMapleLeaf, 1, 3);
		world.setBlock(x + 7, y + 10, z + 3, ExtraPlanets_Blocks.kepler22bMapleLeaf, 1, 3);
		world.setBlock(x + 8, y + 10, z + 3, ExtraPlanets_Blocks.kepler22bMapleLeaf, 1, 3);
		world.setBlock(x + 6, y + 10, z + 5, ExtraPlanets_Blocks.kepler22bMapleLeaf, 1, 3);
		world.setBlock(x + 7, y + 10, z + 5, ExtraPlanets_Blocks.kepler22bMapleLeaf, 1, 3);
		world.setBlock(x + 8, y + 10, z + 5, ExtraPlanets_Blocks.kepler22bMapleLeaf, 1, 3);
		world.setBlock(x + 3, y + 10, z + 6, ExtraPlanets_Blocks.kepler22bMapleLeaf, 1, 3);
		world.setBlock(x + 5, y + 10, z + 6, ExtraPlanets_Blocks.kepler22bMapleLeaf, 1, 3);
		world.setBlock(x + 6, y + 10, z + 6, ExtraPlanets_Blocks.kepler22bMapleLeaf, 1, 3);
		world.setBlock(x + 8, y + 10, z + 6, ExtraPlanets_Blocks.kepler22bMapleLeaf, 1, 3);
		world.setBlock(x + 9, y + 10, z + 6, ExtraPlanets_Blocks.kepler22bMapleLeaf, 1, 3);
		world.setBlock(x + 11, y + 10, z + 6, ExtraPlanets_Blocks.kepler22bMapleLeaf, 1, 3);
		world.setBlock(x + 3, y + 10, z + 7, ExtraPlanets_Blocks.kepler22bMapleLeaf, 1, 3);
		world.setBlock(x + 5, y + 10, z + 7, ExtraPlanets_Blocks.kepler22bMapleLeaf, 1, 3);
		world.setBlock(x + 6, y + 10, z + 7, ExtraPlanets_Blocks.kepler22bMapleLeaf, 1, 3);
		world.setBlock(x + 7, y + 10, z + 7, ExtraPlanets_Blocks.kepler22bMapleLog, 1, 3);
		world.setBlock(x + 8, y + 10, z + 7, ExtraPlanets_Blocks.kepler22bMapleLeaf, 1, 3);
		world.setBlock(x + 9, y + 10, z + 7, ExtraPlanets_Blocks.kepler22bMapleLeaf, 1, 3);
		world.setBlock(x + 11, y + 10, z + 7, ExtraPlanets_Blocks.kepler22bMapleLeaf, 1, 3);
		world.setBlock(x + 3, y + 10, z + 8, ExtraPlanets_Blocks.kepler22bMapleLeaf, 1, 3);
		world.setBlock(x + 5, y + 10, z + 8, ExtraPlanets_Blocks.kepler22bMapleLeaf, 1, 3);
		world.setBlock(x + 8, y + 10, z + 8, ExtraPlanets_Blocks.kepler22bMapleLeaf, 1, 3);
		world.setBlock(x + 9, y + 10, z + 8, ExtraPlanets_Blocks.kepler22bMapleLeaf, 1, 3);
		world.setBlock(x + 11, y + 10, z + 8, ExtraPlanets_Blocks.kepler22bMapleLeaf, 1, 3);
		world.setBlock(x + 6, y + 10, z + 9, ExtraPlanets_Blocks.kepler22bMapleLeaf, 1, 3);
		world.setBlock(x + 7, y + 10, z + 9, ExtraPlanets_Blocks.kepler22bMapleLeaf, 1, 3);
		world.setBlock(x + 8, y + 10, z + 9, ExtraPlanets_Blocks.kepler22bMapleLeaf, 1, 3);
		world.setBlock(x + 6, y + 10, z + 11, ExtraPlanets_Blocks.kepler22bMapleLeaf, 1, 3);
		world.setBlock(x + 7, y + 10, z + 11, ExtraPlanets_Blocks.kepler22bMapleLeaf, 1, 3);
		world.setBlock(x + 8, y + 10, z + 11, ExtraPlanets_Blocks.kepler22bMapleLeaf, 1, 3);
		world.setBlock(x + 7, y + 11, z + 5, ExtraPlanets_Blocks.kepler22bMapleLeaf, 1, 3);
		world.setBlock(x + 6, y + 11, z + 6, ExtraPlanets_Blocks.kepler22bMapleLeaf, 1, 3);
		world.setBlock(x + 7, y + 11, z + 6, ExtraPlanets_Blocks.kepler22bMapleLeaf, 1, 3);
		world.setBlock(x + 8, y + 11, z + 6, ExtraPlanets_Blocks.kepler22bMapleLeaf, 1, 3);
		world.setBlock(x + 5, y + 11, z + 7, ExtraPlanets_Blocks.kepler22bMapleLeaf, 1, 3);
		world.setBlock(x + 6, y + 11, z + 7, ExtraPlanets_Blocks.kepler22bMapleLeaf, 1, 3);
		world.setBlock(x + 7, y + 11, z + 7, ExtraPlanets_Blocks.kepler22bMapleLog, 1, 3);
		world.setBlock(x + 8, y + 11, z + 7, ExtraPlanets_Blocks.kepler22bMapleLeaf, 1, 3);
		world.setBlock(x + 9, y + 11, z + 7, ExtraPlanets_Blocks.kepler22bMapleLeaf, 1, 3);
		world.setBlock(x + 6, y + 11, z + 8, ExtraPlanets_Blocks.kepler22bMapleLeaf, 1, 3);
		world.setBlock(x + 7, y + 11, z + 8, ExtraPlanets_Blocks.kepler22bMapleLeaf, 1, 3);
		world.setBlock(x + 8, y + 11, z + 8, ExtraPlanets_Blocks.kepler22bMapleLeaf, 1, 3);
		world.setBlock(x + 7, y + 11, z + 9, ExtraPlanets_Blocks.kepler22bMapleLeaf, 1, 3);
		world.setBlock(x + 7, y + 12, z + 5, ExtraPlanets_Blocks.kepler22bMapleLeaf, 1, 3);
		world.setBlock(x + 6, y + 12, z + 6, ExtraPlanets_Blocks.kepler22bMapleLeaf, 1, 3);
		world.setBlock(x + 7, y + 12, z + 6, ExtraPlanets_Blocks.kepler22bMapleLeaf, 1, 3);
		world.setBlock(x + 8, y + 12, z + 6, ExtraPlanets_Blocks.kepler22bMapleLeaf, 1, 3);
		world.setBlock(x + 5, y + 12, z + 7, ExtraPlanets_Blocks.kepler22bMapleLeaf, 1, 3);
		world.setBlock(x + 6, y + 12, z + 7, ExtraPlanets_Blocks.kepler22bMapleLeaf, 1, 3);
		world.setBlock(x + 7, y + 12, z + 7, ExtraPlanets_Blocks.kepler22bMapleLog, 1, 3);
		world.setBlock(x + 8, y + 12, z + 7, ExtraPlanets_Blocks.kepler22bMapleLeaf, 1, 3);
		world.setBlock(x + 9, y + 12, z + 7, ExtraPlanets_Blocks.kepler22bMapleLeaf, 1, 3);
		world.setBlock(x + 6, y + 12, z + 8, ExtraPlanets_Blocks.kepler22bMapleLeaf, 1, 3);
		world.setBlock(x + 7, y + 12, z + 8, ExtraPlanets_Blocks.kepler22bMapleLeaf, 1, 3);
		world.setBlock(x + 8, y + 12, z + 8, ExtraPlanets_Blocks.kepler22bMapleLeaf, 1, 3);
		world.setBlock(x + 7, y + 12, z + 9, ExtraPlanets_Blocks.kepler22bMapleLeaf, 1, 3);
		world.setBlock(x + 7, y + 13, z + 6, ExtraPlanets_Blocks.kepler22bMapleLeaf, 1, 3);
		world.setBlock(x + 6, y + 13, z + 7, ExtraPlanets_Blocks.kepler22bMapleLeaf, 1, 3);
		world.setBlock(x + 7, y + 13, z + 7, ExtraPlanets_Blocks.kepler22bMapleLog, 1, 3);
		world.setBlock(x + 8, y + 13, z + 7, ExtraPlanets_Blocks.kepler22bMapleLeaf, 1, 3);
		world.setBlock(x + 7, y + 13, z + 8, ExtraPlanets_Blocks.kepler22bMapleLeaf, 1, 3);
		world.setBlock(x + 7, y + 14, z + 7, ExtraPlanets_Blocks.kepler22bMapleLeaf, 1, 3);
		return true;

	}
}