package com.mjr.extraplanets.world.features;

import java.util.Random;

import net.minecraft.init.Blocks;
import net.minecraft.tileentity.TileEntityChest;
import net.minecraft.util.math.BlockPos;
import net.minecraft.world.World;
import net.minecraft.world.gen.feature.WorldGenerator;

import com.mjr.extraplanets.blocks.ExtraPlanets_Blocks;

public class WorldGenBasicHideout  extends WorldGenerator {

	public WorldGenBasicHideout() {

	}

	@Override
	public boolean generate(World world, Random rand, BlockPos position) {
		int x = position.getX();
		int y = position.getY();
		int z = position.getZ();
		for (int i = 0; i < 11; i++) {
			for (int j = 0; j < 11; j++) {
				try {
					if (world.getBlockState(new BlockPos(x + i, y - 3, z + j)).getBlock() == Blocks.AIR)
						return false;
				} catch (Exception ex) {
					System.out.println("ExtraPlanets: " + ex.getMessage());
				}
			}
		}
		for (int i = 0; i < 11; i++) {
			for (int j = 0; j < 11; j++) {
				for (int k = 0; k < 6; k++) {
					if (world.getBlockState(new BlockPos(x + i, (y + 2) + k, z + j)).getBlock() != Blocks.AIR)
						return false;
				}
			}
		}
		y = y - 1;
		if (!world.isAreaLoaded(new BlockPos(x + 10, y, z + 10), 10))
			return false;
		else {
			System.out.println("Spawning Basic Hideout at (x, y, z)" + x + " " + y + " " + z);
			generate_r0(world, rand, x, y, z);
			fillChests(world, rand, x, y, z);
		}
		return true;
	}

	public boolean generate_r0(World world, Random rand, int x, int y, int z) {

		world.setBlockState(new BlockPos(x + 5, y + 0, z + 0), ExtraPlanets_Blocks.jupiterBlocks.getStateFromMeta(8), 3);
		world.setBlockState(new BlockPos(x + 6, y + 0, z + 0), ExtraPlanets_Blocks.jupiterBlocks.getStateFromMeta(8), 3);
		world.setBlockState(new BlockPos(x + 7, y + 0, z + 0), ExtraPlanets_Blocks.jupiterBlocks.getStateFromMeta(8), 3);
		world.setBlockState(new BlockPos(x + 1, y + 0, z + 1), ExtraPlanets_Blocks.jupiterBlocks.getStateFromMeta(8), 3);
		world.setBlockState(new BlockPos(x + 2, y + 0, z + 1), ExtraPlanets_Blocks.jupiterBlocks.getStateFromMeta(8), 3);
		world.setBlockState(new BlockPos(x + 3, y + 0, z + 1), ExtraPlanets_Blocks.jupiterBlocks.getStateFromMeta(8), 3);
		world.setBlockState(new BlockPos(x + 4, y + 0, z + 1), ExtraPlanets_Blocks.jupiterBlocks.getStateFromMeta(8), 3);
		world.setBlockState(new BlockPos(x + 5, y + 0, z + 1), ExtraPlanets_Blocks.jupiterBlocks.getStateFromMeta(8), 3);
		world.setBlockState(new BlockPos(x + 6, y + 0, z + 1), ExtraPlanets_Blocks.jupiterBlocks.getStateFromMeta(8), 3);
		world.setBlockState(new BlockPos(x + 7, y + 0, z + 1), ExtraPlanets_Blocks.jupiterBlocks.getStateFromMeta(8), 3);
		world.setBlockState(new BlockPos(x + 8, y + 0, z + 1), ExtraPlanets_Blocks.jupiterBlocks.getStateFromMeta(8), 3);
		world.setBlockState(new BlockPos(x + 9, y + 0, z + 1), ExtraPlanets_Blocks.jupiterBlocks.getStateFromMeta(8), 3);
		world.setBlockState(new BlockPos(x + 10, y + 0, z + 1), ExtraPlanets_Blocks.jupiterBlocks.getStateFromMeta(8), 3);
		world.setBlockState(new BlockPos(x + 11, y + 0, z + 1), ExtraPlanets_Blocks.jupiterBlocks.getStateFromMeta(8), 3);
		world.setBlockState(new BlockPos(x + 0, y + 0, z + 2), ExtraPlanets_Blocks.jupiterBlocks.getStateFromMeta(8), 3);
		world.setBlockState(new BlockPos(x + 1, y + 0, z + 2), ExtraPlanets_Blocks.jupiterBlocks.getStateFromMeta(8), 3);
		world.setBlockState(new BlockPos(x + 2, y + 0, z + 2), ExtraPlanets_Blocks.jupiterBlocks.getStateFromMeta(8), 3);
		world.setBlockState(new BlockPos(x + 3, y + 0, z + 2), ExtraPlanets_Blocks.jupiterBlocks.getStateFromMeta(8), 3);
		world.setBlockState(new BlockPos(x + 4, y + 0, z + 2), ExtraPlanets_Blocks.jupiterBlocks.getStateFromMeta(8), 3);
		world.setBlockState(new BlockPos(x + 5, y + 0, z + 2), ExtraPlanets_Blocks.jupiterBlocks.getStateFromMeta(8), 3);
		world.setBlockState(new BlockPos(x + 6, y + 0, z + 2), ExtraPlanets_Blocks.jupiterBlocks.getStateFromMeta(8), 3);
		world.setBlockState(new BlockPos(x + 7, y + 0, z + 2), ExtraPlanets_Blocks.jupiterBlocks.getStateFromMeta(8), 3);
		world.setBlockState(new BlockPos(x + 8, y + 0, z + 2), ExtraPlanets_Blocks.jupiterBlocks.getStateFromMeta(8), 3);
		world.setBlockState(new BlockPos(x + 9, y + 0, z + 2), ExtraPlanets_Blocks.jupiterBlocks.getStateFromMeta(8), 3);
		world.setBlockState(new BlockPos(x + 10, y + 0, z + 2), ExtraPlanets_Blocks.jupiterBlocks.getStateFromMeta(8), 3);
		world.setBlockState(new BlockPos(x + 11, y + 0, z + 2), ExtraPlanets_Blocks.jupiterBlocks.getStateFromMeta(8), 3);
		world.setBlockState(new BlockPos(x + 12, y + 0, z + 2), ExtraPlanets_Blocks.jupiterBlocks.getStateFromMeta(8), 3);
		world.setBlockState(new BlockPos(x + 0, y + 0, z + 3), ExtraPlanets_Blocks.jupiterBlocks.getStateFromMeta(8), 3);
		world.setBlockState(new BlockPos(x + 1, y + 0, z + 3), ExtraPlanets_Blocks.jupiterBlocks.getStateFromMeta(8), 3);
		world.setBlockState(new BlockPos(x + 2, y + 0, z + 3), ExtraPlanets_Blocks.jupiterBlocks.getStateFromMeta(8), 3);
		world.setBlockState(new BlockPos(x + 3, y + 0, z + 3), ExtraPlanets_Blocks.jupiterBlocks.getStateFromMeta(8), 3);
		world.setBlockState(new BlockPos(x + 4, y + 0, z + 3), ExtraPlanets_Blocks.jupiterBlocks.getStateFromMeta(8), 3);
		world.setBlockState(new BlockPos(x + 5, y + 0, z + 3), ExtraPlanets_Blocks.jupiterBlocks.getStateFromMeta(8), 3);
		world.setBlockState(new BlockPos(x + 6, y + 0, z + 3), ExtraPlanets_Blocks.jupiterBlocks.getStateFromMeta(8), 3);
		world.setBlockState(new BlockPos(x + 7, y + 0, z + 3), ExtraPlanets_Blocks.jupiterBlocks.getStateFromMeta(8), 3);
		world.setBlockState(new BlockPos(x + 8, y + 0, z + 3), ExtraPlanets_Blocks.jupiterBlocks.getStateFromMeta(8), 3);
		world.setBlockState(new BlockPos(x + 9, y + 0, z + 3), ExtraPlanets_Blocks.jupiterBlocks.getStateFromMeta(8), 3);
		world.setBlockState(new BlockPos(x + 10, y + 0, z + 3), ExtraPlanets_Blocks.jupiterBlocks.getStateFromMeta(8), 3);
		world.setBlockState(new BlockPos(x + 11, y + 0, z + 3), ExtraPlanets_Blocks.jupiterBlocks.getStateFromMeta(8), 3);
		world.setBlockState(new BlockPos(x + 12, y + 0, z + 3), ExtraPlanets_Blocks.jupiterBlocks.getStateFromMeta(8), 3);
		world.setBlockState(new BlockPos(x + 0, y + 0, z + 4), ExtraPlanets_Blocks.jupiterBlocks.getStateFromMeta(8), 3);
		world.setBlockState(new BlockPos(x + 1, y + 0, z + 4), ExtraPlanets_Blocks.jupiterBlocks.getStateFromMeta(8), 3);
		world.setBlockState(new BlockPos(x + 2, y + 0, z + 4), ExtraPlanets_Blocks.jupiterBlocks.getStateFromMeta(8), 3);
		world.setBlockState(new BlockPos(x + 3, y + 0, z + 4), ExtraPlanets_Blocks.jupiterBlocks.getStateFromMeta(8), 3);
		world.setBlockState(new BlockPos(x + 4, y + 0, z + 4), ExtraPlanets_Blocks.jupiterBlocks.getStateFromMeta(8), 3);
		world.setBlockState(new BlockPos(x + 5, y + 0, z + 4), ExtraPlanets_Blocks.jupiterBlocks.getStateFromMeta(8), 3);
		world.setBlockState(new BlockPos(x + 6, y + 0, z + 4), ExtraPlanets_Blocks.jupiterBlocks.getStateFromMeta(8), 3);
		world.setBlockState(new BlockPos(x + 7, y + 0, z + 4), ExtraPlanets_Blocks.jupiterBlocks.getStateFromMeta(8), 3);
		world.setBlockState(new BlockPos(x + 8, y + 0, z + 4), ExtraPlanets_Blocks.jupiterBlocks.getStateFromMeta(8), 3);
		world.setBlockState(new BlockPos(x + 9, y + 0, z + 4), ExtraPlanets_Blocks.jupiterBlocks.getStateFromMeta(8), 3);
		world.setBlockState(new BlockPos(x + 10, y + 0, z + 4), ExtraPlanets_Blocks.jupiterBlocks.getStateFromMeta(8), 3);
		world.setBlockState(new BlockPos(x + 11, y + 0, z + 4), ExtraPlanets_Blocks.jupiterBlocks.getStateFromMeta(8), 3);
		world.setBlockState(new BlockPos(x + 12, y + 0, z + 4), ExtraPlanets_Blocks.jupiterBlocks.getStateFromMeta(8), 3);
		world.setBlockState(new BlockPos(x + 13, y + 0, z + 4), ExtraPlanets_Blocks.jupiterBlocks.getStateFromMeta(8), 3);
		world.setBlockState(new BlockPos(x + 0, y + 0, z + 5), ExtraPlanets_Blocks.jupiterBlocks.getStateFromMeta(8), 3);
		world.setBlockState(new BlockPos(x + 1, y + 0, z + 5), ExtraPlanets_Blocks.jupiterBlocks.getStateFromMeta(8), 3);
		world.setBlockState(new BlockPos(x + 2, y + 0, z + 5), ExtraPlanets_Blocks.jupiterBlocks.getStateFromMeta(8), 3);
		world.setBlockState(new BlockPos(x + 3, y + 0, z + 5), ExtraPlanets_Blocks.jupiterBlocks.getStateFromMeta(8), 3);
		world.setBlockState(new BlockPos(x + 4, y + 0, z + 5), ExtraPlanets_Blocks.jupiterBlocks.getStateFromMeta(8), 3);
		world.setBlockState(new BlockPos(x + 5, y + 0, z + 5), ExtraPlanets_Blocks.jupiterBlocks.getStateFromMeta(8), 3);
		world.setBlockState(new BlockPos(x + 6, y + 0, z + 5), ExtraPlanets_Blocks.jupiterBlocks.getStateFromMeta(8), 3);
		world.setBlockState(new BlockPos(x + 7, y + 0, z + 5), ExtraPlanets_Blocks.jupiterBlocks.getStateFromMeta(8), 3);
		world.setBlockState(new BlockPos(x + 8, y + 0, z + 5), ExtraPlanets_Blocks.jupiterBlocks.getStateFromMeta(8), 3);
		world.setBlockState(new BlockPos(x + 9, y + 0, z + 5), ExtraPlanets_Blocks.jupiterBlocks.getStateFromMeta(8), 3);
		world.setBlockState(new BlockPos(x + 10, y + 0, z + 5), ExtraPlanets_Blocks.jupiterBlocks.getStateFromMeta(8), 3);
		world.setBlockState(new BlockPos(x + 11, y + 0, z + 5), ExtraPlanets_Blocks.jupiterBlocks.getStateFromMeta(8), 3);
		world.setBlockState(new BlockPos(x + 12, y + 0, z + 5), ExtraPlanets_Blocks.jupiterBlocks.getStateFromMeta(8), 3);
		world.setBlockState(new BlockPos(x + 13, y + 0, z + 5), ExtraPlanets_Blocks.jupiterBlocks.getStateFromMeta(8), 3);
		world.setBlockState(new BlockPos(x + 0, y + 0, z + 6), ExtraPlanets_Blocks.jupiterBlocks.getStateFromMeta(8), 3);
		world.setBlockState(new BlockPos(x + 1, y + 0, z + 6), ExtraPlanets_Blocks.jupiterBlocks.getStateFromMeta(8), 3);
		world.setBlockState(new BlockPos(x + 2, y + 0, z + 6), ExtraPlanets_Blocks.jupiterBlocks.getStateFromMeta(8), 3);
		world.setBlockState(new BlockPos(x + 3, y + 0, z + 6), ExtraPlanets_Blocks.jupiterBlocks.getStateFromMeta(8), 3);
		world.setBlockState(new BlockPos(x + 4, y + 0, z + 6), ExtraPlanets_Blocks.jupiterBlocks.getStateFromMeta(8), 3);
		world.setBlockState(new BlockPos(x + 5, y + 0, z + 6), ExtraPlanets_Blocks.jupiterBlocks.getStateFromMeta(8), 3);
		world.setBlockState(new BlockPos(x + 6, y + 0, z + 6), ExtraPlanets_Blocks.jupiterBlocks.getStateFromMeta(8), 3);
		world.setBlockState(new BlockPos(x + 7, y + 0, z + 6), ExtraPlanets_Blocks.jupiterBlocks.getStateFromMeta(8), 3);
		world.setBlockState(new BlockPos(x + 8, y + 0, z + 6), ExtraPlanets_Blocks.jupiterBlocks.getStateFromMeta(8), 3);
		world.setBlockState(new BlockPos(x + 9, y + 0, z + 6), ExtraPlanets_Blocks.jupiterBlocks.getStateFromMeta(8), 3);
		world.setBlockState(new BlockPos(x + 10, y + 0, z + 6), ExtraPlanets_Blocks.jupiterBlocks.getStateFromMeta(8), 3);
		world.setBlockState(new BlockPos(x + 11, y + 0, z + 6), ExtraPlanets_Blocks.jupiterBlocks.getStateFromMeta(8), 3);
		world.setBlockState(new BlockPos(x + 12, y + 0, z + 6), ExtraPlanets_Blocks.jupiterBlocks.getStateFromMeta(8), 3);
		world.setBlockState(new BlockPos(x + 13, y + 0, z + 6), ExtraPlanets_Blocks.jupiterBlocks.getStateFromMeta(8), 3);
		world.setBlockState(new BlockPos(x + 0, y + 0, z + 7), ExtraPlanets_Blocks.jupiterBlocks.getStateFromMeta(8), 3);
		world.setBlockState(new BlockPos(x + 1, y + 0, z + 7), ExtraPlanets_Blocks.jupiterBlocks.getStateFromMeta(8), 3);
		world.setBlockState(new BlockPos(x + 2, y + 0, z + 7), ExtraPlanets_Blocks.jupiterBlocks.getStateFromMeta(8), 3);
		world.setBlockState(new BlockPos(x + 3, y + 0, z + 7), ExtraPlanets_Blocks.jupiterBlocks.getStateFromMeta(8), 3);
		world.setBlockState(new BlockPos(x + 4, y + 0, z + 7), ExtraPlanets_Blocks.jupiterBlocks.getStateFromMeta(8), 3);
		world.setBlockState(new BlockPos(x + 5, y + 0, z + 7), ExtraPlanets_Blocks.jupiterBlocks.getStateFromMeta(8), 3);
		world.setBlockState(new BlockPos(x + 6, y + 0, z + 7), ExtraPlanets_Blocks.jupiterBlocks.getStateFromMeta(8), 3);
		world.setBlockState(new BlockPos(x + 7, y + 0, z + 7), ExtraPlanets_Blocks.jupiterBlocks.getStateFromMeta(8), 3);
		world.setBlockState(new BlockPos(x + 8, y + 0, z + 7), ExtraPlanets_Blocks.jupiterBlocks.getStateFromMeta(8), 3);
		world.setBlockState(new BlockPos(x + 9, y + 0, z + 7), ExtraPlanets_Blocks.jupiterBlocks.getStateFromMeta(8), 3);
		world.setBlockState(new BlockPos(x + 10, y + 0, z + 7), ExtraPlanets_Blocks.jupiterBlocks.getStateFromMeta(8), 3);
		world.setBlockState(new BlockPos(x + 11, y + 0, z + 7), ExtraPlanets_Blocks.jupiterBlocks.getStateFromMeta(8), 3);
		world.setBlockState(new BlockPos(x + 12, y + 0, z + 7), ExtraPlanets_Blocks.jupiterBlocks.getStateFromMeta(8), 3);
		world.setBlockState(new BlockPos(x + 13, y + 0, z + 7), ExtraPlanets_Blocks.jupiterBlocks.getStateFromMeta(8), 3);
		world.setBlockState(new BlockPos(x + 0, y + 0, z + 8), ExtraPlanets_Blocks.jupiterBlocks.getStateFromMeta(8), 3);
		world.setBlockState(new BlockPos(x + 1, y + 0, z + 8), ExtraPlanets_Blocks.jupiterBlocks.getStateFromMeta(8), 3);
		world.setBlockState(new BlockPos(x + 2, y + 0, z + 8), ExtraPlanets_Blocks.jupiterBlocks.getStateFromMeta(8), 3);
		world.setBlockState(new BlockPos(x + 3, y + 0, z + 8), ExtraPlanets_Blocks.jupiterBlocks.getStateFromMeta(8), 3);
		world.setBlockState(new BlockPos(x + 4, y + 0, z + 8), ExtraPlanets_Blocks.jupiterBlocks.getStateFromMeta(8), 3);
		world.setBlockState(new BlockPos(x + 5, y + 0, z + 8), ExtraPlanets_Blocks.jupiterBlocks.getStateFromMeta(8), 3);
		world.setBlockState(new BlockPos(x + 6, y + 0, z + 8), ExtraPlanets_Blocks.jupiterBlocks.getStateFromMeta(8), 3);
		world.setBlockState(new BlockPos(x + 7, y + 0, z + 8), ExtraPlanets_Blocks.jupiterBlocks.getStateFromMeta(8), 3);
		world.setBlockState(new BlockPos(x + 8, y + 0, z + 8), ExtraPlanets_Blocks.jupiterBlocks.getStateFromMeta(8), 3);
		world.setBlockState(new BlockPos(x + 9, y + 0, z + 8), ExtraPlanets_Blocks.jupiterBlocks.getStateFromMeta(8), 3);
		world.setBlockState(new BlockPos(x + 10, y + 0, z + 8), ExtraPlanets_Blocks.jupiterBlocks.getStateFromMeta(8), 3);
		world.setBlockState(new BlockPos(x + 11, y + 0, z + 8), ExtraPlanets_Blocks.jupiterBlocks.getStateFromMeta(8), 3);
		world.setBlockState(new BlockPos(x + 12, y + 0, z + 8), ExtraPlanets_Blocks.jupiterBlocks.getStateFromMeta(8), 3);
		world.setBlockState(new BlockPos(x + 0, y + 0, z + 9), ExtraPlanets_Blocks.jupiterBlocks.getStateFromMeta(8), 3);
		world.setBlockState(new BlockPos(x + 1, y + 0, z + 9), ExtraPlanets_Blocks.jupiterBlocks.getStateFromMeta(8), 3);
		world.setBlockState(new BlockPos(x + 2, y + 0, z + 9), ExtraPlanets_Blocks.jupiterBlocks.getStateFromMeta(8), 3);
		world.setBlockState(new BlockPos(x + 3, y + 0, z + 9), ExtraPlanets_Blocks.jupiterBlocks.getStateFromMeta(8), 3);
		world.setBlockState(new BlockPos(x + 4, y + 0, z + 9), ExtraPlanets_Blocks.jupiterBlocks.getStateFromMeta(8), 3);
		world.setBlockState(new BlockPos(x + 5, y + 0, z + 9), ExtraPlanets_Blocks.jupiterBlocks.getStateFromMeta(8), 3);
		world.setBlockState(new BlockPos(x + 6, y + 0, z + 9), ExtraPlanets_Blocks.jupiterBlocks.getStateFromMeta(8), 3);
		world.setBlockState(new BlockPos(x + 7, y + 0, z + 9), ExtraPlanets_Blocks.jupiterBlocks.getStateFromMeta(8), 3);
		world.setBlockState(new BlockPos(x + 8, y + 0, z + 9), ExtraPlanets_Blocks.jupiterBlocks.getStateFromMeta(8), 3);
		world.setBlockState(new BlockPos(x + 9, y + 0, z + 9), ExtraPlanets_Blocks.jupiterBlocks.getStateFromMeta(8), 3);
		world.setBlockState(new BlockPos(x + 10, y + 0, z + 9), ExtraPlanets_Blocks.jupiterBlocks.getStateFromMeta(8), 3);
		world.setBlockState(new BlockPos(x + 11, y + 0, z + 9), ExtraPlanets_Blocks.jupiterBlocks.getStateFromMeta(8), 3);
		world.setBlockState(new BlockPos(x + 12, y + 0, z + 9), ExtraPlanets_Blocks.jupiterBlocks.getStateFromMeta(8), 3);
		world.setBlockState(new BlockPos(x + 1, y + 0, z + 10), ExtraPlanets_Blocks.jupiterBlocks.getStateFromMeta(8), 3);
		world.setBlockState(new BlockPos(x + 2, y + 0, z + 10), ExtraPlanets_Blocks.jupiterBlocks.getStateFromMeta(8), 3);
		world.setBlockState(new BlockPos(x + 3, y + 0, z + 10), ExtraPlanets_Blocks.jupiterBlocks.getStateFromMeta(8), 3);
		world.setBlockState(new BlockPos(x + 4, y + 0, z + 10), ExtraPlanets_Blocks.jupiterBlocks.getStateFromMeta(8), 3);
		world.setBlockState(new BlockPos(x + 5, y + 0, z + 10), ExtraPlanets_Blocks.jupiterBlocks.getStateFromMeta(8), 3);
		world.setBlockState(new BlockPos(x + 6, y + 0, z + 10), ExtraPlanets_Blocks.jupiterBlocks.getStateFromMeta(8), 3);
		world.setBlockState(new BlockPos(x + 7, y + 0, z + 10), ExtraPlanets_Blocks.jupiterBlocks.getStateFromMeta(8), 3);
		world.setBlockState(new BlockPos(x + 8, y + 0, z + 10), ExtraPlanets_Blocks.jupiterBlocks.getStateFromMeta(8), 3);
		world.setBlockState(new BlockPos(x + 9, y + 0, z + 10), ExtraPlanets_Blocks.jupiterBlocks.getStateFromMeta(8), 3);
		world.setBlockState(new BlockPos(x + 10, y + 0, z + 10), ExtraPlanets_Blocks.jupiterBlocks.getStateFromMeta(8), 3);
		world.setBlockState(new BlockPos(x + 11, y + 0, z + 10), ExtraPlanets_Blocks.jupiterBlocks.getStateFromMeta(8), 3);
		world.setBlockState(new BlockPos(x + 5, y + 0, z + 11), ExtraPlanets_Blocks.jupiterBlocks.getStateFromMeta(8), 3);
		world.setBlockState(new BlockPos(x + 6, y + 0, z + 11), ExtraPlanets_Blocks.jupiterBlocks.getStateFromMeta(8), 3);
		world.setBlockState(new BlockPos(x + 7, y + 0, z + 11), ExtraPlanets_Blocks.jupiterBlocks.getStateFromMeta(8), 3);
		world.setBlockState(new BlockPos(x + 5, y + 1, z + 0), ExtraPlanets_Blocks.jupiterBlocks.getStateFromMeta(11), 3);
		world.setBlockState(new BlockPos(x + 6, y + 1, z + 0), ExtraPlanets_Blocks.jupiterBlocks.getStateFromMeta(11), 3);
		world.setBlockState(new BlockPos(x + 7, y + 1, z + 0), ExtraPlanets_Blocks.jupiterBlocks.getStateFromMeta(11), 3);
		world.setBlockState(new BlockPos(x + 1, y + 1, z + 1), ExtraPlanets_Blocks.jupiterBlocks.getStateFromMeta(11), 3);
		world.setBlockState(new BlockPos(x + 2, y + 1, z + 1), ExtraPlanets_Blocks.jupiterBlocks.getStateFromMeta(11), 3);
		world.setBlockState(new BlockPos(x + 3, y + 1, z + 1), ExtraPlanets_Blocks.jupiterBlocks.getStateFromMeta(11), 3);
		world.setBlockState(new BlockPos(x + 4, y + 1, z + 1), ExtraPlanets_Blocks.jupiterBlocks.getStateFromMeta(11), 3);
		world.setBlockState(new BlockPos(x + 5, y + 1, z + 1), Blocks.AIR.getDefaultState(), 3);
		world.setBlockState(new BlockPos(x + 6, y + 1, z + 1), Blocks.CHEST.getStateFromMeta(3), 3);
		world.setBlockState(new BlockPos(x + 7, y + 1, z + 1), Blocks.AIR.getDefaultState(), 3);
		world.setBlockState(new BlockPos(x + 8, y + 1, z + 1), ExtraPlanets_Blocks.jupiterBlocks.getStateFromMeta(11), 3);
		world.setBlockState(new BlockPos(x + 9, y + 1, z + 1), ExtraPlanets_Blocks.jupiterBlocks.getStateFromMeta(11), 3);
		world.setBlockState(new BlockPos(x + 10, y + 1, z + 1), ExtraPlanets_Blocks.jupiterBlocks.getStateFromMeta(11), 3);
		world.setBlockState(new BlockPos(x + 11, y + 1, z + 1), ExtraPlanets_Blocks.jupiterBlocks.getStateFromMeta(11), 3);
		world.setBlockState(new BlockPos(x + 0, y + 1, z + 2), ExtraPlanets_Blocks.jupiterBlocks.getStateFromMeta(11), 3);
		world.setBlockState(new BlockPos(x + 1, y + 1, z + 2), Blocks.AIR.getDefaultState(), 3);
		world.setBlockState(new BlockPos(x + 2, y + 1, z + 2), Blocks.AIR.getDefaultState(), 3);
		world.setBlockState(new BlockPos(x + 3, y + 1, z + 2), Blocks.AIR.getDefaultState(), 3);
		world.setBlockState(new BlockPos(x + 4, y + 1, z + 2), Blocks.AIR.getDefaultState(), 3);
		world.setBlockState(new BlockPos(x + 5, y + 1, z + 2), Blocks.AIR.getDefaultState(), 3);
		world.setBlockState(new BlockPos(x + 6, y + 1, z + 2), Blocks.AIR.getDefaultState(), 3);
		world.setBlockState(new BlockPos(x + 7, y + 1, z + 2), Blocks.AIR.getDefaultState(), 3);
		world.setBlockState(new BlockPos(x + 8, y + 1, z + 2), Blocks.AIR.getDefaultState(), 3);
		world.setBlockState(new BlockPos(x + 9, y + 1, z + 2), Blocks.AIR.getDefaultState(), 3);
		world.setBlockState(new BlockPos(x + 10, y + 1, z + 2), Blocks.AIR.getDefaultState(), 3);
		world.setBlockState(new BlockPos(x + 11, y + 1, z + 2), Blocks.JUKEBOX.getDefaultState(), 3);
		world.setBlockState(new BlockPos(x + 12, y + 1, z + 2), ExtraPlanets_Blocks.jupiterBlocks.getStateFromMeta(11), 3);
		world.setBlockState(new BlockPos(x + 0, y + 1, z + 3), ExtraPlanets_Blocks.jupiterBlocks.getStateFromMeta(11), 3);
		world.setBlockState(new BlockPos(x + 1, y + 1, z + 3), Blocks.AIR.getDefaultState(), 3);
		world.setBlockState(new BlockPos(x + 2, y + 1, z + 3), Blocks.QUARTZ_STAIRS.getStateFromMeta(3), 3);
		world.setBlockState(new BlockPos(x + 3, y + 1, z + 3), Blocks.QUARTZ_STAIRS.getStateFromMeta(3), 3);
		world.setBlockState(new BlockPos(x + 4, y + 1, z + 3), Blocks.AIR.getDefaultState(), 3);
		world.setBlockState(new BlockPos(x + 5, y + 1, z + 3), Blocks.AIR.getDefaultState(), 3);
		world.setBlockState(new BlockPos(x + 6, y + 1, z + 3), Blocks.AIR.getDefaultState(), 3);
		world.setBlockState(new BlockPos(x + 7, y + 1, z + 3), Blocks.AIR.getDefaultState(), 3);
		world.setBlockState(new BlockPos(x + 8, y + 1, z + 3), Blocks.AIR.getDefaultState(), 3);
		world.setBlockState(new BlockPos(x + 9, y + 1, z + 3), Blocks.AIR.getDefaultState(), 3);
		world.setBlockState(new BlockPos(x + 10, y + 1, z + 3), Blocks.AIR.getDefaultState(), 3);
		world.setBlockState(new BlockPos(x + 11, y + 1, z + 3), Blocks.AIR.getDefaultState(), 3);
		world.setBlockState(new BlockPos(x + 12, y + 1, z + 3), ExtraPlanets_Blocks.jupiterBlocks.getStateFromMeta(11), 3);
		world.setBlockState(new BlockPos(x + 0, y + 1, z + 4), ExtraPlanets_Blocks.jupiterBlocks.getStateFromMeta(11), 3);
		world.setBlockState(new BlockPos(x + 1, y + 1, z + 4), Blocks.AIR.getDefaultState(), 3);
		world.setBlockState(new BlockPos(x + 2, y + 1, z + 4), Blocks.AIR.getDefaultState(), 3);
		world.setBlockState(new BlockPos(x + 3, y + 1, z + 4), Blocks.AIR.getDefaultState(), 3);
		world.setBlockState(new BlockPos(x + 4, y + 1, z + 4), Blocks.AIR.getDefaultState(), 3);
		world.setBlockState(new BlockPos(x + 5, y + 1, z + 4), Blocks.AIR.getDefaultState(), 3);
		world.setBlockState(new BlockPos(x + 6, y + 1, z + 4), Blocks.CHEST.getStateFromMeta(4), 3);
		world.setBlockState(new BlockPos(x + 7, y + 1, z + 4), ExtraPlanets_Blocks.jupiterBlocks.getStateFromMeta(11), 3);
		world.setBlockState(new BlockPos(x + 8, y + 1, z + 4), Blocks.OAK_STAIRS.getStateFromMeta(5), 3);
		world.setBlockState(new BlockPos(x + 9, y + 1, z + 4), Blocks.AIR.getDefaultState(), 3);
		world.setBlockState(new BlockPos(x + 10, y + 1, z + 4), Blocks.AIR.getDefaultState(), 3);
		world.setBlockState(new BlockPos(x + 11, y + 1, z + 4), Blocks.AIR.getDefaultState(), 3);
		world.setBlockState(new BlockPos(x + 12, y + 1, z + 4), Blocks.AIR.getDefaultState(), 3);
		world.setBlockState(new BlockPos(x + 13, y + 1, z + 4), ExtraPlanets_Blocks.jupiterBlocks.getStateFromMeta(11), 3);
		world.setBlockState(new BlockPos(x + 0, y + 1, z + 5), ExtraPlanets_Blocks.jupiterBlocks.getStateFromMeta(11), 3);
		world.setBlockState(new BlockPos(x + 1, y + 1, z + 5), Blocks.AIR.getDefaultState(), 3);
		world.setBlockState(new BlockPos(x + 2, y + 1, z + 5), Blocks.STONE_SLAB.getStateFromMeta(7), 3);
		world.setBlockState(new BlockPos(x + 3, y + 1, z + 5), Blocks.STONE_SLAB.getStateFromMeta(7), 3);
		world.setBlockState(new BlockPos(x + 4, y + 1, z + 5), Blocks.AIR.getDefaultState(), 3);
		world.setBlockState(new BlockPos(x + 5, y + 1, z + 5), Blocks.AIR.getDefaultState(), 3);
		world.setBlockState(new BlockPos(x + 6, y + 1, z + 5), Blocks.FURNACE.getStateFromMeta(4), 3);
		world.setBlockState(new BlockPos(x + 7, y + 1, z + 5), ExtraPlanets_Blocks.jupiterBlocks.getStateFromMeta(11), 3);
		world.setBlockState(new BlockPos(x + 8, y + 1, z + 5), Blocks.BED.getStateFromMeta(9), 3);
		world.setBlockState(new BlockPos(x + 9, y + 1, z + 5), Blocks.BED.getStateFromMeta(1), 3);
		world.setBlockState(new BlockPos(x + 10, y + 1, z + 5), Blocks.AIR.getDefaultState(), 3);
		world.setBlockState(new BlockPos(x + 11, y + 1, z + 5), Blocks.AIR.getDefaultState(), 3);
		world.setBlockState(new BlockPos(x + 12, y + 1, z + 5), Blocks.AIR.getDefaultState(), 3);
		world.setBlockState(new BlockPos(x + 13, y + 1, z + 5), Blocks.AIR.getDefaultState(), 3);
		world.setBlockState(new BlockPos(x + 0, y + 1, z + 6), ExtraPlanets_Blocks.jupiterBlocks.getStateFromMeta(11), 3);
		world.setBlockState(new BlockPos(x + 1, y + 1, z + 6), Blocks.AIR.getDefaultState(), 3);
		world.setBlockState(new BlockPos(x + 2, y + 1, z + 6), Blocks.STONE_SLAB.getStateFromMeta(7), 3);
		world.setBlockState(new BlockPos(x + 3, y + 1, z + 6), Blocks.STONE_SLAB.getStateFromMeta(7), 3);
		world.setBlockState(new BlockPos(x + 4, y + 1, z + 6), Blocks.AIR.getDefaultState(), 3);
		world.setBlockState(new BlockPos(x + 5, y + 1, z + 6), Blocks.AIR.getDefaultState(), 3);
		world.setBlockState(new BlockPos(x + 6, y + 1, z + 6), Blocks.FURNACE.getStateFromMeta(4), 3);
		world.setBlockState(new BlockPos(x + 7, y + 1, z + 6), ExtraPlanets_Blocks.jupiterBlocks.getStateFromMeta(11), 3);
		world.setBlockState(new BlockPos(x + 8, y + 1, z + 6), Blocks.BED.getStateFromMeta(9), 3);
		world.setBlockState(new BlockPos(x + 9, y + 1, z + 6), Blocks.BED.getStateFromMeta(1), 3);
		world.setBlockState(new BlockPos(x + 10, y + 1, z + 6), Blocks.AIR.getDefaultState(), 3);
		world.setBlockState(new BlockPos(x + 11, y + 1, z + 6), Blocks.AIR.getDefaultState(), 3);
		world.setBlockState(new BlockPos(x + 12, y + 1, z + 6), Blocks.AIR.getDefaultState(), 3);
		world.setBlockState(new BlockPos(x + 13, y + 1, z + 6), Blocks.AIR.getDefaultState(), 3);
		world.setBlockState(new BlockPos(x + 0, y + 1, z + 7), ExtraPlanets_Blocks.jupiterBlocks.getStateFromMeta(11), 3);
		world.setBlockState(new BlockPos(x + 1, y + 1, z + 7), Blocks.AIR.getDefaultState(), 3);
		world.setBlockState(new BlockPos(x + 2, y + 1, z + 7), Blocks.AIR.getDefaultState(), 3);
		world.setBlockState(new BlockPos(x + 3, y + 1, z + 7), Blocks.AIR.getDefaultState(), 3);
		world.setBlockState(new BlockPos(x + 4, y + 1, z + 7), Blocks.AIR.getDefaultState(), 3);
		world.setBlockState(new BlockPos(x + 5, y + 1, z + 7), Blocks.AIR.getDefaultState(), 3);
		world.setBlockState(new BlockPos(x + 6, y + 1, z + 7), Blocks.CHEST.getStateFromMeta(4), 3);
		world.setBlockState(new BlockPos(x + 7, y + 1, z + 7), ExtraPlanets_Blocks.jupiterBlocks.getStateFromMeta(11), 3);
		world.setBlockState(new BlockPos(x + 8, y + 1, z + 7), Blocks.OAK_STAIRS.getStateFromMeta(5), 3);
		world.setBlockState(new BlockPos(x + 9, y + 1, z + 7), Blocks.AIR.getDefaultState(), 3);
		world.setBlockState(new BlockPos(x + 10, y + 1, z + 7), Blocks.AIR.getDefaultState(), 3);
		world.setBlockState(new BlockPos(x + 11, y + 1, z + 7), Blocks.AIR.getDefaultState(), 3);
		world.setBlockState(new BlockPos(x + 12, y + 1, z + 7), Blocks.AIR.getDefaultState(), 3);
		world.setBlockState(new BlockPos(x + 13, y + 1, z + 7), ExtraPlanets_Blocks.jupiterBlocks.getStateFromMeta(11), 3);
		world.setBlockState(new BlockPos(x + 0, y + 1, z + 8), ExtraPlanets_Blocks.jupiterBlocks.getStateFromMeta(11), 3);
		world.setBlockState(new BlockPos(x + 1, y + 1, z + 8), Blocks.AIR.getDefaultState(), 3);
		world.setBlockState(new BlockPos(x + 2, y + 1, z + 8), Blocks.QUARTZ_STAIRS.getStateFromMeta(2), 3);
		world.setBlockState(new BlockPos(x + 3, y + 1, z + 8), Blocks.QUARTZ_STAIRS.getStateFromMeta(2), 3);
		world.setBlockState(new BlockPos(x + 4, y + 1, z + 8), Blocks.AIR.getDefaultState(), 3);
		world.setBlockState(new BlockPos(x + 5, y + 1, z + 8), Blocks.AIR.getDefaultState(), 3);
		world.setBlockState(new BlockPos(x + 6, y + 1, z + 8), Blocks.AIR.getDefaultState(), 3);
		world.setBlockState(new BlockPos(x + 7, y + 1, z + 8), Blocks.AIR.getDefaultState(), 3);
		world.setBlockState(new BlockPos(x + 8, y + 1, z + 8), Blocks.AIR.getDefaultState(), 3);
		world.setBlockState(new BlockPos(x + 9, y + 1, z + 8), Blocks.AIR.getDefaultState(), 3);
		world.setBlockState(new BlockPos(x + 10, y + 1, z + 8), Blocks.AIR.getDefaultState(), 3);
		world.setBlockState(new BlockPos(x + 11, y + 1, z + 8), Blocks.AIR.getDefaultState(), 3);
		world.setBlockState(new BlockPos(x + 12, y + 1, z + 8), ExtraPlanets_Blocks.jupiterBlocks.getStateFromMeta(11), 3);
		world.setBlockState(new BlockPos(x + 0, y + 1, z + 9), ExtraPlanets_Blocks.jupiterBlocks.getStateFromMeta(11), 3);
		world.setBlockState(new BlockPos(x + 1, y + 1, z + 9), Blocks.AIR.getDefaultState(), 3);
		world.setBlockState(new BlockPos(x + 2, y + 1, z + 9), Blocks.AIR.getDefaultState(), 3);
		world.setBlockState(new BlockPos(x + 3, y + 1, z + 9), Blocks.AIR.getDefaultState(), 3);
		world.setBlockState(new BlockPos(x + 4, y + 1, z + 9), Blocks.AIR.getDefaultState(), 3);
		world.setBlockState(new BlockPos(x + 5, y + 1, z + 9), Blocks.AIR.getDefaultState(), 3);
		world.setBlockState(new BlockPos(x + 6, y + 1, z + 9), Blocks.AIR.getDefaultState(), 3);
		world.setBlockState(new BlockPos(x + 7, y + 1, z + 9), Blocks.AIR.getDefaultState(), 3);
		world.setBlockState(new BlockPos(x + 8, y + 1, z + 9), Blocks.AIR.getDefaultState(), 3);
		world.setBlockState(new BlockPos(x + 9, y + 1, z + 9), Blocks.AIR.getDefaultState(), 3);
		world.setBlockState(new BlockPos(x + 10, y + 1, z + 9), Blocks.AIR.getDefaultState(), 3);
		world.setBlockState(new BlockPos(x + 11, y + 1, z + 9), Blocks.JUKEBOX.getDefaultState(), 3);
		world.setBlockState(new BlockPos(x + 12, y + 1, z + 9), ExtraPlanets_Blocks.jupiterBlocks.getStateFromMeta(11), 3);
		world.setBlockState(new BlockPos(x + 1, y + 1, z + 10), ExtraPlanets_Blocks.jupiterBlocks.getStateFromMeta(11), 3);
		world.setBlockState(new BlockPos(x + 2, y + 1, z + 10), ExtraPlanets_Blocks.jupiterBlocks.getStateFromMeta(11), 3);
		world.setBlockState(new BlockPos(x + 3, y + 1, z + 10), ExtraPlanets_Blocks.jupiterBlocks.getStateFromMeta(11), 3);
		world.setBlockState(new BlockPos(x + 4, y + 1, z + 10), ExtraPlanets_Blocks.jupiterBlocks.getStateFromMeta(11), 3);
		world.setBlockState(new BlockPos(x + 5, y + 1, z + 10), Blocks.AIR.getDefaultState(), 3);
		world.setBlockState(new BlockPos(x + 6, y + 1, z + 10), Blocks.CHEST.getStateFromMeta(2), 3);
		world.setBlockState(new BlockPos(x + 7, y + 1, z + 10), Blocks.AIR.getDefaultState(), 3);
		world.setBlockState(new BlockPos(x + 8, y + 1, z + 10), ExtraPlanets_Blocks.jupiterBlocks.getStateFromMeta(11), 3);
		world.setBlockState(new BlockPos(x + 9, y + 1, z + 10), ExtraPlanets_Blocks.jupiterBlocks.getStateFromMeta(11), 3);
		world.setBlockState(new BlockPos(x + 10, y + 1, z + 10), ExtraPlanets_Blocks.jupiterBlocks.getStateFromMeta(11), 3);
		world.setBlockState(new BlockPos(x + 11, y + 1, z + 10), ExtraPlanets_Blocks.jupiterBlocks.getStateFromMeta(11), 3);
		world.setBlockState(new BlockPos(x + 5, y + 1, z + 11), ExtraPlanets_Blocks.jupiterBlocks.getStateFromMeta(11), 3);
		world.setBlockState(new BlockPos(x + 6, y + 1, z + 11), ExtraPlanets_Blocks.jupiterBlocks.getStateFromMeta(11), 3);
		world.setBlockState(new BlockPos(x + 7, y + 1, z + 11), ExtraPlanets_Blocks.jupiterBlocks.getStateFromMeta(11), 3);
		world.setBlockState(new BlockPos(x + 5, y + 2, z + 0), ExtraPlanets_Blocks.jupiterBlocks.getStateFromMeta(11), 3);
		world.setBlockState(new BlockPos(x + 6, y + 2, z + 0), ExtraPlanets_Blocks.jupiterBlocks.getStateFromMeta(11), 3);
		world.setBlockState(new BlockPos(x + 7, y + 2, z + 0), ExtraPlanets_Blocks.jupiterBlocks.getStateFromMeta(11), 3);
		world.setBlockState(new BlockPos(x + 1, y + 2, z + 1), ExtraPlanets_Blocks.jupiterBlocks.getStateFromMeta(11), 3);
		world.setBlockState(new BlockPos(x + 2, y + 2, z + 1), ExtraPlanets_Blocks.jupiterBlocks.getStateFromMeta(11), 3);
		world.setBlockState(new BlockPos(x + 3, y + 2, z + 1), ExtraPlanets_Blocks.jupiterBlocks.getStateFromMeta(11), 3);
		world.setBlockState(new BlockPos(x + 4, y + 2, z + 1), ExtraPlanets_Blocks.jupiterBlocks.getStateFromMeta(11), 3);
		world.setBlockState(new BlockPos(x + 5, y + 2, z + 1), Blocks.AIR.getDefaultState(), 3);
		world.setBlockState(new BlockPos(x + 6, y + 2, z + 1), Blocks.AIR.getDefaultState(), 3);
		world.setBlockState(new BlockPos(x + 7, y + 2, z + 1), Blocks.AIR.getDefaultState(), 3);
		world.setBlockState(new BlockPos(x + 8, y + 2, z + 1), ExtraPlanets_Blocks.jupiterBlocks.getStateFromMeta(11), 3);
		world.setBlockState(new BlockPos(x + 9, y + 2, z + 1), ExtraPlanets_Blocks.jupiterBlocks.getStateFromMeta(11), 3);
		world.setBlockState(new BlockPos(x + 10, y + 2, z + 1), ExtraPlanets_Blocks.jupiterBlocks.getStateFromMeta(11), 3);
		world.setBlockState(new BlockPos(x + 11, y + 2, z + 1), ExtraPlanets_Blocks.jupiterBlocks.getStateFromMeta(11), 3);
		world.setBlockState(new BlockPos(x + 0, y + 2, z + 2), ExtraPlanets_Blocks.jupiterBlocks.getStateFromMeta(11), 3);
		world.setBlockState(new BlockPos(x + 1, y + 2, z + 2), Blocks.AIR.getDefaultState(), 3);
		world.setBlockState(new BlockPos(x + 2, y + 2, z + 2), Blocks.AIR.getDefaultState(), 3);
		world.setBlockState(new BlockPos(x + 3, y + 2, z + 2), Blocks.AIR.getDefaultState(), 3);
		world.setBlockState(new BlockPos(x + 4, y + 2, z + 2), Blocks.AIR.getDefaultState(), 3);
		world.setBlockState(new BlockPos(x + 5, y + 2, z + 2), Blocks.AIR.getDefaultState(), 3);
		world.setBlockState(new BlockPos(x + 6, y + 2, z + 2), Blocks.AIR.getDefaultState(), 3);
		world.setBlockState(new BlockPos(x + 7, y + 2, z + 2), Blocks.AIR.getDefaultState(), 3);
		world.setBlockState(new BlockPos(x + 8, y + 2, z + 2), Blocks.AIR.getDefaultState(), 3);
		world.setBlockState(new BlockPos(x + 9, y + 2, z + 2), Blocks.AIR.getDefaultState(), 3);
		world.setBlockState(new BlockPos(x + 10, y + 2, z + 2), Blocks.AIR.getDefaultState(), 3);
		world.setBlockState(new BlockPos(x + 11, y + 2, z + 2), Blocks.AIR.getDefaultState(), 3);
		world.setBlockState(new BlockPos(x + 12, y + 2, z + 2), ExtraPlanets_Blocks.jupiterBlocks.getStateFromMeta(11), 3);
		world.setBlockState(new BlockPos(x + 0, y + 2, z + 3), ExtraPlanets_Blocks.jupiterBlocks.getStateFromMeta(11), 3);
		world.setBlockState(new BlockPos(x + 1, y + 2, z + 3), Blocks.AIR.getDefaultState(), 3);
		world.setBlockState(new BlockPos(x + 2, y + 2, z + 3), Blocks.AIR.getDefaultState(), 3);
		world.setBlockState(new BlockPos(x + 3, y + 2, z + 3), Blocks.AIR.getDefaultState(), 3);
		world.setBlockState(new BlockPos(x + 4, y + 2, z + 3), Blocks.AIR.getDefaultState(), 3);
		world.setBlockState(new BlockPos(x + 5, y + 2, z + 3), Blocks.AIR.getDefaultState(), 3);
		world.setBlockState(new BlockPos(x + 6, y + 2, z + 3), Blocks.AIR.getDefaultState(), 3);
		world.setBlockState(new BlockPos(x + 7, y + 2, z + 3), Blocks.AIR.getDefaultState(), 3);
		world.setBlockState(new BlockPos(x + 8, y + 2, z + 3), Blocks.AIR.getDefaultState(), 3);
		world.setBlockState(new BlockPos(x + 9, y + 2, z + 3), Blocks.AIR.getDefaultState(), 3);
		world.setBlockState(new BlockPos(x + 10, y + 2, z + 3), Blocks.AIR.getDefaultState(), 3);
		world.setBlockState(new BlockPos(x + 11, y + 2, z + 3), Blocks.AIR.getDefaultState(), 3);
		world.setBlockState(new BlockPos(x + 12, y + 2, z + 3), ExtraPlanets_Blocks.jupiterBlocks.getStateFromMeta(11), 3);
		world.setBlockState(new BlockPos(x + 0, y + 2, z + 4), ExtraPlanets_Blocks.jupiterBlocks.getStateFromMeta(11), 3);
		world.setBlockState(new BlockPos(x + 1, y + 2, z + 4), Blocks.AIR.getDefaultState(), 3);
		world.setBlockState(new BlockPos(x + 2, y + 2, z + 4), Blocks.AIR.getDefaultState(), 3);
		world.setBlockState(new BlockPos(x + 3, y + 2, z + 4), Blocks.AIR.getDefaultState(), 3);
		world.setBlockState(new BlockPos(x + 4, y + 2, z + 4), Blocks.AIR.getDefaultState(), 3);
		world.setBlockState(new BlockPos(x + 5, y + 2, z + 4), Blocks.AIR.getDefaultState(), 3);
		world.setBlockState(new BlockPos(x + 6, y + 2, z + 4), Blocks.CHEST.getStateFromMeta(4), 3);
		world.setBlockState(new BlockPos(x + 7, y + 2, z + 4), ExtraPlanets_Blocks.jupiterBlocks.getStateFromMeta(11), 3);
		world.setBlockState(new BlockPos(x + 8, y + 2, z + 4), Blocks.AIR.getDefaultState(), 3);
		world.setBlockState(new BlockPos(x + 9, y + 2, z + 4), Blocks.AIR.getDefaultState(), 3);
		world.setBlockState(new BlockPos(x + 10, y + 2, z + 4), Blocks.AIR.getDefaultState(), 3);
		world.setBlockState(new BlockPos(x + 11, y + 2, z + 4), Blocks.AIR.getDefaultState(), 3);
		world.setBlockState(new BlockPos(x + 12, y + 2, z + 4), Blocks.AIR.getDefaultState(), 3);
		world.setBlockState(new BlockPos(x + 13, y + 2, z + 4), ExtraPlanets_Blocks.jupiterBlocks.getStateFromMeta(11), 3);
		world.setBlockState(new BlockPos(x + 0, y + 2, z + 5), ExtraPlanets_Blocks.jupiterBlocks.getStateFromMeta(11), 3);
		world.setBlockState(new BlockPos(x + 1, y + 2, z + 5), Blocks.AIR.getDefaultState(), 3);
		world.setBlockState(new BlockPos(x + 2, y + 2, z + 5), Blocks.AIR.getDefaultState(), 3);
		world.setBlockState(new BlockPos(x + 3, y + 2, z + 5), Blocks.AIR.getDefaultState(), 3);
		world.setBlockState(new BlockPos(x + 4, y + 2, z + 5), Blocks.AIR.getDefaultState(), 3);
		world.setBlockState(new BlockPos(x + 5, y + 2, z + 5), Blocks.AIR.getDefaultState(), 3);
		world.setBlockState(new BlockPos(x + 6, y + 2, z + 5), Blocks.FURNACE.getStateFromMeta(4), 3);
		world.setBlockState(new BlockPos(x + 7, y + 2, z + 5), ExtraPlanets_Blocks.jupiterBlocks.getStateFromMeta(11), 3);
		world.setBlockState(new BlockPos(x + 8, y + 2, z + 5), Blocks.AIR.getDefaultState(), 3);
		world.setBlockState(new BlockPos(x + 9, y + 2, z + 5), Blocks.AIR.getDefaultState(), 3);
		world.setBlockState(new BlockPos(x + 10, y + 2, z + 5), Blocks.AIR.getDefaultState(), 3);
		world.setBlockState(new BlockPos(x + 11, y + 2, z + 5), Blocks.AIR.getDefaultState(), 3);
		world.setBlockState(new BlockPos(x + 12, y + 2, z + 5), Blocks.AIR.getDefaultState(), 3);
		world.setBlockState(new BlockPos(x + 13, y + 2, z + 5), Blocks.AIR.getDefaultState(), 3);
		world.setBlockState(new BlockPos(x + 0, y + 2, z + 6), ExtraPlanets_Blocks.jupiterBlocks.getStateFromMeta(11), 3);
		world.setBlockState(new BlockPos(x + 1, y + 2, z + 6), Blocks.AIR.getDefaultState(), 3);
		world.setBlockState(new BlockPos(x + 2, y + 2, z + 6), Blocks.AIR.getDefaultState(), 3);
		world.setBlockState(new BlockPos(x + 3, y + 2, z + 6), Blocks.AIR.getDefaultState(), 3);
		world.setBlockState(new BlockPos(x + 4, y + 2, z + 6), Blocks.AIR.getDefaultState(), 3);
		world.setBlockState(new BlockPos(x + 5, y + 2, z + 6), Blocks.AIR.getDefaultState(), 3);
		world.setBlockState(new BlockPos(x + 6, y + 2, z + 6), Blocks.FURNACE.getStateFromMeta(4), 3);
		world.setBlockState(new BlockPos(x + 7, y + 2, z + 6), ExtraPlanets_Blocks.jupiterBlocks.getStateFromMeta(11), 3);
		world.setBlockState(new BlockPos(x + 8, y + 2, z + 6), Blocks.AIR.getDefaultState(), 3);
		world.setBlockState(new BlockPos(x + 9, y + 2, z + 6), Blocks.AIR.getDefaultState(), 3);
		world.setBlockState(new BlockPos(x + 10, y + 2, z + 6), Blocks.AIR.getDefaultState(), 3);
		world.setBlockState(new BlockPos(x + 11, y + 2, z + 6), Blocks.AIR.getDefaultState(), 3);
		world.setBlockState(new BlockPos(x + 12, y + 2, z + 6), Blocks.AIR.getDefaultState(), 3);
		world.setBlockState(new BlockPos(x + 13, y + 2, z + 6), Blocks.AIR.getDefaultState(), 3);
		world.setBlockState(new BlockPos(x + 0, y + 2, z + 7), ExtraPlanets_Blocks.jupiterBlocks.getStateFromMeta(11), 3);
		world.setBlockState(new BlockPos(x + 1, y + 2, z + 7), Blocks.AIR.getDefaultState(), 3);
		world.setBlockState(new BlockPos(x + 2, y + 2, z + 7), Blocks.AIR.getDefaultState(), 3);
		world.setBlockState(new BlockPos(x + 3, y + 2, z + 7), Blocks.AIR.getDefaultState(), 3);
		world.setBlockState(new BlockPos(x + 4, y + 2, z + 7), Blocks.AIR.getDefaultState(), 3);
		world.setBlockState(new BlockPos(x + 5, y + 2, z + 7), Blocks.AIR.getDefaultState(), 3);
		world.setBlockState(new BlockPos(x + 6, y + 2, z + 7), Blocks.CHEST.getStateFromMeta(4), 3);
		world.setBlockState(new BlockPos(x + 7, y + 2, z + 7), ExtraPlanets_Blocks.jupiterBlocks.getStateFromMeta(11), 3);
		world.setBlockState(new BlockPos(x + 8, y + 2, z + 7), Blocks.AIR.getDefaultState(), 3);
		world.setBlockState(new BlockPos(x + 9, y + 2, z + 7), Blocks.AIR.getDefaultState(), 3);
		world.setBlockState(new BlockPos(x + 10, y + 2, z + 7), Blocks.AIR.getDefaultState(), 3);
		world.setBlockState(new BlockPos(x + 11, y + 2, z + 7), Blocks.AIR.getDefaultState(), 3);
		world.setBlockState(new BlockPos(x + 12, y + 2, z + 7), Blocks.AIR.getDefaultState(), 3);
		world.setBlockState(new BlockPos(x + 13, y + 2, z + 7), ExtraPlanets_Blocks.jupiterBlocks.getStateFromMeta(11), 3);
		world.setBlockState(new BlockPos(x + 0, y + 2, z + 8), ExtraPlanets_Blocks.jupiterBlocks.getStateFromMeta(11), 3);
		world.setBlockState(new BlockPos(x + 1, y + 2, z + 8), Blocks.AIR.getDefaultState(), 3);
		world.setBlockState(new BlockPos(x + 2, y + 2, z + 8), Blocks.AIR.getDefaultState(), 3);
		world.setBlockState(new BlockPos(x + 3, y + 2, z + 8), Blocks.AIR.getDefaultState(), 3);
		world.setBlockState(new BlockPos(x + 4, y + 2, z + 8), Blocks.AIR.getDefaultState(), 3);
		world.setBlockState(new BlockPos(x + 5, y + 2, z + 8), Blocks.AIR.getDefaultState(), 3);
		world.setBlockState(new BlockPos(x + 6, y + 2, z + 8), Blocks.AIR.getDefaultState(), 3);
		world.setBlockState(new BlockPos(x + 7, y + 2, z + 8), Blocks.AIR.getDefaultState(), 3);
		world.setBlockState(new BlockPos(x + 8, y + 2, z + 8), Blocks.AIR.getDefaultState(), 3);
		world.setBlockState(new BlockPos(x + 9, y + 2, z + 8), Blocks.AIR.getDefaultState(), 3);
		world.setBlockState(new BlockPos(x + 10, y + 2, z + 8), Blocks.AIR.getDefaultState(), 3);
		world.setBlockState(new BlockPos(x + 11, y + 2, z + 8), Blocks.AIR.getDefaultState(), 3);
		world.setBlockState(new BlockPos(x + 12, y + 2, z + 8), ExtraPlanets_Blocks.jupiterBlocks.getStateFromMeta(11), 3);
		world.setBlockState(new BlockPos(x + 0, y + 2, z + 9), ExtraPlanets_Blocks.jupiterBlocks.getStateFromMeta(11), 3);
		world.setBlockState(new BlockPos(x + 1, y + 2, z + 9), Blocks.AIR.getDefaultState(), 3);
		world.setBlockState(new BlockPos(x + 2, y + 2, z + 9), Blocks.AIR.getDefaultState(), 3);
		world.setBlockState(new BlockPos(x + 3, y + 2, z + 9), Blocks.AIR.getDefaultState(), 3);
		world.setBlockState(new BlockPos(x + 4, y + 2, z + 9), Blocks.AIR.getDefaultState(), 3);
		world.setBlockState(new BlockPos(x + 5, y + 2, z + 9), Blocks.AIR.getDefaultState(), 3);
		world.setBlockState(new BlockPos(x + 6, y + 2, z + 9), Blocks.AIR.getDefaultState(), 3);
		world.setBlockState(new BlockPos(x + 7, y + 2, z + 9), Blocks.AIR.getDefaultState(), 3);
		world.setBlockState(new BlockPos(x + 8, y + 2, z + 9), Blocks.AIR.getDefaultState(), 3);
		world.setBlockState(new BlockPos(x + 9, y + 2, z + 9), Blocks.AIR.getDefaultState(), 3);
		world.setBlockState(new BlockPos(x + 10, y + 2, z + 9), Blocks.AIR.getDefaultState(), 3);
		world.setBlockState(new BlockPos(x + 11, y + 2, z + 9), Blocks.AIR.getDefaultState(), 3);
		world.setBlockState(new BlockPos(x + 12, y + 2, z + 9), ExtraPlanets_Blocks.jupiterBlocks.getStateFromMeta(11), 3);
		world.setBlockState(new BlockPos(x + 1, y + 2, z + 10), ExtraPlanets_Blocks.jupiterBlocks.getStateFromMeta(11), 3);
		world.setBlockState(new BlockPos(x + 2, y + 2, z + 10), ExtraPlanets_Blocks.jupiterBlocks.getStateFromMeta(11), 3);
		world.setBlockState(new BlockPos(x + 3, y + 2, z + 10), ExtraPlanets_Blocks.jupiterBlocks.getStateFromMeta(11), 3);
		world.setBlockState(new BlockPos(x + 4, y + 2, z + 10), ExtraPlanets_Blocks.jupiterBlocks.getStateFromMeta(11), 3);
		world.setBlockState(new BlockPos(x + 5, y + 2, z + 10), Blocks.AIR.getDefaultState(), 3);
		world.setBlockState(new BlockPos(x + 6, y + 2, z + 10), Blocks.AIR.getDefaultState(), 3);
		world.setBlockState(new BlockPos(x + 7, y + 2, z + 10), Blocks.AIR.getDefaultState(), 3);
		world.setBlockState(new BlockPos(x + 8, y + 2, z + 10), ExtraPlanets_Blocks.jupiterBlocks.getStateFromMeta(11), 3);
		world.setBlockState(new BlockPos(x + 9, y + 2, z + 10), ExtraPlanets_Blocks.jupiterBlocks.getStateFromMeta(11), 3);
		world.setBlockState(new BlockPos(x + 10, y + 2, z + 10), ExtraPlanets_Blocks.jupiterBlocks.getStateFromMeta(11), 3);
		world.setBlockState(new BlockPos(x + 11, y + 2, z + 10), ExtraPlanets_Blocks.jupiterBlocks.getStateFromMeta(11), 3);
		world.setBlockState(new BlockPos(x + 5, y + 2, z + 11), ExtraPlanets_Blocks.jupiterBlocks.getStateFromMeta(11), 3);
		world.setBlockState(new BlockPos(x + 6, y + 2, z + 11), ExtraPlanets_Blocks.jupiterBlocks.getStateFromMeta(11), 3);
		world.setBlockState(new BlockPos(x + 7, y + 2, z + 11), ExtraPlanets_Blocks.jupiterBlocks.getStateFromMeta(11), 3);
		world.setBlockState(new BlockPos(x + 5, y + 3, z + 0), ExtraPlanets_Blocks.jupiterBlocks.getStateFromMeta(11), 3);
		world.setBlockState(new BlockPos(x + 6, y + 3, z + 0), ExtraPlanets_Blocks.jupiterBlocks.getStateFromMeta(11), 3);
		world.setBlockState(new BlockPos(x + 7, y + 3, z + 0), ExtraPlanets_Blocks.jupiterBlocks.getStateFromMeta(11), 3);
		world.setBlockState(new BlockPos(x + 1, y + 3, z + 1), ExtraPlanets_Blocks.jupiterBlocks.getStateFromMeta(11), 3);
		world.setBlockState(new BlockPos(x + 2, y + 3, z + 1), ExtraPlanets_Blocks.jupiterBlocks.getStateFromMeta(11), 3);
		world.setBlockState(new BlockPos(x + 3, y + 3, z + 1), ExtraPlanets_Blocks.jupiterBlocks.getStateFromMeta(11), 3);
		world.setBlockState(new BlockPos(x + 4, y + 3, z + 1), ExtraPlanets_Blocks.jupiterBlocks.getStateFromMeta(11), 3);
		world.setBlockState(new BlockPos(x + 5, y + 3, z + 1), Blocks.AIR.getDefaultState(), 3);
		world.setBlockState(new BlockPos(x + 6, y + 3, z + 1), Blocks.AIR.getDefaultState(), 3);
		world.setBlockState(new BlockPos(x + 7, y + 3, z + 1), Blocks.AIR.getDefaultState(), 3);
		world.setBlockState(new BlockPos(x + 8, y + 3, z + 1), ExtraPlanets_Blocks.jupiterBlocks.getStateFromMeta(11), 3);
		world.setBlockState(new BlockPos(x + 9, y + 3, z + 1), ExtraPlanets_Blocks.jupiterBlocks.getStateFromMeta(11), 3);
		world.setBlockState(new BlockPos(x + 10, y + 3, z + 1), ExtraPlanets_Blocks.jupiterBlocks.getStateFromMeta(11), 3);
		world.setBlockState(new BlockPos(x + 11, y + 3, z + 1), ExtraPlanets_Blocks.jupiterBlocks.getStateFromMeta(11), 3);
		world.setBlockState(new BlockPos(x + 0, y + 3, z + 2), ExtraPlanets_Blocks.jupiterBlocks.getStateFromMeta(11), 3);
		world.setBlockState(new BlockPos(x + 1, y + 3, z + 2), Blocks.AIR.getDefaultState(), 3);
		world.setBlockState(new BlockPos(x + 2, y + 3, z + 2), Blocks.AIR.getDefaultState(), 3);
		world.setBlockState(new BlockPos(x + 3, y + 3, z + 2), Blocks.AIR.getDefaultState(), 3);
		world.setBlockState(new BlockPos(x + 4, y + 3, z + 2), Blocks.AIR.getDefaultState(), 3);
		world.setBlockState(new BlockPos(x + 5, y + 3, z + 2), Blocks.AIR.getDefaultState(), 3);
		world.setBlockState(new BlockPos(x + 6, y + 3, z + 2), Blocks.AIR.getDefaultState(), 3);
		world.setBlockState(new BlockPos(x + 7, y + 3, z + 2), Blocks.AIR.getDefaultState(), 3);
		world.setBlockState(new BlockPos(x + 8, y + 3, z + 2), Blocks.AIR.getDefaultState(), 3);
		world.setBlockState(new BlockPos(x + 9, y + 3, z + 2), Blocks.AIR.getDefaultState(), 3);
		world.setBlockState(new BlockPos(x + 10, y + 3, z + 2), Blocks.AIR.getDefaultState(), 3);
		world.setBlockState(new BlockPos(x + 11, y + 3, z + 2), Blocks.AIR.getDefaultState(), 3);
		world.setBlockState(new BlockPos(x + 12, y + 3, z + 2), ExtraPlanets_Blocks.jupiterBlocks.getStateFromMeta(11), 3);
		world.setBlockState(new BlockPos(x + 0, y + 3, z + 3), ExtraPlanets_Blocks.jupiterBlocks.getStateFromMeta(11), 3);
		world.setBlockState(new BlockPos(x + 1, y + 3, z + 3), Blocks.AIR.getDefaultState(), 3);
		world.setBlockState(new BlockPos(x + 2, y + 3, z + 3), Blocks.AIR.getDefaultState(), 3);
		world.setBlockState(new BlockPos(x + 3, y + 3, z + 3), Blocks.AIR.getDefaultState(), 3);
		world.setBlockState(new BlockPos(x + 4, y + 3, z + 3), Blocks.AIR.getDefaultState(), 3);
		world.setBlockState(new BlockPos(x + 5, y + 3, z + 3), Blocks.AIR.getDefaultState(), 3);
		world.setBlockState(new BlockPos(x + 6, y + 3, z + 3), Blocks.AIR.getDefaultState(), 3);
		world.setBlockState(new BlockPos(x + 7, y + 3, z + 3), Blocks.AIR.getDefaultState(), 3);
		world.setBlockState(new BlockPos(x + 8, y + 3, z + 3), Blocks.AIR.getDefaultState(), 3);
		world.setBlockState(new BlockPos(x + 9, y + 3, z + 3), Blocks.AIR.getDefaultState(), 3);
		world.setBlockState(new BlockPos(x + 10, y + 3, z + 3), Blocks.AIR.getDefaultState(), 3);
		world.setBlockState(new BlockPos(x + 11, y + 3, z + 3), Blocks.AIR.getDefaultState(), 3);
		world.setBlockState(new BlockPos(x + 12, y + 3, z + 3), ExtraPlanets_Blocks.jupiterBlocks.getStateFromMeta(11), 3);
		world.setBlockState(new BlockPos(x + 0, y + 3, z + 4), ExtraPlanets_Blocks.jupiterBlocks.getStateFromMeta(11), 3);
		world.setBlockState(new BlockPos(x + 1, y + 3, z + 4), Blocks.AIR.getDefaultState(), 3);
		world.setBlockState(new BlockPos(x + 2, y + 3, z + 4), Blocks.AIR.getDefaultState(), 3);
		world.setBlockState(new BlockPos(x + 4, y + 3, z + 4), Blocks.AIR.getDefaultState(), 3);
		world.setBlockState(new BlockPos(x + 5, y + 3, z + 4), Blocks.AIR.getDefaultState(), 3);
		world.setBlockState(new BlockPos(x + 6, y + 3, z + 4), Blocks.CHEST.getStateFromMeta(4), 3);
		world.setBlockState(new BlockPos(x + 7, y + 3, z + 4), ExtraPlanets_Blocks.jupiterBlocks.getStateFromMeta(11), 3);
		world.setBlockState(new BlockPos(x + 8, y + 3, z + 4), Blocks.AIR.getDefaultState(), 3);
		world.setBlockState(new BlockPos(x + 10, y + 3, z + 4), Blocks.AIR.getDefaultState(), 3);
		world.setBlockState(new BlockPos(x + 11, y + 3, z + 4), Blocks.AIR.getDefaultState(), 3);
		world.setBlockState(new BlockPos(x + 12, y + 3, z + 4), Blocks.AIR.getDefaultState(), 3);
		world.setBlockState(new BlockPos(x + 13, y + 3, z + 4), ExtraPlanets_Blocks.jupiterBlocks.getStateFromMeta(11), 3);
		world.setBlockState(new BlockPos(x + 0, y + 3, z + 5), ExtraPlanets_Blocks.jupiterBlocks.getStateFromMeta(11), 3);
		world.setBlockState(new BlockPos(x + 1, y + 3, z + 5), Blocks.AIR.getDefaultState(), 3);
		world.setBlockState(new BlockPos(x + 2, y + 3, z + 5), Blocks.AIR.getDefaultState(), 3);
		world.setBlockState(new BlockPos(x + 3, y + 3, z + 5), Blocks.AIR.getDefaultState(), 3);
		world.setBlockState(new BlockPos(x + 4, y + 3, z + 5), Blocks.AIR.getDefaultState(), 3);
		world.setBlockState(new BlockPos(x + 5, y + 3, z + 5), Blocks.AIR.getDefaultState(), 3);
		world.setBlockState(new BlockPos(x + 6, y + 3, z + 5), Blocks.FURNACE.getStateFromMeta(4), 3);
		world.setBlockState(new BlockPos(x + 7, y + 3, z + 5), ExtraPlanets_Blocks.jupiterBlocks.getStateFromMeta(11), 3);
		world.setBlockState(new BlockPos(x + 8, y + 3, z + 5), Blocks.AIR.getDefaultState(), 3);
		world.setBlockState(new BlockPos(x + 9, y + 3, z + 5), Blocks.AIR.getDefaultState(), 3);
		world.setBlockState(new BlockPos(x + 10, y + 3, z + 5), Blocks.AIR.getDefaultState(), 3);
		world.setBlockState(new BlockPos(x + 11, y + 3, z + 5), Blocks.AIR.getDefaultState(), 3);
		world.setBlockState(new BlockPos(x + 12, y + 3, z + 5), Blocks.AIR.getDefaultState(), 3);
		world.setBlockState(new BlockPos(x + 13, y + 3, z + 5), ExtraPlanets_Blocks.jupiterBlocks.getStateFromMeta(11), 3);
		world.setBlockState(new BlockPos(x + 0, y + 3, z + 6), ExtraPlanets_Blocks.jupiterBlocks.getStateFromMeta(11), 3);
		world.setBlockState(new BlockPos(x + 1, y + 3, z + 6), Blocks.AIR.getDefaultState(), 3);
		world.setBlockState(new BlockPos(x + 2, y + 3, z + 6), Blocks.AIR.getDefaultState(), 3);
		world.setBlockState(new BlockPos(x + 3, y + 3, z + 6), Blocks.AIR.getDefaultState(), 3);
		world.setBlockState(new BlockPos(x + 4, y + 3, z + 6), Blocks.AIR.getDefaultState(), 3);
		world.setBlockState(new BlockPos(x + 5, y + 3, z + 6), Blocks.AIR.getDefaultState(), 3);
		world.setBlockState(new BlockPos(x + 6, y + 3, z + 6), Blocks.FURNACE.getStateFromMeta(4), 3);
		world.setBlockState(new BlockPos(x + 7, y + 3, z + 6), ExtraPlanets_Blocks.jupiterBlocks.getStateFromMeta(11), 3);
		world.setBlockState(new BlockPos(x + 8, y + 3, z + 6), Blocks.AIR.getDefaultState(), 3);
		world.setBlockState(new BlockPos(x + 9, y + 3, z + 6), Blocks.AIR.getDefaultState(), 3);
		world.setBlockState(new BlockPos(x + 10, y + 3, z + 6), Blocks.AIR.getDefaultState(), 3);
		world.setBlockState(new BlockPos(x + 11, y + 3, z + 6), Blocks.AIR.getDefaultState(), 3);
		world.setBlockState(new BlockPos(x + 12, y + 3, z + 6), Blocks.AIR.getDefaultState(), 3);
		world.setBlockState(new BlockPos(x + 13, y + 3, z + 6), ExtraPlanets_Blocks.jupiterBlocks.getStateFromMeta(11), 3);
		world.setBlockState(new BlockPos(x + 0, y + 3, z + 7), ExtraPlanets_Blocks.jupiterBlocks.getStateFromMeta(11), 3);
		world.setBlockState(new BlockPos(x + 1, y + 3, z + 7), Blocks.AIR.getDefaultState(), 3);
		world.setBlockState(new BlockPos(x + 2, y + 3, z + 7), Blocks.AIR.getDefaultState(), 3);
		world.setBlockState(new BlockPos(x + 4, y + 3, z + 7), Blocks.AIR.getDefaultState(), 3);
		world.setBlockState(new BlockPos(x + 5, y + 3, z + 7), Blocks.AIR.getDefaultState(), 3);
		world.setBlockState(new BlockPos(x + 6, y + 3, z + 7), Blocks.CHEST.getStateFromMeta(4), 3);
		world.setBlockState(new BlockPos(x + 7, y + 3, z + 7), ExtraPlanets_Blocks.jupiterBlocks.getStateFromMeta(11), 3);
		world.setBlockState(new BlockPos(x + 8, y + 3, z + 7), Blocks.AIR.getDefaultState(), 3);
		world.setBlockState(new BlockPos(x + 10, y + 3, z + 7), Blocks.AIR.getDefaultState(), 3);
		world.setBlockState(new BlockPos(x + 11, y + 3, z + 7), Blocks.AIR.getDefaultState(), 3);
		world.setBlockState(new BlockPos(x + 12, y + 3, z + 7), Blocks.AIR.getDefaultState(), 3);
		world.setBlockState(new BlockPos(x + 13, y + 3, z + 7), ExtraPlanets_Blocks.jupiterBlocks.getStateFromMeta(11), 3);
		world.setBlockState(new BlockPos(x + 0, y + 3, z + 8), ExtraPlanets_Blocks.jupiterBlocks.getStateFromMeta(11), 3);
		world.setBlockState(new BlockPos(x + 1, y + 3, z + 8), Blocks.AIR.getDefaultState(), 3);
		world.setBlockState(new BlockPos(x + 2, y + 3, z + 8), Blocks.AIR.getDefaultState(), 3);
		world.setBlockState(new BlockPos(x + 3, y + 3, z + 8), Blocks.AIR.getDefaultState(), 3);
		world.setBlockState(new BlockPos(x + 4, y + 3, z + 8), Blocks.AIR.getDefaultState(), 3);
		world.setBlockState(new BlockPos(x + 5, y + 3, z + 8), Blocks.AIR.getDefaultState(), 3);
		world.setBlockState(new BlockPos(x + 6, y + 3, z + 8), Blocks.AIR.getDefaultState(), 3);
		world.setBlockState(new BlockPos(x + 7, y + 3, z + 8), Blocks.AIR.getDefaultState(), 3);
		world.setBlockState(new BlockPos(x + 8, y + 3, z + 8), Blocks.AIR.getDefaultState(), 3);
		world.setBlockState(new BlockPos(x + 9, y + 3, z + 8), Blocks.AIR.getDefaultState(), 3);
		world.setBlockState(new BlockPos(x + 10, y + 3, z + 8), Blocks.AIR.getDefaultState(), 3);
		world.setBlockState(new BlockPos(x + 11, y + 3, z + 8), Blocks.AIR.getDefaultState(), 3);
		world.setBlockState(new BlockPos(x + 12, y + 3, z + 8), ExtraPlanets_Blocks.jupiterBlocks.getStateFromMeta(11), 3);
		world.setBlockState(new BlockPos(x + 0, y + 3, z + 9), ExtraPlanets_Blocks.jupiterBlocks.getStateFromMeta(11), 3);
		world.setBlockState(new BlockPos(x + 1, y + 3, z + 9), Blocks.AIR.getDefaultState(), 3);
		world.setBlockState(new BlockPos(x + 2, y + 3, z + 9), Blocks.AIR.getDefaultState(), 3);
		world.setBlockState(new BlockPos(x + 3, y + 3, z + 9), Blocks.AIR.getDefaultState(), 3);
		world.setBlockState(new BlockPos(x + 4, y + 3, z + 9), Blocks.AIR.getDefaultState(), 3);
		world.setBlockState(new BlockPos(x + 5, y + 3, z + 9), Blocks.AIR.getDefaultState(), 3);
		world.setBlockState(new BlockPos(x + 6, y + 3, z + 9), Blocks.AIR.getDefaultState(), 3);
		world.setBlockState(new BlockPos(x + 7, y + 3, z + 9), Blocks.AIR.getDefaultState(), 3);
		world.setBlockState(new BlockPos(x + 8, y + 3, z + 9), Blocks.AIR.getDefaultState(), 3);
		world.setBlockState(new BlockPos(x + 9, y + 3, z + 9), Blocks.AIR.getDefaultState(), 3);
		world.setBlockState(new BlockPos(x + 10, y + 3, z + 9), Blocks.AIR.getDefaultState(), 3);
		world.setBlockState(new BlockPos(x + 11, y + 3, z + 9), Blocks.AIR.getDefaultState(), 3);
		world.setBlockState(new BlockPos(x + 12, y + 3, z + 9), ExtraPlanets_Blocks.jupiterBlocks.getStateFromMeta(11), 3);
		world.setBlockState(new BlockPos(x + 1, y + 3, z + 10), ExtraPlanets_Blocks.jupiterBlocks.getStateFromMeta(11), 3);
		world.setBlockState(new BlockPos(x + 2, y + 3, z + 10), ExtraPlanets_Blocks.jupiterBlocks.getStateFromMeta(11), 3);
		world.setBlockState(new BlockPos(x + 3, y + 3, z + 10), ExtraPlanets_Blocks.jupiterBlocks.getStateFromMeta(11), 3);
		world.setBlockState(new BlockPos(x + 4, y + 3, z + 10), ExtraPlanets_Blocks.jupiterBlocks.getStateFromMeta(11), 3);
		world.setBlockState(new BlockPos(x + 5, y + 3, z + 10), Blocks.AIR.getDefaultState(), 3);
		world.setBlockState(new BlockPos(x + 6, y + 3, z + 10), Blocks.AIR.getDefaultState(), 3);
		world.setBlockState(new BlockPos(x + 7, y + 3, z + 10), Blocks.AIR.getDefaultState(), 3);
		world.setBlockState(new BlockPos(x + 8, y + 3, z + 10), ExtraPlanets_Blocks.jupiterBlocks.getStateFromMeta(11), 3);
		world.setBlockState(new BlockPos(x + 9, y + 3, z + 10), ExtraPlanets_Blocks.jupiterBlocks.getStateFromMeta(11), 3);
		world.setBlockState(new BlockPos(x + 10, y + 3, z + 10), ExtraPlanets_Blocks.jupiterBlocks.getStateFromMeta(11), 3);
		world.setBlockState(new BlockPos(x + 11, y + 3, z + 10), ExtraPlanets_Blocks.jupiterBlocks.getStateFromMeta(11), 3);
		world.setBlockState(new BlockPos(x + 5, y + 3, z + 11), ExtraPlanets_Blocks.jupiterBlocks.getStateFromMeta(11), 3);
		world.setBlockState(new BlockPos(x + 6, y + 3, z + 11), ExtraPlanets_Blocks.jupiterBlocks.getStateFromMeta(11), 3);
		world.setBlockState(new BlockPos(x + 7, y + 3, z + 11), ExtraPlanets_Blocks.jupiterBlocks.getStateFromMeta(11), 3);
		world.setBlockState(new BlockPos(x + 5, y + 4, z + 1), Blocks.STONE_SLAB.getStateFromMeta(7), 3);
		world.setBlockState(new BlockPos(x + 6, y + 4, z + 1), Blocks.STONE_SLAB.getStateFromMeta(7), 3);
		world.setBlockState(new BlockPos(x + 7, y + 4, z + 1), Blocks.STONE_SLAB.getStateFromMeta(7), 3);
		world.setBlockState(new BlockPos(x + 1, y + 4, z + 2), Blocks.STONE_SLAB.getStateFromMeta(7), 3);
		world.setBlockState(new BlockPos(x + 2, y + 4, z + 2), Blocks.STONE_SLAB.getStateFromMeta(7), 3);
		world.setBlockState(new BlockPos(x + 3, y + 4, z + 2), Blocks.STONE_SLAB.getStateFromMeta(7), 3);
		world.setBlockState(new BlockPos(x + 4, y + 4, z + 2), Blocks.STONE_SLAB.getStateFromMeta(7), 3);
		world.setBlockState(new BlockPos(x + 5, y + 4, z + 2), Blocks.STONE_SLAB.getStateFromMeta(7), 3);
		world.setBlockState(new BlockPos(x + 6, y + 4, z + 2), Blocks.STONE_SLAB.getStateFromMeta(7), 3);
		world.setBlockState(new BlockPos(x + 7, y + 4, z + 2), Blocks.STONE_SLAB.getStateFromMeta(7), 3);
		world.setBlockState(new BlockPos(x + 8, y + 4, z + 2), Blocks.STONE_SLAB.getStateFromMeta(7), 3);
		world.setBlockState(new BlockPos(x + 9, y + 4, z + 2), Blocks.STONE_SLAB.getStateFromMeta(7), 3);
		world.setBlockState(new BlockPos(x + 10, y + 4, z + 2), Blocks.STONE_SLAB.getStateFromMeta(7), 3);
		world.setBlockState(new BlockPos(x + 11, y + 4, z + 2), Blocks.STONE_SLAB.getStateFromMeta(7), 3);
		world.setBlockState(new BlockPos(x + 1, y + 4, z + 3), Blocks.STONE_SLAB.getStateFromMeta(7), 3);
		world.setBlockState(new BlockPos(x + 2, y + 4, z + 3), Blocks.DOUBLE_STONE_SLAB.getStateFromMeta(7), 3);
		world.setBlockState(new BlockPos(x + 3, y + 4, z + 3), Blocks.DOUBLE_STONE_SLAB.getStateFromMeta(7), 3);
		world.setBlockState(new BlockPos(x + 4, y + 4, z + 3), Blocks.DOUBLE_STONE_SLAB.getStateFromMeta(7), 3);
		world.setBlockState(new BlockPos(x + 5, y + 4, z + 3), Blocks.STONE_SLAB.getStateFromMeta(7), 3);
		world.setBlockState(new BlockPos(x + 6, y + 4, z + 3), Blocks.STONE_SLAB.getStateFromMeta(7), 3);
		world.setBlockState(new BlockPos(x + 7, y + 4, z + 3), Blocks.STONE_SLAB.getStateFromMeta(7), 3);
		world.setBlockState(new BlockPos(x + 8, y + 4, z + 3), Blocks.DOUBLE_STONE_SLAB.getStateFromMeta(7), 3);
		world.setBlockState(new BlockPos(x + 9, y + 4, z + 3), Blocks.DOUBLE_STONE_SLAB.getStateFromMeta(7), 3);
		world.setBlockState(new BlockPos(x + 10, y + 4, z + 3), Blocks.DOUBLE_STONE_SLAB.getStateFromMeta(7), 3);
		world.setBlockState(new BlockPos(x + 11, y + 4, z + 3), Blocks.STONE_SLAB.getStateFromMeta(7), 3);
		world.setBlockState(new BlockPos(x + 1, y + 4, z + 4), Blocks.STONE_SLAB.getStateFromMeta(7), 3);
		world.setBlockState(new BlockPos(x + 2, y + 4, z + 4), Blocks.DOUBLE_STONE_SLAB.getStateFromMeta(7), 3);
		world.setBlockState(new BlockPos(x + 3, y + 4, z + 4), Blocks.REDSTONE_LAMP.getDefaultState(), 3);
		world.setBlockState(new BlockPos(x + 4, y + 4, z + 4), Blocks.DOUBLE_STONE_SLAB.getStateFromMeta(7), 3);
		world.setBlockState(new BlockPos(x + 5, y + 4, z + 4), Blocks.STONE_SLAB.getStateFromMeta(7), 3);
		world.setBlockState(new BlockPos(x + 6, y + 4, z + 4), Blocks.STONE_SLAB.getStateFromMeta(7), 3);
		world.setBlockState(new BlockPos(x + 7, y + 4, z + 4), Blocks.STONE_SLAB.getStateFromMeta(7), 3);
		world.setBlockState(new BlockPos(x + 8, y + 4, z + 4), Blocks.DOUBLE_STONE_SLAB.getStateFromMeta(7), 3);
		world.setBlockState(new BlockPos(x + 9, y + 4, z + 4), Blocks.REDSTONE_LAMP.getDefaultState(), 3);
		world.setBlockState(new BlockPos(x + 10, y + 4, z + 4), Blocks.DOUBLE_STONE_SLAB.getStateFromMeta(7), 3);
		world.setBlockState(new BlockPos(x + 11, y + 4, z + 4), Blocks.STONE_SLAB.getStateFromMeta(7), 3);
		world.setBlockState(new BlockPos(x + 12, y + 4, z + 4), Blocks.STONE_SLAB.getStateFromMeta(7), 3);
		world.setBlockState(new BlockPos(x + 1, y + 4, z + 5), Blocks.STONE_SLAB.getStateFromMeta(7), 3);
		world.setBlockState(new BlockPos(x + 2, y + 4, z + 5), Blocks.DOUBLE_STONE_SLAB.getStateFromMeta(7), 3);
		world.setBlockState(new BlockPos(x + 3, y + 4, z + 5), Blocks.DOUBLE_STONE_SLAB.getStateFromMeta(7), 3);
		world.setBlockState(new BlockPos(x + 4, y + 4, z + 5), Blocks.DOUBLE_STONE_SLAB.getStateFromMeta(7), 3);
		world.setBlockState(new BlockPos(x + 5, y + 4, z + 5), Blocks.STONE_SLAB.getStateFromMeta(7), 3);
		world.setBlockState(new BlockPos(x + 6, y + 4, z + 5), Blocks.STONE_SLAB.getStateFromMeta(7), 3);
		world.setBlockState(new BlockPos(x + 7, y + 4, z + 5), Blocks.STONE_SLAB.getStateFromMeta(7), 3);
		world.setBlockState(new BlockPos(x + 8, y + 4, z + 5), Blocks.DOUBLE_STONE_SLAB.getStateFromMeta(7), 3);
		world.setBlockState(new BlockPos(x + 9, y + 4, z + 5), Blocks.DOUBLE_STONE_SLAB.getStateFromMeta(7), 3);
		world.setBlockState(new BlockPos(x + 10, y + 4, z + 5), Blocks.DOUBLE_STONE_SLAB.getStateFromMeta(7), 3);
		world.setBlockState(new BlockPos(x + 11, y + 4, z + 5), Blocks.STONE_SLAB.getStateFromMeta(7), 3);
		world.setBlockState(new BlockPos(x + 12, y + 4, z + 5), Blocks.STONE_SLAB.getStateFromMeta(7), 3);
		world.setBlockState(new BlockPos(x + 1, y + 4, z + 6), Blocks.STONE_SLAB.getStateFromMeta(7), 3);
		world.setBlockState(new BlockPos(x + 2, y + 4, z + 6), Blocks.DOUBLE_STONE_SLAB.getStateFromMeta(7), 3);
		world.setBlockState(new BlockPos(x + 3, y + 4, z + 6), Blocks.DOUBLE_STONE_SLAB.getStateFromMeta(7), 3);
		world.setBlockState(new BlockPos(x + 4, y + 4, z + 6), Blocks.DOUBLE_STONE_SLAB.getStateFromMeta(7), 3);
		world.setBlockState(new BlockPos(x + 5, y + 4, z + 6), Blocks.STONE_SLAB.getStateFromMeta(7), 3);
		world.setBlockState(new BlockPos(x + 6, y + 4, z + 6), Blocks.STONE_SLAB.getStateFromMeta(7), 3);
		world.setBlockState(new BlockPos(x + 7, y + 4, z + 6), Blocks.STONE_SLAB.getStateFromMeta(7), 3);
		world.setBlockState(new BlockPos(x + 8, y + 4, z + 6), Blocks.DOUBLE_STONE_SLAB.getStateFromMeta(7), 3);
		world.setBlockState(new BlockPos(x + 9, y + 4, z + 6), Blocks.DOUBLE_STONE_SLAB.getStateFromMeta(7), 3);
		world.setBlockState(new BlockPos(x + 10, y + 4, z + 6), Blocks.DOUBLE_STONE_SLAB.getStateFromMeta(7), 3);
		world.setBlockState(new BlockPos(x + 11, y + 4, z + 6), Blocks.STONE_SLAB.getStateFromMeta(7), 3);
		world.setBlockState(new BlockPos(x + 12, y + 4, z + 6), Blocks.STONE_SLAB.getStateFromMeta(7), 3);
		world.setBlockState(new BlockPos(x + 1, y + 4, z + 7), Blocks.STONE_SLAB.getStateFromMeta(7), 3);
		world.setBlockState(new BlockPos(x + 2, y + 4, z + 7), Blocks.DOUBLE_STONE_SLAB.getStateFromMeta(7), 3);
		world.setBlockState(new BlockPos(x + 3, y + 4, z + 7), Blocks.REDSTONE_LAMP.getDefaultState(), 3);
		world.setBlockState(new BlockPos(x + 4, y + 4, z + 7), Blocks.DOUBLE_STONE_SLAB.getStateFromMeta(7), 3);
		world.setBlockState(new BlockPos(x + 5, y + 4, z + 7), Blocks.STONE_SLAB.getStateFromMeta(7), 3);
		world.setBlockState(new BlockPos(x + 6, y + 4, z + 7), Blocks.STONE_SLAB.getStateFromMeta(7), 3);
		world.setBlockState(new BlockPos(x + 7, y + 4, z + 7), Blocks.STONE_SLAB.getStateFromMeta(7), 3);
		world.setBlockState(new BlockPos(x + 8, y + 4, z + 7), Blocks.DOUBLE_STONE_SLAB.getStateFromMeta(7), 3);
		world.setBlockState(new BlockPos(x + 9, y + 4, z + 7), Blocks.REDSTONE_LAMP.getDefaultState(), 3);
		world.setBlockState(new BlockPos(x + 10, y + 4, z + 7), Blocks.DOUBLE_STONE_SLAB.getStateFromMeta(7), 3);
		world.setBlockState(new BlockPos(x + 11, y + 4, z + 7), Blocks.STONE_SLAB.getStateFromMeta(7), 3);
		world.setBlockState(new BlockPos(x + 12, y + 4, z + 7), Blocks.STONE_SLAB.getStateFromMeta(7), 3);
		world.setBlockState(new BlockPos(x + 1, y + 4, z + 8), Blocks.STONE_SLAB.getStateFromMeta(7), 3);
		world.setBlockState(new BlockPos(x + 2, y + 4, z + 8), Blocks.DOUBLE_STONE_SLAB.getStateFromMeta(7), 3);
		world.setBlockState(new BlockPos(x + 3, y + 4, z + 8), Blocks.DOUBLE_STONE_SLAB.getStateFromMeta(7), 3);
		world.setBlockState(new BlockPos(x + 4, y + 4, z + 8), Blocks.DOUBLE_STONE_SLAB.getStateFromMeta(7), 3);
		world.setBlockState(new BlockPos(x + 5, y + 4, z + 8), Blocks.STONE_SLAB.getStateFromMeta(7), 3);
		world.setBlockState(new BlockPos(x + 6, y + 4, z + 8), Blocks.STONE_SLAB.getStateFromMeta(7), 3);
		world.setBlockState(new BlockPos(x + 7, y + 4, z + 8), Blocks.STONE_SLAB.getStateFromMeta(7), 3);
		world.setBlockState(new BlockPos(x + 8, y + 4, z + 8), Blocks.DOUBLE_STONE_SLAB.getStateFromMeta(7), 3);
		world.setBlockState(new BlockPos(x + 9, y + 4, z + 8), Blocks.DOUBLE_STONE_SLAB.getStateFromMeta(7), 3);
		world.setBlockState(new BlockPos(x + 10, y + 4, z + 8), Blocks.DOUBLE_STONE_SLAB.getStateFromMeta(7), 3);
		world.setBlockState(new BlockPos(x + 11, y + 4, z + 8), Blocks.STONE_SLAB.getStateFromMeta(7), 3);
		world.setBlockState(new BlockPos(x + 1, y + 4, z + 9), Blocks.STONE_SLAB.getStateFromMeta(7), 3);
		world.setBlockState(new BlockPos(x + 2, y + 4, z + 9), Blocks.STONE_SLAB.getStateFromMeta(7), 3);
		world.setBlockState(new BlockPos(x + 3, y + 4, z + 9), Blocks.STONE_SLAB.getStateFromMeta(7), 3);
		world.setBlockState(new BlockPos(x + 4, y + 4, z + 9), Blocks.STONE_SLAB.getStateFromMeta(7), 3);
		world.setBlockState(new BlockPos(x + 5, y + 4, z + 9), Blocks.STONE_SLAB.getStateFromMeta(7), 3);
		world.setBlockState(new BlockPos(x + 6, y + 4, z + 9), Blocks.STONE_SLAB.getStateFromMeta(7), 3);
		world.setBlockState(new BlockPos(x + 7, y + 4, z + 9), Blocks.STONE_SLAB.getStateFromMeta(7), 3);
		world.setBlockState(new BlockPos(x + 8, y + 4, z + 9), Blocks.STONE_SLAB.getStateFromMeta(7), 3);
		world.setBlockState(new BlockPos(x + 9, y + 4, z + 9), Blocks.STONE_SLAB.getStateFromMeta(7), 3);
		world.setBlockState(new BlockPos(x + 10, y + 4, z + 9), Blocks.STONE_SLAB.getStateFromMeta(7), 3);
		world.setBlockState(new BlockPos(x + 11, y + 4, z + 9), Blocks.STONE_SLAB.getStateFromMeta(7), 3);
		world.setBlockState(new BlockPos(x + 5, y + 4, z + 10), Blocks.STONE_SLAB.getStateFromMeta(7), 3);
		world.setBlockState(new BlockPos(x + 6, y + 4, z + 10), Blocks.STONE_SLAB.getStateFromMeta(7), 3);
		world.setBlockState(new BlockPos(x + 7, y + 4, z + 10), Blocks.STONE_SLAB.getStateFromMeta(7), 3);
		world.setBlockState(new BlockPos(x + 3, y + 3, z + 4), Blocks.LEVER.getDefaultState(), 3);
		world.setBlockState(new BlockPos(x + 9, y + 3, z + 4), Blocks.LEVER.getDefaultState(), 3);
		world.setBlockState(new BlockPos(x + 3, y + 3, z + 7), Blocks.LEVER.getDefaultState(), 3);
		world.setBlockState(new BlockPos(x + 9, y + 3, z + 7), Blocks.LEVER.getDefaultState(), 3);
		return true;

	}

	public boolean fillChests(World world, Random rand, int x, int y, int z) {
		int random = rand.nextInt(15) + 1;
		if (random < 5) {
			System.out.println("Yes Spawn Loot");
			int lastNumber = 0;
			for (int i = 0; i < rand.nextInt(4); i++) {
				int randomChests;
				do {
					randomChests = rand.nextInt(9);
				} while (lastNumber == randomChests);
				lastNumber = randomChests;
				System.out.println("Chest " + randomChests);
				TileEntityChest CHEST;
				switch (randomChests) {
				case 1:
					CHEST = (TileEntityChest) world.getTileEntity(new BlockPos(x + 6, y + 1, z + 1));

					if (CHEST != null) {
						for (int j = 0; j < CHEST.getSizeInventory(); j++) {
							CHEST.setInventorySlotContents(j, null);
						}

						ChestGenHooks info = ChestGenHooks.getInfo(ChestGenHooks.DUNGEON_CHEST);

						WeightedRandomChestContent.generateChestContents(rand, info.getItems(rand), CHEST, info.getCount(rand));
					}
					break;
				case 2:
					CHEST = (TileEntityChest) world.getTileEntity(new BlockPos(x + 6, y + 1, z + 4));

					if (CHEST != null) {
						for (int j = 0; j < CHEST.getSizeInventory(); j++) {
							CHEST.setInventorySlotContents(j, null);
						}

						ChestGenHooks info = ChestGenHooks.getInfo(ChestGenHooks.DUNGEON_CHEST);

						WeightedRandomChestContent.generateChestContents(rand, info.getItems(rand), CHEST, info.getCount(rand));
					}
					break;
				case 3:
					CHEST = (TileEntityChest) world.getTileEntity(new BlockPos(x + 6, y + 1, z + 7));

					if (CHEST != null) {
						for (int j = 0; j < CHEST.getSizeInventory(); j++) {
							CHEST.setInventorySlotContents(j, null);
						}

						ChestGenHooks info = ChestGenHooks.getInfo(ChestGenHooks.DUNGEON_CHEST);

						WeightedRandomChestContent.generateChestContents(rand, info.getItems(rand), CHEST, info.getCount(rand));
					}
					break;
				case 4:
					CHEST = (TileEntityChest) world.getTileEntity(new BlockPos(x + 6, y + 1, z + 10));

					if (CHEST != null) {
						for (int j = 0; j < CHEST.getSizeInventory(); j++) {
							CHEST.setInventorySlotContents(j, null);
						}

						ChestGenHooks info = ChestGenHooks.getInfo(ChestGenHooks.DUNGEON_CHEST);

						WeightedRandomChestContent.generateChestContents(rand, info.getItems(rand), CHEST, info.getCount(rand));
					}
					break;
				case 5:
					CHEST = (TileEntityChest) world.getTileEntity(new BlockPos(x + 6, y + 2, z + 4));

					if (CHEST != null) {
						for (int j = 0; j < CHEST.getSizeInventory(); j++) {
							CHEST.setInventorySlotContents(j, null);
						}

						ChestGenHooks info = ChestGenHooks.getInfo(ChestGenHooks.DUNGEON_CHEST);

						WeightedRandomChestContent.generateChestContents(rand, info.getItems(rand), CHEST, info.getCount(rand));
					}
					break;
				case 6:
					CHEST = (TileEntityChest) world.getTileEntity(new BlockPos(x + 6, y + 2, z + 7));

					if (CHEST != null) {
						for (int j = 0; j < CHEST.getSizeInventory(); j++) {
							CHEST.setInventorySlotContents(j, null);
						}

						ChestGenHooks info = ChestGenHooks.getInfo(ChestGenHooks.DUNGEON_CHEST);

						WeightedRandomChestContent.generateChestContents(rand, info.getItems(rand), CHEST, info.getCount(rand));
					}
					break;
				case 7:
					CHEST = (TileEntityChest) world.getTileEntity(new BlockPos(x + 6, y + 3, z + 4));

					if (CHEST != null) {
						for (int j = 0; j < CHEST.getSizeInventory(); j++) {
							CHEST.setInventorySlotContents(j, null);
						}

						ChestGenHooks info = ChestGenHooks.getInfo(ChestGenHooks.DUNGEON_CHEST);

						WeightedRandomChestContent.generateChestContents(rand, info.getItems(rand), CHEST, info.getCount(rand));
					}
					break;
				case 8:
					CHEST = (TileEntityChest) world.getTileEntity(new BlockPos(x + 6, y + 3, z + 7));

					if (CHEST != null) {
						for (int j = 0; j < CHEST.getSizeInventory(); j++) {
							CHEST.setInventorySlotContents(j, null);
						}

						ChestGenHooks info = ChestGenHooks.getInfo(ChestGenHooks.DUNGEON_CHEST);

						WeightedRandomChestContent.generateChestContents(rand, info.getItems(rand), CHEST, info.getCount(rand));
					}
					break;
				}
			}
		}
		return false;
	}
}