package com.mjr.extraplanets.world.features;

import java.util.Random;

import micdoodle8.mods.galacticraft.core.GCBlocks;
import micdoodle8.mods.galacticraft.planets.mars.world.gen.RoomTreasureMars;
import net.minecraft.init.Blocks;
import net.minecraft.item.ItemStack;
import net.minecraft.tileentity.TileEntityChest;
import net.minecraft.util.math.BlockPos;
import net.minecraft.world.World;
import net.minecraft.world.gen.feature.WorldGenerator;

import com.mjr.extraplanets.Config;
import com.mjr.extraplanets.Constants;
import com.mjr.extraplanets.blocks.ExtraPlanets_Blocks;
import com.mjr.mjrlegendslib.util.MessageUtilities;
import com.mjr.mjrlegendslib.util.WorldGenUtilities;

public class WorldGenSpaceShip extends WorldGenerator {

	public WorldGenSpaceShip() {

	}

	@Override
	public boolean generate(World world, Random rand, BlockPos position) {
		if (WorldGenUtilities.checkValidSpawn(world, position, 8, 12) == false)
			return false;
		else {
			if (Config.DEBUG_MODE)
				MessageUtilities.debugMessageToLog(Constants.modID, "Spawning Space Ship at (x, y, z)" + position.toString());
			generateStructure(world, rand, position);
			fillChests(world, rand, position);
		}
		return true;
	}

	public boolean generateStructure(World world, Random rand, BlockPos position) {
		int x = position.getX();
		int y = position.getY();
		int z = position.getZ();
		world.setBlockState(new BlockPos(x + 5, y + 0, z + 0), GCBlocks.basicBlock.getStateFromMeta(10), 3);
		world.setBlockState(new BlockPos(x + 6, y + 0, z + 0), GCBlocks.basicBlock.getStateFromMeta(11), 3);
		world.setBlockState(new BlockPos(x + 7, y + 0, z + 0), GCBlocks.basicBlock.getStateFromMeta(10), 3);
		world.setBlockState(new BlockPos(x + 2, y + 0, z + 3), GCBlocks.basicBlock.getStateFromMeta(10), 3);
		world.setBlockState(new BlockPos(x + 10, y + 0, z + 3), GCBlocks.basicBlock.getStateFromMeta(10), 3);
		world.setBlockState(new BlockPos(x + 2, y + 0, z + 4), GCBlocks.basicBlock.getStateFromMeta(11), 3);
		world.setBlockState(new BlockPos(x + 10, y + 0, z + 4), GCBlocks.basicBlock.getStateFromMeta(11), 3);
		world.setBlockState(new BlockPos(x + 2, y + 0, z + 5), GCBlocks.basicBlock.getStateFromMeta(10), 3);
		world.setBlockState(new BlockPos(x + 10, y + 0, z + 5), GCBlocks.basicBlock.getStateFromMeta(10), 3);
		world.setBlockState(new BlockPos(x + 5, y + 0, z + 8), GCBlocks.basicBlock.getStateFromMeta(10), 3);
		world.setBlockState(new BlockPos(x + 6, y + 0, z + 8), GCBlocks.basicBlock.getStateFromMeta(11), 3);
		world.setBlockState(new BlockPos(x + 7, y + 0, z + 8), GCBlocks.basicBlock.getStateFromMeta(10), 3);
		world.setBlockState(new BlockPos(x + 5, y + 1, z + 0), GCBlocks.basicBlock.getStateFromMeta(10), 3);
		world.setBlockState(new BlockPos(x + 6, y + 1, z + 0), GCBlocks.basicBlock.getStateFromMeta(11), 3);
		world.setBlockState(new BlockPos(x + 7, y + 1, z + 0), GCBlocks.basicBlock.getStateFromMeta(10), 3);
		world.setBlockState(new BlockPos(x + 2, y + 1, z + 3), GCBlocks.basicBlock.getStateFromMeta(10), 3);
		world.setBlockState(new BlockPos(x + 10, y + 1, z + 3), GCBlocks.basicBlock.getStateFromMeta(10), 3);
		world.setBlockState(new BlockPos(x + 2, y + 1, z + 4), GCBlocks.basicBlock.getStateFromMeta(11), 3);
		world.setBlockState(new BlockPos(x + 10, y + 1, z + 4), GCBlocks.basicBlock.getStateFromMeta(11), 3);
		world.setBlockState(new BlockPos(x + 2, y + 1, z + 5), GCBlocks.basicBlock.getStateFromMeta(10), 3);
		world.setBlockState(new BlockPos(x + 10, y + 1, z + 5), GCBlocks.basicBlock.getStateFromMeta(10), 3);
		world.setBlockState(new BlockPos(x + 5, y + 1, z + 8), GCBlocks.basicBlock.getStateFromMeta(10), 3);
		world.setBlockState(new BlockPos(x + 6, y + 1, z + 8), GCBlocks.basicBlock.getStateFromMeta(11), 3);
		world.setBlockState(new BlockPos(x + 7, y + 1, z + 8), GCBlocks.basicBlock.getStateFromMeta(10), 3);
		world.setBlockState(new BlockPos(x + 5, y + 2, z + 0), GCBlocks.basicBlock.getStateFromMeta(10), 3);
		world.setBlockState(new BlockPos(x + 6, y + 2, z + 0), GCBlocks.basicBlock.getStateFromMeta(11), 3);
		world.setBlockState(new BlockPos(x + 7, y + 2, z + 0), GCBlocks.basicBlock.getStateFromMeta(10), 3);
		world.setBlockState(new BlockPos(x + 2, y + 2, z + 3), GCBlocks.basicBlock.getStateFromMeta(10), 3);
		world.setBlockState(new BlockPos(x + 10, y + 2, z + 3), GCBlocks.basicBlock.getStateFromMeta(10), 3);
		world.setBlockState(new BlockPos(x + 2, y + 2, z + 4), GCBlocks.basicBlock.getStateFromMeta(11), 3);
		world.setBlockState(new BlockPos(x + 10, y + 2, z + 4), GCBlocks.basicBlock.getStateFromMeta(11), 3);
		world.setBlockState(new BlockPos(x + 2, y + 2, z + 5), GCBlocks.basicBlock.getStateFromMeta(10), 3);
		world.setBlockState(new BlockPos(x + 10, y + 2, z + 5), GCBlocks.basicBlock.getStateFromMeta(10), 3);
		world.setBlockState(new BlockPos(x + 5, y + 2, z + 8), GCBlocks.basicBlock.getStateFromMeta(10), 3);
		world.setBlockState(new BlockPos(x + 6, y + 2, z + 8), GCBlocks.basicBlock.getStateFromMeta(11), 3);
		world.setBlockState(new BlockPos(x + 7, y + 2, z + 8), GCBlocks.basicBlock.getStateFromMeta(10), 3);
		world.setBlockState(new BlockPos(x + 5, y + 3, z + 1), GCBlocks.basicBlock.getStateFromMeta(10), 3);
		world.setBlockState(new BlockPos(x + 6, y + 3, z + 1), GCBlocks.basicBlock.getStateFromMeta(11), 3);
		world.setBlockState(new BlockPos(x + 7, y + 3, z + 1), GCBlocks.basicBlock.getStateFromMeta(10), 3);
		world.setBlockState(new BlockPos(x + 2, y + 3, z + 3), GCBlocks.basicBlock.getStateFromMeta(10), 3);
		world.setBlockState(new BlockPos(x + 9, y + 3, z + 3), GCBlocks.basicBlock.getStateFromMeta(10), 3);
		world.setBlockState(new BlockPos(x + 2, y + 3, z + 4), GCBlocks.basicBlock.getStateFromMeta(11), 3);
		world.setBlockState(new BlockPos(x + 9, y + 3, z + 4), GCBlocks.basicBlock.getStateFromMeta(11), 3);
		world.setBlockState(new BlockPos(x + 2, y + 3, z + 5), GCBlocks.basicBlock.getStateFromMeta(10), 3);
		world.setBlockState(new BlockPos(x + 9, y + 3, z + 5), GCBlocks.basicBlock.getStateFromMeta(10), 3);
		world.setBlockState(new BlockPos(x + 5, y + 3, z + 7), GCBlocks.basicBlock.getStateFromMeta(10), 3);
		world.setBlockState(new BlockPos(x + 6, y + 3, z + 7), GCBlocks.basicBlock.getStateFromMeta(11), 3);
		world.setBlockState(new BlockPos(x + 7, y + 3, z + 7), GCBlocks.basicBlock.getStateFromMeta(10), 3);
		world.setBlockState(new BlockPos(x + 5, y + 4, z + 1), GCBlocks.basicBlock.getStateFromMeta(10), 3);
		world.setBlockState(new BlockPos(x + 6, y + 4, z + 1), GCBlocks.basicBlock.getStateFromMeta(11), 3);
		world.setBlockState(new BlockPos(x + 7, y + 4, z + 1), GCBlocks.basicBlock.getStateFromMeta(10), 3);
		world.setBlockState(new BlockPos(x + 3, y + 4, z + 3), GCBlocks.basicBlock.getStateFromMeta(10), 3);
		world.setBlockState(new BlockPos(x + 9, y + 4, z + 3), GCBlocks.basicBlock.getStateFromMeta(10), 3);
		world.setBlockState(new BlockPos(x + 3, y + 4, z + 4), GCBlocks.basicBlock.getStateFromMeta(11), 3);
		world.setBlockState(new BlockPos(x + 9, y + 4, z + 4), GCBlocks.basicBlock.getStateFromMeta(11), 3);
		world.setBlockState(new BlockPos(x + 3, y + 4, z + 5), GCBlocks.basicBlock.getStateFromMeta(10), 3);
		world.setBlockState(new BlockPos(x + 9, y + 4, z + 5), GCBlocks.basicBlock.getStateFromMeta(10), 3);
		world.setBlockState(new BlockPos(x + 5, y + 4, z + 7), GCBlocks.basicBlock.getStateFromMeta(10), 3);
		world.setBlockState(new BlockPos(x + 6, y + 4, z + 7), GCBlocks.basicBlock.getStateFromMeta(11), 3);
		world.setBlockState(new BlockPos(x + 7, y + 4, z + 7), GCBlocks.basicBlock.getStateFromMeta(10), 3);
		world.setBlockState(new BlockPos(x + 5, y + 5, z + 1), GCBlocks.basicBlock.getStateFromMeta(10), 3);
		world.setBlockState(new BlockPos(x + 6, y + 5, z + 1), GCBlocks.basicBlock.getStateFromMeta(11), 3);
		world.setBlockState(new BlockPos(x + 7, y + 5, z + 1), GCBlocks.basicBlock.getStateFromMeta(10), 3);
		world.setBlockState(new BlockPos(x + 4, y + 5, z + 2), GCBlocks.basicBlock.getStateFromMeta(11), 3);
		world.setBlockState(new BlockPos(x + 5, y + 5, z + 2), GCBlocks.basicBlock.getStateFromMeta(10), 3);
		world.setBlockState(new BlockPos(x + 6, y + 5, z + 2), GCBlocks.basicBlock.getStateFromMeta(10), 3);
		world.setBlockState(new BlockPos(x + 7, y + 5, z + 2), GCBlocks.basicBlock.getStateFromMeta(10), 3);
		world.setBlockState(new BlockPos(x + 8, y + 5, z + 2), GCBlocks.basicBlock.getStateFromMeta(11), 3);
		world.setBlockState(new BlockPos(x + 4, y + 5, z + 3), GCBlocks.basicBlock.getStateFromMeta(10), 3);
		world.setBlockState(new BlockPos(x + 8, y + 5, z + 3), GCBlocks.basicBlock.getStateFromMeta(11), 3);
		world.setBlockState(new BlockPos(x + 4, y + 5, z + 4), GCBlocks.basicBlock.getStateFromMeta(10), 3);
		world.setBlockState(new BlockPos(x + 8, y + 5, z + 4), GCBlocks.basicBlock.getStateFromMeta(11), 3);
		world.setBlockState(new BlockPos(x + 4, y + 5, z + 5), GCBlocks.basicBlock.getStateFromMeta(10), 3);
		world.setBlockState(new BlockPos(x + 8, y + 5, z + 5), GCBlocks.basicBlock.getStateFromMeta(11), 3);
		world.setBlockState(new BlockPos(x + 4, y + 5, z + 6), GCBlocks.basicBlock.getStateFromMeta(11), 3);
		world.setBlockState(new BlockPos(x + 5, y + 5, z + 6), GCBlocks.basicBlock.getStateFromMeta(11), 3);
		world.setBlockState(new BlockPos(x + 6, y + 5, z + 6), GCBlocks.basicBlock.getStateFromMeta(11), 3);
		world.setBlockState(new BlockPos(x + 7, y + 5, z + 6), GCBlocks.basicBlock.getStateFromMeta(11), 3);
		world.setBlockState(new BlockPos(x + 8, y + 5, z + 6), GCBlocks.basicBlock.getStateFromMeta(11), 3);
		world.setBlockState(new BlockPos(x + 5, y + 5, z + 7), GCBlocks.basicBlock.getStateFromMeta(10), 3);
		world.setBlockState(new BlockPos(x + 6, y + 5, z + 7), GCBlocks.basicBlock.getStateFromMeta(11), 3);
		world.setBlockState(new BlockPos(x + 7, y + 5, z + 7), GCBlocks.basicBlock.getStateFromMeta(10), 3);
		world.setBlockState(new BlockPos(x + 4, y + 6, z + 2), GCBlocks.basicBlock.getStateFromMeta(11), 3);
		world.setBlockState(new BlockPos(x + 5, y + 6, z + 2), GCBlocks.basicBlock.getStateFromMeta(10), 3);
		world.setBlockState(new BlockPos(x + 6, y + 6, z + 2), GCBlocks.basicBlock.getStateFromMeta(10), 3);
		world.setBlockState(new BlockPos(x + 7, y + 6, z + 2), GCBlocks.basicBlock.getStateFromMeta(10), 3);
		world.setBlockState(new BlockPos(x + 8, y + 6, z + 2), GCBlocks.basicBlock.getStateFromMeta(11), 3);
		world.setBlockState(new BlockPos(x + 4, y + 6, z + 3), GCBlocks.basicBlock.getStateFromMeta(10), 3);
		world.setBlockState(new BlockPos(x + 8, y + 6, z + 3), GCBlocks.basicBlock.getStateFromMeta(10), 3);
		world.setBlockState(new BlockPos(x + 4, y + 6, z + 4), GCBlocks.basicBlock.getStateFromMeta(10), 3);
		world.setBlockState(new BlockPos(x + 8, y + 6, z + 4), GCBlocks.basicBlock.getStateFromMeta(10), 3);
		world.setBlockState(new BlockPos(x + 4, y + 6, z + 5), GCBlocks.basicBlock.getStateFromMeta(10), 3);
		world.setBlockState(new BlockPos(x + 8, y + 6, z + 5), GCBlocks.basicBlock.getStateFromMeta(10), 3);
		world.setBlockState(new BlockPos(x + 4, y + 6, z + 6), GCBlocks.basicBlock.getStateFromMeta(11), 3);
		world.setBlockState(new BlockPos(x + 5, y + 6, z + 6), GCBlocks.basicBlock.getStateFromMeta(10), 3);
		world.setBlockState(new BlockPos(x + 6, y + 6, z + 6), GCBlocks.basicBlock.getStateFromMeta(10), 3);
		world.setBlockState(new BlockPos(x + 7, y + 6, z + 6), GCBlocks.basicBlock.getStateFromMeta(10), 3);
		world.setBlockState(new BlockPos(x + 8, y + 6, z + 6), GCBlocks.basicBlock.getStateFromMeta(11), 3);
		world.setBlockState(new BlockPos(x + 4, y + 7, z + 2), GCBlocks.basicBlock.getStateFromMeta(11), 3);
		world.setBlockState(new BlockPos(x + 5, y + 7, z + 2), GCBlocks.basicBlock.getStateFromMeta(10), 3);
		world.setBlockState(new BlockPos(x + 6, y + 7, z + 2), GCBlocks.basicBlock.getStateFromMeta(10), 3);
		world.setBlockState(new BlockPos(x + 7, y + 7, z + 2), GCBlocks.basicBlock.getStateFromMeta(10), 3);
		world.setBlockState(new BlockPos(x + 8, y + 7, z + 2), GCBlocks.basicBlock.getStateFromMeta(11), 3);
		world.setBlockState(new BlockPos(x + 4, y + 7, z + 3), GCBlocks.basicBlock.getStateFromMeta(10), 3);
		world.setBlockState(new BlockPos(x + 8, y + 7, z + 3), GCBlocks.basicBlock.getStateFromMeta(10), 3);
		world.setBlockState(new BlockPos(x + 4, y + 7, z + 4), GCBlocks.basicBlock.getStateFromMeta(10), 3);
		world.setBlockState(new BlockPos(x + 8, y + 7, z + 4), GCBlocks.basicBlock.getStateFromMeta(10), 3);
		world.setBlockState(new BlockPos(x + 4, y + 7, z + 5), GCBlocks.basicBlock.getStateFromMeta(10), 3);
		world.setBlockState(new BlockPos(x + 8, y + 7, z + 5), GCBlocks.basicBlock.getStateFromMeta(10), 3);
		world.setBlockState(new BlockPos(x + 4, y + 7, z + 6), GCBlocks.basicBlock.getStateFromMeta(11), 3);
		world.setBlockState(new BlockPos(x + 5, y + 7, z + 6), GCBlocks.basicBlock.getStateFromMeta(10), 3);
		world.setBlockState(new BlockPos(x + 6, y + 7, z + 6), GCBlocks.basicBlock.getStateFromMeta(10), 3);
		world.setBlockState(new BlockPos(x + 7, y + 7, z + 6), GCBlocks.basicBlock.getStateFromMeta(10), 3);
		world.setBlockState(new BlockPos(x + 8, y + 7, z + 6), GCBlocks.basicBlock.getStateFromMeta(11), 3);
		world.setBlockState(new BlockPos(x + 4, y + 8, z + 2), GCBlocks.basicBlock.getStateFromMeta(11), 3);
		world.setBlockState(new BlockPos(x + 5, y + 8, z + 2), GCBlocks.basicBlock.getStateFromMeta(10), 3);
		world.setBlockState(new BlockPos(x + 6, y + 8, z + 2), GCBlocks.basicBlock.getStateFromMeta(10), 3);
		world.setBlockState(new BlockPos(x + 7, y + 8, z + 2), GCBlocks.basicBlock.getStateFromMeta(10), 3);
		world.setBlockState(new BlockPos(x + 8, y + 8, z + 2), GCBlocks.basicBlock.getStateFromMeta(11), 3);
		world.setBlockState(new BlockPos(x + 4, y + 8, z + 3), GCBlocks.basicBlock.getStateFromMeta(10), 3);
		world.setBlockState(new BlockPos(x + 8, y + 8, z + 3), GCBlocks.basicBlock.getStateFromMeta(10), 3);
		world.setBlockState(new BlockPos(x + 4, y + 8, z + 4), GCBlocks.basicBlock.getStateFromMeta(10), 3);
		world.setBlockState(new BlockPos(x + 8, y + 8, z + 4), GCBlocks.basicBlock.getStateFromMeta(10), 3);
		world.setBlockState(new BlockPos(x + 4, y + 8, z + 5), GCBlocks.basicBlock.getStateFromMeta(10), 3);
		world.setBlockState(new BlockPos(x + 8, y + 8, z + 5), GCBlocks.basicBlock.getStateFromMeta(10), 3);
		world.setBlockState(new BlockPos(x + 4, y + 8, z + 6), GCBlocks.basicBlock.getStateFromMeta(11), 3);
		world.setBlockState(new BlockPos(x + 5, y + 8, z + 6), GCBlocks.basicBlock.getStateFromMeta(10), 3);
		world.setBlockState(new BlockPos(x + 6, y + 8, z + 6), GCBlocks.basicBlock.getStateFromMeta(10), 3);
		world.setBlockState(new BlockPos(x + 7, y + 8, z + 6), GCBlocks.basicBlock.getStateFromMeta(10), 3);
		world.setBlockState(new BlockPos(x + 8, y + 8, z + 6), GCBlocks.basicBlock.getStateFromMeta(11), 3);
		world.setBlockState(new BlockPos(x + 4, y + 9, z + 2), GCBlocks.basicBlock.getStateFromMeta(11), 3);
		world.setBlockState(new BlockPos(x + 5, y + 9, z + 2), GCBlocks.basicBlock.getStateFromMeta(10), 3);
		world.setBlockState(new BlockPos(x + 6, y + 9, z + 2), GCBlocks.basicBlock.getStateFromMeta(10), 3);
		world.setBlockState(new BlockPos(x + 7, y + 9, z + 2), GCBlocks.basicBlock.getStateFromMeta(10), 3);
		world.setBlockState(new BlockPos(x + 8, y + 9, z + 2), GCBlocks.basicBlock.getStateFromMeta(11), 3);
		world.setBlockState(new BlockPos(x + 4, y + 9, z + 3), GCBlocks.basicBlock.getStateFromMeta(10), 3);
		world.setBlockState(new BlockPos(x + 8, y + 9, z + 3), GCBlocks.basicBlock.getStateFromMeta(10), 3);
		world.setBlockState(new BlockPos(x + 0, y + 9, z + 4), GCBlocks.basicBlock.getStateFromMeta(11), 3);
		world.setBlockState(new BlockPos(x + 4, y + 9, z + 4), GCBlocks.basicBlock.getStateFromMeta(10), 3);
		world.setBlockState(new BlockPos(x + 8, y + 9, z + 4), GCBlocks.basicBlock.getStateFromMeta(10), 3);
		world.setBlockState(new BlockPos(x + 12, y + 9, z + 4), GCBlocks.basicBlock.getStateFromMeta(11), 3);
		world.setBlockState(new BlockPos(x + 4, y + 9, z + 5), GCBlocks.basicBlock.getStateFromMeta(10), 3);
		world.setBlockState(new BlockPos(x + 8, y + 9, z + 5), GCBlocks.basicBlock.getStateFromMeta(10), 3);
		world.setBlockState(new BlockPos(x + 4, y + 9, z + 6), GCBlocks.basicBlock.getStateFromMeta(11), 3);
		world.setBlockState(new BlockPos(x + 5, y + 9, z + 6), GCBlocks.basicBlock.getStateFromMeta(10), 3);
		world.setBlockState(new BlockPos(x + 6, y + 9, z + 6), GCBlocks.basicBlock.getStateFromMeta(10), 3);
		world.setBlockState(new BlockPos(x + 7, y + 9, z + 6), GCBlocks.basicBlock.getStateFromMeta(10), 3);
		world.setBlockState(new BlockPos(x + 8, y + 9, z + 6), GCBlocks.basicBlock.getStateFromMeta(11), 3);
		world.setBlockState(new BlockPos(x + 4, y + 10, z + 2), GCBlocks.basicBlock.getStateFromMeta(11), 3);
		world.setBlockState(new BlockPos(x + 5, y + 10, z + 2), GCBlocks.basicBlock.getStateFromMeta(10), 3);
		world.setBlockState(new BlockPos(x + 6, y + 10, z + 2), GCBlocks.basicBlock.getStateFromMeta(10), 3);
		world.setBlockState(new BlockPos(x + 7, y + 10, z + 2), GCBlocks.basicBlock.getStateFromMeta(10), 3);
		world.setBlockState(new BlockPos(x + 8, y + 10, z + 2), GCBlocks.basicBlock.getStateFromMeta(11), 3);
		world.setBlockState(new BlockPos(x + 4, y + 10, z + 3), GCBlocks.basicBlock.getStateFromMeta(10), 3);
		world.setBlockState(new BlockPos(x + 8, y + 10, z + 3), GCBlocks.basicBlock.getStateFromMeta(10), 3);
		world.setBlockState(new BlockPos(x + 0, y + 10, z + 4), GCBlocks.basicBlock.getStateFromMeta(11), 3);
		world.setBlockState(new BlockPos(x + 4, y + 10, z + 4), GCBlocks.basicBlock.getStateFromMeta(10), 3);
		world.setBlockState(new BlockPos(x + 8, y + 10, z + 4), GCBlocks.basicBlock.getStateFromMeta(10), 3);
		world.setBlockState(new BlockPos(x + 12, y + 10, z + 4), GCBlocks.basicBlock.getStateFromMeta(11), 3);
		world.setBlockState(new BlockPos(x + 4, y + 10, z + 5), GCBlocks.basicBlock.getStateFromMeta(10), 3);
		world.setBlockState(new BlockPos(x + 8, y + 10, z + 5), GCBlocks.basicBlock.getStateFromMeta(10), 3);
		world.setBlockState(new BlockPos(x + 4, y + 10, z + 6), GCBlocks.basicBlock.getStateFromMeta(11), 3);
		world.setBlockState(new BlockPos(x + 5, y + 10, z + 6), GCBlocks.basicBlock.getStateFromMeta(10), 3);
		world.setBlockState(new BlockPos(x + 6, y + 10, z + 6), GCBlocks.basicBlock.getStateFromMeta(10), 3);
		world.setBlockState(new BlockPos(x + 7, y + 10, z + 6), GCBlocks.basicBlock.getStateFromMeta(10), 3);
		world.setBlockState(new BlockPos(x + 8, y + 10, z + 6), GCBlocks.basicBlock.getStateFromMeta(11), 3);
		world.setBlockState(new BlockPos(x + 4, y + 11, z + 2), GCBlocks.basicBlock.getStateFromMeta(11), 3);
		world.setBlockState(new BlockPos(x + 5, y + 11, z + 2), GCBlocks.basicBlock.getStateFromMeta(11), 3);
		world.setBlockState(new BlockPos(x + 6, y + 11, z + 2), GCBlocks.basicBlock.getStateFromMeta(11), 3);
		world.setBlockState(new BlockPos(x + 7, y + 11, z + 2), GCBlocks.basicBlock.getStateFromMeta(11), 3);
		world.setBlockState(new BlockPos(x + 8, y + 11, z + 2), GCBlocks.basicBlock.getStateFromMeta(11), 3);
		world.setBlockState(new BlockPos(x + 4, y + 11, z + 3), GCBlocks.basicBlock.getStateFromMeta(11), 3);
		world.setBlockState(new BlockPos(x + 5, y + 11, z + 3), GCBlocks.basicBlock.getStateFromMeta(10), 3);
		world.setBlockState(new BlockPos(x + 6, y + 11, z + 3), GCBlocks.basicBlock.getStateFromMeta(10), 3);
		world.setBlockState(new BlockPos(x + 7, y + 11, z + 3), GCBlocks.basicBlock.getStateFromMeta(10), 3);
		world.setBlockState(new BlockPos(x + 8, y + 11, z + 3), GCBlocks.basicBlock.getStateFromMeta(11), 3);
		world.setBlockState(new BlockPos(x + 0, y + 11, z + 4), GCBlocks.basicBlock.getStateFromMeta(11), 3);
		world.setBlockState(new BlockPos(x + 4, y + 11, z + 4), GCBlocks.basicBlock.getStateFromMeta(11), 3);
		world.setBlockState(new BlockPos(x + 5, y + 11, z + 4), GCBlocks.basicBlock.getStateFromMeta(10), 3);
		world.setBlockState(new BlockPos(x + 6, y + 11, z + 4), GCBlocks.basicBlock.getStateFromMeta(10), 3);
		world.setBlockState(new BlockPos(x + 7, y + 11, z + 4), GCBlocks.basicBlock.getStateFromMeta(10), 3);
		world.setBlockState(new BlockPos(x + 8, y + 11, z + 4), GCBlocks.basicBlock.getStateFromMeta(11), 3);
		world.setBlockState(new BlockPos(x + 12, y + 11, z + 4), GCBlocks.basicBlock.getStateFromMeta(11), 3);
		world.setBlockState(new BlockPos(x + 4, y + 11, z + 5), GCBlocks.basicBlock.getStateFromMeta(11), 3);
		world.setBlockState(new BlockPos(x + 5, y + 11, z + 5), GCBlocks.basicBlock.getStateFromMeta(10), 3);
		world.setBlockState(new BlockPos(x + 6, y + 11, z + 5), GCBlocks.basicBlock.getStateFromMeta(10), 3);
		world.setBlockState(new BlockPos(x + 7, y + 11, z + 5), GCBlocks.basicBlock.getStateFromMeta(10), 3);
		world.setBlockState(new BlockPos(x + 8, y + 11, z + 5), GCBlocks.basicBlock.getStateFromMeta(11), 3);
		world.setBlockState(new BlockPos(x + 4, y + 11, z + 6), GCBlocks.basicBlock.getStateFromMeta(11), 3);
		world.setBlockState(new BlockPos(x + 5, y + 11, z + 6), GCBlocks.basicBlock.getStateFromMeta(11), 3);
		world.setBlockState(new BlockPos(x + 6, y + 11, z + 6), GCBlocks.basicBlock.getStateFromMeta(11), 3);
		world.setBlockState(new BlockPos(x + 7, y + 11, z + 6), GCBlocks.basicBlock.getStateFromMeta(11), 3);
		world.setBlockState(new BlockPos(x + 8, y + 11, z + 6), GCBlocks.basicBlock.getStateFromMeta(11), 3);
		world.setBlockState(new BlockPos(x + 4, y + 12, z + 2), GCBlocks.basicBlock.getStateFromMeta(11), 3);
		world.setBlockState(new BlockPos(x + 5, y + 12, z + 2), GCBlocks.basicBlock.getStateFromMeta(10), 3);
		world.setBlockState(new BlockPos(x + 6, y + 12, z + 2), GCBlocks.spaceGlassClear.getDefaultState(), 3);
		world.setBlockState(new BlockPos(x + 7, y + 12, z + 2), GCBlocks.basicBlock.getStateFromMeta(10), 3);
		world.setBlockState(new BlockPos(x + 8, y + 12, z + 2), GCBlocks.basicBlock.getStateFromMeta(11), 3);
		world.setBlockState(new BlockPos(x + 4, y + 12, z + 3), GCBlocks.basicBlock.getStateFromMeta(10), 3);
		world.setBlockState(new BlockPos(x + 5, y + 12, z + 3), GCBlocks.basicBlock.getStateFromMeta(12), 3);
		world.setBlockState(new BlockPos(x + 7, y + 12, z + 3), GCBlocks.basicBlock.getStateFromMeta(12), 3);
		world.setBlockState(new BlockPos(x + 8, y + 12, z + 3), GCBlocks.basicBlock.getStateFromMeta(10), 3);
		world.setBlockState(new BlockPos(x + 0, y + 12, z + 4), GCBlocks.basicBlock.getStateFromMeta(11), 3);
		world.setBlockState(new BlockPos(x + 4, y + 12, z + 4), GCBlocks.spaceGlassClear.getDefaultState(), 3);
		world.setBlockState(new BlockPos(x + 6, y + 12, z + 4), GCBlocks.basicBlock.getStateFromMeta(12), 3);
		world.setBlockState(new BlockPos(x + 8, y + 12, z + 4), GCBlocks.spaceGlassClear.getDefaultState(), 3);
		world.setBlockState(new BlockPos(x + 12, y + 12, z + 4), GCBlocks.basicBlock.getStateFromMeta(11), 3);
		world.setBlockState(new BlockPos(x + 4, y + 12, z + 5), GCBlocks.basicBlock.getStateFromMeta(10), 3);
		world.setBlockState(new BlockPos(x + 5, y + 12, z + 5), GCBlocks.basicBlock.getStateFromMeta(12), 3);
		world.setBlockState(new BlockPos(x + 7, y + 12, z + 5), GCBlocks.basicBlock.getStateFromMeta(12), 3);
		world.setBlockState(new BlockPos(x + 8, y + 12, z + 5), GCBlocks.basicBlock.getStateFromMeta(10), 3);
		world.setBlockState(new BlockPos(x + 4, y + 12, z + 6), GCBlocks.basicBlock.getStateFromMeta(11), 3);
		world.setBlockState(new BlockPos(x + 5, y + 12, z + 6), GCBlocks.basicBlock.getStateFromMeta(10), 3);
		world.setBlockState(new BlockPos(x + 6, y + 12, z + 6), GCBlocks.spaceGlassClear.getDefaultState(), 3);
		world.setBlockState(new BlockPos(x + 7, y + 12, z + 6), GCBlocks.basicBlock.getStateFromMeta(10), 3);
		world.setBlockState(new BlockPos(x + 8, y + 12, z + 6), GCBlocks.basicBlock.getStateFromMeta(11), 3);
		world.setBlockState(new BlockPos(x + 4, y + 13, z + 2), GCBlocks.basicBlock.getStateFromMeta(11), 3);
		world.setBlockState(new BlockPos(x + 5, y + 13, z + 2), GCBlocks.basicBlock.getStateFromMeta(10), 3);
		world.setBlockState(new BlockPos(x + 6, y + 13, z + 2), GCBlocks.spaceGlassClear.getDefaultState(), 3);
		world.setBlockState(new BlockPos(x + 7, y + 13, z + 2), GCBlocks.basicBlock.getStateFromMeta(10), 3);
		world.setBlockState(new BlockPos(x + 8, y + 13, z + 2), GCBlocks.basicBlock.getStateFromMeta(11), 3);
		world.setBlockState(new BlockPos(x + 4, y + 13, z + 3), GCBlocks.basicBlock.getStateFromMeta(10), 3);
		world.setBlockState(new BlockPos(x + 5, y + 13, z + 3), GCBlocks.basicBlock.getStateFromMeta(12), 3);
		world.setBlockState(new BlockPos(x + 7, y + 13, z + 3), GCBlocks.basicBlock.getStateFromMeta(12), 3);
		world.setBlockState(new BlockPos(x + 8, y + 13, z + 3), GCBlocks.basicBlock.getStateFromMeta(10), 3);
		world.setBlockState(new BlockPos(x + 0, y + 13, z + 4), GCBlocks.basicBlock.getStateFromMeta(11), 3);
		world.setBlockState(new BlockPos(x + 4, y + 13, z + 4), GCBlocks.basicBlock.getStateFromMeta(10), 3);
		world.setBlockState(new BlockPos(x + 6, y + 13, z + 4), GCBlocks.basicBlock.getStateFromMeta(12), 3);
		world.setBlockState(new BlockPos(x + 8, y + 13, z + 4), GCBlocks.basicBlock.getStateFromMeta(10), 3);
		world.setBlockState(new BlockPos(x + 12, y + 13, z + 4), GCBlocks.basicBlock.getStateFromMeta(11), 3);
		world.setBlockState(new BlockPos(x + 4, y + 13, z + 5), GCBlocks.basicBlock.getStateFromMeta(10), 3);
		world.setBlockState(new BlockPos(x + 5, y + 13, z + 5), GCBlocks.basicBlock.getStateFromMeta(12), 3);
		world.setBlockState(new BlockPos(x + 7, y + 13, z + 5), GCBlocks.basicBlock.getStateFromMeta(12), 3);
		world.setBlockState(new BlockPos(x + 8, y + 13, z + 5), GCBlocks.basicBlock.getStateFromMeta(10), 3);
		world.setBlockState(new BlockPos(x + 4, y + 13, z + 6), GCBlocks.basicBlock.getStateFromMeta(11), 3);
		world.setBlockState(new BlockPos(x + 5, y + 13, z + 6), GCBlocks.basicBlock.getStateFromMeta(10), 3);
		world.setBlockState(new BlockPos(x + 6, y + 13, z + 6), GCBlocks.spaceGlassClear.getDefaultState(), 3);
		world.setBlockState(new BlockPos(x + 7, y + 13, z + 6), GCBlocks.basicBlock.getStateFromMeta(10), 3);
		world.setBlockState(new BlockPos(x + 8, y + 13, z + 6), GCBlocks.basicBlock.getStateFromMeta(11), 3);
		world.setBlockState(new BlockPos(x + 4, y + 14, z + 2), GCBlocks.basicBlock.getStateFromMeta(11), 3);
		world.setBlockState(new BlockPos(x + 5, y + 14, z + 2), GCBlocks.basicBlock.getStateFromMeta(10), 3);
		world.setBlockState(new BlockPos(x + 6, y + 14, z + 2), GCBlocks.spaceGlassClear.getDefaultState(), 3);
		world.setBlockState(new BlockPos(x + 7, y + 14, z + 2), GCBlocks.basicBlock.getStateFromMeta(10), 3);
		world.setBlockState(new BlockPos(x + 8, y + 14, z + 2), GCBlocks.basicBlock.getStateFromMeta(11), 3);
		world.setBlockState(new BlockPos(x + 4, y + 14, z + 3), GCBlocks.basicBlock.getStateFromMeta(10), 3);
		world.setBlockState(new BlockPos(x + 5, y + 14, z + 3), GCBlocks.basicBlock.getStateFromMeta(12), 3);
		world.setBlockState(new BlockPos(x + 7, y + 14, z + 3), GCBlocks.basicBlock.getStateFromMeta(12), 3);
		world.setBlockState(new BlockPos(x + 8, y + 14, z + 3), GCBlocks.basicBlock.getStateFromMeta(10), 3);
		world.setBlockState(new BlockPos(x + 0, y + 14, z + 4), GCBlocks.basicBlock.getStateFromMeta(11), 3);
		world.setBlockState(new BlockPos(x + 1, y + 14, z + 4), GCBlocks.basicBlock.getStateFromMeta(10), 3);
		world.setBlockState(new BlockPos(x + 3, y + 14, z + 4), GCBlocks.basicBlock.getStateFromMeta(10), 3);
		world.setBlockState(new BlockPos(x + 4, y + 14, z + 4), GCBlocks.basicBlock.getStateFromMeta(10), 3);
		world.setBlockState(new BlockPos(x + 6, y + 14, z + 4), GCBlocks.basicBlock.getStateFromMeta(12), 3);
		world.setBlockState(new BlockPos(x + 8, y + 14, z + 4), GCBlocks.basicBlock.getStateFromMeta(10), 3);
		world.setBlockState(new BlockPos(x + 9, y + 14, z + 4), GCBlocks.basicBlock.getStateFromMeta(10), 3);
		world.setBlockState(new BlockPos(x + 11, y + 14, z + 4), GCBlocks.basicBlock.getStateFromMeta(10), 3);
		world.setBlockState(new BlockPos(x + 12, y + 14, z + 4), GCBlocks.basicBlock.getStateFromMeta(11), 3);
		world.setBlockState(new BlockPos(x + 4, y + 14, z + 5), GCBlocks.basicBlock.getStateFromMeta(10), 3);
		world.setBlockState(new BlockPos(x + 5, y + 14, z + 5), GCBlocks.basicBlock.getStateFromMeta(12), 3);
		world.setBlockState(new BlockPos(x + 7, y + 14, z + 5), GCBlocks.basicBlock.getStateFromMeta(12), 3);
		world.setBlockState(new BlockPos(x + 8, y + 14, z + 5), GCBlocks.basicBlock.getStateFromMeta(10), 3);
		world.setBlockState(new BlockPos(x + 4, y + 14, z + 6), GCBlocks.basicBlock.getStateFromMeta(11), 3);
		world.setBlockState(new BlockPos(x + 5, y + 14, z + 6), GCBlocks.basicBlock.getStateFromMeta(10), 3);
		world.setBlockState(new BlockPos(x + 6, y + 14, z + 6), GCBlocks.spaceGlassClear.getDefaultState(), 3);
		world.setBlockState(new BlockPos(x + 7, y + 14, z + 6), GCBlocks.basicBlock.getStateFromMeta(10), 3);
		world.setBlockState(new BlockPos(x + 8, y + 14, z + 6), GCBlocks.basicBlock.getStateFromMeta(11), 3);
		world.setBlockState(new BlockPos(x + 4, y + 15, z + 2), GCBlocks.basicBlock.getStateFromMeta(11), 3);
		world.setBlockState(new BlockPos(x + 5, y + 15, z + 2), GCBlocks.basicBlock.getStateFromMeta(10), 3);
		world.setBlockState(new BlockPos(x + 6, y + 15, z + 2), GCBlocks.spaceGlassClear.getDefaultState(), 3);
		world.setBlockState(new BlockPos(x + 7, y + 15, z + 2), GCBlocks.basicBlock.getStateFromMeta(10), 3);
		world.setBlockState(new BlockPos(x + 8, y + 15, z + 2), GCBlocks.basicBlock.getStateFromMeta(11), 3);
		world.setBlockState(new BlockPos(x + 4, y + 15, z + 3), GCBlocks.basicBlock.getStateFromMeta(10), 3);
		world.setBlockState(new BlockPos(x + 5, y + 15, z + 3), GCBlocks.basicBlock.getStateFromMeta(12), 3);
		world.setBlockState(new BlockPos(x + 7, y + 15, z + 3), GCBlocks.basicBlock.getStateFromMeta(12), 3);
		world.setBlockState(new BlockPos(x + 8, y + 15, z + 3), GCBlocks.basicBlock.getStateFromMeta(10), 3);
		world.setBlockState(new BlockPos(x + 0, y + 15, z + 4), GCBlocks.basicBlock.getStateFromMeta(11), 3);
		world.setBlockState(new BlockPos(x + 1, y + 15, z + 4), GCBlocks.basicBlock.getStateFromMeta(10), 3);
		world.setBlockState(new BlockPos(x + 2, y + 15, z + 4), GCBlocks.basicBlock.getStateFromMeta(10), 3);
		world.setBlockState(new BlockPos(x + 3, y + 15, z + 4), GCBlocks.basicBlock.getStateFromMeta(10), 3);
		world.setBlockState(new BlockPos(x + 4, y + 15, z + 4), GCBlocks.basicBlock.getStateFromMeta(10), 3);
		world.setBlockState(new BlockPos(x + 6, y + 15, z + 4), GCBlocks.basicBlock.getStateFromMeta(12), 3);
		world.setBlockState(new BlockPos(x + 8, y + 15, z + 4), GCBlocks.basicBlock.getStateFromMeta(10), 3);
		world.setBlockState(new BlockPos(x + 9, y + 15, z + 4), GCBlocks.basicBlock.getStateFromMeta(10), 3);
		world.setBlockState(new BlockPos(x + 10, y + 15, z + 4), GCBlocks.basicBlock.getStateFromMeta(10), 3);
		world.setBlockState(new BlockPos(x + 11, y + 15, z + 4), GCBlocks.basicBlock.getStateFromMeta(10), 3);
		world.setBlockState(new BlockPos(x + 12, y + 15, z + 4), GCBlocks.basicBlock.getStateFromMeta(11), 3);
		world.setBlockState(new BlockPos(x + 4, y + 15, z + 5), GCBlocks.basicBlock.getStateFromMeta(10), 3);
		world.setBlockState(new BlockPos(x + 5, y + 15, z + 5), GCBlocks.basicBlock.getStateFromMeta(12), 3);
		world.setBlockState(new BlockPos(x + 7, y + 15, z + 5), GCBlocks.basicBlock.getStateFromMeta(12), 3);
		world.setBlockState(new BlockPos(x + 8, y + 15, z + 5), GCBlocks.basicBlock.getStateFromMeta(10), 3);
		world.setBlockState(new BlockPos(x + 4, y + 15, z + 6), GCBlocks.basicBlock.getStateFromMeta(11), 3);
		world.setBlockState(new BlockPos(x + 5, y + 15, z + 6), GCBlocks.basicBlock.getStateFromMeta(10), 3);
		world.setBlockState(new BlockPos(x + 6, y + 15, z + 6), GCBlocks.spaceGlassClear.getDefaultState(), 3);
		world.setBlockState(new BlockPos(x + 7, y + 15, z + 6), GCBlocks.basicBlock.getStateFromMeta(10), 3);
		world.setBlockState(new BlockPos(x + 8, y + 15, z + 6), GCBlocks.basicBlock.getStateFromMeta(11), 3);
		world.setBlockState(new BlockPos(x + 4, y + 16, z + 2), GCBlocks.basicBlock.getStateFromMeta(11), 3);
		world.setBlockState(new BlockPos(x + 5, y + 16, z + 2), GCBlocks.basicBlock.getStateFromMeta(10), 3);
		world.setBlockState(new BlockPos(x + 6, y + 16, z + 2), GCBlocks.spaceGlassClear.getDefaultState(), 3);
		world.setBlockState(new BlockPos(x + 7, y + 16, z + 2), GCBlocks.basicBlock.getStateFromMeta(10), 3);
		world.setBlockState(new BlockPos(x + 8, y + 16, z + 2), GCBlocks.basicBlock.getStateFromMeta(11), 3);
		world.setBlockState(new BlockPos(x + 4, y + 16, z + 3), GCBlocks.basicBlock.getStateFromMeta(10), 3);
		world.setBlockState(new BlockPos(x + 5, y + 16, z + 3), GCBlocks.basicBlock.getStateFromMeta(12), 3);
		world.setBlockState(new BlockPos(x + 7, y + 16, z + 3), GCBlocks.basicBlock.getStateFromMeta(12), 3);
		world.setBlockState(new BlockPos(x + 8, y + 16, z + 3), GCBlocks.basicBlock.getStateFromMeta(10), 3);
		world.setBlockState(new BlockPos(x + 0, y + 16, z + 4), GCBlocks.basicBlock.getStateFromMeta(11), 3);
		world.setBlockState(new BlockPos(x + 1, y + 16, z + 4), GCBlocks.basicBlock.getStateFromMeta(10), 3);
		world.setBlockState(new BlockPos(x + 2, y + 16, z + 4), GCBlocks.basicBlock.getStateFromMeta(10), 3);
		world.setBlockState(new BlockPos(x + 3, y + 16, z + 4), GCBlocks.basicBlock.getStateFromMeta(10), 3);
		world.setBlockState(new BlockPos(x + 4, y + 16, z + 4), GCBlocks.basicBlock.getStateFromMeta(10), 3);
		world.setBlockState(new BlockPos(x + 6, y + 16, z + 4), GCBlocks.basicBlock.getStateFromMeta(12), 3);
		world.setBlockState(new BlockPos(x + 8, y + 16, z + 4), GCBlocks.basicBlock.getStateFromMeta(10), 3);
		world.setBlockState(new BlockPos(x + 9, y + 16, z + 4), GCBlocks.basicBlock.getStateFromMeta(10), 3);
		world.setBlockState(new BlockPos(x + 10, y + 16, z + 4), GCBlocks.basicBlock.getStateFromMeta(10), 3);
		world.setBlockState(new BlockPos(x + 11, y + 16, z + 4), GCBlocks.basicBlock.getStateFromMeta(10), 3);
		world.setBlockState(new BlockPos(x + 12, y + 16, z + 4), GCBlocks.basicBlock.getStateFromMeta(11), 3);
		world.setBlockState(new BlockPos(x + 4, y + 16, z + 5), GCBlocks.basicBlock.getStateFromMeta(10), 3);
		world.setBlockState(new BlockPos(x + 5, y + 16, z + 5), GCBlocks.basicBlock.getStateFromMeta(12), 3);
		world.setBlockState(new BlockPos(x + 7, y + 16, z + 5), GCBlocks.basicBlock.getStateFromMeta(12), 3);
		world.setBlockState(new BlockPos(x + 8, y + 16, z + 5), GCBlocks.basicBlock.getStateFromMeta(10), 3);
		world.setBlockState(new BlockPos(x + 4, y + 16, z + 6), GCBlocks.basicBlock.getStateFromMeta(11), 3);
		world.setBlockState(new BlockPos(x + 5, y + 16, z + 6), GCBlocks.basicBlock.getStateFromMeta(10), 3);
		world.setBlockState(new BlockPos(x + 6, y + 16, z + 6), GCBlocks.spaceGlassClear.getDefaultState(), 3);
		world.setBlockState(new BlockPos(x + 7, y + 16, z + 6), GCBlocks.basicBlock.getStateFromMeta(10), 3);
		world.setBlockState(new BlockPos(x + 8, y + 16, z + 6), GCBlocks.basicBlock.getStateFromMeta(11), 3);
		world.setBlockState(new BlockPos(x + 4, y + 17, z + 2), GCBlocks.basicBlock.getStateFromMeta(11), 3);
		world.setBlockState(new BlockPos(x + 5, y + 17, z + 2), GCBlocks.basicBlock.getStateFromMeta(10), 3);
		world.setBlockState(new BlockPos(x + 6, y + 17, z + 2), GCBlocks.spaceGlassClear.getDefaultState(), 3);
		world.setBlockState(new BlockPos(x + 7, y + 17, z + 2), GCBlocks.basicBlock.getStateFromMeta(10), 3);
		world.setBlockState(new BlockPos(x + 8, y + 17, z + 2), GCBlocks.basicBlock.getStateFromMeta(11), 3);
		world.setBlockState(new BlockPos(x + 4, y + 17, z + 3), GCBlocks.basicBlock.getStateFromMeta(10), 3);
		world.setBlockState(new BlockPos(x + 5, y + 17, z + 3), GCBlocks.basicBlock.getStateFromMeta(12), 3);
		world.setBlockState(new BlockPos(x + 7, y + 17, z + 3), GCBlocks.basicBlock.getStateFromMeta(12), 3);
		world.setBlockState(new BlockPos(x + 8, y + 17, z + 3), GCBlocks.basicBlock.getStateFromMeta(10), 3);
		world.setBlockState(new BlockPos(x + 0, y + 17, z + 4), GCBlocks.basicBlock.getStateFromMeta(11), 3);
		world.setBlockState(new BlockPos(x + 2, y + 17, z + 4), GCBlocks.basicBlock.getStateFromMeta(10), 3);
		world.setBlockState(new BlockPos(x + 3, y + 17, z + 4), GCBlocks.basicBlock.getStateFromMeta(10), 3);
		world.setBlockState(new BlockPos(x + 4, y + 17, z + 4), GCBlocks.basicBlock.getStateFromMeta(10), 3);
		world.setBlockState(new BlockPos(x + 6, y + 17, z + 4), GCBlocks.basicBlock.getStateFromMeta(12), 3);
		world.setBlockState(new BlockPos(x + 8, y + 17, z + 4), GCBlocks.basicBlock.getStateFromMeta(10), 3);
		world.setBlockState(new BlockPos(x + 9, y + 17, z + 4), GCBlocks.basicBlock.getStateFromMeta(10), 3);
		world.setBlockState(new BlockPos(x + 10, y + 17, z + 4), GCBlocks.basicBlock.getStateFromMeta(10), 3);
		world.setBlockState(new BlockPos(x + 12, y + 17, z + 4), GCBlocks.basicBlock.getStateFromMeta(11), 3);
		world.setBlockState(new BlockPos(x + 4, y + 17, z + 5), GCBlocks.basicBlock.getStateFromMeta(10), 3);
		world.setBlockState(new BlockPos(x + 5, y + 17, z + 5), GCBlocks.basicBlock.getStateFromMeta(12), 3);
		world.setBlockState(new BlockPos(x + 7, y + 17, z + 5), GCBlocks.basicBlock.getStateFromMeta(12), 3);
		world.setBlockState(new BlockPos(x + 8, y + 17, z + 5), GCBlocks.basicBlock.getStateFromMeta(10), 3);
		world.setBlockState(new BlockPos(x + 4, y + 17, z + 6), GCBlocks.basicBlock.getStateFromMeta(11), 3);
		world.setBlockState(new BlockPos(x + 5, y + 17, z + 6), GCBlocks.basicBlock.getStateFromMeta(10), 3);
		world.setBlockState(new BlockPos(x + 6, y + 17, z + 6), GCBlocks.spaceGlassClear.getDefaultState(), 3);
		world.setBlockState(new BlockPos(x + 7, y + 17, z + 6), GCBlocks.basicBlock.getStateFromMeta(10), 3);
		world.setBlockState(new BlockPos(x + 8, y + 17, z + 6), GCBlocks.basicBlock.getStateFromMeta(11), 3);
		world.setBlockState(new BlockPos(x + 4, y + 18, z + 2), GCBlocks.basicBlock.getStateFromMeta(11), 3);
		world.setBlockState(new BlockPos(x + 5, y + 18, z + 2), GCBlocks.basicBlock.getStateFromMeta(10), 3);
		world.setBlockState(new BlockPos(x + 6, y + 18, z + 2), GCBlocks.spaceGlassClear.getDefaultState(), 3);
		world.setBlockState(new BlockPos(x + 7, y + 18, z + 2), GCBlocks.basicBlock.getStateFromMeta(10), 3);
		world.setBlockState(new BlockPos(x + 8, y + 18, z + 2), GCBlocks.basicBlock.getStateFromMeta(11), 3);
		world.setBlockState(new BlockPos(x + 4, y + 18, z + 3), GCBlocks.basicBlock.getStateFromMeta(10), 3);
		world.setBlockState(new BlockPos(x + 5, y + 18, z + 3), GCBlocks.basicBlock.getStateFromMeta(12), 3);
		world.setBlockState(new BlockPos(x + 7, y + 18, z + 3), GCBlocks.basicBlock.getStateFromMeta(12), 3);
		world.setBlockState(new BlockPos(x + 8, y + 18, z + 3), GCBlocks.basicBlock.getStateFromMeta(10), 3);
		world.setBlockState(new BlockPos(x + 0, y + 18, z + 4), GCBlocks.basicBlock.getStateFromMeta(11), 3);
		world.setBlockState(new BlockPos(x + 3, y + 18, z + 4), GCBlocks.basicBlock.getStateFromMeta(10), 3);
		world.setBlockState(new BlockPos(x + 4, y + 18, z + 4), GCBlocks.basicBlock.getStateFromMeta(10), 3);
		world.setBlockState(new BlockPos(x + 6, y + 18, z + 4), GCBlocks.basicBlock.getStateFromMeta(12), 3);
		world.setBlockState(new BlockPos(x + 8, y + 18, z + 4), GCBlocks.basicBlock.getStateFromMeta(10), 3);
		world.setBlockState(new BlockPos(x + 9, y + 18, z + 4), GCBlocks.basicBlock.getStateFromMeta(10), 3);
		world.setBlockState(new BlockPos(x + 12, y + 18, z + 4), GCBlocks.basicBlock.getStateFromMeta(11), 3);
		world.setBlockState(new BlockPos(x + 4, y + 18, z + 5), GCBlocks.basicBlock.getStateFromMeta(10), 3);
		world.setBlockState(new BlockPos(x + 5, y + 18, z + 5), GCBlocks.basicBlock.getStateFromMeta(12), 3);
		world.setBlockState(new BlockPos(x + 7, y + 18, z + 5), GCBlocks.basicBlock.getStateFromMeta(12), 3);
		world.setBlockState(new BlockPos(x + 8, y + 18, z + 5), GCBlocks.basicBlock.getStateFromMeta(10), 3);
		world.setBlockState(new BlockPos(x + 4, y + 18, z + 6), GCBlocks.basicBlock.getStateFromMeta(11), 3);
		world.setBlockState(new BlockPos(x + 5, y + 18, z + 6), GCBlocks.basicBlock.getStateFromMeta(10), 3);
		world.setBlockState(new BlockPos(x + 6, y + 18, z + 6), GCBlocks.spaceGlassClear.getDefaultState(), 3);
		world.setBlockState(new BlockPos(x + 7, y + 18, z + 6), GCBlocks.basicBlock.getStateFromMeta(10), 3);
		world.setBlockState(new BlockPos(x + 8, y + 18, z + 6), GCBlocks.basicBlock.getStateFromMeta(11), 3);
		world.setBlockState(new BlockPos(x + 4, y + 19, z + 2), GCBlocks.basicBlock.getStateFromMeta(11), 3);
		world.setBlockState(new BlockPos(x + 5, y + 19, z + 2), GCBlocks.basicBlock.getStateFromMeta(10), 3);
		world.setBlockState(new BlockPos(x + 6, y + 19, z + 2), GCBlocks.spaceGlassClear.getDefaultState(), 3);
		world.setBlockState(new BlockPos(x + 7, y + 19, z + 2), GCBlocks.basicBlock.getStateFromMeta(10), 3);
		world.setBlockState(new BlockPos(x + 8, y + 19, z + 2), GCBlocks.basicBlock.getStateFromMeta(11), 3);
		world.setBlockState(new BlockPos(x + 4, y + 19, z + 3), GCBlocks.basicBlock.getStateFromMeta(10), 3);
		world.setBlockState(new BlockPos(x + 5, y + 19, z + 3), GCBlocks.basicBlock.getStateFromMeta(12), 3);
		world.setBlockState(new BlockPos(x + 7, y + 19, z + 3), GCBlocks.basicBlock.getStateFromMeta(12), 3);
		world.setBlockState(new BlockPos(x + 8, y + 19, z + 3), GCBlocks.basicBlock.getStateFromMeta(10), 3);
		world.setBlockState(new BlockPos(x + 4, y + 19, z + 4), GCBlocks.spaceGlassClear.getDefaultState(), 3);
		world.setBlockState(new BlockPos(x + 6, y + 19, z + 4), GCBlocks.basicBlock.getStateFromMeta(12), 3);
		world.setBlockState(new BlockPos(x + 8, y + 19, z + 4), GCBlocks.spaceGlassClear.getDefaultState(), 3);
		world.setBlockState(new BlockPos(x + 4, y + 19, z + 5), GCBlocks.basicBlock.getStateFromMeta(10), 3);
		world.setBlockState(new BlockPos(x + 5, y + 19, z + 5), GCBlocks.basicBlock.getStateFromMeta(12), 3);
		world.setBlockState(new BlockPos(x + 7, y + 19, z + 5), GCBlocks.basicBlock.getStateFromMeta(12), 3);
		world.setBlockState(new BlockPos(x + 8, y + 19, z + 5), GCBlocks.basicBlock.getStateFromMeta(10), 3);
		world.setBlockState(new BlockPos(x + 4, y + 19, z + 6), GCBlocks.basicBlock.getStateFromMeta(11), 3);
		world.setBlockState(new BlockPos(x + 5, y + 19, z + 6), GCBlocks.basicBlock.getStateFromMeta(10), 3);
		world.setBlockState(new BlockPos(x + 6, y + 19, z + 6), GCBlocks.spaceGlassClear.getDefaultState(), 3);
		world.setBlockState(new BlockPos(x + 7, y + 19, z + 6), GCBlocks.basicBlock.getStateFromMeta(10), 3);
		world.setBlockState(new BlockPos(x + 8, y + 19, z + 6), GCBlocks.basicBlock.getStateFromMeta(11), 3);
		world.setBlockState(new BlockPos(x + 4, y + 20, z + 2), GCBlocks.tinStairs2.getStateFromMeta(2), 3);
		world.setBlockState(new BlockPos(x + 5, y + 20, z + 2), GCBlocks.tinStairs2.getStateFromMeta(2), 3);
		world.setBlockState(new BlockPos(x + 6, y + 20, z + 2), GCBlocks.basicBlock.getStateFromMeta(10), 3);
		world.setBlockState(new BlockPos(x + 7, y + 20, z + 2), GCBlocks.tinStairs2.getStateFromMeta(2), 3);
		world.setBlockState(new BlockPos(x + 8, y + 20, z + 2), GCBlocks.tinStairs2.getStateFromMeta(2), 3);
		world.setBlockState(new BlockPos(x + 4, y + 20, z + 3), GCBlocks.tinStairs2.getStateFromMeta(0), 3);
		world.setBlockState(new BlockPos(x + 5, y + 20, z + 3), GCBlocks.basicBlock.getStateFromMeta(12), 3);
		world.setBlockState(new BlockPos(x + 7, y + 20, z + 3), GCBlocks.basicBlock.getStateFromMeta(12), 3);
		world.setBlockState(new BlockPos(x + 8, y + 20, z + 3), GCBlocks.tinStairs2.getStateFromMeta(1), 3);
		world.setBlockState(new BlockPos(x + 4, y + 20, z + 4), GCBlocks.basicBlock.getStateFromMeta(10), 3);
		world.setBlockState(new BlockPos(x + 6, y + 20, z + 4), GCBlocks.basicBlock.getStateFromMeta(12), 3);
		world.setBlockState(new BlockPos(x + 8, y + 20, z + 4), GCBlocks.basicBlock.getStateFromMeta(10), 3);
		world.setBlockState(new BlockPos(x + 4, y + 20, z + 5), GCBlocks.tinStairs2.getStateFromMeta(0), 3);
		world.setBlockState(new BlockPos(x + 5, y + 20, z + 5), GCBlocks.basicBlock.getStateFromMeta(12), 3);
		world.setBlockState(new BlockPos(x + 7, y + 20, z + 5), GCBlocks.basicBlock.getStateFromMeta(12), 3);
		world.setBlockState(new BlockPos(x + 8, y + 20, z + 5), GCBlocks.tinStairs2.getStateFromMeta(1), 3);
		world.setBlockState(new BlockPos(x + 4, y + 20, z + 6), GCBlocks.tinStairs2.getStateFromMeta(3), 3);
		world.setBlockState(new BlockPos(x + 5, y + 20, z + 6), GCBlocks.tinStairs2.getStateFromMeta(3), 3);
		world.setBlockState(new BlockPos(x + 6, y + 20, z + 6), GCBlocks.basicBlock.getStateFromMeta(10), 3);
		world.setBlockState(new BlockPos(x + 7, y + 20, z + 6), GCBlocks.tinStairs2.getStateFromMeta(3), 3);
		world.setBlockState(new BlockPos(x + 8, y + 20, z + 6), GCBlocks.tinStairs2.getStateFromMeta(1), 3);
		world.setBlockState(new BlockPos(x + 6, y + 21, z + 2), GCBlocks.tinStairs2.getStateFromMeta(2), 3);
		world.setBlockState(new BlockPos(x + 5, y + 21, z + 3), GCBlocks.basicBlock.getStateFromMeta(10), 3);
		world.setBlockState(new BlockPos(x + 6, y + 21, z + 3), GCBlocks.basicBlock.getStateFromMeta(10), 3);
		world.setBlockState(new BlockPos(x + 7, y + 21, z + 3), GCBlocks.basicBlock.getStateFromMeta(10), 3);
		world.setBlockState(new BlockPos(x + 4, y + 21, z + 4), GCBlocks.tinStairs2.getStateFromMeta(0), 3);
		world.setBlockState(new BlockPos(x + 5, y + 21, z + 4), GCBlocks.basicBlock.getStateFromMeta(10), 3);
		world.setBlockState(new BlockPos(x + 6, y + 21, z + 4), Blocks.TNT.getDefaultState(), 3);
		world.setBlockState(new BlockPos(x + 7, y + 21, z + 4), GCBlocks.basicBlock.getStateFromMeta(10), 3);
		world.setBlockState(new BlockPos(x + 8, y + 21, z + 4), GCBlocks.tinStairs2.getStateFromMeta(1), 3);
		world.setBlockState(new BlockPos(x + 5, y + 21, z + 5), GCBlocks.basicBlock.getStateFromMeta(10), 3);
		world.setBlockState(new BlockPos(x + 6, y + 21, z + 5), GCBlocks.basicBlock.getStateFromMeta(10), 3);
		world.setBlockState(new BlockPos(x + 7, y + 21, z + 5), GCBlocks.basicBlock.getStateFromMeta(10), 3);
		world.setBlockState(new BlockPos(x + 6, y + 21, z + 6), GCBlocks.tinStairs2.getStateFromMeta(3), 3);
		world.setBlockState(new BlockPos(x + 5, y + 22, z + 3), GCBlocks.basicBlock.getStateFromMeta(10), 3);
		world.setBlockState(new BlockPos(x + 6, y + 22, z + 3), GCBlocks.basicBlock.getStateFromMeta(10), 3);
		world.setBlockState(new BlockPos(x + 7, y + 22, z + 3), GCBlocks.basicBlock.getStateFromMeta(10), 3);
		world.setBlockState(new BlockPos(x + 5, y + 22, z + 4), GCBlocks.basicBlock.getStateFromMeta(10), 3);
		world.setBlockState(new BlockPos(x + 6, y + 22, z + 4), Blocks.TRAPPED_CHEST.getStateFromMeta(3), 3);
		world.setBlockState(new BlockPos(x + 7, y + 22, z + 4), GCBlocks.basicBlock.getStateFromMeta(10), 3);
		world.setBlockState(new BlockPos(x + 5, y + 22, z + 5), GCBlocks.basicBlock.getStateFromMeta(10), 3);
		world.setBlockState(new BlockPos(x + 6, y + 22, z + 5), GCBlocks.basicBlock.getStateFromMeta(10), 3);
		world.setBlockState(new BlockPos(x + 7, y + 22, z + 5), GCBlocks.basicBlock.getStateFromMeta(10), 3);
		world.setBlockState(new BlockPos(x + 5, y + 23, z + 3), GCBlocks.tinStairs2.getStateFromMeta(2), 3);
		world.setBlockState(new BlockPos(x + 6, y + 23, z + 3), GCBlocks.basicBlock.getStateFromMeta(10), 3);
		world.setBlockState(new BlockPos(x + 7, y + 23, z + 3), GCBlocks.tinStairs2.getStateFromMeta(2), 3);
		world.setBlockState(new BlockPos(x + 5, y + 23, z + 4), GCBlocks.basicBlock.getStateFromMeta(10), 3);
		world.setBlockState(new BlockPos(x + 6, y + 23, z + 4), Blocks.TNT.getDefaultState(), 3);
		world.setBlockState(new BlockPos(x + 7, y + 23, z + 4), GCBlocks.basicBlock.getStateFromMeta(10), 3);
		world.setBlockState(new BlockPos(x + 5, y + 23, z + 5), GCBlocks.tinStairs2.getStateFromMeta(3), 3);
		world.setBlockState(new BlockPos(x + 6, y + 23, z + 5), GCBlocks.basicBlock.getStateFromMeta(10), 3);
		world.setBlockState(new BlockPos(x + 7, y + 23, z + 5), GCBlocks.tinStairs2.getStateFromMeta(3), 3);
		world.setBlockState(new BlockPos(x + 6, y + 24, z + 4), GCBlocks.basicBlock.getStateFromMeta(12), 3);
		world.setBlockState(new BlockPos(x + 6, y + 25, z + 4), GCBlocks.basicBlock.getStateFromMeta(12), 3);
		world.setBlockState(new BlockPos(x + 6, y + 26, z + 4), GCBlocks.basicBlock.getStateFromMeta(12), 3);
		world.setBlockState(new BlockPos(x + 6, y + 27, z + 4), GCBlocks.basicBlock.getStateFromMeta(12), 3);
		world.setBlockState(new BlockPos(x + 6, y + 28, z + 4), GCBlocks.basicBlock.getStateFromMeta(12), 3);
		world.setBlockState(new BlockPos(x + 6, y + 29, z + 4), GCBlocks.basicBlock.getStateFromMeta(12), 3);
		world.setBlockState(new BlockPos(x + 6, y + 30, z + 4), ExtraPlanets_Blocks.DECORATIVE_BLOCKS2.getStateFromMeta(2), 3);
		return true;
	}

	public boolean fillChests(World world, Random rand, BlockPos position) {
		int x = position.getX();
		int y = position.getY();
		int z = position.getZ();
		// Determined if loot should be generated using a 1/2 chance
		int random = rand.nextInt(10) + 1;
		if (random < 5) {
			TileEntityChest chest = (TileEntityChest) world.getTileEntity(new BlockPos(x + 6, y + 22, z + 4));

			if (chest != null) {
				for (int i = 0; i < chest.getSizeInventory(); i++) {
					chest.setInventorySlotContents(i, ItemStack.EMPTY);
				}

				chest.setLootTable(RoomTreasureMars.TABLE_TIER_2_DUNGEON, rand.nextLong());
			}
		}
		return false;
	}
}