package com.mjr.extraplanets.world.features;

import java.util.Random;

import net.minecraft.init.Blocks;
import net.minecraft.tileentity.TileEntityChest;
import net.minecraft.util.WeightedRandomChestContent;
import net.minecraft.world.World;
import net.minecraft.world.gen.feature.WorldGenerator;
import net.minecraftforge.common.ChestGenHooks;

import com.mjr.extraplanets.Config;
import com.mjr.extraplanets.blocks.ExtraPlanets_Blocks;
import com.mjr.extraplanets.util.WorldGenHelper;

public class WorldGenVolcano extends WorldGenerator {

	@Override
	public boolean generate(World world, Random rand, int x, int y, int z) {
		if (WorldGenHelper.checkValidSpawn(world, x, y, z, 25) == false)
			return false;
		else {
			if (Config.DEBUG_MODE)
				System.out.println("Spawning Volcano Pile at (x, y, z)" + x + " " + y + " " + z);
			generatreStructure(world, rand, x, y, z);
		}
		return true;
	}

	public boolean generatreStructure(World world, Random rand, int x, int y, int z) {
		world.setBlock(x + 11, y + 0, z + 1, ExtraPlanets_Blocks.volcanicRock, 0, 3);
		world.setBlock(x + 13, y + 0, z + 1, ExtraPlanets_Blocks.volcanicRock, 0, 3);
		world.setBlock(x + 10, y + 0, z + 2, ExtraPlanets_Blocks.volcanicRock, 0, 3);
		world.setBlock(x + 11, y + 0, z + 2, ExtraPlanets_Blocks.volcanicRock, 0, 3);
		world.setBlock(x + 12, y + 0, z + 2, ExtraPlanets_Blocks.volcanicRock, 0, 3);
		world.setBlock(x + 13, y + 0, z + 2, ExtraPlanets_Blocks.volcanicRock, 0, 3);
		world.setBlock(x + 14, y + 0, z + 2, ExtraPlanets_Blocks.volcanicRock, 0, 3);
		world.setBlock(x + 8, y + 0, z + 3, ExtraPlanets_Blocks.volcanicRock, 0, 3);
		world.setBlock(x + 9, y + 0, z + 3, ExtraPlanets_Blocks.volcanicRock, 0, 3);
		world.setBlock(x + 10, y + 0, z + 3, ExtraPlanets_Blocks.volcanicRock, 0, 3);
		world.setBlock(x + 11, y + 0, z + 3, ExtraPlanets_Blocks.volcanicRock, 0, 3);
		world.setBlock(x + 12, y + 0, z + 3, ExtraPlanets_Blocks.volcanicRock, 0, 3);
		world.setBlock(x + 13, y + 0, z + 3, ExtraPlanets_Blocks.volcanicRock, 0, 3);
		world.setBlock(x + 14, y + 0, z + 3, ExtraPlanets_Blocks.volcanicRock, 0, 3);
		world.setBlock(x + 15, y + 0, z + 3, ExtraPlanets_Blocks.volcanicRock, 0, 3);
		world.setBlock(x + 5, y + 0, z + 4, ExtraPlanets_Blocks.volcanicRock, 0, 3);
		world.setBlock(x + 6, y + 0, z + 4, ExtraPlanets_Blocks.volcanicRock, 0, 3);
		world.setBlock(x + 7, y + 0, z + 4, ExtraPlanets_Blocks.volcanicRock, 0, 3);
		world.setBlock(x + 8, y + 0, z + 4, ExtraPlanets_Blocks.volcanicRock, 0, 3);
		world.setBlock(x + 9, y + 0, z + 4, ExtraPlanets_Blocks.volcanicRock, 0, 3);
		world.setBlock(x + 10, y + 0, z + 4, ExtraPlanets_Blocks.volcanicRock, 0, 3);
		world.setBlock(x + 11, y + 0, z + 4, ExtraPlanets_Blocks.volcanicRock, 0, 3);
		world.setBlock(x + 12, y + 0, z + 4, ExtraPlanets_Blocks.volcanicRock, 0, 3);
		world.setBlock(x + 13, y + 0, z + 4, ExtraPlanets_Blocks.volcanicRock, 0, 3);
		world.setBlock(x + 14, y + 0, z + 4, ExtraPlanets_Blocks.volcanicRock, 0, 3);
		world.setBlock(x + 15, y + 0, z + 4, ExtraPlanets_Blocks.volcanicRock, 0, 3);
		world.setBlock(x + 16, y + 0, z + 4, ExtraPlanets_Blocks.volcanicRock, 0, 3);
		world.setBlock(x + 17, y + 0, z + 4, ExtraPlanets_Blocks.volcanicRock, 0, 3);
		world.setBlock(x + 4, y + 0, z + 5, ExtraPlanets_Blocks.volcanicRock, 0, 3);
		world.setBlock(x + 5, y + 0, z + 5, ExtraPlanets_Blocks.volcanicRock, 0, 3);
		world.setBlock(x + 6, y + 0, z + 5, Blocks.lava, 0, 3);
		world.setBlock(x + 7, y + 0, z + 5, Blocks.lava, 0, 3);
		world.setBlock(x + 8, y + 0, z + 5, Blocks.lava, 0, 3);
		world.setBlock(x + 9, y + 0, z + 5, Blocks.lava, 0, 3);
		world.setBlock(x + 10, y + 0, z + 5, Blocks.lava, 0, 3);
		world.setBlock(x + 11, y + 0, z + 5, Blocks.lava, 0, 3);
		world.setBlock(x + 12, y + 0, z + 5, ExtraPlanets_Blocks.volcanicRock, 0, 3);
		world.setBlock(x + 13, y + 0, z + 5, ExtraPlanets_Blocks.volcanicRock, 0, 3);
		world.setBlock(x + 14, y + 0, z + 5, ExtraPlanets_Blocks.volcanicRock, 0, 3);
		world.setBlock(x + 15, y + 0, z + 5, ExtraPlanets_Blocks.volcanicRock, 0, 3);
		world.setBlock(x + 16, y + 0, z + 5, ExtraPlanets_Blocks.volcanicRock, 0, 3);
		world.setBlock(x + 17, y + 0, z + 5, ExtraPlanets_Blocks.volcanicRock, 0, 3);
		world.setBlock(x + 18, y + 0, z + 5, ExtraPlanets_Blocks.volcanicRock, 0, 3);
		world.setBlock(x + 19, y + 0, z + 5, ExtraPlanets_Blocks.volcanicRock, 0, 3);
		world.setBlock(x + 4, y + 0, z + 6, ExtraPlanets_Blocks.volcanicRock, 0, 3);
		world.setBlock(x + 5, y + 0, z + 6, ExtraPlanets_Blocks.ashBlock, 0, 3);
		world.setBlock(x + 6, y + 0, z + 6, ExtraPlanets_Blocks.ashBlock, 0, 3);
		world.setBlock(x + 7, y + 0, z + 6, ExtraPlanets_Blocks.ashBlock, 0, 3);
		world.setBlock(x + 8, y + 0, z + 6, ExtraPlanets_Blocks.ashBlock, 0, 3);
		world.setBlock(x + 9, y + 0, z + 6, ExtraPlanets_Blocks.ashBlock, 0, 3);
		world.setBlock(x + 10, y + 0, z + 6, ExtraPlanets_Blocks.ashBlock, 0, 3);
		world.setBlock(x + 11, y + 0, z + 6, ExtraPlanets_Blocks.ashBlock, 10, 3);
		world.setBlock(x + 12, y + 0, z + 6, ExtraPlanets_Blocks.ashBlock, 0, 3);
		world.setBlock(x + 13, y + 0, z + 6, ExtraPlanets_Blocks.volcanicRock, 0, 3);
		world.setBlock(x + 14, y + 0, z + 6, ExtraPlanets_Blocks.volcanicRock, 0, 3);
		world.setBlock(x + 15, y + 0, z + 6, ExtraPlanets_Blocks.volcanicRock, 0, 3);
		world.setBlock(x + 16, y + 0, z + 6, ExtraPlanets_Blocks.volcanicRock, 0, 3);
		world.setBlock(x + 17, y + 0, z + 6, ExtraPlanets_Blocks.volcanicRock, 0, 3);
		world.setBlock(x + 18, y + 0, z + 6, ExtraPlanets_Blocks.volcanicRock, 0, 3);
		world.setBlock(x + 19, y + 0, z + 6, ExtraPlanets_Blocks.volcanicRock, 0, 3);
		world.setBlock(x + 3, y + 0, z + 7, ExtraPlanets_Blocks.volcanicRock, 0, 3);
		world.setBlock(x + 4, y + 0, z + 7, ExtraPlanets_Blocks.volcanicRock, 0, 3);
		world.setBlock(x + 5, y + 0, z + 7, ExtraPlanets_Blocks.volcanicRock, 0, 3);
		world.setBlock(x + 6, y + 0, z + 7, Blocks.lava, 0, 3);
		world.setBlock(x + 7, y + 0, z + 7, Blocks.lava, 8, 3);
		world.setBlock(x + 8, y + 0, z + 7, Blocks.lava, 8, 3);
		world.setBlock(x + 9, y + 0, z + 7, Blocks.lava, 8, 3);
		world.setBlock(x + 10, y + 0, z + 7, Blocks.lava, 0, 3);
		world.setBlock(x + 11, y + 0, z + 7, Blocks.lava, 0, 3);
		world.setBlock(x + 12, y + 0, z + 7, Blocks.lava, 0, 3);
		world.setBlock(x + 13, y + 0, z + 7, Blocks.lava, 0, 3);
		world.setBlock(x + 14, y + 0, z + 7, Blocks.lava, 0, 3);
		world.setBlock(x + 15, y + 0, z + 7, ExtraPlanets_Blocks.volcanicRock, 0, 3);
		world.setBlock(x + 16, y + 0, z + 7, ExtraPlanets_Blocks.volcanicRock, 0, 3);
		world.setBlock(x + 17, y + 0, z + 7, ExtraPlanets_Blocks.volcanicRock, 0, 3);
		world.setBlock(x + 18, y + 0, z + 7, ExtraPlanets_Blocks.volcanicRock, 0, 3);
		world.setBlock(x + 19, y + 0, z + 7, ExtraPlanets_Blocks.volcanicRock, 0, 3);
		world.setBlock(x + 20, y + 0, z + 7, ExtraPlanets_Blocks.volcanicRock, 0, 3);
		world.setBlock(x + 21, y + 0, z + 7, ExtraPlanets_Blocks.volcanicRock, 0, 3);
		world.setBlock(x + 22, y + 0, z + 7, ExtraPlanets_Blocks.volcanicRock, 0, 3);
		world.setBlock(x + 2, y + 0, z + 8, ExtraPlanets_Blocks.volcanicRock, 0, 3);
		world.setBlock(x + 3, y + 0, z + 8, ExtraPlanets_Blocks.volcanicRock, 0, 3);
		world.setBlock(x + 4, y + 0, z + 8, ExtraPlanets_Blocks.volcanicRock, 0, 3);
		world.setBlock(x + 5, y + 0, z + 8, Blocks.lava, 0, 3);
		world.setBlock(x + 6, y + 0, z + 8, Blocks.lava, 8, 3);
		world.setBlock(x + 7, y + 0, z + 8, Blocks.lava, 8, 3);
		world.setBlock(x + 8, y + 0, z + 8, Blocks.lava, 0, 3);
		world.setBlock(x + 9, y + 0, z + 8, Blocks.lava, 0, 3);
		world.setBlock(x + 10, y + 0, z + 8, Blocks.lava, 0, 3);
		world.setBlock(x + 11, y + 0, z + 8, Blocks.lava, 0, 3);
		world.setBlock(x + 12, y + 0, z + 8, Blocks.lava, 8, 3);
		world.setBlock(x + 13, y + 0, z + 8, Blocks.lava, 2, 3);
		world.setBlock(x + 14, y + 0, z + 8, Blocks.lava, 0, 3);
		world.setBlock(x + 15, y + 0, z + 8, Blocks.lava, 0, 3);
		world.setBlock(x + 16, y + 0, z + 8, ExtraPlanets_Blocks.volcanicRock, 0, 3);
		world.setBlock(x + 17, y + 0, z + 8, ExtraPlanets_Blocks.volcanicRock, 0, 3);
		world.setBlock(x + 18, y + 0, z + 8, ExtraPlanets_Blocks.volcanicRock, 0, 3);
		world.setBlock(x + 19, y + 0, z + 8, ExtraPlanets_Blocks.volcanicRock, 0, 3);
		world.setBlock(x + 20, y + 0, z + 8, ExtraPlanets_Blocks.volcanicRock, 0, 3);
		world.setBlock(x + 21, y + 0, z + 8, ExtraPlanets_Blocks.volcanicRock, 0, 3);
		world.setBlock(x + 22, y + 0, z + 8, ExtraPlanets_Blocks.volcanicRock, 0, 3);
		world.setBlock(x + 23, y + 0, z + 8, ExtraPlanets_Blocks.volcanicRock, 0, 3);
		world.setBlock(x + 1, y + 0, z + 9, ExtraPlanets_Blocks.volcanicRock, 0, 3);
		world.setBlock(x + 2, y + 0, z + 9, ExtraPlanets_Blocks.volcanicRock, 0, 3);
		world.setBlock(x + 3, y + 0, z + 9, Blocks.lava, 0, 3);
		world.setBlock(x + 4, y + 0, z + 9, Blocks.lava, 0, 3);
		world.setBlock(x + 5, y + 0, z + 9, Blocks.lava, 8, 3);
		world.setBlock(x + 6, y + 0, z + 9, Blocks.lava, 10, 3);
		world.setBlock(x + 7, y + 0, z + 9, Blocks.lava, 0, 3);
		world.setBlock(x + 8, y + 0, z + 9, Blocks.lava, 0, 3);
		world.setBlock(x + 9, y + 0, z + 9, Blocks.lava, 0, 3);
		world.setBlock(x + 10, y + 0, z + 9, Blocks.lava, 8, 3);
		world.setBlock(x + 11, y + 0, z + 9, Blocks.lava, 0, 3);
		world.setBlock(x + 12, y + 0, z + 9, Blocks.lava, 8, 3);
		world.setBlock(x + 13, y + 0, z + 9, Blocks.lava, 0, 3);
		world.setBlock(x + 14, y + 0, z + 9, Blocks.lava, 8, 3);
		world.setBlock(x + 15, y + 0, z + 9, Blocks.lava, 0, 3);
		world.setBlock(x + 16, y + 0, z + 9, Blocks.lava, 0, 3);
		world.setBlock(x + 17, y + 0, z + 9, Blocks.lava, 0, 3);
		world.setBlock(x + 18, y + 0, z + 9, ExtraPlanets_Blocks.volcanicRock, 0, 3);
		world.setBlock(x + 19, y + 0, z + 9, ExtraPlanets_Blocks.volcanicRock, 0, 3);
		world.setBlock(x + 20, y + 0, z + 9, ExtraPlanets_Blocks.volcanicRock, 0, 3);
		world.setBlock(x + 21, y + 0, z + 9, ExtraPlanets_Blocks.volcanicRock, 0, 3);
		world.setBlock(x + 22, y + 0, z + 9, ExtraPlanets_Blocks.volcanicRock, 0, 3);
		world.setBlock(x + 23, y + 0, z + 9, ExtraPlanets_Blocks.volcanicRock, 0, 3);
		world.setBlock(x + 24, y + 0, z + 9, ExtraPlanets_Blocks.volcanicRock, 0, 3);
		world.setBlock(x + 25, y + 0, z + 9, ExtraPlanets_Blocks.volcanicRock, 0, 3);
		world.setBlock(x + 1, y + 0, z + 10, ExtraPlanets_Blocks.volcanicRock, 0, 3);
		world.setBlock(x + 2, y + 0, z + 10, ExtraPlanets_Blocks.volcanicRock, 0, 3);
		world.setBlock(x + 3, y + 0, z + 10, Blocks.lava, 0, 3);
		world.setBlock(x + 4, y + 0, z + 10, Blocks.lava, 0, 3);
		world.setBlock(x + 5, y + 0, z + 10, Blocks.lava, 0, 3);
		world.setBlock(x + 6, y + 0, z + 10, Blocks.lava, 0, 3);
		world.setBlock(x + 7, y + 0, z + 10, Blocks.lava, 0, 3);
		world.setBlock(x + 8, y + 0, z + 10, Blocks.lava, 0, 3);
		world.setBlock(x + 9, y + 0, z + 10, Blocks.lava, 0, 3);
		world.setBlock(x + 10, y + 0, z + 10, Blocks.lava, 0, 3);
		world.setBlock(x + 11, y + 0, z + 10, Blocks.lava, 0, 3);
		world.setBlock(x + 12, y + 0, z + 10, Blocks.lava, 8, 3);
		world.setBlock(x + 13, y + 0, z + 10, Blocks.lava, 0, 3);
		world.setBlock(x + 14, y + 0, z + 10, Blocks.lava, 8, 3);
		world.setBlock(x + 15, y + 0, z + 10, Blocks.lava, 0, 3);
		world.setBlock(x + 16, y + 0, z + 10, Blocks.lava, 0, 3);
		world.setBlock(x + 17, y + 0, z + 10, Blocks.lava, 2, 3);
		world.setBlock(x + 18, y + 0, z + 10, Blocks.lava, 0, 3);
		world.setBlock(x + 19, y + 0, z + 10, ExtraPlanets_Blocks.volcanicRock, 0, 3);
		world.setBlock(x + 20, y + 0, z + 10, ExtraPlanets_Blocks.volcanicRock, 0, 3);
		world.setBlock(x + 21, y + 0, z + 10, ExtraPlanets_Blocks.volcanicRock, 0, 3);
		world.setBlock(x + 22, y + 0, z + 10, ExtraPlanets_Blocks.volcanicRock, 0, 3);
		world.setBlock(x + 23, y + 0, z + 10, ExtraPlanets_Blocks.volcanicRock, 0, 3);
		world.setBlock(x + 24, y + 0, z + 10, ExtraPlanets_Blocks.volcanicRock, 0, 3);
		world.setBlock(x + 25, y + 0, z + 10, ExtraPlanets_Blocks.volcanicRock, 0, 3);
		world.setBlock(x + 0, y + 0, z + 11, ExtraPlanets_Blocks.volcanicRock, 0, 3);
		world.setBlock(x + 1, y + 0, z + 11, ExtraPlanets_Blocks.volcanicRock, 0, 3);
		world.setBlock(x + 2, y + 0, z + 11, ExtraPlanets_Blocks.volcanicRock, 0, 3);
		world.setBlock(x + 3, y + 0, z + 11, Blocks.lava, 0, 3);
		world.setBlock(x + 4, y + 0, z + 11, Blocks.lava, 0, 3);
		world.setBlock(x + 5, y + 0, z + 11, Blocks.lava, 0, 3);
		world.setBlock(x + 6, y + 0, z + 11, Blocks.lava, 0, 3);
		world.setBlock(x + 7, y + 0, z + 11, Blocks.lava, 8, 3);
		world.setBlock(x + 8, y + 0, z + 11, Blocks.lava, 0, 3);
		world.setBlock(x + 9, y + 0, z + 11, Blocks.lava, 0, 3);
		world.setBlock(x + 10, y + 0, z + 11, Blocks.lava, 0, 3);
		world.setBlock(x + 11, y + 0, z + 11, Blocks.lava, 0, 3);
		world.setBlock(x + 12, y + 0, z + 11, Blocks.lava, 0, 3);
		world.setBlock(x + 13, y + 0, z + 11, Blocks.lava, 0, 3);
		world.setBlock(x + 14, y + 0, z + 11, Blocks.lava, 10, 3);
		world.setBlock(x + 15, y + 0, z + 11, Blocks.lava, 0, 3);
		world.setBlock(x + 16, y + 0, z + 11, Blocks.lava, 8, 3);
		world.setBlock(x + 17, y + 0, z + 11, Blocks.lava, 8, 3);
		world.setBlock(x + 18, y + 0, z + 11, Blocks.lava, 0, 3);
		world.setBlock(x + 19, y + 0, z + 11, Blocks.lava, 0, 3);
		world.setBlock(x + 20, y + 0, z + 11, Blocks.lava, 0, 3);
		world.setBlock(x + 21, y + 0, z + 11, ExtraPlanets_Blocks.volcanicRock, 0, 3);
		world.setBlock(x + 22, y + 0, z + 11, ExtraPlanets_Blocks.volcanicRock, 0, 3);
		world.setBlock(x + 23, y + 0, z + 11, ExtraPlanets_Blocks.volcanicRock, 0, 3);
		world.setBlock(x + 24, y + 0, z + 11, ExtraPlanets_Blocks.volcanicRock, 0, 3);
		world.setBlock(x + 25, y + 0, z + 11, ExtraPlanets_Blocks.volcanicRock, 0, 3);
		world.setBlock(x + 26, y + 0, z + 11, Blocks.lava, 6, 3);
		world.setBlock(x + 0, y + 0, z + 12, ExtraPlanets_Blocks.volcanicRock, 0, 3);
		world.setBlock(x + 1, y + 0, z + 12, ExtraPlanets_Blocks.volcanicRock, 0, 3);
		world.setBlock(x + 2, y + 0, z + 12, ExtraPlanets_Blocks.volcanicRock, 0, 3);
		world.setBlock(x + 3, y + 0, z + 12, Blocks.lava, 0, 3);
		world.setBlock(x + 4, y + 0, z + 12, Blocks.lava, 0, 3);
		world.setBlock(x + 5, y + 0, z + 12, Blocks.lava, 0, 3);
		world.setBlock(x + 6, y + 0, z + 12, Blocks.lava, 0, 3);
		world.setBlock(x + 7, y + 0, z + 12, Blocks.lava, 0, 3);
		world.setBlock(x + 8, y + 0, z + 12, Blocks.lava, 0, 3);
		world.setBlock(x + 9, y + 0, z + 12, Blocks.lava, 0, 3);
		world.setBlock(x + 10, y + 0, z + 12, Blocks.lava, 10, 3);
		world.setBlock(x + 11, y + 0, z + 12, Blocks.lava, 0, 3);
		world.setBlock(x + 12, y + 0, z + 12, Blocks.lava, 0, 3);
		world.setBlock(x + 13, y + 0, z + 12, Blocks.lava, 0, 3);
		world.setBlock(x + 14, y + 0, z + 12, Blocks.lava, 0, 3);
		world.setBlock(x + 15, y + 0, z + 12, Blocks.lava, 0, 3);
		world.setBlock(x + 16, y + 0, z + 12, Blocks.lava, 0, 3);
		world.setBlock(x + 17, y + 0, z + 12, Blocks.lava, 0, 3);
		world.setBlock(x + 18, y + 0, z + 12, Blocks.lava, 10, 3);
		world.setBlock(x + 19, y + 0, z + 12, Blocks.lava, 0, 3);
		world.setBlock(x + 20, y + 0, z + 12, Blocks.lava, 0, 3);
		world.setBlock(x + 21, y + 0, z + 12, Blocks.lava, 0, 3);
		world.setBlock(x + 22, y + 0, z + 12, Blocks.lava, 2, 3);
		world.setBlock(x + 23, y + 0, z + 12, ExtraPlanets_Blocks.volcanicRock, 0, 3);
		world.setBlock(x + 24, y + 0, z + 12, ExtraPlanets_Blocks.volcanicRock, 0, 3);
		world.setBlock(x + 25, y + 0, z + 12, ExtraPlanets_Blocks.volcanicRock, 0, 3);
		world.setBlock(x + 26, y + 0, z + 12, Blocks.lava, 4, 3);
		world.setBlock(x + 27, y + 0, z + 12, Blocks.lava, 6, 3);
		world.setBlock(x + 0, y + 0, z + 13, ExtraPlanets_Blocks.volcanicRock, 0, 3);
		world.setBlock(x + 1, y + 0, z + 13, ExtraPlanets_Blocks.volcanicRock, 0, 3);
		world.setBlock(x + 2, y + 0, z + 13, ExtraPlanets_Blocks.volcanicRock, 0, 3);
		world.setBlock(x + 3, y + 0, z + 13, Blocks.lava, 0, 3);
		world.setBlock(x + 4, y + 0, z + 13, Blocks.lava, 8, 3);
		world.setBlock(x + 5, y + 0, z + 13, Blocks.lava, 0, 3);
		if (rand.nextInt(30) == 1)
			world.setBlock(x + 6, y + 0, z + 13, Blocks.chest, 5, 3);

		world.setBlock(x + 7, y + 0, z + 13, Blocks.lava, 0, 3);
		world.setBlock(x + 8, y + 0, z + 13, Blocks.lava, 0, 3);
		world.setBlock(x + 9, y + 0, z + 13, Blocks.lava, 8, 3);
		world.setBlock(x + 10, y + 0, z + 13, Blocks.lava, 8, 3);
		world.setBlock(x + 11, y + 0, z + 13, Blocks.lava, 10, 3);
		world.setBlock(x + 12, y + 0, z + 13, Blocks.lava, 8, 3);
		world.setBlock(x + 13, y + 0, z + 13, Blocks.lava, 0, 3);
		world.setBlock(x + 14, y + 0, z + 13, Blocks.lava, 8, 3);
		world.setBlock(x + 15, y + 0, z + 13, Blocks.lava, 0, 3);
		world.setBlock(x + 16, y + 0, z + 13, Blocks.lava, 0, 3);
		world.setBlock(x + 17, y + 0, z + 13, Blocks.lava, 0, 3);
		if (rand.nextInt(30) == 1)
			world.setBlock(x + 18, y + 0, z + 13, Blocks.chest, 4, 3);

		world.setBlock(x + 19, y + 0, z + 13, Blocks.lava, 10, 3);
		world.setBlock(x + 20, y + 0, z + 13, Blocks.lava, 0, 3);
		world.setBlock(x + 21, y + 0, z + 13, Blocks.lava, 0, 3);
		world.setBlock(x + 22, y + 0, z + 13, ExtraPlanets_Blocks.volcanicRock, 0, 3);
		world.setBlock(x + 23, y + 0, z + 13, ExtraPlanets_Blocks.volcanicRock, 0, 3);
		world.setBlock(x + 24, y + 0, z + 13, ExtraPlanets_Blocks.volcanicRock, 0, 3);
		world.setBlock(x + 25, y + 0, z + 13, Blocks.lava, 14, 3);
		world.setBlock(x + 26, y + 0, z + 13, Blocks.lava, 2, 3);
		world.setBlock(x + 27, y + 0, z + 13, Blocks.lava, 4, 3);
		world.setBlock(x + 28, y + 0, z + 13, Blocks.lava, 6, 3);
		world.setBlock(x + 0, y + 0, z + 14, ExtraPlanets_Blocks.volcanicRock, 0, 3);
		world.setBlock(x + 1, y + 0, z + 14, ExtraPlanets_Blocks.volcanicRock, 0, 3);
		world.setBlock(x + 2, y + 0, z + 14, ExtraPlanets_Blocks.volcanicRock, 0, 3);
		world.setBlock(x + 3, y + 0, z + 14, Blocks.lava, 0, 3);
		world.setBlock(x + 4, y + 0, z + 14, Blocks.lava, 0, 3);
		world.setBlock(x + 5, y + 0, z + 14, Blocks.lava, 0, 3);
		world.setBlock(x + 6, y + 0, z + 14, Blocks.lava, 0, 3);
		world.setBlock(x + 7, y + 0, z + 14, Blocks.lava, 0, 3);
		world.setBlock(x + 8, y + 0, z + 14, Blocks.lava, 0, 3);
		world.setBlock(x + 9, y + 0, z + 14, Blocks.lava, 0, 3);
		world.setBlock(x + 10, y + 0, z + 14, Blocks.lava, 8, 3);
		world.setBlock(x + 11, y + 0, z + 14, Blocks.lava, 0, 3);
		world.setBlock(x + 12, y + 0, z + 14, Blocks.lava, 0, 3);
		world.setBlock(x + 13, y + 0, z + 14, Blocks.lava, 0, 3);
		world.setBlock(x + 14, y + 0, z + 14, Blocks.lava, 0, 3);
		world.setBlock(x + 15, y + 0, z + 14, Blocks.lava, 0, 3);
		world.setBlock(x + 16, y + 0, z + 14, Blocks.lava, 0, 3);
		world.setBlock(x + 17, y + 0, z + 14, Blocks.lava, 0, 3);
		world.setBlock(x + 18, y + 0, z + 14, Blocks.lava, 0, 3);
		world.setBlock(x + 19, y + 0, z + 14, Blocks.lava, 0, 3);
		world.setBlock(x + 20, y + 0, z + 14, Blocks.lava, 0, 3);
		world.setBlock(x + 21, y + 0, z + 14, Blocks.lava, 0, 3);
		world.setBlock(x + 22, y + 0, z + 14, ExtraPlanets_Blocks.volcanicRock, 0, 3);
		world.setBlock(x + 23, y + 0, z + 14, ExtraPlanets_Blocks.volcanicRock, 0, 3);
		world.setBlock(x + 24, y + 0, z + 14, Blocks.lava, 14, 3);
		world.setBlock(x + 25, y + 0, z + 14, Blocks.lava, 2, 3);
		world.setBlock(x + 26, y + 0, z + 14, Blocks.lava, 4, 3);
		world.setBlock(x + 27, y + 0, z + 14, Blocks.lava, 6, 3);
		world.setBlock(x + 1, y + 0, z + 15, ExtraPlanets_Blocks.volcanicRock, 0, 3);
		world.setBlock(x + 2, y + 0, z + 15, ExtraPlanets_Blocks.volcanicRock, 0, 3);
		world.setBlock(x + 3, y + 0, z + 15, ExtraPlanets_Blocks.volcanicRock, 0, 3);
		world.setBlock(x + 4, y + 0, z + 15, Blocks.lava, 0, 3);
		world.setBlock(x + 5, y + 0, z + 15, Blocks.lava, 0, 3);
		world.setBlock(x + 6, y + 0, z + 15, Blocks.lava, 0, 3);
		world.setBlock(x + 7, y + 0, z + 15, Blocks.lava, 0, 3);
		world.setBlock(x + 8, y + 0, z + 15, Blocks.lava, 0, 3);
		world.setBlock(x + 9, y + 0, z + 15, Blocks.lava, 0, 3);
		world.setBlock(x + 10, y + 0, z + 15, Blocks.lava, 0, 3);
		world.setBlock(x + 11, y + 0, z + 15, Blocks.lava, 0, 3);
		world.setBlock(x + 12, y + 0, z + 15, Blocks.lava, 0, 3);
		world.setBlock(x + 13, y + 0, z + 15, Blocks.lava, 0, 3);
		world.setBlock(x + 14, y + 0, z + 15, Blocks.lava, 0, 3);
		world.setBlock(x + 15, y + 0, z + 15, Blocks.lava, 0, 3);
		world.setBlock(x + 16, y + 0, z + 15, Blocks.lava, 0, 3);
		world.setBlock(x + 17, y + 0, z + 15, Blocks.lava, 0, 3);
		world.setBlock(x + 18, y + 0, z + 15, Blocks.lava, 0, 3);
		world.setBlock(x + 19, y + 0, z + 15, Blocks.lava, 0, 3);
		world.setBlock(x + 20, y + 0, z + 15, Blocks.lava, 2, 3);
		world.setBlock(x + 21, y + 0, z + 15, Blocks.lava, 2, 3);
		world.setBlock(x + 22, y + 0, z + 15, ExtraPlanets_Blocks.volcanicRock, 0, 3);
		world.setBlock(x + 23, y + 0, z + 15, Blocks.lava, 14, 3);
		world.setBlock(x + 24, y + 0, z + 15, Blocks.lava, 2, 3);
		world.setBlock(x + 25, y + 0, z + 15, Blocks.lava, 4, 3);
		world.setBlock(x + 26, y + 0, z + 15, Blocks.lava, 6, 3);
		world.setBlock(x + 2, y + 0, z + 16, ExtraPlanets_Blocks.volcanicRock, 0, 3);
		world.setBlock(x + 3, y + 0, z + 16, ExtraPlanets_Blocks.volcanicRock, 0, 3);
		world.setBlock(x + 4, y + 0, z + 16, Blocks.lava, 0, 3);
		world.setBlock(x + 5, y + 0, z + 16, Blocks.lava, 0, 3);
		world.setBlock(x + 6, y + 0, z + 16, Blocks.lava, 0, 3);
		world.setBlock(x + 7, y + 0, z + 16, Blocks.lava, 0, 3);
		world.setBlock(x + 8, y + 0, z + 16, Blocks.lava, 0, 3);
		world.setBlock(x + 9, y + 0, z + 16, Blocks.lava, 8, 3);
		world.setBlock(x + 10, y + 0, z + 16, Blocks.lava, 0, 3);
		world.setBlock(x + 11, y + 0, z + 16, Blocks.lava, 0, 3);
		world.setBlock(x + 12, y + 0, z + 16, Blocks.lava, 0, 3);
		world.setBlock(x + 13, y + 0, z + 16, Blocks.lava, 8, 3);
		world.setBlock(x + 14, y + 0, z + 16, Blocks.lava, 0, 3);
		world.setBlock(x + 15, y + 0, z + 16, Blocks.lava, 0, 3);
		world.setBlock(x + 16, y + 0, z + 16, Blocks.lava, 0, 3);
		world.setBlock(x + 17, y + 0, z + 16, Blocks.lava, 0, 3);
		world.setBlock(x + 18, y + 0, z + 16, Blocks.lava, 0, 3);
		world.setBlock(x + 19, y + 0, z + 16, Blocks.lava, 0, 3);
		world.setBlock(x + 20, y + 0, z + 16, Blocks.lava, 0, 3);
		world.setBlock(x + 21, y + 0, z + 16, ExtraPlanets_Blocks.volcanicRock, 0, 3);
		world.setBlock(x + 22, y + 0, z + 16, Blocks.lava, 12, 3);
		world.setBlock(x + 23, y + 0, z + 16, Blocks.lava, 2, 3);
		world.setBlock(x + 24, y + 0, z + 16, Blocks.lava, 4, 3);
		world.setBlock(x + 25, y + 0, z + 16, Blocks.lava, 6, 3);
		world.setBlock(x + 2, y + 0, z + 17, ExtraPlanets_Blocks.volcanicRock, 0, 3);
		world.setBlock(x + 3, y + 0, z + 17, ExtraPlanets_Blocks.volcanicRock, 0, 3);
		world.setBlock(x + 4, y + 0, z + 17, Blocks.lava, 0, 3);
		world.setBlock(x + 5, y + 0, z + 17, Blocks.lava, 8, 3);
		world.setBlock(x + 6, y + 0, z + 17, Blocks.lava, 0, 3);
		world.setBlock(x + 7, y + 0, z + 17, Blocks.lava, 0, 3);
		world.setBlock(x + 8, y + 0, z + 17, Blocks.lava, 8, 3);
		world.setBlock(x + 9, y + 0, z + 17, Blocks.lava, 8, 3);
		world.setBlock(x + 10, y + 0, z + 17, Blocks.lava, 8, 3);
		world.setBlock(x + 11, y + 0, z + 17, Blocks.lava, 8, 3);
		world.setBlock(x + 12, y + 0, z + 17, Blocks.lava, 0, 3);
		world.setBlock(x + 13, y + 0, z + 17, Blocks.lava, 0, 3);
		world.setBlock(x + 14, y + 0, z + 17, Blocks.lava, 8, 3);
		world.setBlock(x + 15, y + 0, z + 17, Blocks.lava, 0, 3);
		world.setBlock(x + 16, y + 0, z + 17, Blocks.lava, 0, 3);
		world.setBlock(x + 17, y + 0, z + 17, Blocks.lava, 0, 3);
		world.setBlock(x + 18, y + 0, z + 17, Blocks.lava, 0, 3);
		world.setBlock(x + 19, y + 0, z + 17, ExtraPlanets_Blocks.volcanicRock, 0, 3);
		world.setBlock(x + 20, y + 0, z + 17, ExtraPlanets_Blocks.volcanicRock, 0, 3);
		world.setBlock(x + 21, y + 0, z + 17, ExtraPlanets_Blocks.volcanicRock, 0, 3);
		world.setBlock(x + 22, y + 0, z + 17, ExtraPlanets_Blocks.volcanicRock, 0, 3);
		world.setBlock(x + 23, y + 0, z + 17, Blocks.lava, 12, 3);
		world.setBlock(x + 24, y + 0, z + 17, Blocks.lava, 2, 3);
		world.setBlock(x + 25, y + 0, z + 17, Blocks.lava, 4, 3);
		world.setBlock(x + 26, y + 0, z + 17, Blocks.lava, 6, 3);
		world.setBlock(x + 2, y + 0, z + 18, ExtraPlanets_Blocks.volcanicRock, 0, 3);
		world.setBlock(x + 3, y + 0, z + 18, ExtraPlanets_Blocks.volcanicRock, 0, 3);
		world.setBlock(x + 4, y + 0, z + 18, ExtraPlanets_Blocks.volcanicRock, 0, 3);
		world.setBlock(x + 5, y + 0, z + 18, Blocks.lava, 0, 3);
		world.setBlock(x + 6, y + 0, z + 18, ExtraPlanets_Blocks.volcanicRock, 0, 3);
		world.setBlock(x + 7, y + 0, z + 18, Blocks.lava, 0, 3);
		world.setBlock(x + 8, y + 0, z + 18, Blocks.lava, 0, 3);
		world.setBlock(x + 9, y + 0, z + 18, Blocks.lava, 0, 3);
		world.setBlock(x + 10, y + 0, z + 18, Blocks.lava, 0, 3);
		world.setBlock(x + 11, y + 0, z + 18, Blocks.lava, 0, 3);
		world.setBlock(x + 12, y + 0, z + 18, Blocks.lava, 0, 3);
		world.setBlock(x + 13, y + 0, z + 18, Blocks.lava, 0, 3);
		world.setBlock(x + 14, y + 0, z + 18, Blocks.lava, 0, 3);
		world.setBlock(x + 15, y + 0, z + 18, Blocks.lava, 0, 3);
		world.setBlock(x + 16, y + 0, z + 18, Blocks.lava, 0, 3);
		world.setBlock(x + 17, y + 0, z + 18, ExtraPlanets_Blocks.volcanicRock, 0, 3);
		world.setBlock(x + 18, y + 0, z + 18, ExtraPlanets_Blocks.volcanicRock, 0, 3);
		world.setBlock(x + 19, y + 0, z + 18, ExtraPlanets_Blocks.volcanicRock, 0, 3);
		world.setBlock(x + 20, y + 0, z + 18, ExtraPlanets_Blocks.volcanicRock, 0, 3);
		world.setBlock(x + 21, y + 0, z + 18, ExtraPlanets_Blocks.volcanicRock, 0, 3);
		world.setBlock(x + 22, y + 0, z + 18, Blocks.lava, 12, 3);
		world.setBlock(x + 23, y + 0, z + 18, Blocks.lava, 2, 3);
		world.setBlock(x + 24, y + 0, z + 18, Blocks.lava, 4, 3);
		world.setBlock(x + 25, y + 0, z + 18, Blocks.lava, 6, 3);
		world.setBlock(x + 3, y + 0, z + 19, ExtraPlanets_Blocks.volcanicRock, 0, 3);
		world.setBlock(x + 4, y + 0, z + 19, ExtraPlanets_Blocks.volcanicRock, 0, 3);
		world.setBlock(x + 5, y + 0, z + 19, ExtraPlanets_Blocks.volcanicRock, 0, 3);
		world.setBlock(x + 6, y + 0, z + 19, ExtraPlanets_Blocks.volcanicRock, 0, 3);
		world.setBlock(x + 7, y + 0, z + 19, ExtraPlanets_Blocks.volcanicRock, 0, 3);
		world.setBlock(x + 8, y + 0, z + 19, ExtraPlanets_Blocks.volcanicRock, 0, 3);
		world.setBlock(x + 9, y + 0, z + 19, ExtraPlanets_Blocks.volcanicRock, 0, 3);
		world.setBlock(x + 10, y + 0, z + 19, ExtraPlanets_Blocks.volcanicRock, 0, 3);
		world.setBlock(x + 11, y + 0, z + 19, ExtraPlanets_Blocks.volcanicRock, 0, 3);
		world.setBlock(x + 12, y + 0, z + 19, ExtraPlanets_Blocks.volcanicRock, 0, 3);
		world.setBlock(x + 13, y + 0, z + 19, ExtraPlanets_Blocks.volcanicRock, 0, 3);
		world.setBlock(x + 14, y + 0, z + 19, ExtraPlanets_Blocks.volcanicRock, 0, 3);
		world.setBlock(x + 15, y + 0, z + 19, ExtraPlanets_Blocks.volcanicRock, 0, 3);
		world.setBlock(x + 16, y + 0, z + 19, ExtraPlanets_Blocks.volcanicRock, 0, 3);
		world.setBlock(x + 17, y + 0, z + 19, ExtraPlanets_Blocks.volcanicRock, 0, 3);
		world.setBlock(x + 18, y + 0, z + 19, ExtraPlanets_Blocks.volcanicRock, 0, 3);
		world.setBlock(x + 19, y + 0, z + 19, ExtraPlanets_Blocks.volcanicRock, 0, 3);
		world.setBlock(x + 20, y + 0, z + 19, ExtraPlanets_Blocks.volcanicRock, 0, 3);
		world.setBlock(x + 21, y + 0, z + 19, ExtraPlanets_Blocks.volcanicRock, 0, 3);
		world.setBlock(x + 22, y + 0, z + 19, Blocks.lava, 12, 3);
		world.setBlock(x + 23, y + 0, z + 19, Blocks.lava, 2, 3);
		world.setBlock(x + 24, y + 0, z + 19, Blocks.lava, 4, 3);
		world.setBlock(x + 25, y + 0, z + 19, Blocks.lava, 6, 3);
		world.setBlock(x + 3, y + 0, z + 20, ExtraPlanets_Blocks.volcanicRock, 0, 3);
		world.setBlock(x + 4, y + 0, z + 20, ExtraPlanets_Blocks.volcanicRock, 0, 3);
		world.setBlock(x + 5, y + 0, z + 20, ExtraPlanets_Blocks.volcanicRock, 0, 3);
		world.setBlock(x + 6, y + 0, z + 20, ExtraPlanets_Blocks.volcanicRock, 0, 3);
		world.setBlock(x + 7, y + 0, z + 20, ExtraPlanets_Blocks.volcanicRock, 0, 3);
		world.setBlock(x + 8, y + 0, z + 20, ExtraPlanets_Blocks.volcanicRock, 0, 3);
		world.setBlock(x + 9, y + 0, z + 20, ExtraPlanets_Blocks.volcanicRock, 0, 3);
		world.setBlock(x + 10, y + 0, z + 20, ExtraPlanets_Blocks.volcanicRock, 0, 3);
		world.setBlock(x + 11, y + 0, z + 20, ExtraPlanets_Blocks.volcanicRock, 0, 3);
		world.setBlock(x + 12, y + 0, z + 20, ExtraPlanets_Blocks.volcanicRock, 0, 3);
		world.setBlock(x + 13, y + 0, z + 20, ExtraPlanets_Blocks.volcanicRock, 0, 3);
		world.setBlock(x + 14, y + 0, z + 20, ExtraPlanets_Blocks.volcanicRock, 0, 3);
		world.setBlock(x + 15, y + 0, z + 20, ExtraPlanets_Blocks.volcanicRock, 0, 3);
		world.setBlock(x + 16, y + 0, z + 20, ExtraPlanets_Blocks.volcanicRock, 0, 3);
		world.setBlock(x + 17, y + 0, z + 20, ExtraPlanets_Blocks.volcanicRock, 0, 3);
		world.setBlock(x + 18, y + 0, z + 20, ExtraPlanets_Blocks.volcanicRock, 0, 3);
		world.setBlock(x + 19, y + 0, z + 20, ExtraPlanets_Blocks.volcanicRock, 0, 3);
		world.setBlock(x + 20, y + 0, z + 20, ExtraPlanets_Blocks.volcanicRock, 0, 3);
		world.setBlock(x + 21, y + 0, z + 20, Blocks.lava, 10, 3);
		world.setBlock(x + 22, y + 0, z + 20, Blocks.lava, 2, 3);
		world.setBlock(x + 23, y + 0, z + 20, Blocks.lava, 4, 3);
		world.setBlock(x + 24, y + 0, z + 20, Blocks.lava, 6, 3);
		world.setBlock(x + 4, y + 0, z + 21, Blocks.lava, 6, 3);
		world.setBlock(x + 5, y + 0, z + 21, ExtraPlanets_Blocks.volcanicRock, 0, 3);
		world.setBlock(x + 6, y + 0, z + 21, ExtraPlanets_Blocks.volcanicRock, 0, 3);
		world.setBlock(x + 7, y + 0, z + 21, ExtraPlanets_Blocks.volcanicRock, 0, 3);
		world.setBlock(x + 8, y + 0, z + 21, ExtraPlanets_Blocks.volcanicRock, 0, 3);
		world.setBlock(x + 9, y + 0, z + 21, ExtraPlanets_Blocks.volcanicRock, 0, 3);
		world.setBlock(x + 10, y + 0, z + 21, ExtraPlanets_Blocks.volcanicRock, 0, 3);
		world.setBlock(x + 11, y + 0, z + 21, ExtraPlanets_Blocks.volcanicRock, 0, 3);
		world.setBlock(x + 12, y + 0, z + 21, ExtraPlanets_Blocks.volcanicRock, 0, 3);
		world.setBlock(x + 13, y + 0, z + 21, ExtraPlanets_Blocks.volcanicRock, 0, 3);
		world.setBlock(x + 14, y + 0, z + 21, ExtraPlanets_Blocks.volcanicRock, 0, 3);
		world.setBlock(x + 15, y + 0, z + 21, ExtraPlanets_Blocks.volcanicRock, 0, 3);
		world.setBlock(x + 16, y + 0, z + 21, ExtraPlanets_Blocks.volcanicRock, 0, 3);
		world.setBlock(x + 17, y + 0, z + 21, ExtraPlanets_Blocks.volcanicRock, 0, 3);
		world.setBlock(x + 18, y + 0, z + 21, ExtraPlanets_Blocks.volcanicRock, 0, 3);
		world.setBlock(x + 19, y + 0, z + 21, ExtraPlanets_Blocks.volcanicRock, 0, 3);
		world.setBlock(x + 20, y + 0, z + 21, ExtraPlanets_Blocks.volcanicRock, 0, 3);
		world.setBlock(x + 21, y + 0, z + 21, Blocks.lava, 12, 3);
		world.setBlock(x + 22, y + 0, z + 21, Blocks.lava, 2, 3);
		world.setBlock(x + 23, y + 0, z + 21, Blocks.lava, 4, 3);
		world.setBlock(x + 24, y + 0, z + 21, Blocks.lava, 6, 3);
		world.setBlock(x + 3, y + 0, z + 22, Blocks.lava, 6, 3);
		world.setBlock(x + 4, y + 0, z + 22, Blocks.lava, 4, 3);
		world.setBlock(x + 5, y + 0, z + 22, Blocks.lava, 2, 3);
		world.setBlock(x + 6, y + 0, z + 22, Blocks.lava, 12, 3);
		world.setBlock(x + 7, y + 0, z + 22, ExtraPlanets_Blocks.volcanicRock, 0, 3);
		world.setBlock(x + 8, y + 0, z + 22, ExtraPlanets_Blocks.volcanicRock, 0, 3);
		world.setBlock(x + 9, y + 0, z + 22, ExtraPlanets_Blocks.volcanicRock, 0, 3);
		world.setBlock(x + 10, y + 0, z + 22, ExtraPlanets_Blocks.volcanicRock, 0, 3);
		world.setBlock(x + 11, y + 0, z + 22, ExtraPlanets_Blocks.volcanicRock, 0, 3);
		world.setBlock(x + 12, y + 0, z + 22, ExtraPlanets_Blocks.volcanicRock, 0, 3);
		world.setBlock(x + 13, y + 0, z + 22, ExtraPlanets_Blocks.volcanicRock, 0, 3);
		world.setBlock(x + 14, y + 0, z + 22, ExtraPlanets_Blocks.volcanicRock, 0, 3);
		world.setBlock(x + 15, y + 0, z + 22, ExtraPlanets_Blocks.volcanicRock, 0, 3);
		world.setBlock(x + 16, y + 0, z + 22, ExtraPlanets_Blocks.volcanicRock, 0, 3);
		world.setBlock(x + 17, y + 0, z + 22, ExtraPlanets_Blocks.volcanicRock, 0, 3);
		world.setBlock(x + 18, y + 0, z + 22, ExtraPlanets_Blocks.volcanicRock, 0, 3);
		world.setBlock(x + 19, y + 0, z + 22, ExtraPlanets_Blocks.volcanicRock, 0, 3);
		world.setBlock(x + 20, y + 0, z + 22, Blocks.lava, 12, 3);
		world.setBlock(x + 21, y + 0, z + 22, Blocks.lava, 2, 3);
		world.setBlock(x + 22, y + 0, z + 22, Blocks.lava, 4, 3);
		world.setBlock(x + 23, y + 0, z + 22, Blocks.lava, 6, 3);
		world.setBlock(x + 4, y + 0, z + 23, Blocks.lava, 6, 3);
		world.setBlock(x + 5, y + 0, z + 23, Blocks.lava, 4, 3);
		world.setBlock(x + 6, y + 0, z + 23, Blocks.lava, 2, 3);
		world.setBlock(x + 7, y + 0, z + 23, Blocks.lava, 14, 3);
		world.setBlock(x + 8, y + 0, z + 23, ExtraPlanets_Blocks.volcanicRock, 0, 3);
		world.setBlock(x + 9, y + 0, z + 23, ExtraPlanets_Blocks.volcanicRock, 0, 3);
		world.setBlock(x + 10, y + 0, z + 23, ExtraPlanets_Blocks.volcanicRock, 0, 3);
		world.setBlock(x + 11, y + 0, z + 23, ExtraPlanets_Blocks.volcanicRock, 0, 3);
		world.setBlock(x + 12, y + 0, z + 23, ExtraPlanets_Blocks.volcanicRock, 0, 3);
		world.setBlock(x + 13, y + 0, z + 23, ExtraPlanets_Blocks.volcanicRock, 0, 3);
		world.setBlock(x + 14, y + 0, z + 23, ExtraPlanets_Blocks.volcanicRock, 0, 3);
		world.setBlock(x + 15, y + 0, z + 23, ExtraPlanets_Blocks.volcanicRock, 0, 3);
		world.setBlock(x + 16, y + 0, z + 23, ExtraPlanets_Blocks.volcanicRock, 0, 3);
		world.setBlock(x + 17, y + 0, z + 23, ExtraPlanets_Blocks.volcanicRock, 0, 3);
		world.setBlock(x + 18, y + 0, z + 23, ExtraPlanets_Blocks.volcanicRock, 0, 3);
		world.setBlock(x + 19, y + 0, z + 23, ExtraPlanets_Blocks.volcanicRock, 0, 3);
		world.setBlock(x + 20, y + 0, z + 23, Blocks.lava, 2, 3);
		world.setBlock(x + 21, y + 0, z + 23, Blocks.lava, 4, 3);
		world.setBlock(x + 22, y + 0, z + 23, Blocks.lava, 6, 3);
		world.setBlock(x + 5, y + 0, z + 24, Blocks.lava, 6, 3);
		world.setBlock(x + 6, y + 0, z + 24, Blocks.lava, 4, 3);
		world.setBlock(x + 7, y + 0, z + 24, Blocks.lava, 2, 3);
		world.setBlock(x + 8, y + 0, z + 24, Blocks.lava, 14, 3);
		world.setBlock(x + 9, y + 0, z + 24, ExtraPlanets_Blocks.volcanicRock, 0, 3);
		world.setBlock(x + 10, y + 0, z + 24, ExtraPlanets_Blocks.volcanicRock, 0, 3);
		world.setBlock(x + 11, y + 0, z + 24, ExtraPlanets_Blocks.volcanicRock, 0, 3);
		world.setBlock(x + 12, y + 0, z + 24, ExtraPlanets_Blocks.volcanicRock, 0, 3);
		world.setBlock(x + 13, y + 0, z + 24, ExtraPlanets_Blocks.volcanicRock, 0, 3);
		world.setBlock(x + 14, y + 0, z + 24, ExtraPlanets_Blocks.volcanicRock, 0, 3);
		world.setBlock(x + 15, y + 0, z + 24, ExtraPlanets_Blocks.volcanicRock, 0, 3);
		world.setBlock(x + 16, y + 0, z + 24, ExtraPlanets_Blocks.volcanicRock, 0, 3);
		world.setBlock(x + 17, y + 0, z + 24, ExtraPlanets_Blocks.volcanicRock, 0, 3);
		world.setBlock(x + 18, y + 0, z + 24, Blocks.lava, 12, 3);
		world.setBlock(x + 19, y + 0, z + 24, Blocks.lava, 2, 3);
		world.setBlock(x + 20, y + 0, z + 24, Blocks.lava, 4, 3);
		world.setBlock(x + 21, y + 0, z + 24, Blocks.lava, 6, 3);
		world.setBlock(x + 6, y + 0, z + 25, Blocks.lava, 6, 3);
		world.setBlock(x + 7, y + 0, z + 25, Blocks.lava, 4, 3);
		world.setBlock(x + 8, y + 0, z + 25, Blocks.lava, 2, 3);
		world.setBlock(x + 9, y + 0, z + 25, Blocks.lava, 14, 3);
		world.setBlock(x + 10, y + 0, z + 25, ExtraPlanets_Blocks.volcanicRock, 0, 3);
		world.setBlock(x + 11, y + 0, z + 25, ExtraPlanets_Blocks.volcanicRock, 0, 3);
		world.setBlock(x + 12, y + 0, z + 25, ExtraPlanets_Blocks.volcanicRock, 0, 3);
		world.setBlock(x + 13, y + 0, z + 25, ExtraPlanets_Blocks.volcanicRock, 0, 3);
		world.setBlock(x + 14, y + 0, z + 25, ExtraPlanets_Blocks.volcanicRock, 0, 3);
		world.setBlock(x + 15, y + 0, z + 25, ExtraPlanets_Blocks.volcanicRock, 0, 3);
		world.setBlock(x + 16, y + 0, z + 25, ExtraPlanets_Blocks.volcanicRock, 0, 3);
		world.setBlock(x + 17, y + 0, z + 25, ExtraPlanets_Blocks.volcanicRock, 0, 3);
		world.setBlock(x + 18, y + 0, z + 25, Blocks.lava, 2, 3);
		world.setBlock(x + 19, y + 0, z + 25, Blocks.lava, 4, 3);
		world.setBlock(x + 20, y + 0, z + 25, Blocks.lava, 6, 3);
		world.setBlock(x + 7, y + 0, z + 26, Blocks.lava, 6, 3);
		world.setBlock(x + 8, y + 0, z + 26, Blocks.lava, 4, 3);
		world.setBlock(x + 9, y + 0, z + 26, Blocks.lava, 2, 3);
		world.setBlock(x + 10, y + 0, z + 26, ExtraPlanets_Blocks.volcanicRock, 0, 3);
		world.setBlock(x + 11, y + 0, z + 26, ExtraPlanets_Blocks.volcanicRock, 0, 3);
		world.setBlock(x + 12, y + 0, z + 26, ExtraPlanets_Blocks.volcanicRock, 0, 3);
		world.setBlock(x + 13, y + 0, z + 26, ExtraPlanets_Blocks.volcanicRock, 0, 3);
		world.setBlock(x + 14, y + 0, z + 26, ExtraPlanets_Blocks.volcanicRock, 0, 3);
		world.setBlock(x + 15, y + 0, z + 26, ExtraPlanets_Blocks.volcanicRock, 0, 3);
		world.setBlock(x + 16, y + 0, z + 26, ExtraPlanets_Blocks.volcanicRock, 0, 3);
		world.setBlock(x + 17, y + 0, z + 26, Blocks.lava, 6, 3);
		world.setBlock(x + 18, y + 0, z + 26, Blocks.lava, 4, 3);
		world.setBlock(x + 19, y + 0, z + 26, Blocks.lava, 6, 3);
		world.setBlock(x + 8, y + 0, z + 27, Blocks.lava, 6, 3);
		world.setBlock(x + 9, y + 0, z + 27, Blocks.lava, 4, 3);
		world.setBlock(x + 10, y + 0, z + 27, Blocks.lava, 6, 3);
		world.setBlock(x + 12, y + 0, z + 27, ExtraPlanets_Blocks.volcanicRock, 0, 3);
		world.setBlock(x + 13, y + 0, z + 27, ExtraPlanets_Blocks.volcanicRock, 0, 3);
		world.setBlock(x + 14, y + 0, z + 27, ExtraPlanets_Blocks.volcanicRock, 0, 3);
		world.setBlock(x + 15, y + 0, z + 27, Blocks.lava, 14, 3);
		world.setBlock(x + 16, y + 0, z + 27, Blocks.lava, 2, 3);
		world.setBlock(x + 17, y + 0, z + 27, Blocks.lava, 4, 3);
		world.setBlock(x + 18, y + 0, z + 27, Blocks.lava, 6, 3);
		world.setBlock(x + 9, y + 0, z + 28, Blocks.lava, 6, 3);
		world.setBlock(x + 13, y + 0, z + 28, Blocks.lava, 6, 3);
		world.setBlock(x + 14, y + 0, z + 28, Blocks.lava, 4, 3);
		world.setBlock(x + 15, y + 0, z + 28, Blocks.lava, 2, 3);
		world.setBlock(x + 16, y + 0, z + 28, Blocks.lava, 4, 3);
		world.setBlock(x + 17, y + 0, z + 28, Blocks.lava, 6, 3);
		world.setBlock(x + 14, y + 0, z + 29, Blocks.lava, 6, 3);
		world.setBlock(x + 15, y + 0, z + 29, Blocks.lava, 4, 3);
		world.setBlock(x + 16, y + 0, z + 29, Blocks.lava, 6, 3);
		world.setBlock(x + 15, y + 0, z + 30, Blocks.lava, 6, 3);
		world.setBlock(x + 9, y + 1, z + 4, ExtraPlanets_Blocks.volcanicRock, 0, 3);
		world.setBlock(x + 10, y + 1, z + 4, ExtraPlanets_Blocks.volcanicRock, 0, 3);
		world.setBlock(x + 11, y + 1, z + 4, ExtraPlanets_Blocks.volcanicRock, 0, 3);
		world.setBlock(x + 6, y + 1, z + 5, ExtraPlanets_Blocks.volcanicRock, 0, 3);
		world.setBlock(x + 7, y + 1, z + 5, ExtraPlanets_Blocks.volcanicRock, 0, 3);
		world.setBlock(x + 8, y + 1, z + 5, ExtraPlanets_Blocks.volcanicRock, 0, 3);
		world.setBlock(x + 9, y + 1, z + 5, ExtraPlanets_Blocks.volcanicRock, 0, 3);
		world.setBlock(x + 10, y + 1, z + 5, ExtraPlanets_Blocks.volcanicRock, 0, 3);
		world.setBlock(x + 11, y + 1, z + 5, Blocks.lava, 0, 3);
		world.setBlock(x + 12, y + 1, z + 5, Blocks.lava, 0, 3);
		world.setBlock(x + 16, y + 1, z + 5, Blocks.lava, 6, 3);
		world.setBlock(x + 17, y + 1, z + 5, Blocks.lava, 6, 3);
		world.setBlock(x + 5, y + 1, z + 6, ExtraPlanets_Blocks.volcanicRock, 0, 3);
		world.setBlock(x + 6, y + 1, z + 6, ExtraPlanets_Blocks.volcanicRock, 0, 3);
		world.setBlock(x + 7, y + 1, z + 6, ExtraPlanets_Blocks.volcanicRock, 0, 3);
		world.setBlock(x + 8, y + 1, z + 6, Blocks.lava, 0, 3);
		world.setBlock(x + 9, y + 1, z + 6, Blocks.lava, 0, 3);
		world.setBlock(x + 10, y + 1, z + 6, Blocks.lava, 0, 3);
		world.setBlock(x + 11, y + 1, z + 6, Blocks.lava, 2, 3);
		world.setBlock(x + 12, y + 1, z + 6, Blocks.lava, 2, 3);
		world.setBlock(x + 13, y + 1, z + 6, Blocks.lava, 2, 3);
		world.setBlock(x + 14, y + 1, z + 6, Blocks.lava, 12, 3);
		world.setBlock(x + 15, y + 1, z + 6, Blocks.lava, 2, 3);
		world.setBlock(x + 16, y + 1, z + 6, Blocks.lava, 4, 3);
		world.setBlock(x + 17, y + 1, z + 6, Blocks.lava, 4, 3);
		world.setBlock(x + 18, y + 1, z + 6, Blocks.lava, 6, 3);
		world.setBlock(x + 5, y + 1, z + 7, ExtraPlanets_Blocks.volcanicRock, 0, 3);
		world.setBlock(x + 6, y + 1, z + 7, Blocks.lava, 2, 3);
		world.setBlock(x + 7, y + 1, z + 7, Blocks.lava, 0, 3);
		world.setBlock(x + 8, y + 1, z + 7, Blocks.lava, 0, 3);
		world.setBlock(x + 9, y + 1, z + 7, Blocks.lava, 0, 3);
		world.setBlock(x + 10, y + 1, z + 7, Blocks.lava, 2, 3);
		world.setBlock(x + 11, y + 1, z + 7, Blocks.lava, 12, 3);
		world.setBlock(x + 12, y + 1, z + 7, Blocks.lava, 0, 3);
		world.setBlock(x + 13, y + 1, z + 7, ExtraPlanets_Blocks.volcanicRock, 0, 3);
		world.setBlock(x + 14, y + 1, z + 7, ExtraPlanets_Blocks.volcanicRock, 0, 3);
		world.setBlock(x + 15, y + 1, z + 7, Blocks.lava, 12, 3);
		world.setBlock(x + 16, y + 1, z + 7, Blocks.lava, 2, 3);
		world.setBlock(x + 17, y + 1, z + 7, Blocks.lava, 2, 3);
		world.setBlock(x + 18, y + 1, z + 7, Blocks.lava, 4, 3);
		world.setBlock(x + 19, y + 1, z + 7, Blocks.lava, 6, 3);
		world.setBlock(x + 20, y + 1, z + 7, Blocks.lava, 6, 3);
		world.setBlock(x + 4, y + 1, z + 8, ExtraPlanets_Blocks.volcanicRock, 0, 3);
		world.setBlock(x + 5, y + 1, z + 8, ExtraPlanets_Blocks.volcanicRock, 0, 3);
		world.setBlock(x + 6, y + 1, z + 8, Blocks.lava, 0, 3);
		world.setBlock(x + 7, y + 1, z + 8, Blocks.lava, 0, 3);
		world.setBlock(x + 8, y + 1, z + 8, Blocks.lava, 2, 3);
		world.setBlock(x + 9, y + 1, z + 8, Blocks.lava, 8, 3);
		world.setBlock(x + 10, y + 1, z + 8, Blocks.lava, 10, 3);
		world.setBlock(x + 11, y + 1, z + 8, Blocks.lava, 2, 3);
		world.setBlock(x + 12, y + 1, z + 8, Blocks.lava, 0, 3);
		world.setBlock(x + 13, y + 1, z + 8, ExtraPlanets_Blocks.volcanicRock, 0, 3);
		world.setBlock(x + 14, y + 1, z + 8, ExtraPlanets_Blocks.volcanicRock, 0, 3);
		world.setBlock(x + 15, y + 1, z + 8, ExtraPlanets_Blocks.volcanicRock, 0, 3);
		world.setBlock(x + 16, y + 1, z + 8, Blocks.lava, 10, 3);
		world.setBlock(x + 17, y + 1, z + 8, Blocks.lava, 0, 3);
		world.setBlock(x + 18, y + 1, z + 8, Blocks.lava, 2, 3);
		world.setBlock(x + 19, y + 1, z + 8, Blocks.lava, 4, 3);
		world.setBlock(x + 20, y + 1, z + 8, Blocks.lava, 4, 3);
		world.setBlock(x + 21, y + 1, z + 8, Blocks.lava, 6, 3);
		world.setBlock(x + 3, y + 1, z + 9, ExtraPlanets_Blocks.volcanicRock, 0, 3);
		world.setBlock(x + 4, y + 1, z + 9, ExtraPlanets_Blocks.volcanicRock, 0, 3);
		world.setBlock(x + 5, y + 1, z + 9, Blocks.lava, 0, 3);
		world.setBlock(x + 6, y + 1, z + 9, Blocks.lava, 2, 3);
		world.setBlock(x + 7, y + 1, z + 9, Blocks.lava, 8, 3);
		world.setBlock(x + 8, y + 1, z + 9, Blocks.lava, 8, 3);
		world.setBlock(x + 9, y + 1, z + 9, Blocks.lava, 8, 3);
		world.setBlock(x + 10, y + 1, z + 9, Blocks.lava, 8, 3);
		world.setBlock(x + 11, y + 1, z + 9, Blocks.lava, 2, 3);
		world.setBlock(x + 12, y + 1, z + 9, Blocks.lava, 0, 3);
		world.setBlock(x + 13, y + 1, z + 9, Blocks.lava, 0, 3);
		world.setBlock(x + 14, y + 1, z + 9, Blocks.lava, 0, 3);
		world.setBlock(x + 15, y + 1, z + 9, ExtraPlanets_Blocks.volcanicRock, 0, 3);
		world.setBlock(x + 16, y + 1, z + 9, ExtraPlanets_Blocks.volcanicRock, 0, 3);
		world.setBlock(x + 17, y + 1, z + 9, ExtraPlanets_Blocks.volcanicRock, 0, 3);
		world.setBlock(x + 18, y + 1, z + 9, Blocks.lava, 10, 3);
		world.setBlock(x + 19, y + 1, z + 9, Blocks.lava, 2, 3);
		world.setBlock(x + 20, y + 1, z + 9, Blocks.lava, 2, 3);
		world.setBlock(x + 21, y + 1, z + 9, Blocks.lava, 4, 3);
		world.setBlock(x + 3, y + 1, z + 10, ExtraPlanets_Blocks.volcanicRock, 0, 3);
		world.setBlock(x + 4, y + 1, z + 10, Blocks.lava, 0, 3);
		world.setBlock(x + 5, y + 1, z + 10, Blocks.lava, 8, 3);
		world.setBlock(x + 6, y + 1, z + 10, Blocks.lava, 8, 3);
		world.setBlock(x + 7, y + 1, z + 10, Blocks.lava, 8, 3);
		world.setBlock(x + 8, y + 1, z + 10, Blocks.lava, 10, 3);
		world.setBlock(x + 9, y + 1, z + 10, Blocks.lava, 8, 3);
		world.setBlock(x + 10, y + 1, z + 10, Blocks.lava, 8, 3);
		world.setBlock(x + 11, y + 1, z + 10, Blocks.lava, 8, 3);
		world.setBlock(x + 12, y + 1, z + 10, Blocks.lava, 0, 3);
		world.setBlock(x + 13, y + 1, z + 10, Blocks.lava, 2, 3);
		world.setBlock(x + 14, y + 1, z + 10, Blocks.lava, 0, 3);
		world.setBlock(x + 15, y + 1, z + 10, Blocks.lava, 0, 3);
		world.setBlock(x + 16, y + 1, z + 10, ExtraPlanets_Blocks.volcanicRock, 0, 3);
		world.setBlock(x + 17, y + 1, z + 10, ExtraPlanets_Blocks.volcanicRock, 0, 3);
		world.setBlock(x + 18, y + 1, z + 10, ExtraPlanets_Blocks.volcanicRock, 0, 3);
		world.setBlock(x + 19, y + 1, z + 10, Blocks.lava, 10, 3);
		world.setBlock(x + 20, y + 1, z + 10, Blocks.lava, 12, 3);
		world.setBlock(x + 21, y + 1, z + 10, Blocks.lava, 2, 3);
		world.setBlock(x + 2, y + 1, z + 11, ExtraPlanets_Blocks.volcanicRock, 0, 3);
		world.setBlock(x + 3, y + 1, z + 11, ExtraPlanets_Blocks.volcanicRock, 0, 3);
		world.setBlock(x + 4, y + 1, z + 11, Blocks.lava, 0, 3);
		world.setBlock(x + 5, y + 1, z + 11, Blocks.lava, 10, 3);
		world.setBlock(x + 6, y + 1, z + 11, Blocks.lava, 8, 3);
		world.setBlock(x + 7, y + 1, z + 11, Blocks.lava, 8, 3);
		world.setBlock(x + 8, y + 1, z + 11, Blocks.lava, 8, 3);
		world.setBlock(x + 9, y + 1, z + 11, Blocks.lava, 10, 3);
		world.setBlock(x + 10, y + 1, z + 11, Blocks.lava, 8, 3);
		world.setBlock(x + 11, y + 1, z + 11, Blocks.lava, 10, 3);
		world.setBlock(x + 12, y + 1, z + 11, Blocks.lava, 8, 3);
		world.setBlock(x + 13, y + 1, z + 11, Blocks.lava, 8, 3);
		world.setBlock(x + 14, y + 1, z + 11, Blocks.lava, 2, 3);
		world.setBlock(x + 15, y + 1, z + 11, Blocks.lava, 0, 3);
		world.setBlock(x + 16, y + 1, z + 11, Blocks.lava, 0, 3);
		world.setBlock(x + 17, y + 1, z + 11, Blocks.lava, 0, 3);
		world.setBlock(x + 18, y + 1, z + 11, ExtraPlanets_Blocks.volcanicRock, 0, 3);
		world.setBlock(x + 19, y + 1, z + 11, ExtraPlanets_Blocks.volcanicRock, 0, 3);
		world.setBlock(x + 20, y + 1, z + 11, ExtraPlanets_Blocks.volcanicRock, 0, 3);
		world.setBlock(x + 21, y + 1, z + 11, Blocks.lava, 12, 3);
		world.setBlock(x + 22, y + 1, z + 11, Blocks.lava, 2, 3);
		world.setBlock(x + 23, y + 1, z + 11, Blocks.lava, 4, 3);
		world.setBlock(x + 24, y + 1, z + 11, Blocks.lava, 6, 3);
		world.setBlock(x + 2, y + 1, z + 12, ExtraPlanets_Blocks.volcanicRock, 0, 3);
		world.setBlock(x + 3, y + 1, z + 12, ExtraPlanets_Blocks.volcanicRock, 0, 3);
		world.setBlock(x + 4, y + 1, z + 12, Blocks.lava, 0, 3);
		world.setBlock(x + 5, y + 1, z + 12, Blocks.lava, 8, 3);
		world.setBlock(x + 6, y + 1, z + 12, Blocks.lava, 8, 3);
		world.setBlock(x + 7, y + 1, z + 12, Blocks.lava, 10, 3);
		world.setBlock(x + 8, y + 1, z + 12, Blocks.lava, 8, 3);
		world.setBlock(x + 9, y + 1, z + 12, Blocks.lava, 8, 3);
		world.setBlock(x + 10, y + 1, z + 12, Blocks.lava, 10, 3);
		world.setBlock(x + 11, y + 1, z + 12, Blocks.lava, 8, 3);
		world.setBlock(x + 12, y + 1, z + 12, Blocks.lava, 10, 3);
		world.setBlock(x + 13, y + 1, z + 12, Blocks.lava, 10, 3);
		world.setBlock(x + 14, y + 1, z + 12, Blocks.lava, 8, 3);
		world.setBlock(x + 15, y + 1, z + 12, Blocks.lava, 8, 3);
		world.setBlock(x + 16, y + 1, z + 12, Blocks.lava, 8, 3);
		world.setBlock(x + 17, y + 1, z + 12, Blocks.lava, 8, 3);
		world.setBlock(x + 18, y + 1, z + 12, Blocks.lava, 2, 3);
		world.setBlock(x + 19, y + 1, z + 12, ExtraPlanets_Blocks.volcanicRock, 0, 3);
		world.setBlock(x + 20, y + 1, z + 12, ExtraPlanets_Blocks.volcanicRock, 0, 3);
		world.setBlock(x + 21, y + 1, z + 12, ExtraPlanets_Blocks.volcanicRock, 0, 3);
		world.setBlock(x + 22, y + 1, z + 12, ExtraPlanets_Blocks.volcanicRock, 0, 3);
		world.setBlock(x + 2, y + 1, z + 13, ExtraPlanets_Blocks.volcanicRock, 0, 3);
		world.setBlock(x + 3, y + 1, z + 13, ExtraPlanets_Blocks.volcanicRock, 0, 3);
		world.setBlock(x + 4, y + 1, z + 13, Blocks.lava, 0, 3);
		world.setBlock(x + 5, y + 1, z + 13, Blocks.lava, 8, 3);
		world.setBlock(x + 6, y + 1, z + 13, Blocks.lava, 8, 3);
		world.setBlock(x + 7, y + 1, z + 13, Blocks.lava, 8, 3);
		world.setBlock(x + 8, y + 1, z + 13, Blocks.lava, 8, 3);
		world.setBlock(x + 9, y + 1, z + 13, Blocks.lava, 8, 3);
		world.setBlock(x + 10, y + 1, z + 13, Blocks.lava, 8, 3);
		world.setBlock(x + 11, y + 1, z + 13, Blocks.lava, 10, 3);
		world.setBlock(x + 12, y + 1, z + 13, Blocks.lava, 8, 3);
		world.setBlock(x + 13, y + 1, z + 13, Blocks.lava, 10, 3);
		world.setBlock(x + 14, y + 1, z + 13, Blocks.lava, 8, 3);
		world.setBlock(x + 15, y + 1, z + 13, Blocks.lava, 8, 3);
		world.setBlock(x + 16, y + 1, z + 13, Blocks.lava, 8, 3);
		world.setBlock(x + 17, y + 1, z + 13, Blocks.lava, 8, 3);
		world.setBlock(x + 18, y + 1, z + 13, Blocks.lava, 8, 3);
		world.setBlock(x + 19, y + 1, z + 13, Blocks.lava, 2, 3);
		world.setBlock(x + 20, y + 1, z + 13, ExtraPlanets_Blocks.volcanicRock, 0, 3);
		world.setBlock(x + 21, y + 1, z + 13, ExtraPlanets_Blocks.volcanicRock, 0, 3);
		world.setBlock(x + 22, y + 1, z + 13, Blocks.lava, 14, 3);
		world.setBlock(x + 23, y + 1, z + 13, Blocks.lava, 2, 3);
		world.setBlock(x + 24, y + 1, z + 13, Blocks.lava, 4, 3);
		world.setBlock(x + 25, y + 1, z + 13, Blocks.lava, 6, 3);
		world.setBlock(x + 2, y + 1, z + 14, ExtraPlanets_Blocks.volcanicRock, 0, 3);
		world.setBlock(x + 3, y + 1, z + 14, ExtraPlanets_Blocks.volcanicRock, 0, 3);
		world.setBlock(x + 4, y + 1, z + 14, Blocks.lava, 0, 3);
		world.setBlock(x + 5, y + 1, z + 14, Blocks.lava, 8, 3);
		world.setBlock(x + 6, y + 1, z + 14, Blocks.lava, 8, 3);
		world.setBlock(x + 7, y + 1, z + 14, Blocks.lava, 8, 3);
		world.setBlock(x + 8, y + 1, z + 14, Blocks.lava, 8, 3);
		world.setBlock(x + 9, y + 1, z + 14, Blocks.lava, 8, 3);
		world.setBlock(x + 10, y + 1, z + 14, Blocks.lava, 8, 3);
		world.setBlock(x + 11, y + 1, z + 14, Blocks.lava, 8, 3);
		world.setBlock(x + 12, y + 1, z + 14, Blocks.lava, 8, 3);
		world.setBlock(x + 13, y + 1, z + 14, Blocks.lava, 8, 3);
		world.setBlock(x + 14, y + 1, z + 14, Blocks.lava, 8, 3);
		world.setBlock(x + 15, y + 1, z + 14, Blocks.lava, 8, 3);
		world.setBlock(x + 16, y + 1, z + 14, Blocks.lava, 8, 3);
		world.setBlock(x + 17, y + 1, z + 14, Blocks.lava, 8, 3);
		world.setBlock(x + 18, y + 1, z + 14, Blocks.lava, 8, 3);
		world.setBlock(x + 20, y + 1, z + 14, ExtraPlanets_Blocks.volcanicRock, 0, 3);
		world.setBlock(x + 21, y + 1, z + 14, ExtraPlanets_Blocks.volcanicRock, 0, 3);
		world.setBlock(x + 22, y + 1, z + 14, Blocks.lava, 2, 3);
		world.setBlock(x + 23, y + 1, z + 14, Blocks.lava, 4, 3);
		world.setBlock(x + 24, y + 1, z + 14, Blocks.lava, 6, 3);
		world.setBlock(x + 3, y + 1, z + 15, ExtraPlanets_Blocks.volcanicRock, 0, 3);
		world.setBlock(x + 4, y + 1, z + 15, Blocks.lava, 0, 3);
		world.setBlock(x + 5, y + 1, z + 15, Blocks.lava, 0, 3);
		world.setBlock(x + 6, y + 1, z + 15, Blocks.lava, 8, 3);
		world.setBlock(x + 7, y + 1, z + 15, Blocks.lava, 8, 3);
		world.setBlock(x + 8, y + 1, z + 15, Blocks.lava, 8, 3);
		world.setBlock(x + 9, y + 1, z + 15, Blocks.lava, 8, 3);
		world.setBlock(x + 10, y + 1, z + 15, Blocks.lava, 8, 3);
		world.setBlock(x + 11, y + 1, z + 15, Blocks.lava, 8, 3);
		world.setBlock(x + 12, y + 1, z + 15, Blocks.lava, 8, 3);
		world.setBlock(x + 13, y + 1, z + 15, Blocks.lava, 8, 3);
		world.setBlock(x + 14, y + 1, z + 15, Blocks.lava, 8, 3);
		world.setBlock(x + 15, y + 1, z + 15, Blocks.lava, 8, 3);
		world.setBlock(x + 16, y + 1, z + 15, Blocks.lava, 8, 3);
		world.setBlock(x + 17, y + 1, z + 15, Blocks.lava, 8, 3);
		world.setBlock(x + 18, y + 1, z + 15, Blocks.lava, 8, 3);
		world.setBlock(x + 19, y + 1, z + 15, ExtraPlanets_Blocks.volcanicRock, 0, 3);
		world.setBlock(x + 20, y + 1, z + 15, ExtraPlanets_Blocks.volcanicRock, 0, 3);
		world.setBlock(x + 21, y + 1, z + 15, ExtraPlanets_Blocks.volcanicRock, 0, 3);
		world.setBlock(x + 22, y + 1, z + 15, Blocks.lava, 4, 3);
		world.setBlock(x + 23, y + 1, z + 15, Blocks.lava, 6, 3);
		world.setBlock(x + 3, y + 1, z + 16, ExtraPlanets_Blocks.volcanicRock, 0, 3);
		world.setBlock(x + 4, y + 1, z + 16, ExtraPlanets_Blocks.volcanicRock, 0, 3);
		world.setBlock(x + 5, y + 1, z + 16, Blocks.lava, 0, 3);
		world.setBlock(x + 6, y + 1, z + 16, Blocks.lava, 8, 3);
		world.setBlock(x + 7, y + 1, z + 16, Blocks.lava, 8, 3);
		world.setBlock(x + 8, y + 1, z + 16, Blocks.lava, 8, 3);
		world.setBlock(x + 9, y + 1, z + 16, Blocks.lava, 8, 3);
		world.setBlock(x + 10, y + 1, z + 16, Blocks.lava, 8, 3);
		world.setBlock(x + 11, y + 1, z + 16, Blocks.lava, 8, 3);
		world.setBlock(x + 12, y + 1, z + 16, Blocks.lava, 8, 3);
		world.setBlock(x + 13, y + 1, z + 16, Blocks.lava, 8, 3);
		world.setBlock(x + 14, y + 1, z + 16, Blocks.lava, 8, 3);
		world.setBlock(x + 15, y + 1, z + 16, Blocks.lava, 8, 3);
		world.setBlock(x + 16, y + 1, z + 16, Blocks.lava, 8, 3);
		world.setBlock(x + 17, y + 1, z + 16, Blocks.lava, 0, 3);
		world.setBlock(x + 18, y + 1, z + 16, ExtraPlanets_Blocks.volcanicRock, 0, 3);
		world.setBlock(x + 19, y + 1, z + 16, ExtraPlanets_Blocks.volcanicRock, 0, 3);
		world.setBlock(x + 20, y + 1, z + 16, ExtraPlanets_Blocks.volcanicRock, 0, 3);
		world.setBlock(x + 21, y + 1, z + 16, Blocks.lava, 2, 3);
		world.setBlock(x + 22, y + 1, z + 16, Blocks.lava, 4, 3);
		world.setBlock(x + 4, y + 1, z + 17, ExtraPlanets_Blocks.volcanicRock, 0, 3);
		world.setBlock(x + 5, y + 1, z + 17, Blocks.lava, 0, 3);
		world.setBlock(x + 6, y + 1, z + 17, Blocks.lava, 0, 3);
		world.setBlock(x + 7, y + 1, z + 17, Blocks.lava, 2, 3);
		world.setBlock(x + 8, y + 1, z + 17, Blocks.lava, 8, 3);
		world.setBlock(x + 9, y + 1, z + 17, Blocks.lava, 8, 3);
		world.setBlock(x + 10, y + 1, z + 17, Blocks.lava, 8, 3);
		world.setBlock(x + 11, y + 1, z + 17, Blocks.lava, 8, 3);
		world.setBlock(x + 12, y + 1, z + 17, Blocks.lava, 10, 3);
		world.setBlock(x + 13, y + 1, z + 17, Blocks.lava, 8, 3);
		world.setBlock(x + 14, y + 1, z + 17, Blocks.lava, 8, 3);
		world.setBlock(x + 15, y + 1, z + 17, Blocks.lava, 8, 3);
		world.setBlock(x + 16, y + 1, z + 17, ExtraPlanets_Blocks.volcanicRock, 0, 3);
		world.setBlock(x + 17, y + 1, z + 17, ExtraPlanets_Blocks.volcanicRock, 0, 3);
		world.setBlock(x + 18, y + 1, z + 17, ExtraPlanets_Blocks.volcanicRock, 0, 3);
		world.setBlock(x + 19, y + 1, z + 17, ExtraPlanets_Blocks.volcanicRock, 0, 3);
		world.setBlock(x + 20, y + 1, z + 17, ExtraPlanets_Blocks.volcanicRock, 0, 3);
		world.setBlock(x + 21, y + 1, z + 17, Blocks.lava, 12, 3);
		world.setBlock(x + 22, y + 1, z + 17, Blocks.lava, 2, 3);
		world.setBlock(x + 23, y + 1, z + 17, Blocks.lava, 4, 3);
		world.setBlock(x + 4, y + 1, z + 18, ExtraPlanets_Blocks.volcanicRock, 0, 3);
		world.setBlock(x + 5, y + 1, z + 18, ExtraPlanets_Blocks.volcanicRock, 0, 3);
		world.setBlock(x + 6, y + 1, z + 18, ExtraPlanets_Blocks.volcanicRock, 0, 3);
		world.setBlock(x + 7, y + 1, z + 18, Blocks.lava, 0, 3);
		world.setBlock(x + 8, y + 1, z + 18, Blocks.lava, 0, 3);
		world.setBlock(x + 9, y + 1, z + 18, Blocks.lava, 0, 3);
		world.setBlock(x + 10, y + 1, z + 18, Blocks.lava, 0, 3);
		world.setBlock(x + 11, y + 1, z + 18, Blocks.lava, 0, 3);
		world.setBlock(x + 12, y + 1, z + 18, Blocks.lava, 0, 3);
		world.setBlock(x + 13, y + 1, z + 18, Blocks.lava, 0, 3);
		world.setBlock(x + 14, y + 1, z + 18, ExtraPlanets_Blocks.volcanicRock, 0, 3);
		world.setBlock(x + 15, y + 1, z + 18, ExtraPlanets_Blocks.volcanicRock, 0, 3);
		world.setBlock(x + 16, y + 1, z + 18, ExtraPlanets_Blocks.volcanicRock, 0, 3);
		world.setBlock(x + 17, y + 1, z + 18, Blocks.lava, 8, 3);
		world.setBlock(x + 18, y + 1, z + 18, Blocks.lava, 2, 3);
		world.setBlock(x + 19, y + 1, z + 18, ExtraPlanets_Blocks.volcanicRock, 0, 3);
		world.setBlock(x + 20, y + 1, z + 18, Blocks.lava, 10, 3);
		world.setBlock(x + 21, y + 1, z + 18, Blocks.lava, 2, 3);
		world.setBlock(x + 22, y + 1, z + 18, Blocks.lava, 4, 3);
		world.setBlock(x + 5, y + 1, z + 19, ExtraPlanets_Blocks.volcanicRock, 0, 3);
		world.setBlock(x + 6, y + 1, z + 19, ExtraPlanets_Blocks.volcanicRock, 0, 3);
		world.setBlock(x + 7, y + 1, z + 19, ExtraPlanets_Blocks.volcanicRock, 0, 3);
		world.setBlock(x + 8, y + 1, z + 19, ExtraPlanets_Blocks.volcanicRock, 0, 3);
		world.setBlock(x + 9, y + 1, z + 19, ExtraPlanets_Blocks.volcanicRock, 0, 3);
		world.setBlock(x + 10, y + 1, z + 19, ExtraPlanets_Blocks.volcanicRock, 0, 3);
		world.setBlock(x + 11, y + 1, z + 19, ExtraPlanets_Blocks.volcanicRock, 0, 3);
		world.setBlock(x + 12, y + 1, z + 19, ExtraPlanets_Blocks.volcanicRock, 0, 3);
		world.setBlock(x + 13, y + 1, z + 19, ExtraPlanets_Blocks.volcanicRock, 0, 3);
		world.setBlock(x + 14, y + 1, z + 19, ExtraPlanets_Blocks.volcanicRock, 0, 3);
		world.setBlock(x + 15, y + 1, z + 19, ExtraPlanets_Blocks.volcanicRock, 0, 3);
		world.setBlock(x + 16, y + 1, z + 19, Blocks.lava, 0, 3);
		world.setBlock(x + 17, y + 1, z + 19, ExtraPlanets_Blocks.volcanicRock, 0, 3);
		world.setBlock(x + 18, y + 1, z + 19, ExtraPlanets_Blocks.volcanicRock, 0, 3);
		world.setBlock(x + 19, y + 1, z + 19, ExtraPlanets_Blocks.volcanicRock, 0, 3);
		world.setBlock(x + 20, y + 1, z + 19, Blocks.lava, 12, 3);
		world.setBlock(x + 21, y + 1, z + 19, Blocks.lava, 2, 3);
		world.setBlock(x + 22, y + 1, z + 19, Blocks.lava, 4, 3);
		world.setBlock(x + 6, y + 1, z + 20, Blocks.lava, 12, 3);
		world.setBlock(x + 7, y + 1, z + 20, Blocks.lava, 10, 3);
		world.setBlock(x + 8, y + 1, z + 20, ExtraPlanets_Blocks.volcanicRock, 0, 3);
		world.setBlock(x + 9, y + 1, z + 20, ExtraPlanets_Blocks.volcanicRock, 0, 3);
		world.setBlock(x + 10, y + 1, z + 20, ExtraPlanets_Blocks.volcanicRock, 0, 3);
		world.setBlock(x + 11, y + 1, z + 20, ExtraPlanets_Blocks.volcanicRock, 0, 3);
		world.setBlock(x + 12, y + 1, z + 20, ExtraPlanets_Blocks.volcanicRock, 0, 3);
		world.setBlock(x + 13, y + 1, z + 20, ExtraPlanets_Blocks.volcanicRock, 0, 3);
		world.setBlock(x + 14, y + 1, z + 20, Blocks.lava, 8, 3);
		world.setBlock(x + 15, y + 1, z + 20, Blocks.lava, 8, 3);
		world.setBlock(x + 16, y + 1, z + 20, Blocks.lava, 2, 3);
		world.setBlock(x + 17, y + 1, z + 20, Blocks.lava, 4, 3);
		world.setBlock(x + 18, y + 1, z + 20, ExtraPlanets_Blocks.volcanicRock, 0, 3);
		world.setBlock(x + 19, y + 1, z + 20, ExtraPlanets_Blocks.volcanicRock, 0, 3);
		world.setBlock(x + 20, y + 1, z + 20, Blocks.lava, 12, 3);
		world.setBlock(x + 21, y + 1, z + 20, Blocks.lava, 2, 3);
		world.setBlock(x + 6, y + 1, z + 21, Blocks.lava, 2, 3);
		world.setBlock(x + 7, y + 1, z + 21, Blocks.lava, 2, 3);
		world.setBlock(x + 8, y + 1, z + 21, Blocks.lava, 10, 3);
		world.setBlock(x + 9, y + 1, z + 21, ExtraPlanets_Blocks.volcanicRock, 0, 3);
		world.setBlock(x + 10, y + 1, z + 21, ExtraPlanets_Blocks.volcanicRock, 0, 3);
		world.setBlock(x + 11, y + 1, z + 21, ExtraPlanets_Blocks.volcanicRock, 0, 3);
		world.setBlock(x + 12, y + 1, z + 21, ExtraPlanets_Blocks.volcanicRock, 0, 3);
		world.setBlock(x + 13, y + 1, z + 21, ExtraPlanets_Blocks.volcanicRock, 0, 3);
		world.setBlock(x + 14, y + 1, z + 21, ExtraPlanets_Blocks.volcanicRock, 0, 3);
		world.setBlock(x + 15, y + 1, z + 21, ExtraPlanets_Blocks.volcanicRock, 0, 3);
		world.setBlock(x + 16, y + 1, z + 21, ExtraPlanets_Blocks.volcanicRock, 0, 3);
		world.setBlock(x + 17, y + 1, z + 21, ExtraPlanets_Blocks.volcanicRock, 0, 3);
		world.setBlock(x + 18, y + 1, z + 21, ExtraPlanets_Blocks.volcanicRock, 0, 3);
		world.setBlock(x + 19, y + 1, z + 21, Blocks.lava, 12, 3);
		world.setBlock(x + 20, y + 1, z + 21, Blocks.lava, 2, 3);
		world.setBlock(x + 21, y + 1, z + 21, Blocks.lava, 4, 3);
		world.setBlock(x + 6, y + 1, z + 22, Blocks.lava, 4, 3);
		world.setBlock(x + 7, y + 1, z + 22, Blocks.lava, 4, 3);
		world.setBlock(x + 8, y + 1, z + 22, Blocks.lava, 2, 3);
		world.setBlock(x + 9, y + 1, z + 22, Blocks.lava, 12, 3);
		world.setBlock(x + 10, y + 1, z + 22, ExtraPlanets_Blocks.volcanicRock, 0, 3);
		world.setBlock(x + 11, y + 1, z + 22, ExtraPlanets_Blocks.volcanicRock, 0, 3);
		world.setBlock(x + 12, y + 1, z + 22, ExtraPlanets_Blocks.volcanicRock, 0, 3);
		world.setBlock(x + 13, y + 1, z + 22, ExtraPlanets_Blocks.volcanicRock, 0, 3);
		world.setBlock(x + 14, y + 1, z + 22, ExtraPlanets_Blocks.volcanicRock, 0, 3);
		world.setBlock(x + 15, y + 1, z + 22, ExtraPlanets_Blocks.volcanicRock, 0, 3);
		world.setBlock(x + 16, y + 1, z + 22, ExtraPlanets_Blocks.volcanicRock, 0, 3);
		world.setBlock(x + 17, y + 1, z + 22, ExtraPlanets_Blocks.volcanicRock, 0, 3);
		world.setBlock(x + 18, y + 1, z + 22, ExtraPlanets_Blocks.volcanicRock, 0, 3);
		world.setBlock(x + 19, y + 1, z + 22, Blocks.lava, 2, 3);
		world.setBlock(x + 20, y + 1, z + 22, Blocks.lava, 4, 3);
		world.setBlock(x + 7, y + 1, z + 23, Blocks.lava, 6, 3);
		world.setBlock(x + 8, y + 1, z + 23, Blocks.lava, 4, 3);
		world.setBlock(x + 9, y + 1, z + 23, Blocks.lava, 2, 3);
		world.setBlock(x + 10, y + 1, z + 23, ExtraPlanets_Blocks.volcanicRock, 0, 3);
		world.setBlock(x + 11, y + 1, z + 23, ExtraPlanets_Blocks.volcanicRock, 0, 3);
		world.setBlock(x + 12, y + 1, z + 23, ExtraPlanets_Blocks.volcanicRock, 0, 3);
		world.setBlock(x + 13, y + 1, z + 23, ExtraPlanets_Blocks.volcanicRock, 0, 3);
		world.setBlock(x + 14, y + 1, z + 23, ExtraPlanets_Blocks.volcanicRock, 0, 3);
		world.setBlock(x + 15, y + 1, z + 23, ExtraPlanets_Blocks.volcanicRock, 0, 3);
		world.setBlock(x + 16, y + 1, z + 23, ExtraPlanets_Blocks.volcanicRock, 0, 3);
		world.setBlock(x + 17, y + 1, z + 23, Blocks.lava, 12, 3);
		world.setBlock(x + 18, y + 1, z + 23, Blocks.lava, 2, 3);
		world.setBlock(x + 8, y + 1, z + 24, Blocks.lava, 6, 3);
		world.setBlock(x + 9, y + 1, z + 24, Blocks.lava, 4, 3);
		world.setBlock(x + 13, y + 1, z + 24, ExtraPlanets_Blocks.volcanicRock, 0, 3);
		world.setBlock(x + 15, y + 1, z + 24, Blocks.lava, 10, 3);
		world.setBlock(x + 16, y + 1, z + 24, Blocks.lava, 12, 3);
		world.setBlock(x + 17, y + 1, z + 24, Blocks.lava, 2, 3);
		world.setBlock(x + 18, y + 1, z + 24, Blocks.lava, 4, 3);
		world.setBlock(x + 9, y + 1, z + 25, Blocks.lava, 6, 3);
		world.setBlock(x + 15, y + 1, z + 25, Blocks.lava, 2, 3);
		world.setBlock(x + 15, y + 1, z + 26, Blocks.lava, 4, 3);
		world.setBlock(x + 15, y + 1, z + 27, Blocks.lava, 6, 3);
		world.setBlock(x + 8, y + 2, z + 6, ExtraPlanets_Blocks.volcanicRock, 0, 3);
		world.setBlock(x + 9, y + 2, z + 6, ExtraPlanets_Blocks.volcanicRock, 0, 3);
		world.setBlock(x + 10, y + 2, z + 6, ExtraPlanets_Blocks.volcanicRock, 0, 3);
		world.setBlock(x + 14, y + 2, z + 6, Blocks.lava, 4, 3);
		world.setBlock(x + 6, y + 2, z + 7, ExtraPlanets_Blocks.volcanicRock, 0, 3);
		world.setBlock(x + 7, y + 2, z + 7, ExtraPlanets_Blocks.volcanicRock, 0, 3);
		world.setBlock(x + 8, y + 2, z + 7, ExtraPlanets_Blocks.volcanicRock, 0, 3);
		world.setBlock(x + 9, y + 2, z + 7, ExtraPlanets_Blocks.volcanicRock, 0, 3);
		world.setBlock(x + 10, y + 2, z + 7, ExtraPlanets_Blocks.volcanicRock, 0, 3);
		world.setBlock(x + 11, y + 2, z + 7, Blocks.lava, 12, 3);
		world.setBlock(x + 14, y + 2, z + 7, Blocks.lava, 2, 3);
		world.setBlock(x + 15, y + 2, z + 7, Blocks.lava, 4, 3);
		world.setBlock(x + 4, y + 2, z + 8, ExtraPlanets_Blocks.volcanicRock, 0, 3);
		world.setBlock(x + 5, y + 2, z + 8, ExtraPlanets_Blocks.volcanicRock, 0, 3);
		world.setBlock(x + 6, y + 2, z + 8, ExtraPlanets_Blocks.volcanicRock, 0, 3);
		world.setBlock(x + 7, y + 2, z + 8, ExtraPlanets_Blocks.volcanicRock, 0, 3);
		world.setBlock(x + 8, y + 2, z + 8, ExtraPlanets_Blocks.volcanicRock, 0, 3);
		world.setBlock(x + 9, y + 2, z + 8, Blocks.lava, 0, 3);
		world.setBlock(x + 10, y + 2, z + 8, Blocks.lava, 2, 3);
		world.setBlock(x + 11, y + 2, z + 8, ExtraPlanets_Blocks.volcanicRock, 0, 3);
		world.setBlock(x + 12, y + 2, z + 8, Blocks.lava, 12, 3);
		world.setBlock(x + 13, y + 2, z + 8, Blocks.lava, 2, 3);
		world.setBlock(x + 14, y + 2, z + 8, Blocks.lava, 14, 3);
		world.setBlock(x + 15, y + 2, z + 8, Blocks.lava, 2, 3);
		world.setBlock(x + 16, y + 2, z + 8, Blocks.lava, 2, 3);
		world.setBlock(x + 17, y + 2, z + 8, Blocks.lava, 2, 3);
		world.setBlock(x + 3, y + 2, z + 9, ExtraPlanets_Blocks.volcanicRock, 0, 3);
		world.setBlock(x + 4, y + 2, z + 9, ExtraPlanets_Blocks.volcanicRock, 0, 3);
		world.setBlock(x + 5, y + 2, z + 9, ExtraPlanets_Blocks.volcanicRock, 0, 3);
		world.setBlock(x + 6, y + 2, z + 9, ExtraPlanets_Blocks.volcanicRock, 0, 3);
		world.setBlock(x + 7, y + 2, z + 9, Blocks.lava, 0, 3);
		world.setBlock(x + 8, y + 2, z + 9, Blocks.lava, 0, 3);
		world.setBlock(x + 9, y + 2, z + 9, Blocks.lava, 8, 3);
		world.setBlock(x + 10, y + 2, z + 9, Blocks.lava, 0, 3);
		world.setBlock(x + 11, y + 2, z + 9, ExtraPlanets_Blocks.volcanicRock, 0, 3);
		world.setBlock(x + 12, y + 2, z + 9, ExtraPlanets_Blocks.volcanicRock, 0, 3);
		world.setBlock(x + 13, y + 2, z + 9, Blocks.lava, 0, 3);
		world.setBlock(x + 14, y + 2, z + 9, ExtraPlanets_Blocks.volcanicRock, 0, 3);
		world.setBlock(x + 15, y + 2, z + 9, Blocks.lava, 10, 3);
		world.setBlock(x + 16, y + 2, z + 9, Blocks.lava, 0, 3);
		world.setBlock(x + 17, y + 2, z + 9, Blocks.lava, 0, 3);
		world.setBlock(x + 18, y + 2, z + 9, Blocks.lava, 2, 3);
		world.setBlock(x + 3, y + 2, z + 10, ExtraPlanets_Blocks.volcanicRock, 0, 3);
		world.setBlock(x + 4, y + 2, z + 10, Blocks.lava, 0, 3);
		world.setBlock(x + 5, y + 2, z + 10, Blocks.lava, 0, 3);
		world.setBlock(x + 6, y + 2, z + 10, Blocks.lava, 0, 3);
		world.setBlock(x + 7, y + 2, z + 10, Blocks.lava, 8, 3);
		world.setBlock(x + 8, y + 2, z + 10, Blocks.lava, 10, 3);
		world.setBlock(x + 9, y + 2, z + 10, Blocks.lava, 8, 3);
		world.setBlock(x + 10, y + 2, z + 10, Blocks.lava, 0, 3);
		world.setBlock(x + 11, y + 2, z + 10, Blocks.lava, 0, 3);
		world.setBlock(x + 12, y + 2, z + 10, ExtraPlanets_Blocks.volcanicRock, 0, 3);
		world.setBlock(x + 13, y + 2, z + 10, ExtraPlanets_Blocks.volcanicRock, 0, 3);
		world.setBlock(x + 14, y + 2, z + 10, ExtraPlanets_Blocks.volcanicRock, 0, 3);
		world.setBlock(x + 15, y + 2, z + 10, ExtraPlanets_Blocks.volcanicRock, 0, 3);
		world.setBlock(x + 16, y + 2, z + 10, ExtraPlanets_Blocks.volcanicRock, 0, 3);
		world.setBlock(x + 17, y + 2, z + 10, ExtraPlanets_Blocks.volcanicRock, 0, 3);
		world.setBlock(x + 18, y + 2, z + 10, Blocks.lava, 10, 3);
		world.setBlock(x + 19, y + 2, z + 10, Blocks.lava, 2, 3);
		world.setBlock(x + 20, y + 2, z + 10, Blocks.lava, 4, 3);
		world.setBlock(x + 3, y + 2, z + 11, ExtraPlanets_Blocks.volcanicRock, 0, 3);
		world.setBlock(x + 4, y + 2, z + 11, Blocks.lava, 0, 3);
		world.setBlock(x + 5, y + 2, z + 11, Blocks.lava, 2, 3);
		world.setBlock(x + 6, y + 2, z + 11, Blocks.lava, 8, 3);
		world.setBlock(x + 7, y + 2, z + 11, Blocks.lava, 8, 3);
		world.setBlock(x + 8, y + 2, z + 11, Blocks.lava, 8, 3);
		world.setBlock(x + 9, y + 2, z + 11, Blocks.lava, 10, 3);
		world.setBlock(x + 10, y + 2, z + 11, Blocks.lava, 8, 3);
		world.setBlock(x + 11, y + 2, z + 11, Blocks.lava, 2, 3);
		world.setBlock(x + 12, y + 2, z + 11, Blocks.lava, 0, 3);
		world.setBlock(x + 13, y + 2, z + 11, Blocks.lava, 0, 3);
		world.setBlock(x + 14, y + 2, z + 11, ExtraPlanets_Blocks.volcanicRock, 0, 3);
		world.setBlock(x + 15, y + 2, z + 11, ExtraPlanets_Blocks.volcanicRock, 0, 3);
		world.setBlock(x + 16, y + 2, z + 11, ExtraPlanets_Blocks.volcanicRock, 0, 3);
		world.setBlock(x + 17, y + 2, z + 11, ExtraPlanets_Blocks.volcanicRock, 0, 3);
		world.setBlock(x + 18, y + 2, z + 11, Blocks.lava, 10, 3);
		world.setBlock(x + 19, y + 2, z + 11, Blocks.lava, 12, 3);
		world.setBlock(x + 20, y + 2, z + 11, Blocks.lava, 2, 3);
		world.setBlock(x + 21, y + 2, z + 11, Blocks.lava, 4, 3);
		world.setBlock(x + 3, y + 2, z + 12, ExtraPlanets_Blocks.volcanicRock, 0, 3);
		world.setBlock(x + 4, y + 2, z + 12, ExtraPlanets_Blocks.volcanicRock, 0, 3);
		world.setBlock(x + 5, y + 2, z + 12, Blocks.lava, 0, 3);
		world.setBlock(x + 6, y + 2, z + 12, Blocks.lava, 8, 3);
		world.setBlock(x + 7, y + 2, z + 12, Blocks.lava, 10, 3);
		world.setBlock(x + 8, y + 2, z + 12, Blocks.lava, 8, 3);
		world.setBlock(x + 9, y + 2, z + 12, Blocks.lava, 8, 3);
		world.setBlock(x + 10, y + 2, z + 12, Blocks.lava, 10, 3);
		world.setBlock(x + 11, y + 2, z + 12, Blocks.lava, 8, 3);
		world.setBlock(x + 12, y + 2, z + 12, Blocks.lava, 2, 3);
		world.setBlock(x + 13, y + 2, z + 12, Blocks.lava, 2, 3);
		world.setBlock(x + 14, y + 2, z + 12, Blocks.lava, 0, 3);
		world.setBlock(x + 15, y + 2, z + 12, Blocks.lava, 0, 3);
		world.setBlock(x + 16, y + 2, z + 12, Blocks.lava, 0, 3);
		world.setBlock(x + 17, y + 2, z + 12, Blocks.lava, 0, 3);
		world.setBlock(x + 18, y + 2, z + 12, ExtraPlanets_Blocks.volcanicRock, 0, 3);
		world.setBlock(x + 19, y + 2, z + 12, ExtraPlanets_Blocks.volcanicRock, 0, 3);
		world.setBlock(x + 20, y + 2, z + 12, Blocks.lava, 12, 3);
		world.setBlock(x + 21, y + 2, z + 12, Blocks.lava, 2, 3);
		world.setBlock(x + 3, y + 2, z + 13, ExtraPlanets_Blocks.volcanicRock, 0, 3);
		world.setBlock(x + 4, y + 2, z + 13, ExtraPlanets_Blocks.volcanicRock, 0, 3);
		world.setBlock(x + 5, y + 2, z + 13, Blocks.lava, 0, 3);
		world.setBlock(x + 6, y + 2, z + 13, Blocks.lava, 0, 3);
		world.setBlock(x + 7, y + 2, z + 13, Blocks.lava, 8, 3);
		world.setBlock(x + 8, y + 2, z + 13, Blocks.lava, 8, 3);
		world.setBlock(x + 9, y + 2, z + 13, Blocks.lava, 8, 3);
		world.setBlock(x + 10, y + 2, z + 13, Blocks.lava, 8, 3);
		world.setBlock(x + 11, y + 2, z + 13, Blocks.lava, 10, 3);
		world.setBlock(x + 12, y + 2, z + 13, Blocks.lava, 8, 3);
		world.setBlock(x + 13, y + 2, z + 13, Blocks.lava, 2, 3);
		world.setBlock(x + 14, y + 2, z + 13, Blocks.lava, 0, 3);
		world.setBlock(x + 15, y + 2, z + 13, Blocks.lava, 0, 3);
		world.setBlock(x + 16, y + 2, z + 13, Blocks.lava, 0, 3);
		world.setBlock(x + 17, y + 2, z + 13, Blocks.lava, 0, 3);
		world.setBlock(x + 18, y + 2, z + 13, Blocks.lava, 0, 3);
		world.setBlock(x + 19, y + 2, z + 13, ExtraPlanets_Blocks.volcanicRock, 0, 3);
		world.setBlock(x + 20, y + 2, z + 13, ExtraPlanets_Blocks.volcanicRock, 0, 3);
		world.setBlock(x + 21, y + 2, z + 13, Blocks.lava, 4, 3);
		world.setBlock(x + 22, y + 2, z + 13, Blocks.lava, 6, 3);
		world.setBlock(x + 4, y + 2, z + 14, ExtraPlanets_Blocks.volcanicRock, 0, 3);
		world.setBlock(x + 5, y + 2, z + 14, Blocks.lava, 0, 3);
		world.setBlock(x + 6, y + 2, z + 14, Blocks.lava, 0, 3);
		world.setBlock(x + 7, y + 2, z + 14, Blocks.lava, 8, 3);
		world.setBlock(x + 8, y + 2, z + 14, Blocks.lava, 8, 3);
		world.setBlock(x + 9, y + 2, z + 14, Blocks.lava, 8, 3);
		world.setBlock(x + 10, y + 2, z + 14, Blocks.lava, 8, 3);
		world.setBlock(x + 11, y + 2, z + 14, Blocks.lava, 8, 3);
		world.setBlock(x + 12, y + 2, z + 14, Blocks.lava, 8, 3);
		world.setBlock(x + 13, y + 2, z + 14, Blocks.lava, 0, 3);
		world.setBlock(x + 14, y + 2, z + 14, Blocks.lava, 0, 3);
		world.setBlock(x + 15, y + 2, z + 14, Blocks.lava, 0, 3);
		world.setBlock(x + 16, y + 2, z + 14, Blocks.lava, 8, 3);
		world.setBlock(x + 17, y + 2, z + 14, Blocks.lava, 0, 3);
		world.setBlock(x + 18, y + 2, z + 14, Blocks.lava, 0, 3);
		world.setBlock(x + 19, y + 2, z + 14, ExtraPlanets_Blocks.volcanicRock, 0, 3);
		world.setBlock(x + 20, y + 2, z + 14, ExtraPlanets_Blocks.volcanicRock, 0, 3);
		world.setBlock(x + 4, y + 2, z + 15, ExtraPlanets_Blocks.volcanicRock, 0, 3);
		world.setBlock(x + 5, y + 2, z + 15, ExtraPlanets_Blocks.volcanicRock, 0, 3);
		world.setBlock(x + 6, y + 2, z + 15, Blocks.lava, 0, 3);
		world.setBlock(x + 7, y + 2, z + 15, Blocks.lava, 0, 3);
		world.setBlock(x + 8, y + 2, z + 15, Blocks.lava, 8, 3);
		world.setBlock(x + 9, y + 2, z + 15, Blocks.lava, 8, 3);
		world.setBlock(x + 10, y + 2, z + 15, Blocks.lava, 8, 3);
		world.setBlock(x + 11, y + 2, z + 15, Blocks.lava, 8, 3);
		world.setBlock(x + 12, y + 2, z + 15, Blocks.lava, 8, 3);
		world.setBlock(x + 13, y + 2, z + 15, Blocks.lava, 0, 3);
		world.setBlock(x + 14, y + 2, z + 15, Blocks.lava, 0, 3);
		world.setBlock(x + 15, y + 2, z + 15, Blocks.lava, 0, 3);
		world.setBlock(x + 16, y + 2, z + 15, Blocks.lava, 8, 3);
		world.setBlock(x + 17, y + 2, z + 15, Blocks.lava, 8, 3);
		world.setBlock(x + 18, y + 2, z + 15, Blocks.lava, 0, 3);
		world.setBlock(x + 19, y + 2, z + 15, ExtraPlanets_Blocks.volcanicRock, 0, 3);
		world.setBlock(x + 5, y + 2, z + 16, ExtraPlanets_Blocks.volcanicRock, 0, 3);
		world.setBlock(x + 6, y + 2, z + 16, Blocks.lava, 0, 3);
		world.setBlock(x + 7, y + 2, z + 16, Blocks.lava, 0, 3);
		world.setBlock(x + 8, y + 2, z + 16, Blocks.lava, 0, 3);
		world.setBlock(x + 9, y + 2, z + 16, Blocks.lava, 8, 3);
		world.setBlock(x + 10, y + 2, z + 16, Blocks.lava, 8, 3);
		world.setBlock(x + 11, y + 2, z + 16, Blocks.lava, 8, 3);
		world.setBlock(x + 12, y + 2, z + 16, Blocks.lava, 8, 3);
		world.setBlock(x + 13, y + 2, z + 16, Blocks.lava, 8, 3);
		world.setBlock(x + 14, y + 2, z + 16, Blocks.lava, 8, 3);
		world.setBlock(x + 15, y + 2, z + 16, Blocks.lava, 8, 3);
		world.setBlock(x + 16, y + 2, z + 16, Blocks.lava, 8, 3);
		world.setBlock(x + 17, y + 2, z + 16, Blocks.lava, 0, 3);
		world.setBlock(x + 18, y + 2, z + 16, ExtraPlanets_Blocks.volcanicRock, 0, 3);
		world.setBlock(x + 19, y + 2, z + 16, ExtraPlanets_Blocks.volcanicRock, 0, 3);
		world.setBlock(x + 5, y + 2, z + 17, ExtraPlanets_Blocks.volcanicRock, 0, 3);
		world.setBlock(x + 6, y + 2, z + 17, ExtraPlanets_Blocks.volcanicRock, 0, 3);
		world.setBlock(x + 7, y + 2, z + 17, ExtraPlanets_Blocks.volcanicRock, 0, 3);
		world.setBlock(x + 8, y + 2, z + 17, Blocks.lava, 0, 3);
		world.setBlock(x + 9, y + 2, z + 17, Blocks.lava, 0, 3);
		world.setBlock(x + 10, y + 2, z + 17, Blocks.lava, 0, 3);
		world.setBlock(x + 11, y + 2, z + 17, Blocks.lava, 0, 3);
		world.setBlock(x + 12, y + 2, z + 17, Blocks.lava, 10, 3);
		world.setBlock(x + 13, y + 2, z + 17, Blocks.lava, 8, 3);
		world.setBlock(x + 14, y + 2, z + 17, Blocks.lava, 8, 3);
		world.setBlock(x + 15, y + 2, z + 17, Blocks.lava, 8, 3);
		world.setBlock(x + 16, y + 2, z + 17, Blocks.lava, 0, 3);
		world.setBlock(x + 17, y + 2, z + 17, Blocks.lava, 0, 3);
		world.setBlock(x + 18, y + 2, z + 17, ExtraPlanets_Blocks.volcanicRock, 0, 3);
		world.setBlock(x + 19, y + 2, z + 17, Blocks.lava, 10, 3);
		world.setBlock(x + 20, y + 2, z + 17, Blocks.lava, 2, 3);
		world.setBlock(x + 21, y + 2, z + 17, Blocks.lava, 4, 3);
		world.setBlock(x + 6, y + 2, z + 18, Blocks.lava, 12, 3);
		world.setBlock(x + 7, y + 2, z + 18, ExtraPlanets_Blocks.volcanicRock, 0, 3);
		world.setBlock(x + 8, y + 2, z + 18, ExtraPlanets_Blocks.volcanicRock, 0, 3);
		world.setBlock(x + 9, y + 2, z + 18, ExtraPlanets_Blocks.volcanicRock, 0, 3);
		world.setBlock(x + 10, y + 2, z + 18, ExtraPlanets_Blocks.volcanicRock, 0, 3);
		world.setBlock(x + 11, y + 2, z + 18, ExtraPlanets_Blocks.volcanicRock, 0, 3);
		world.setBlock(x + 12, y + 2, z + 18, Blocks.lava, 10, 3);
		world.setBlock(x + 13, y + 2, z + 18, Blocks.lava, 0, 3);
		world.setBlock(x + 14, y + 2, z + 18, Blocks.lava, 0, 3);
		world.setBlock(x + 15, y + 2, z + 18, Blocks.lava, 0, 3);
		world.setBlock(x + 16, y + 2, z + 18, Blocks.lava, 0, 3);
		world.setBlock(x + 17, y + 2, z + 18, Blocks.lava, 0, 3);
		world.setBlock(x + 18, y + 2, z + 18, ExtraPlanets_Blocks.volcanicRock, 0, 3);
		world.setBlock(x + 19, y + 2, z + 18, Blocks.lava, 10, 3);
		world.setBlock(x + 20, y + 2, z + 18, Blocks.lava, 2, 3);
		world.setBlock(x + 6, y + 2, z + 19, Blocks.lava, 2, 3);
		world.setBlock(x + 7, y + 2, z + 19, Blocks.lava, 10, 3);
		world.setBlock(x + 8, y + 2, z + 19, ExtraPlanets_Blocks.volcanicRock, 0, 3);
		world.setBlock(x + 9, y + 2, z + 19, ExtraPlanets_Blocks.volcanicRock, 0, 3);
		world.setBlock(x + 10, y + 2, z + 19, ExtraPlanets_Blocks.volcanicRock, 0, 3);
		world.setBlock(x + 12, y + 2, z + 19, Blocks.lava, 2, 3);
		world.setBlock(x + 13, y + 2, z + 19, Blocks.lava, 0, 3);
		world.setBlock(x + 14, y + 2, z + 19, Blocks.lava, 0, 3);
		world.setBlock(x + 15, y + 2, z + 19, Blocks.lava, 2, 3);
		world.setBlock(x + 16, y + 2, z + 19, Blocks.lava, 0, 3);
		world.setBlock(x + 17, y + 2, z + 19, ExtraPlanets_Blocks.volcanicRock, 0, 3);
		world.setBlock(x + 18, y + 2, z + 19, Blocks.lava, 10, 3);
		world.setBlock(x + 19, y + 2, z + 19, Blocks.lava, 2, 3);
		world.setBlock(x + 20, y + 2, z + 19, Blocks.lava, 4, 3);
		world.setBlock(x + 6, y + 2, z + 20, Blocks.lava, 4, 3);
		world.setBlock(x + 7, y + 2, z + 20, Blocks.lava, 2, 3);
		world.setBlock(x + 8, y + 2, z + 20, Blocks.lava, 10, 3);
		world.setBlock(x + 9, y + 2, z + 20, Blocks.lava, 10, 3);
		world.setBlock(x + 10, y + 2, z + 20, ExtraPlanets_Blocks.volcanicRock, 0, 3);
		world.setBlock(x + 11, y + 2, z + 20, ExtraPlanets_Blocks.volcanicRock, 0, 3);
		world.setBlock(x + 12, y + 2, z + 20, Blocks.lava, 0, 3);
		world.setBlock(x + 13, y + 2, z + 20, Blocks.lava, 0, 3);
		world.setBlock(x + 14, y + 2, z + 20, Blocks.lava, 0, 3);
		world.setBlock(x + 15, y + 2, z + 20, Blocks.lava, 0, 3);
		world.setBlock(x + 16, y + 2, z + 20, ExtraPlanets_Blocks.volcanicRock, 0, 3);
		world.setBlock(x + 17, y + 2, z + 20, ExtraPlanets_Blocks.volcanicRock, 0, 3);
		world.setBlock(x + 18, y + 2, z + 20, Blocks.lava, 12, 3);
		world.setBlock(x + 19, y + 2, z + 20, Blocks.lava, 2, 3);
		world.setBlock(x + 20, y + 2, z + 20, Blocks.lava, 4, 3);
		world.setBlock(x + 8, y + 2, z + 21, Blocks.lava, 2, 3);
		world.setBlock(x + 9, y + 2, z + 21, Blocks.lava, 2, 3);
		world.setBlock(x + 10, y + 2, z + 21, Blocks.lava, 10, 3);
		world.setBlock(x + 12, y + 2, z + 21, ExtraPlanets_Blocks.volcanicRock, 0, 3);
		world.setBlock(x + 13, y + 2, z + 21, ExtraPlanets_Blocks.volcanicRock, 0, 3);
		world.setBlock(x + 14, y + 2, z + 21, ExtraPlanets_Blocks.volcanicRock, 0, 3);
		world.setBlock(x + 15, y + 2, z + 21, ExtraPlanets_Blocks.volcanicRock, 0, 3);
		world.setBlock(x + 16, y + 2, z + 21, ExtraPlanets_Blocks.volcanicRock, 0, 3);
		world.setBlock(x + 17, y + 2, z + 21, Blocks.lava, 12, 3);
		world.setBlock(x + 18, y + 2, z + 21, Blocks.lava, 2, 3);
		world.setBlock(x + 19, y + 2, z + 21, Blocks.lava, 4, 3);
		world.setBlock(x + 9, y + 2, z + 22, Blocks.lava, 4, 3);
		world.setBlock(x + 10, y + 2, z + 22, Blocks.lava, 2, 3);
		world.setBlock(x + 14, y + 2, z + 22, ExtraPlanets_Blocks.volcanicRock, 0, 3);
		world.setBlock(x + 15, y + 2, z + 22, ExtraPlanets_Blocks.volcanicRock, 0, 3);
		world.setBlock(x + 16, y + 2, z + 22, Blocks.lava, 12, 3);
		world.setBlock(x + 17, y + 2, z + 22, Blocks.lava, 2, 3);
		world.setBlock(x + 15, y + 2, z + 23, Blocks.lava, 12, 3);
		world.setBlock(x + 16, y + 2, z + 23, Blocks.lava, 2, 3);
		world.setBlock(x + 17, y + 2, z + 23, Blocks.lava, 4, 3);
		world.setBlock(x + 15, y + 2, z + 24, Blocks.lava, 2, 3);
		world.setBlock(x + 16, y + 2, z + 24, Blocks.lava, 4, 3);
		world.setBlock(x + 9, y + 3, z + 7, ExtraPlanets_Blocks.volcanicRock, 0, 3);
		world.setBlock(x + 11, y + 3, z + 7, Blocks.lava, 4, 3);
		world.setBlock(x + 5, y + 3, z + 8, ExtraPlanets_Blocks.volcanicRock, 0, 3);
		world.setBlock(x + 6, y + 3, z + 8, ExtraPlanets_Blocks.volcanicRock, 0, 3);
		world.setBlock(x + 7, y + 3, z + 8, ExtraPlanets_Blocks.volcanicRock, 0, 3);
		world.setBlock(x + 8, y + 3, z + 8, ExtraPlanets_Blocks.volcanicRock, 0, 3);
		world.setBlock(x + 9, y + 3, z + 8, ExtraPlanets_Blocks.volcanicRock, 0, 3);
		world.setBlock(x + 10, y + 3, z + 8, ExtraPlanets_Blocks.volcanicRock, 0, 3);
		world.setBlock(x + 11, y + 3, z + 8, Blocks.lava, 2, 3);
		world.setBlock(x + 12, y + 3, z + 8, Blocks.lava, 4, 3);
		world.setBlock(x + 14, y + 3, z + 8, Blocks.lava, 6, 3);
		world.setBlock(x + 4, y + 3, z + 9, ExtraPlanets_Blocks.volcanicRock, 0, 3);
		world.setBlock(x + 5, y + 3, z + 9, ExtraPlanets_Blocks.volcanicRock, 0, 3);
		world.setBlock(x + 6, y + 3, z + 9, ExtraPlanets_Blocks.volcanicRock, 0, 3);
		world.setBlock(x + 7, y + 3, z + 9, ExtraPlanets_Blocks.volcanicRock, 0, 3);
		world.setBlock(x + 8, y + 3, z + 9, Blocks.lava, 0, 3);
		world.setBlock(x + 9, y + 3, z + 9, Blocks.lava, 0, 3);
		world.setBlock(x + 10, y + 3, z + 9, ExtraPlanets_Blocks.volcanicRock, 0, 3);
		world.setBlock(x + 11, y + 3, z + 9, Blocks.lava, 10, 3);
		world.setBlock(x + 12, y + 3, z + 9, Blocks.lava, 2, 3);
		world.setBlock(x + 13, y + 3, z + 9, Blocks.lava, 2, 3);
		world.setBlock(x + 14, y + 3, z + 9, Blocks.lava, 4, 3);
		world.setBlock(x + 15, y + 3, z + 9, Blocks.lava, 2, 3);
		world.setBlock(x + 16, y + 3, z + 9, Blocks.lava, 4, 3);
		world.setBlock(x + 17, y + 3, z + 9, Blocks.lava, 2, 3);
		world.setBlock(x + 4, y + 3, z + 10, ExtraPlanets_Blocks.volcanicRock, 0, 3);
		world.setBlock(x + 5, y + 3, z + 10, ExtraPlanets_Blocks.volcanicRock, 0, 3);
		world.setBlock(x + 6, y + 3, z + 10, Blocks.lava, 0, 3);
		world.setBlock(x + 7, y + 3, z + 10, Blocks.lava, 0, 3);
		world.setBlock(x + 8, y + 3, z + 10, Blocks.lava, 2, 3);
		world.setBlock(x + 9, y + 3, z + 10, Blocks.lava, 0, 3);
		world.setBlock(x + 10, y + 3, z + 10, ExtraPlanets_Blocks.volcanicRock, 0, 3);
		world.setBlock(x + 11, y + 3, z + 10, ExtraPlanets_Blocks.volcanicRock, 0, 3);
		world.setBlock(x + 12, y + 3, z + 10, Blocks.lava, 0, 3);
		world.setBlock(x + 13, y + 3, z + 10, Blocks.lava, 10, 3);
		world.setBlock(x + 14, y + 3, z + 10, Blocks.lava, 2, 3);
		world.setBlock(x + 15, y + 3, z + 10, Blocks.lava, 12, 3);
		world.setBlock(x + 16, y + 3, z + 10, Blocks.lava, 2, 3);
		world.setBlock(x + 17, y + 3, z + 10, Blocks.lava, 0, 3);
		world.setBlock(x + 18, y + 3, z + 10, Blocks.lava, 2, 3);
		world.setBlock(x + 4, y + 3, z + 11, ExtraPlanets_Blocks.volcanicRock, 0, 3);
		world.setBlock(x + 5, y + 3, z + 11, ExtraPlanets_Blocks.volcanicRock, 0, 3);
		world.setBlock(x + 6, y + 3, z + 11, Blocks.lava, 0, 3);
		world.setBlock(x + 7, y + 3, z + 11, Blocks.lava, 8, 3);
		world.setBlock(x + 8, y + 3, z + 11, Blocks.lava, 8, 3);
		world.setBlock(x + 9, y + 3, z + 11, Blocks.lava, 10, 3);
		world.setBlock(x + 10, y + 3, z + 11, Blocks.lava, 0, 3);
		world.setBlock(x + 11, y + 3, z + 11, ExtraPlanets_Blocks.volcanicRock, 0, 3);
		world.setBlock(x + 12, y + 3, z + 11, ExtraPlanets_Blocks.volcanicRock, 0, 3);
		world.setBlock(x + 13, y + 3, z + 11, ExtraPlanets_Blocks.volcanicRock, 0, 3);
		world.setBlock(x + 14, y + 3, z + 11, Blocks.lava, 0, 3);
		world.setBlock(x + 15, y + 3, z + 11, ExtraPlanets_Blocks.volcanicRock, 0, 3);
		world.setBlock(x + 16, y + 3, z + 11, Blocks.lava, 12, 3);
		world.setBlock(x + 17, y + 3, z + 11, Blocks.lava, 14, 3);
		world.setBlock(x + 18, y + 3, z + 11, Blocks.lava, 2, 3);
		world.setBlock(x + 19, y + 3, z + 11, Blocks.lava, 4, 3);
		world.setBlock(x + 5, y + 3, z + 12, ExtraPlanets_Blocks.volcanicRock, 0, 3);
		world.setBlock(x + 6, y + 3, z + 12, Blocks.lava, 0, 3);
		world.setBlock(x + 7, y + 3, z + 12, Blocks.lava, 2, 3);
		world.setBlock(x + 8, y + 3, z + 12, Blocks.lava, 8, 3);
		world.setBlock(x + 9, y + 3, z + 12, Blocks.lava, 8, 3);
		world.setBlock(x + 10, y + 3, z + 12, Blocks.lava, 10, 3);
		world.setBlock(x + 11, y + 3, z + 12, Blocks.lava, 0, 3);
		world.setBlock(x + 12, y + 3, z + 12, ExtraPlanets_Blocks.volcanicRock, 0, 3);
		world.setBlock(x + 13, y + 3, z + 12, ExtraPlanets_Blocks.volcanicRock, 0, 3);
		world.setBlock(x + 14, y + 3, z + 12, ExtraPlanets_Blocks.volcanicRock, 0, 3);
		world.setBlock(x + 15, y + 3, z + 12, ExtraPlanets_Blocks.volcanicRock, 0, 3);
		world.setBlock(x + 16, y + 3, z + 12, ExtraPlanets_Blocks.volcanicRock, 0, 3);
		world.setBlock(x + 17, y + 3, z + 12, ExtraPlanets_Blocks.volcanicRock, 0, 3);
		world.setBlock(x + 18, y + 3, z + 12, Blocks.lava, 14, 3);
		world.setBlock(x + 19, y + 3, z + 12, Blocks.lava, 2, 3);
		world.setBlock(x + 20, y + 3, z + 12, Blocks.lava, 4, 3);
		world.setBlock(x + 5, y + 3, z + 13, ExtraPlanets_Blocks.volcanicRock, 0, 3);
		world.setBlock(x + 6, y + 3, z + 13, ExtraPlanets_Blocks.volcanicRock, 0, 3);
		world.setBlock(x + 7, y + 3, z + 13, Blocks.lava, 0, 3);
		world.setBlock(x + 8, y + 3, z + 13, Blocks.lava, 8, 3);
		world.setBlock(x + 9, y + 3, z + 13, Blocks.lava, 8, 3);
		world.setBlock(x + 10, y + 3, z + 13, Blocks.lava, 8, 3);
		world.setBlock(x + 11, y + 3, z + 13, Blocks.lava, 10, 3);
		world.setBlock(x + 12, y + 3, z + 13, Blocks.lava, 0, 3);
		world.setBlock(x + 13, y + 3, z + 13, ExtraPlanets_Blocks.volcanicRock, 0, 3);
		world.setBlock(x + 14, y + 3, z + 13, ExtraPlanets_Blocks.volcanicRock, 0, 3);
		world.setBlock(x + 15, y + 3, z + 13, ExtraPlanets_Blocks.volcanicRock, 0, 3);
		world.setBlock(x + 16, y + 3, z + 13, ExtraPlanets_Blocks.volcanicRock, 0, 3);
		world.setBlock(x + 17, y + 3, z + 13, ExtraPlanets_Blocks.volcanicRock, 0, 3);
		world.setBlock(x + 18, y + 3, z + 13, ExtraPlanets_Blocks.volcanicRock, 0, 3);
		world.setBlock(x + 19, y + 3, z + 13, Blocks.lava, 4, 3);
		world.setBlock(x + 20, y + 3, z + 13, Blocks.lava, 6, 3);
		world.setBlock(x + 5, y + 3, z + 14, ExtraPlanets_Blocks.volcanicRock, 0, 3);
		world.setBlock(x + 6, y + 3, z + 14, ExtraPlanets_Blocks.volcanicRock, 0, 3);
		world.setBlock(x + 7, y + 3, z + 14, Blocks.lava, 0, 3);
		world.setBlock(x + 8, y + 3, z + 14, Blocks.lava, 0, 3);
		world.setBlock(x + 9, y + 3, z + 14, Blocks.lava, 8, 3);
		world.setBlock(x + 10, y + 3, z + 14, Blocks.lava, 8, 3);
		world.setBlock(x + 11, y + 3, z + 14, Blocks.lava, 8, 3);
		world.setBlock(x + 12, y + 3, z + 14, Blocks.lava, 0, 3);
		world.setBlock(x + 13, y + 3, z + 14, ExtraPlanets_Blocks.volcanicRock, 0, 3);
		world.setBlock(x + 14, y + 3, z + 14, ExtraPlanets_Blocks.volcanicRock, 0, 3);
		world.setBlock(x + 15, y + 3, z + 14, ExtraPlanets_Blocks.volcanicRock, 0, 3);
		world.setBlock(x + 16, y + 3, z + 14, Blocks.lava, 0, 3);
		world.setBlock(x + 17, y + 3, z + 14, ExtraPlanets_Blocks.volcanicRock, 0, 3);
		world.setBlock(x + 18, y + 3, z + 14, ExtraPlanets_Blocks.volcanicRock, 0, 3);
		world.setBlock(x + 5, y + 3, z + 15, ExtraPlanets_Blocks.volcanicRock, 0, 3);
		world.setBlock(x + 6, y + 3, z + 15, ExtraPlanets_Blocks.volcanicRock, 0, 3);
		world.setBlock(x + 7, y + 3, z + 15, ExtraPlanets_Blocks.volcanicRock, 0, 3);
		world.setBlock(x + 8, y + 3, z + 15, Blocks.lava, 0, 3);
		world.setBlock(x + 9, y + 3, z + 15, Blocks.lava, 8, 3);
		world.setBlock(x + 10, y + 3, z + 15, Blocks.lava, 8, 3);
		world.setBlock(x + 11, y + 3, z + 15, Blocks.lava, 8, 3);
		world.setBlock(x + 12, y + 3, z + 15, Blocks.lava, 0, 3);
		world.setBlock(x + 13, y + 3, z + 15, ExtraPlanets_Blocks.volcanicRock, 0, 3);
		world.setBlock(x + 14, y + 3, z + 15, ExtraPlanets_Blocks.volcanicRock, 0, 3);
		world.setBlock(x + 15, y + 3, z + 15, ExtraPlanets_Blocks.volcanicRock, 0, 3);
		world.setBlock(x + 16, y + 3, z + 15, Blocks.lava, 0, 3);
		world.setBlock(x + 17, y + 3, z + 15, Blocks.lava, 0, 3);
		world.setBlock(x + 18, y + 3, z + 15, ExtraPlanets_Blocks.volcanicRock, 0, 3);
		world.setBlock(x + 6, y + 3, z + 16, ExtraPlanets_Blocks.volcanicRock, 0, 3);
		world.setBlock(x + 7, y + 3, z + 16, ExtraPlanets_Blocks.volcanicRock, 0, 3);
		world.setBlock(x + 8, y + 3, z + 16, ExtraPlanets_Blocks.volcanicRock, 0, 3);
		world.setBlock(x + 9, y + 3, z + 16, Blocks.lava, 0, 3);
		world.setBlock(x + 10, y + 3, z + 16, Blocks.lava, 8, 3);
		world.setBlock(x + 11, y + 3, z + 16, Blocks.lava, 0, 3);
		world.setBlock(x + 12, y + 3, z + 16, Blocks.lava, 8, 3);
		world.setBlock(x + 13, y + 3, z + 16, Blocks.lava, 0, 3);
		world.setBlock(x + 14, y + 3, z + 16, Blocks.lava, 0, 3);
		world.setBlock(x + 15, y + 3, z + 16, Blocks.lava, 0, 3);
		world.setBlock(x + 16, y + 3, z + 16, Blocks.lava, 0, 3);
		world.setBlock(x + 17, y + 3, z + 16, Blocks.lava, 0, 3);
		world.setBlock(x + 18, y + 3, z + 16, ExtraPlanets_Blocks.volcanicRock, 0, 3);
		world.setBlock(x + 7, y + 3, z + 17, ExtraPlanets_Blocks.volcanicRock, 0, 3);
		world.setBlock(x + 8, y + 3, z + 17, ExtraPlanets_Blocks.volcanicRock, 0, 3);
		world.setBlock(x + 9, y + 3, z + 17, ExtraPlanets_Blocks.volcanicRock, 0, 3);
		world.setBlock(x + 10, y + 3, z + 17, Blocks.lava, 0, 3);
		world.setBlock(x + 11, y + 3, z + 17, Blocks.lava, 0, 3);
		world.setBlock(x + 12, y + 3, z + 17, Blocks.lava, 2, 3);
		world.setBlock(x + 13, y + 3, z + 17, Blocks.lava, 0, 3);
		world.setBlock(x + 14, y + 3, z + 17, Blocks.lava, 0, 3);
		world.setBlock(x + 15, y + 3, z + 17, Blocks.lava, 0, 3);
		world.setBlock(x + 16, y + 3, z + 17, Blocks.lava, 0, 3);
		world.setBlock(x + 17, y + 3, z + 17, ExtraPlanets_Blocks.volcanicRock, 0, 3);
		world.setBlock(x + 18, y + 3, z + 17, Blocks.lava, 10, 3);
		world.setBlock(x + 19, y + 3, z + 17, Blocks.lava, 2, 3);
		world.setBlock(x + 6, y + 3, z + 18, Blocks.lava, 4, 3);
		world.setBlock(x + 7, y + 3, z + 18, Blocks.lava, 2, 3);
		world.setBlock(x + 8, y + 3, z + 18, Blocks.lava, 0, 3);
		world.setBlock(x + 9, y + 3, z + 18, ExtraPlanets_Blocks.volcanicRock, 0, 3);
		world.setBlock(x + 10, y + 3, z + 18, ExtraPlanets_Blocks.volcanicRock, 0, 3);
		world.setBlock(x + 11, y + 3, z + 18, Blocks.lava, 0, 3);
		world.setBlock(x + 12, y + 3, z + 18, Blocks.lava, 2, 3);
		world.setBlock(x + 13, y + 3, z + 18, ExtraPlanets_Blocks.volcanicRock, 0, 3);
		world.setBlock(x + 14, y + 3, z + 18, ExtraPlanets_Blocks.volcanicRock, 0, 3);
		world.setBlock(x + 15, y + 3, z + 18, ExtraPlanets_Blocks.volcanicRock, 0, 3);
		world.setBlock(x + 16, y + 3, z + 18, ExtraPlanets_Blocks.volcanicRock, 0, 3);
		world.setBlock(x + 17, y + 3, z + 18, ExtraPlanets_Blocks.volcanicRock, 0, 3);
		world.setBlock(x + 18, y + 3, z + 18, Blocks.lava, 12, 3);
		world.setBlock(x + 19, y + 3, z + 18, Blocks.lava, 2, 3);
		world.setBlock(x + 7, y + 3, z + 19, Blocks.lava, 2, 3);
		world.setBlock(x + 8, y + 3, z + 19, Blocks.lava, 10, 3);
		world.setBlock(x + 9, y + 3, z + 19, Blocks.lava, 0, 3);
		world.setBlock(x + 10, y + 3, z + 19, ExtraPlanets_Blocks.volcanicRock, 0, 3);
		world.setBlock(x + 11, y + 3, z + 19, ExtraPlanets_Blocks.volcanicRock, 0, 3);
		world.setBlock(x + 12, y + 3, z + 19, ExtraPlanets_Blocks.volcanicRock, 0, 3);
		world.setBlock(x + 13, y + 3, z + 19, ExtraPlanets_Blocks.volcanicRock, 0, 3);
		world.setBlock(x + 14, y + 3, z + 19, ExtraPlanets_Blocks.volcanicRock, 0, 3);
		world.setBlock(x + 15, y + 3, z + 19, ExtraPlanets_Blocks.volcanicRock, 0, 3);
		world.setBlock(x + 16, y + 3, z + 19, ExtraPlanets_Blocks.volcanicRock, 0, 3);
		world.setBlock(x + 17, y + 3, z + 19, Blocks.lava, 12, 3);
		world.setBlock(x + 18, y + 3, z + 19, Blocks.lava, 2, 3);
		world.setBlock(x + 8, y + 3, z + 20, Blocks.lava, 2, 3);
		world.setBlock(x + 9, y + 3, z + 20, Blocks.lava, 10, 3);
		world.setBlock(x + 10, y + 3, z + 20, Blocks.lava, 10, 3);
		world.setBlock(x + 12, y + 3, z + 20, ExtraPlanets_Blocks.volcanicRock, 0, 3);
		world.setBlock(x + 13, y + 3, z + 20, ExtraPlanets_Blocks.volcanicRock, 0, 3);
		world.setBlock(x + 14, y + 3, z + 20, ExtraPlanets_Blocks.volcanicRock, 0, 3);
		world.setBlock(x + 15, y + 3, z + 20, ExtraPlanets_Blocks.volcanicRock, 0, 3);
		world.setBlock(x + 16, y + 3, z + 20, Blocks.lava, 12, 3);
		world.setBlock(x + 17, y + 3, z + 20, Blocks.lava, 2, 3);
		world.setBlock(x + 18, y + 3, z + 20, Blocks.lava, 4, 3);
		world.setBlock(x + 10, y + 3, z + 21, Blocks.lava, 2, 3);
		world.setBlock(x + 13, y + 3, z + 21, ExtraPlanets_Blocks.volcanicRock, 0, 3);
		world.setBlock(x + 14, y + 3, z + 21, ExtraPlanets_Blocks.volcanicRock, 0, 3);
		world.setBlock(x + 15, y + 3, z + 21, Blocks.lava, 14, 3);
		world.setBlock(x + 16, y + 3, z + 21, Blocks.lava, 2, 3);
		world.setBlock(x + 17, y + 3, z + 21, Blocks.lava, 4, 3);
		world.setBlock(x + 15, y + 3, z + 22, Blocks.lava, 2, 3);
		world.setBlock(x + 16, y + 3, z + 22, Blocks.lava, 4, 3);
		world.setBlock(x + 15, y + 3, z + 23, Blocks.lava, 4, 3);
		world.setBlock(x + 8, y + 4, z + 9, ExtraPlanets_Blocks.volcanicRock, 0, 3);
		world.setBlock(x + 9, y + 4, z + 9, ExtraPlanets_Blocks.volcanicRock, 0, 3);
		world.setBlock(x + 11, y + 4, z + 9, Blocks.lava, 2, 3);
		world.setBlock(x + 6, y + 4, z + 10, ExtraPlanets_Blocks.volcanicRock, 0, 3);
		world.setBlock(x + 7, y + 4, z + 10, ExtraPlanets_Blocks.volcanicRock, 0, 3);
		world.setBlock(x + 8, y + 4, z + 10, ExtraPlanets_Blocks.volcanicRock, 0, 3);
		world.setBlock(x + 9, y + 4, z + 10, Blocks.lava, 0, 3);
		world.setBlock(x + 10, y + 4, z + 10, Blocks.lava, 0, 3);
		world.setBlock(x + 11, y + 4, z + 10, Blocks.lava, 0, 3);
		world.setBlock(x + 12, y + 4, z + 10, Blocks.lava, 2, 3);
		world.setBlock(x + 13, y + 4, z + 10, Blocks.lava, 2, 3);
		world.setBlock(x + 15, y + 4, z + 10, Blocks.lava, 4, 3);
		world.setBlock(x + 6, y + 4, z + 11, ExtraPlanets_Blocks.volcanicRock, 0, 3);
		world.setBlock(x + 7, y + 4, z + 11, Blocks.lava, 0, 3);
		world.setBlock(x + 8, y + 4, z + 11, Blocks.lava, 0, 3);
		world.setBlock(x + 9, y + 4, z + 11, Blocks.lava, 10, 3);
		world.setBlock(x + 10, y + 4, z + 11, Blocks.lava, 2, 3);
		world.setBlock(x + 11, y + 4, z + 11, Blocks.lava, 0, 3);
		world.setBlock(x + 12, y + 4, z + 11, Blocks.lava, 0, 3);
		world.setBlock(x + 13, y + 4, z + 11, Blocks.lava, 0, 3);
		world.setBlock(x + 14, y + 4, z + 11, Blocks.lava, 2, 3);
		world.setBlock(x + 15, y + 4, z + 11, Blocks.lava, 2, 3);
		world.setBlock(x + 16, y + 4, z + 11, Blocks.lava, 4, 3);
		world.setBlock(x + 17, y + 4, z + 11, Blocks.lava, 6, 3);
		world.setBlock(x + 6, y + 4, z + 12, ExtraPlanets_Blocks.volcanicRock, 0, 3);
		world.setBlock(x + 7, y + 4, z + 12, ExtraPlanets_Blocks.volcanicRock, 0, 3);
		world.setBlock(x + 8, y + 4, z + 12, Blocks.lava, 0, 3);
		world.setBlock(x + 9, y + 4, z + 12, Blocks.lava, 8, 3);
		world.setBlock(x + 10, y + 4, z + 12, Blocks.lava, 10, 3);
		world.setBlock(x + 11, y + 4, z + 12, Blocks.lava, 2, 3);
		world.setBlock(x + 12, y + 4, z + 12, Blocks.lava, 0, 3);
		world.setBlock(x + 13, y + 4, z + 12, Blocks.lava, 0, 3);
		world.setBlock(x + 14, y + 4, z + 12, Blocks.lava, 2, 3);
		world.setBlock(x + 15, y + 4, z + 12, Blocks.lava, 0, 3);
		world.setBlock(x + 16, y + 4, z + 12, Blocks.lava, 2, 3);
		world.setBlock(x + 17, y + 4, z + 12, Blocks.lava, 4, 3);
		world.setBlock(x + 18, y + 4, z + 12, Blocks.lava, 6, 3);
		world.setBlock(x + 6, y + 4, z + 13, ExtraPlanets_Blocks.volcanicRock, 0, 3);
		world.setBlock(x + 7, y + 4, z + 13, ExtraPlanets_Blocks.volcanicRock, 0, 3);
		world.setBlock(x + 8, y + 4, z + 13, Blocks.lava, 0, 3);
		world.setBlock(x + 9, y + 4, z + 13, Blocks.lava, 0, 3);
		world.setBlock(x + 10, y + 4, z + 13, Blocks.lava, 8, 3);
		world.setBlock(x + 11, y + 4, z + 13, Blocks.lava, 10, 3);
		world.setBlock(x + 12, y + 4, z + 13, Blocks.lava, 2, 3);
		world.setBlock(x + 13, y + 4, z + 13, Blocks.lava, 0, 3);
		world.setBlock(x + 14, y + 4, z + 13, Blocks.lava, 0, 3);
		world.setBlock(x + 15, y + 4, z + 13, Blocks.lava, 0, 3);
		world.setBlock(x + 16, y + 4, z + 13, ExtraPlanets_Blocks.volcanicRock, 0, 3);
		world.setBlock(x + 17, y + 4, z + 13, Blocks.lava, 6, 3);
		world.setBlock(x + 7, y + 4, z + 14, ExtraPlanets_Blocks.volcanicRock, 0, 3);
		world.setBlock(x + 8, y + 4, z + 14, ExtraPlanets_Blocks.volcanicRock, 0, 3);
		world.setBlock(x + 9, y + 4, z + 14, Blocks.lava, 0, 3);
		world.setBlock(x + 10, y + 4, z + 14, Blocks.lava, 0, 3);
		world.setBlock(x + 11, y + 4, z + 14, Blocks.lava, 8, 3);
		world.setBlock(x + 12, y + 4, z + 14, Blocks.lava, 10, 3);
		world.setBlock(x + 13, y + 4, z + 14, Blocks.lava, 0, 3);
		world.setBlock(x + 14, y + 4, z + 14, Blocks.lava, 0, 3);
		world.setBlock(x + 15, y + 4, z + 14, Blocks.lava, 0, 3);
		world.setBlock(x + 16, y + 4, z + 14, ExtraPlanets_Blocks.volcanicRock, 0, 3);
		world.setBlock(x + 17, y + 4, z + 14, ExtraPlanets_Blocks.volcanicRock, 0, 3);
		world.setBlock(x + 7, y + 4, z + 15, ExtraPlanets_Blocks.volcanicRock, 0, 3);
		world.setBlock(x + 8, y + 4, z + 15, ExtraPlanets_Blocks.volcanicRock, 0, 3);
		world.setBlock(x + 9, y + 4, z + 15, Blocks.lava, 0, 3);
		world.setBlock(x + 10, y + 4, z + 15, Blocks.lava, 0, 3);
		world.setBlock(x + 11, y + 4, z + 15, Blocks.lava, 0, 3);
		world.setBlock(x + 12, y + 4, z + 15, Blocks.lava, 8, 3);
		world.setBlock(x + 13, y + 4, z + 15, Blocks.lava, 0, 3);
		world.setBlock(x + 14, y + 4, z + 15, Blocks.lava, 0, 3);
		world.setBlock(x + 15, y + 4, z + 15, Blocks.lava, 0, 3);
		world.setBlock(x + 16, y + 4, z + 15, ExtraPlanets_Blocks.volcanicRock, 0, 3);
		world.setBlock(x + 17, y + 4, z + 15, ExtraPlanets_Blocks.volcanicRock, 0, 3);
		world.setBlock(x + 8, y + 4, z + 16, ExtraPlanets_Blocks.volcanicRock, 0, 3);
		world.setBlock(x + 9, y + 4, z + 16, Blocks.lava, 8, 3);
		world.setBlock(x + 10, y + 4, z + 16, Blocks.lava, 8, 3);
		world.setBlock(x + 11, y + 4, z + 16, ExtraPlanets_Blocks.volcanicRock, 0, 3);
		world.setBlock(x + 12, y + 4, z + 16, Blocks.lava, 0, 3);
		world.setBlock(x + 13, y + 4, z + 16, ExtraPlanets_Blocks.volcanicRock, 0, 3);
		world.setBlock(x + 14, y + 4, z + 16, ExtraPlanets_Blocks.volcanicRock, 0, 3);
		world.setBlock(x + 15, y + 4, z + 16, ExtraPlanets_Blocks.volcanicRock, 0, 3);
		world.setBlock(x + 16, y + 4, z + 16, ExtraPlanets_Blocks.volcanicRock, 0, 3);
		world.setBlock(x + 17, y + 4, z + 16, ExtraPlanets_Blocks.volcanicRock, 0, 3);
		world.setBlock(x + 8, y + 4, z + 17, Blocks.lava, 0, 3);
		world.setBlock(x + 9, y + 4, z + 17, Blocks.lava, 0, 3);
		world.setBlock(x + 10, y + 4, z + 17, ExtraPlanets_Blocks.volcanicRock, 0, 3);
		world.setBlock(x + 11, y + 4, z + 17, ExtraPlanets_Blocks.volcanicRock, 0, 3);
		world.setBlock(x + 12, y + 4, z + 17, ExtraPlanets_Blocks.volcanicRock, 0, 3);
		world.setBlock(x + 13, y + 4, z + 17, ExtraPlanets_Blocks.volcanicRock, 0, 3);
		world.setBlock(x + 14, y + 4, z + 17, ExtraPlanets_Blocks.volcanicRock, 0, 3);
		world.setBlock(x + 15, y + 4, z + 17, ExtraPlanets_Blocks.volcanicRock, 0, 3);
		world.setBlock(x + 16, y + 4, z + 17, ExtraPlanets_Blocks.volcanicRock, 0, 3);
		world.setBlock(x + 17, y + 4, z + 17, Blocks.lava, 0, 3);
		world.setBlock(x + 18, y + 4, z + 17, Blocks.lava, 2, 3);
		world.setBlock(x + 8, y + 4, z + 18, Blocks.lava, 10, 3);
		world.setBlock(x + 9, y + 4, z + 18, ExtraPlanets_Blocks.volcanicRock, 0, 3);
		world.setBlock(x + 10, y + 4, z + 18, ExtraPlanets_Blocks.volcanicRock, 0, 3);
		world.setBlock(x + 11, y + 4, z + 18, ExtraPlanets_Blocks.volcanicRock, 0, 3);
		world.setBlock(x + 12, y + 4, z + 18, ExtraPlanets_Blocks.volcanicRock, 0, 3);
		world.setBlock(x + 14, y + 4, z + 18, Blocks.lava, 10, 3);
		world.setBlock(x + 15, y + 4, z + 18, Blocks.lava, 0, 3);
		world.setBlock(x + 16, y + 4, z + 18, Blocks.lava, 10, 3);
		world.setBlock(x + 17, y + 4, z + 18, Blocks.lava, 2, 3);
		world.setBlock(x + 18, y + 4, z + 18, Blocks.lava, 4, 3);
		world.setBlock(x + 8, y + 4, z + 19, Blocks.lava, 2, 3);
		world.setBlock(x + 9, y + 4, z + 19, Blocks.lava, 0, 3);
		world.setBlock(x + 10, y + 4, z + 19, Blocks.lava, 12, 3);
		world.setBlock(x + 14, y + 4, z + 19, Blocks.lava, 2, 3);
		world.setBlock(x + 15, y + 4, z + 19, Blocks.lava, 2, 3);
		world.setBlock(x + 16, y + 4, z + 19, Blocks.lava, 2, 3);
		world.setBlock(x + 17, y + 4, z + 19, Blocks.lava, 4, 3);
		world.setBlock(x + 9, y + 4, z + 20, Blocks.lava, 2, 3);
		world.setBlock(x + 10, y + 4, z + 20, Blocks.lava, 2, 3);
		world.setBlock(x + 14, y + 4, z + 20, Blocks.lava, 4, 3);
		world.setBlock(x + 15, y + 4, z + 20, Blocks.lava, 4, 3);
		world.setBlock(x + 16, y + 4, z + 20, Blocks.lava, 4, 3);
		world.setBlock(x + 14, y + 4, z + 21, Blocks.lava, 6, 3);
		world.setBlock(x + 15, y + 4, z + 21, Blocks.lava, 6, 3);
		world.setBlock(x + 8, y + 5, z + 11, Blocks.lava, 2, 3);
		world.setBlock(x + 9, y + 5, z + 11, Blocks.lava, 2, 3);
		world.setBlock(x + 8, y + 5, z + 12, Blocks.lava, 0, 3);
		world.setBlock(x + 9, y + 5, z + 12, Blocks.lava, 0, 3);
		world.setBlock(x + 10, y + 5, z + 12, Blocks.lava, 2, 3);
		world.setBlock(x + 8, y + 5, z + 13, ExtraPlanets_Blocks.volcanicRock, 0, 3);
		world.setBlock(x + 9, y + 5, z + 13, ExtraPlanets_Blocks.volcanicRock, 0, 3);
		world.setBlock(x + 10, y + 5, z + 13, Blocks.lava, 0, 3);
		world.setBlock(x + 11, y + 5, z + 13, Blocks.lava, 2, 3);
		world.setBlock(x + 7, y + 5, z + 14, ExtraPlanets_Blocks.volcanicRock, 0, 3);
		world.setBlock(x + 8, y + 5, z + 14, ExtraPlanets_Blocks.volcanicRock, 0, 3);
		world.setBlock(x + 9, y + 5, z + 14, ExtraPlanets_Blocks.volcanicRock, 0, 3);
		world.setBlock(x + 10, y + 5, z + 14, ExtraPlanets_Blocks.volcanicRock, 0, 3);
		world.setBlock(x + 11, y + 5, z + 14, Blocks.lava, 0, 3);
		world.setBlock(x + 12, y + 5, z + 14, Blocks.lava, 2, 3);
		world.setBlock(x + 8, y + 5, z + 15, ExtraPlanets_Blocks.volcanicRock, 0, 3);
		world.setBlock(x + 9, y + 5, z + 15, ExtraPlanets_Blocks.volcanicRock, 0, 3);
		world.setBlock(x + 10, y + 5, z + 15, ExtraPlanets_Blocks.volcanicRock, 0, 3);
		world.setBlock(x + 11, y + 5, z + 15, Blocks.lava, 0, 3);
		world.setBlock(x + 12, y + 5, z + 15, Blocks.lava, 0, 3);
