package com.mjr.extraplanets.world.features;

import java.util.Random;

import net.minecraft.init.Blocks;
import net.minecraft.tileentity.TileEntityChest;
import net.minecraft.util.math.BlockPos;
import net.minecraft.world.World;
import net.minecraft.world.gen.feature.WorldGenerator;
import net.minecraft.world.storage.loot.LootTableList;

import com.mjr.extraplanets.Config;
import com.mjr.extraplanets.blocks.ExtraPlanets_Blocks;
import com.mjr.extraplanets.blocks.fluid.ExtraPlanets_Fluids;
import com.mjr.extraplanets.util.WorldGenHelper;

public class WorldGenVolcano extends WorldGenerator {

	@Override
	public boolean generate(World world, Random rand, BlockPos position) {
		position = position.down(2);
		if (WorldGenHelper.checkValidSpawn(world, position, 10, 20) == false)
			return false;
		else {
			if (Config.DEBUG_MODE)
				System.out.println("Spawning Volcano at (x, y, z)" + position.toString());
			generateStructure(world, rand, position);
			fillChests(world, rand, position);
		}
		return true;
	}

	public boolean generateStructure(World world, Random rand, BlockPos position) {
		int x = position.getX();
		int y = position.getY();
		int z = position.getZ();
		world.setBlockState(new BlockPos(x + 11, y + 0, z + 1), ExtraPlanets_Blocks.VOLCANIC_ROCK.getDefaultState(), 3);
		world.setBlockState(new BlockPos(x + 13, y + 0, z + 1), ExtraPlanets_Blocks.VOLCANIC_ROCK.getDefaultState(), 3);
		world.setBlockState(new BlockPos(x + 10, y + 0, z + 2), ExtraPlanets_Blocks.VOLCANIC_ROCK.getDefaultState(), 3);
		world.setBlockState(new BlockPos(x + 11, y + 0, z + 2), ExtraPlanets_Blocks.VOLCANIC_ROCK.getDefaultState(), 3);
		world.setBlockState(new BlockPos(x + 12, y + 0, z + 2), ExtraPlanets_Blocks.VOLCANIC_ROCK.getDefaultState(), 3);
		world.setBlockState(new BlockPos(x + 13, y + 0, z + 2), ExtraPlanets_Blocks.VOLCANIC_ROCK.getDefaultState(), 3);
		world.setBlockState(new BlockPos(x + 14, y + 0, z + 2), ExtraPlanets_Blocks.VOLCANIC_ROCK.getDefaultState(), 3);
		world.setBlockState(new BlockPos(x + 8, y + 0, z + 3), ExtraPlanets_Blocks.VOLCANIC_ROCK.getDefaultState(), 3);
		world.setBlockState(new BlockPos(x + 9, y + 0, z + 3), ExtraPlanets_Blocks.VOLCANIC_ROCK.getDefaultState(), 3);
		world.setBlockState(new BlockPos(x + 10, y + 0, z + 3), ExtraPlanets_Blocks.VOLCANIC_ROCK.getDefaultState(), 3);
		world.setBlockState(new BlockPos(x + 11, y + 0, z + 3), ExtraPlanets_Blocks.VOLCANIC_ROCK.getDefaultState(), 3);
		world.setBlockState(new BlockPos(x + 12, y + 0, z + 3), ExtraPlanets_Blocks.VOLCANIC_ROCK.getDefaultState(), 3);
		world.setBlockState(new BlockPos(x + 13, y + 0, z + 3), ExtraPlanets_Blocks.VOLCANIC_ROCK.getDefaultState(), 3);
		world.setBlockState(new BlockPos(x + 14, y + 0, z + 3), ExtraPlanets_Blocks.VOLCANIC_ROCK.getDefaultState(), 3);
		world.setBlockState(new BlockPos(x + 15, y + 0, z + 3), ExtraPlanets_Blocks.VOLCANIC_ROCK.getDefaultState(), 3);
		world.setBlockState(new BlockPos(x + 5, y + 0, z + 4), ExtraPlanets_Blocks.VOLCANIC_ROCK.getDefaultState(), 3);
		world.setBlockState(new BlockPos(x + 6, y + 0, z + 4), ExtraPlanets_Blocks.VOLCANIC_ROCK.getDefaultState(), 3);
		world.setBlockState(new BlockPos(x + 7, y + 0, z + 4), ExtraPlanets_Blocks.VOLCANIC_ROCK.getDefaultState(), 3);
		world.setBlockState(new BlockPos(x + 8, y + 0, z + 4), ExtraPlanets_Blocks.VOLCANIC_ROCK.getDefaultState(), 3);
		world.setBlockState(new BlockPos(x + 9, y + 0, z + 4), ExtraPlanets_Blocks.VOLCANIC_ROCK.getDefaultState(), 3);
		world.setBlockState(new BlockPos(x + 10, y + 0, z + 4), ExtraPlanets_Blocks.VOLCANIC_ROCK.getDefaultState(), 3);
		world.setBlockState(new BlockPos(x + 11, y + 0, z + 4), ExtraPlanets_Blocks.VOLCANIC_ROCK.getDefaultState(), 3);
		world.setBlockState(new BlockPos(x + 12, y + 0, z + 4), ExtraPlanets_Blocks.VOLCANIC_ROCK.getDefaultState(), 3);
		world.setBlockState(new BlockPos(x + 13, y + 0, z + 4), ExtraPlanets_Blocks.VOLCANIC_ROCK.getDefaultState(), 3);
		world.setBlockState(new BlockPos(x + 14, y + 0, z + 4), ExtraPlanets_Blocks.VOLCANIC_ROCK.getDefaultState(), 3);
		world.setBlockState(new BlockPos(x + 15, y + 0, z + 4), ExtraPlanets_Blocks.VOLCANIC_ROCK.getDefaultState(), 3);
		world.setBlockState(new BlockPos(x + 16, y + 0, z + 4), ExtraPlanets_Blocks.VOLCANIC_ROCK.getDefaultState(), 3);
		world.setBlockState(new BlockPos(x + 17, y + 0, z + 4), ExtraPlanets_Blocks.VOLCANIC_ROCK.getDefaultState(), 3);
		world.setBlockState(new BlockPos(x + 4, y + 0, z + 5), ExtraPlanets_Blocks.VOLCANIC_ROCK.getDefaultState(), 3);
		world.setBlockState(new BlockPos(x + 5, y + 0, z + 5), ExtraPlanets_Blocks.VOLCANIC_ROCK.getDefaultState(), 3);
		world.setBlockState(new BlockPos(x + 6, y + 0, z + 5), ExtraPlanets_Fluids.MAGMA.getDefaultState(), 3);
		world.setBlockState(new BlockPos(x + 7, y + 0, z + 5), ExtraPlanets_Fluids.MAGMA.getDefaultState(), 3);
		world.setBlockState(new BlockPos(x + 8, y + 0, z + 5), ExtraPlanets_Fluids.MAGMA.getDefaultState(), 3);
		world.setBlockState(new BlockPos(x + 9, y + 0, z + 5), ExtraPlanets_Fluids.MAGMA.getDefaultState(), 3);
		world.setBlockState(new BlockPos(x + 10, y + 0, z + 5), ExtraPlanets_Fluids.MAGMA.getDefaultState(), 3);
		world.setBlockState(new BlockPos(x + 11, y + 0, z + 5), ExtraPlanets_Fluids.MAGMA.getDefaultState(), 3);
		world.setBlockState(new BlockPos(x + 12, y + 0, z + 5), ExtraPlanets_Blocks.VOLCANIC_ROCK.getDefaultState(), 3);
		world.setBlockState(new BlockPos(x + 13, y + 0, z + 5), ExtraPlanets_Blocks.VOLCANIC_ROCK.getDefaultState(), 3);
		world.setBlockState(new BlockPos(x + 14, y + 0, z + 5), ExtraPlanets_Blocks.VOLCANIC_ROCK.getDefaultState(), 3);
		world.setBlockState(new BlockPos(x + 15, y + 0, z + 5), ExtraPlanets_Blocks.VOLCANIC_ROCK.getDefaultState(), 3);
		world.setBlockState(new BlockPos(x + 16, y + 0, z + 5), ExtraPlanets_Blocks.VOLCANIC_ROCK.getDefaultState(), 3);
		world.setBlockState(new BlockPos(x + 17, y + 0, z + 5), ExtraPlanets_Blocks.VOLCANIC_ROCK.getDefaultState(), 3);
		world.setBlockState(new BlockPos(x + 18, y + 0, z + 5), ExtraPlanets_Blocks.VOLCANIC_ROCK.getDefaultState(), 3);
		world.setBlockState(new BlockPos(x + 19, y + 0, z + 5), ExtraPlanets_Blocks.VOLCANIC_ROCK.getDefaultState(), 3);
		world.setBlockState(new BlockPos(x + 4, y + 0, z + 6), ExtraPlanets_Blocks.VOLCANIC_ROCK.getDefaultState(), 3);
		world.setBlockState(new BlockPos(x + 5, y + 0, z + 6), ExtraPlanets_Fluids.MAGMA.getDefaultState(), 3);
		world.setBlockState(new BlockPos(x + 6, y + 0, z + 6), ExtraPlanets_Fluids.MAGMA.getDefaultState(), 3);
		world.setBlockState(new BlockPos(x + 7, y + 0, z + 6), ExtraPlanets_Fluids.MAGMA.getDefaultState(), 3);
		world.setBlockState(new BlockPos(x + 8, y + 0, z + 6), ExtraPlanets_Fluids.MAGMA.getDefaultState(), 3);
		world.setBlockState(new BlockPos(x + 9, y + 0, z + 6), ExtraPlanets_Fluids.MAGMA.getDefaultState(), 3);
		world.setBlockState(new BlockPos(x + 10, y + 0, z + 6), ExtraPlanets_Fluids.MAGMA.getDefaultState(), 3);
		world.setBlockState(new BlockPos(x + 11, y + 0, z + 6), ExtraPlanets_Fluids.MAGMA.getDefaultState(), 3);
		world.setBlockState(new BlockPos(x + 12, y + 0, z + 6), ExtraPlanets_Fluids.MAGMA.getDefaultState(), 3);
		world.setBlockState(new BlockPos(x + 13, y + 0, z + 6), ExtraPlanets_Blocks.VOLCANIC_ROCK.getDefaultState(), 3);
		world.setBlockState(new BlockPos(x + 14, y + 0, z + 6), ExtraPlanets_Blocks.VOLCANIC_ROCK.getDefaultState(), 3);
		world.setBlockState(new BlockPos(x + 15, y + 0, z + 6), ExtraPlanets_Blocks.VOLCANIC_ROCK.getDefaultState(), 3);
		world.setBlockState(new BlockPos(x + 16, y + 0, z + 6), ExtraPlanets_Blocks.VOLCANIC_ROCK.getDefaultState(), 3);
		world.setBlockState(new BlockPos(x + 17, y + 0, z + 6), ExtraPlanets_Blocks.VOLCANIC_ROCK.getDefaultState(), 3);
		world.setBlockState(new BlockPos(x + 18, y + 0, z + 6), ExtraPlanets_Blocks.VOLCANIC_ROCK.getDefaultState(), 3);
		world.setBlockState(new BlockPos(x + 3, y + 0, z + 7), ExtraPlanets_Blocks.VOLCANIC_ROCK.getDefaultState(), 3);
		world.setBlockState(new BlockPos(x + 4, y + 0, z + 7), ExtraPlanets_Blocks.VOLCANIC_ROCK.getDefaultState(), 3);
		world.setBlockState(new BlockPos(x + 5, y + 0, z + 7), ExtraPlanets_Blocks.VOLCANIC_ROCK.getDefaultState(), 3);
		world.setBlockState(new BlockPos(x + 6, y + 0, z + 7), ExtraPlanets_Fluids.MAGMA.getDefaultState(), 3);
		world.setBlockState(new BlockPos(x + 7, y + 0, z + 7), ExtraPlanets_Fluids.MAGMA.getDefaultState(), 3);
		world.setBlockState(new BlockPos(x + 8, y + 0, z + 7), ExtraPlanets_Fluids.MAGMA.getDefaultState(), 3);
		world.setBlockState(new BlockPos(x + 9, y + 0, z + 7), ExtraPlanets_Fluids.MAGMA.getDefaultState(), 3);
		world.setBlockState(new BlockPos(x + 10, y + 0, z + 7), ExtraPlanets_Fluids.MAGMA.getDefaultState(), 3);
		world.setBlockState(new BlockPos(x + 11, y + 0, z + 7), ExtraPlanets_Fluids.MAGMA.getDefaultState(), 3);
		world.setBlockState(new BlockPos(x + 12, y + 0, z + 7), ExtraPlanets_Fluids.MAGMA.getDefaultState(), 3);
		world.setBlockState(new BlockPos(x + 13, y + 0, z + 7), ExtraPlanets_Fluids.MAGMA.getDefaultState(), 3);
		world.setBlockState(new BlockPos(x + 14, y + 0, z + 7), ExtraPlanets_Fluids.MAGMA.getDefaultState(), 3);
		world.setBlockState(new BlockPos(x + 15, y + 0, z + 7), ExtraPlanets_Blocks.VOLCANIC_ROCK.getDefaultState(), 3);
		world.setBlockState(new BlockPos(x + 16, y + 0, z + 7), ExtraPlanets_Blocks.VOLCANIC_ROCK.getDefaultState(), 3);
		world.setBlockState(new BlockPos(x + 17, y + 0, z + 7), ExtraPlanets_Blocks.VOLCANIC_ROCK.getDefaultState(), 3);
		world.setBlockState(new BlockPos(x + 18, y + 0, z + 7), ExtraPlanets_Blocks.VOLCANIC_ROCK.getDefaultState(), 3);
		world.setBlockState(new BlockPos(x + 2, y + 0, z + 8), ExtraPlanets_Blocks.VOLCANIC_ROCK.getDefaultState(), 3);
		world.setBlockState(new BlockPos(x + 3, y + 0, z + 8), ExtraPlanets_Blocks.VOLCANIC_ROCK.getDefaultState(), 3);
		world.setBlockState(new BlockPos(x + 4, y + 0, z + 8), ExtraPlanets_Blocks.VOLCANIC_ROCK.getDefaultState(), 3);
		world.setBlockState(new BlockPos(x + 5, y + 0, z + 8), ExtraPlanets_Fluids.MAGMA.getDefaultState(), 3);
		world.setBlockState(new BlockPos(x + 6, y + 0, z + 8), ExtraPlanets_Fluids.MAGMA.getDefaultState(), 3);
		world.setBlockState(new BlockPos(x + 7, y + 0, z + 8), ExtraPlanets_Fluids.MAGMA.getDefaultState(), 3);
		world.setBlockState(new BlockPos(x + 8, y + 0, z + 8), ExtraPlanets_Fluids.MAGMA.getDefaultState(), 3);
		world.setBlockState(new BlockPos(x + 9, y + 0, z + 8), ExtraPlanets_Fluids.MAGMA.getDefaultState(), 3);
		world.setBlockState(new BlockPos(x + 10, y + 0, z + 8), ExtraPlanets_Fluids.MAGMA.getDefaultState(), 3);
		world.setBlockState(new BlockPos(x + 11, y + 0, z + 8), ExtraPlanets_Fluids.MAGMA.getDefaultState(), 3);
		world.setBlockState(new BlockPos(x + 12, y + 0, z + 8), ExtraPlanets_Fluids.MAGMA.getDefaultState(), 3);
		world.setBlockState(new BlockPos(x + 13, y + 0, z + 8), ExtraPlanets_Fluids.MAGMA.getDefaultState(), 3);
		world.setBlockState(new BlockPos(x + 14, y + 0, z + 8), ExtraPlanets_Fluids.MAGMA.getDefaultState(), 3);
		world.setBlockState(new BlockPos(x + 15, y + 0, z + 8), ExtraPlanets_Fluids.MAGMA.getDefaultState(), 3);
		world.setBlockState(new BlockPos(x + 16, y + 0, z + 8), ExtraPlanets_Blocks.VOLCANIC_ROCK.getDefaultState(), 3);
		world.setBlockState(new BlockPos(x + 17, y + 0, z + 8), ExtraPlanets_Blocks.VOLCANIC_ROCK.getDefaultState(), 3);
		world.setBlockState(new BlockPos(x + 18, y + 0, z + 8), ExtraPlanets_Blocks.VOLCANIC_ROCK.getDefaultState(), 3);
		world.setBlockState(new BlockPos(x + 1, y + 0, z + 9), ExtraPlanets_Blocks.VOLCANIC_ROCK.getDefaultState(), 3);
		world.setBlockState(new BlockPos(x + 2, y + 0, z + 9), ExtraPlanets_Blocks.VOLCANIC_ROCK.getDefaultState(), 3);
		world.setBlockState(new BlockPos(x + 3, y + 0, z + 9), ExtraPlanets_Fluids.MAGMA.getDefaultState(), 3);
		world.setBlockState(new BlockPos(x + 4, y + 0, z + 9), ExtraPlanets_Fluids.MAGMA.getDefaultState(), 3);
		world.setBlockState(new BlockPos(x + 5, y + 0, z + 9), ExtraPlanets_Fluids.MAGMA.getDefaultState(), 3);
		world.setBlockState(new BlockPos(x + 6, y + 0, z + 9), ExtraPlanets_Fluids.MAGMA.getDefaultState(), 3);
		world.setBlockState(new BlockPos(x + 7, y + 0, z + 9), ExtraPlanets_Fluids.MAGMA.getDefaultState(), 3);
		world.setBlockState(new BlockPos(x + 8, y + 0, z + 9), ExtraPlanets_Fluids.MAGMA.getDefaultState(), 3);
		world.setBlockState(new BlockPos(x + 9, y + 0, z + 9), ExtraPlanets_Fluids.MAGMA.getDefaultState(), 3);
		world.setBlockState(new BlockPos(x + 10, y + 0, z + 9), ExtraPlanets_Fluids.MAGMA.getDefaultState(), 3);
		world.setBlockState(new BlockPos(x + 11, y + 0, z + 9), ExtraPlanets_Fluids.MAGMA.getDefaultState(), 3);
		world.setBlockState(new BlockPos(x + 12, y + 0, z + 9), ExtraPlanets_Fluids.MAGMA.getDefaultState(), 3);
		world.setBlockState(new BlockPos(x + 13, y + 0, z + 9), ExtraPlanets_Fluids.MAGMA.getDefaultState(), 3);
		world.setBlockState(new BlockPos(x + 14, y + 0, z + 9), ExtraPlanets_Fluids.MAGMA.getDefaultState(), 3);
		world.setBlockState(new BlockPos(x + 15, y + 0, z + 9), ExtraPlanets_Fluids.MAGMA.getDefaultState(), 3);
		world.setBlockState(new BlockPos(x + 16, y + 0, z + 9), ExtraPlanets_Fluids.MAGMA.getDefaultState(), 3);
		world.setBlockState(new BlockPos(x + 17, y + 0, z + 9), ExtraPlanets_Fluids.MAGMA.getDefaultState(), 3);
		world.setBlockState(new BlockPos(x + 18, y + 0, z + 9), ExtraPlanets_Blocks.VOLCANIC_ROCK.getDefaultState(), 3);
		world.setBlockState(new BlockPos(x + 3, y + 0, z + 10), ExtraPlanets_Fluids.MAGMA.getDefaultState(), 3);
		world.setBlockState(new BlockPos(x + 4, y + 0, z + 10), ExtraPlanets_Fluids.MAGMA.getDefaultState(), 3);
		world.setBlockState(new BlockPos(x + 5, y + 0, z + 10), ExtraPlanets_Fluids.MAGMA.getDefaultState(), 3);
		world.setBlockState(new BlockPos(x + 6, y + 0, z + 10), ExtraPlanets_Fluids.MAGMA.getDefaultState(), 3);
		world.setBlockState(new BlockPos(x + 7, y + 0, z + 10), ExtraPlanets_Fluids.MAGMA.getDefaultState(), 3);
		world.setBlockState(new BlockPos(x + 8, y + 0, z + 10), ExtraPlanets_Fluids.MAGMA.getDefaultState(), 3);
		world.setBlockState(new BlockPos(x + 9, y + 0, z + 10), ExtraPlanets_Fluids.MAGMA.getDefaultState(), 3);
		world.setBlockState(new BlockPos(x + 10, y + 0, z + 10), ExtraPlanets_Fluids.MAGMA.getDefaultState(), 3);
		world.setBlockState(new BlockPos(x + 11, y + 0, z + 10), ExtraPlanets_Fluids.MAGMA.getDefaultState(), 3);
		world.setBlockState(new BlockPos(x + 12, y + 0, z + 10), ExtraPlanets_Fluids.MAGMA.getDefaultState(), 3);
		world.setBlockState(new BlockPos(x + 13, y + 0, z + 10), ExtraPlanets_Fluids.MAGMA.getDefaultState(), 3);
		world.setBlockState(new BlockPos(x + 14, y + 0, z + 10), ExtraPlanets_Fluids.MAGMA.getDefaultState(), 3);
		world.setBlockState(new BlockPos(x + 15, y + 0, z + 10), ExtraPlanets_Fluids.MAGMA.getDefaultState(), 3);
		world.setBlockState(new BlockPos(x + 16, y + 0, z + 10), ExtraPlanets_Fluids.MAGMA.getDefaultState(), 3);
		world.setBlockState(new BlockPos(x + 17, y + 0, z + 10), ExtraPlanets_Fluids.MAGMA.getDefaultState(), 3);
		world.setBlockState(new BlockPos(x + 18, y + 0, z + 10), ExtraPlanets_Fluids.MAGMA.getDefaultState(), 3);
		world.setBlockState(new BlockPos(x + 0, y + 0, z + 11), ExtraPlanets_Blocks.VOLCANIC_ROCK.getDefaultState(), 3);
		world.setBlockState(new BlockPos(x + 1, y + 0, z + 11), ExtraPlanets_Blocks.VOLCANIC_ROCK.getDefaultState(), 3);
		world.setBlockState(new BlockPos(x + 2, y + 0, z + 11), ExtraPlanets_Blocks.VOLCANIC_ROCK.getDefaultState(), 3);
		world.setBlockState(new BlockPos(x + 3, y + 0, z + 11), ExtraPlanets_Fluids.MAGMA.getDefaultState(), 3);
		world.setBlockState(new BlockPos(x + 4, y + 0, z + 11), ExtraPlanets_Fluids.MAGMA.getDefaultState(), 3);
		world.setBlockState(new BlockPos(x + 5, y + 0, z + 11), ExtraPlanets_Fluids.MAGMA.getDefaultState(), 3);
		world.setBlockState(new BlockPos(x + 6, y + 0, z + 11), ExtraPlanets_Fluids.MAGMA.getDefaultState(), 3);
		world.setBlockState(new BlockPos(x + 7, y + 0, z + 11), ExtraPlanets_Fluids.MAGMA.getDefaultState(), 3);
		world.setBlockState(new BlockPos(x + 8, y + 0, z + 11), ExtraPlanets_Fluids.MAGMA.getDefaultState(), 3);
		world.setBlockState(new BlockPos(x + 9, y + 0, z + 11), ExtraPlanets_Fluids.MAGMA.getDefaultState(), 3);
		world.setBlockState(new BlockPos(x + 10, y + 0, z + 11), ExtraPlanets_Fluids.MAGMA.getDefaultState(), 3);
		world.setBlockState(new BlockPos(x + 11, y + 0, z + 11), ExtraPlanets_Fluids.MAGMA.getDefaultState(), 3);
		world.setBlockState(new BlockPos(x + 12, y + 0, z + 11), ExtraPlanets_Fluids.MAGMA.getDefaultState(), 3);
		world.setBlockState(new BlockPos(x + 13, y + 0, z + 11), ExtraPlanets_Fluids.MAGMA.getDefaultState(), 3);
		world.setBlockState(new BlockPos(x + 14, y + 0, z + 11), ExtraPlanets_Fluids.MAGMA.getDefaultState(), 3);
		world.setBlockState(new BlockPos(x + 15, y + 0, z + 11), ExtraPlanets_Fluids.MAGMA.getDefaultState(), 3);
		world.setBlockState(new BlockPos(x + 16, y + 0, z + 11), ExtraPlanets_Fluids.MAGMA.getDefaultState(), 3);
		world.setBlockState(new BlockPos(x + 17, y + 0, z + 11), ExtraPlanets_Fluids.MAGMA.getDefaultState(), 3);
		world.setBlockState(new BlockPos(x + 18, y + 0, z + 11), ExtraPlanets_Fluids.MAGMA.getDefaultState(), 3);
		world.setBlockState(new BlockPos(x + 0, y + 0, z + 12), ExtraPlanets_Blocks.VOLCANIC_ROCK.getDefaultState(), 3);
		world.setBlockState(new BlockPos(x + 1, y + 0, z + 12), ExtraPlanets_Blocks.VOLCANIC_ROCK.getDefaultState(), 3);
		world.setBlockState(new BlockPos(x + 2, y + 0, z + 12), ExtraPlanets_Blocks.VOLCANIC_ROCK.getDefaultState(), 3);
		world.setBlockState(new BlockPos(x + 3, y + 0, z + 12), ExtraPlanets_Fluids.MAGMA.getDefaultState(), 3);
		world.setBlockState(new BlockPos(x + 4, y + 0, z + 12), ExtraPlanets_Fluids.MAGMA.getDefaultState(), 3);
		world.setBlockState(new BlockPos(x + 5, y + 0, z + 12), ExtraPlanets_Fluids.MAGMA.getDefaultState(), 3);
		world.setBlockState(new BlockPos(x + 6, y + 0, z + 12), ExtraPlanets_Fluids.MAGMA.getDefaultState(), 3);
		world.setBlockState(new BlockPos(x + 7, y + 0, z + 12), ExtraPlanets_Fluids.MAGMA.getDefaultState(), 3);
		world.setBlockState(new BlockPos(x + 8, y + 0, z + 12), ExtraPlanets_Fluids.MAGMA.getDefaultState(), 3);
		world.setBlockState(new BlockPos(x + 9, y + 0, z + 12), ExtraPlanets_Fluids.MAGMA.getDefaultState(), 3);
		world.setBlockState(new BlockPos(x + 10, y + 0, z + 12), ExtraPlanets_Fluids.MAGMA.getDefaultState(), 3);
		world.setBlockState(new BlockPos(x + 11, y + 0, z + 12), ExtraPlanets_Fluids.MAGMA.getDefaultState(), 3);
		world.setBlockState(new BlockPos(x + 12, y + 0, z + 12), ExtraPlanets_Fluids.MAGMA.getDefaultState(), 3);
		world.setBlockState(new BlockPos(x + 13, y + 0, z + 12), ExtraPlanets_Fluids.MAGMA.getDefaultState(), 3);
		world.setBlockState(new BlockPos(x + 14, y + 0, z + 12), ExtraPlanets_Fluids.MAGMA.getDefaultState(), 3);
		world.setBlockState(new BlockPos(x + 15, y + 0, z + 12), ExtraPlanets_Fluids.MAGMA.getDefaultState(), 3);
		world.setBlockState(new BlockPos(x + 16, y + 0, z + 12), ExtraPlanets_Fluids.MAGMA.getDefaultState(), 3);
		world.setBlockState(new BlockPos(x + 17, y + 0, z + 12), ExtraPlanets_Fluids.MAGMA.getDefaultState(), 3);
		world.setBlockState(new BlockPos(x + 18, y + 0, z + 12), ExtraPlanets_Fluids.MAGMA.getDefaultState(), 3);
		world.setBlockState(new BlockPos(x + 0, y + 0, z + 13), ExtraPlanets_Blocks.VOLCANIC_ROCK.getDefaultState(), 3);
		world.setBlockState(new BlockPos(x + 1, y + 0, z + 13), ExtraPlanets_Blocks.VOLCANIC_ROCK.getDefaultState(), 3);
		world.setBlockState(new BlockPos(x + 2, y + 0, z + 13), ExtraPlanets_Blocks.VOLCANIC_ROCK.getDefaultState(), 3);
		world.setBlockState(new BlockPos(x + 3, y + 0, z + 13), ExtraPlanets_Fluids.MAGMA.getDefaultState(), 3);
		world.setBlockState(new BlockPos(x + 4, y + 0, z + 13), ExtraPlanets_Fluids.MAGMA.getDefaultState(), 3);
		world.setBlockState(new BlockPos(x + 5, y + 0, z + 13), ExtraPlanets_Fluids.MAGMA.getDefaultState(), 3);
		if (rand.nextInt(30) == 1)
			world.setBlockState(new BlockPos(x + 6, y + 0, z + 13), Blocks.CHEST.getDefaultState(), 3);

		world.setBlockState(new BlockPos(x + 7, y + 0, z + 13), ExtraPlanets_Fluids.MAGMA.getDefaultState(), 3);
		world.setBlockState(new BlockPos(x + 8, y + 0, z + 13), ExtraPlanets_Fluids.MAGMA.getDefaultState(), 3);
		world.setBlockState(new BlockPos(x + 9, y + 0, z + 13), ExtraPlanets_Fluids.MAGMA.getDefaultState(), 3);
		world.setBlockState(new BlockPos(x + 10, y + 0, z + 13), ExtraPlanets_Fluids.MAGMA.getDefaultState(), 3);
		world.setBlockState(new BlockPos(x + 11, y + 0, z + 13), ExtraPlanets_Fluids.MAGMA.getDefaultState(), 3);
		world.setBlockState(new BlockPos(x + 12, y + 0, z + 13), ExtraPlanets_Fluids.MAGMA.getDefaultState(), 3);
		world.setBlockState(new BlockPos(x + 13, y + 0, z + 13), ExtraPlanets_Fluids.MAGMA.getDefaultState(), 3);
		world.setBlockState(new BlockPos(x + 14, y + 0, z + 13), ExtraPlanets_Fluids.MAGMA.getDefaultState(), 3);
		world.setBlockState(new BlockPos(x + 15, y + 0, z + 13), ExtraPlanets_Fluids.MAGMA.getDefaultState(), 3);
		world.setBlockState(new BlockPos(x + 16, y + 0, z + 13), ExtraPlanets_Fluids.MAGMA.getDefaultState(), 3);
		world.setBlockState(new BlockPos(x + 17, y + 0, z + 13), ExtraPlanets_Fluids.MAGMA.getDefaultState(), 3);
		if (rand.nextInt(30) == 1)
			world.setBlockState(new BlockPos(x + 18, y + 0, z + 13), Blocks.CHEST.getDefaultState(), 3);
		world.setBlockState(new BlockPos(x + 0, y + 0, z + 14), ExtraPlanets_Blocks.VOLCANIC_ROCK.getDefaultState(), 3);
		world.setBlockState(new BlockPos(x + 1, y + 0, z + 14), ExtraPlanets_Blocks.VOLCANIC_ROCK.getDefaultState(), 3);
		world.setBlockState(new BlockPos(x + 2, y + 0, z + 14), ExtraPlanets_Blocks.VOLCANIC_ROCK.getDefaultState(), 3);
		world.setBlockState(new BlockPos(x + 3, y + 0, z + 14), ExtraPlanets_Fluids.MAGMA.getDefaultState(), 3);
		world.setBlockState(new BlockPos(x + 4, y + 0, z + 14), ExtraPlanets_Fluids.MAGMA.getDefaultState(), 3);
		world.setBlockState(new BlockPos(x + 5, y + 0, z + 14), ExtraPlanets_Fluids.MAGMA.getDefaultState(), 3);
		world.setBlockState(new BlockPos(x + 6, y + 0, z + 14), ExtraPlanets_Fluids.MAGMA.getDefaultState(), 3);
		world.setBlockState(new BlockPos(x + 7, y + 0, z + 14), ExtraPlanets_Fluids.MAGMA.getDefaultState(), 3);
		world.setBlockState(new BlockPos(x + 8, y + 0, z + 14), ExtraPlanets_Fluids.MAGMA.getDefaultState(), 3);
		world.setBlockState(new BlockPos(x + 9, y + 0, z + 14), ExtraPlanets_Fluids.MAGMA.getDefaultState(), 3);
		world.setBlockState(new BlockPos(x + 10, y + 0, z + 14), ExtraPlanets_Fluids.MAGMA.getDefaultState(), 3);
		world.setBlockState(new BlockPos(x + 11, y + 0, z + 14), ExtraPlanets_Fluids.MAGMA.getDefaultState(), 3);
		world.setBlockState(new BlockPos(x + 12, y + 0, z + 14), ExtraPlanets_Fluids.MAGMA.getDefaultState(), 3);
		world.setBlockState(new BlockPos(x + 13, y + 0, z + 14), ExtraPlanets_Fluids.MAGMA.getDefaultState(), 3);
		world.setBlockState(new BlockPos(x + 14, y + 0, z + 14), ExtraPlanets_Fluids.MAGMA.getDefaultState(), 3);
		world.setBlockState(new BlockPos(x + 15, y + 0, z + 14), ExtraPlanets_Fluids.MAGMA.getDefaultState(), 3);
		world.setBlockState(new BlockPos(x + 16, y + 0, z + 14), ExtraPlanets_Fluids.MAGMA.getDefaultState(), 3);
		world.setBlockState(new BlockPos(x + 17, y + 0, z + 14), ExtraPlanets_Fluids.MAGMA.getDefaultState(), 3);
		world.setBlockState(new BlockPos(x + 18, y + 0, z + 14), ExtraPlanets_Fluids.MAGMA.getDefaultState(), 3);
		world.setBlockState(new BlockPos(x + 1, y + 0, z + 15), ExtraPlanets_Blocks.VOLCANIC_ROCK.getDefaultState(), 3);
		world.setBlockState(new BlockPos(x + 2, y + 0, z + 15), ExtraPlanets_Blocks.VOLCANIC_ROCK.getDefaultState(), 3);
		world.setBlockState(new BlockPos(x + 3, y + 0, z + 15), ExtraPlanets_Blocks.VOLCANIC_ROCK.getDefaultState(), 3);
		world.setBlockState(new BlockPos(x + 4, y + 0, z + 15), ExtraPlanets_Fluids.MAGMA.getDefaultState(), 3);
		world.setBlockState(new BlockPos(x + 5, y + 0, z + 15), ExtraPlanets_Fluids.MAGMA.getDefaultState(), 3);
		world.setBlockState(new BlockPos(x + 6, y + 0, z + 15), ExtraPlanets_Fluids.MAGMA.getDefaultState(), 3);
		world.setBlockState(new BlockPos(x + 7, y + 0, z + 15), ExtraPlanets_Fluids.MAGMA.getDefaultState(), 3);
		world.setBlockState(new BlockPos(x + 8, y + 0, z + 15), ExtraPlanets_Fluids.MAGMA.getDefaultState(), 3);
		world.setBlockState(new BlockPos(x + 9, y + 0, z + 15), ExtraPlanets_Fluids.MAGMA.getDefaultState(), 3);
		world.setBlockState(new BlockPos(x + 10, y + 0, z + 15), ExtraPlanets_Fluids.MAGMA.getDefaultState(), 3);
		world.setBlockState(new BlockPos(x + 11, y + 0, z + 15), ExtraPlanets_Fluids.MAGMA.getDefaultState(), 3);
		world.setBlockState(new BlockPos(x + 12, y + 0, z + 15), ExtraPlanets_Fluids.MAGMA.getDefaultState(), 3);
		world.setBlockState(new BlockPos(x + 13, y + 0, z + 15), ExtraPlanets_Fluids.MAGMA.getDefaultState(), 3);
		world.setBlockState(new BlockPos(x + 14, y + 0, z + 15), ExtraPlanets_Fluids.MAGMA.getDefaultState(), 3);
		world.setBlockState(new BlockPos(x + 15, y + 0, z + 15), ExtraPlanets_Fluids.MAGMA.getDefaultState(), 3);
		world.setBlockState(new BlockPos(x + 16, y + 0, z + 15), ExtraPlanets_Fluids.MAGMA.getDefaultState(), 3);
		world.setBlockState(new BlockPos(x + 17, y + 0, z + 15), ExtraPlanets_Fluids.MAGMA.getDefaultState(), 3);
		world.setBlockState(new BlockPos(x + 18, y + 0, z + 15), ExtraPlanets_Fluids.MAGMA.getDefaultState(), 3);
		world.setBlockState(new BlockPos(x + 2, y + 0, z + 16), ExtraPlanets_Blocks.VOLCANIC_ROCK.getDefaultState(), 3);
		world.setBlockState(new BlockPos(x + 3, y + 0, z + 16), ExtraPlanets_Blocks.VOLCANIC_ROCK.getDefaultState(), 3);
		world.setBlockState(new BlockPos(x + 4, y + 0, z + 16), ExtraPlanets_Fluids.MAGMA.getDefaultState(), 3);
		world.setBlockState(new BlockPos(x + 5, y + 0, z + 16), ExtraPlanets_Fluids.MAGMA.getDefaultState(), 3);
		world.setBlockState(new BlockPos(x + 6, y + 0, z + 16), ExtraPlanets_Fluids.MAGMA.getDefaultState(), 3);
		world.setBlockState(new BlockPos(x + 7, y + 0, z + 16), ExtraPlanets_Fluids.MAGMA.getDefaultState(), 3);
		world.setBlockState(new BlockPos(x + 8, y + 0, z + 16), ExtraPlanets_Fluids.MAGMA.getDefaultState(), 3);
		world.setBlockState(new BlockPos(x + 9, y + 0, z + 16), ExtraPlanets_Fluids.MAGMA.getDefaultState(), 3);
		world.setBlockState(new BlockPos(x + 10, y + 0, z + 16), ExtraPlanets_Fluids.MAGMA.getDefaultState(), 3);
		world.setBlockState(new BlockPos(x + 11, y + 0, z + 16), ExtraPlanets_Fluids.MAGMA.getDefaultState(), 3);
		world.setBlockState(new BlockPos(x + 12, y + 0, z + 16), ExtraPlanets_Fluids.MAGMA.getDefaultState(), 3);
		world.setBlockState(new BlockPos(x + 13, y + 0, z + 16), ExtraPlanets_Fluids.MAGMA.getDefaultState(), 3);
		world.setBlockState(new BlockPos(x + 14, y + 0, z + 16), ExtraPlanets_Fluids.MAGMA.getDefaultState(), 3);
		world.setBlockState(new BlockPos(x + 15, y + 0, z + 16), ExtraPlanets_Fluids.MAGMA.getDefaultState(), 3);
		world.setBlockState(new BlockPos(x + 16, y + 0, z + 16), ExtraPlanets_Fluids.MAGMA.getDefaultState(), 3);
		world.setBlockState(new BlockPos(x + 17, y + 0, z + 16), ExtraPlanets_Fluids.MAGMA.getDefaultState(), 3);
		world.setBlockState(new BlockPos(x + 18, y + 0, z + 16), ExtraPlanets_Fluids.MAGMA.getDefaultState(), 3);
		world.setBlockState(new BlockPos(x + 2, y + 0, z + 17), ExtraPlanets_Blocks.VOLCANIC_ROCK.getDefaultState(), 3);
		world.setBlockState(new BlockPos(x + 3, y + 0, z + 17), ExtraPlanets_Blocks.VOLCANIC_ROCK.getDefaultState(), 3);
		world.setBlockState(new BlockPos(x + 4, y + 0, z + 17), ExtraPlanets_Fluids.MAGMA.getDefaultState(), 3);
		world.setBlockState(new BlockPos(x + 5, y + 0, z + 17), ExtraPlanets_Fluids.MAGMA.getDefaultState(), 3);
		world.setBlockState(new BlockPos(x + 6, y + 0, z + 17), ExtraPlanets_Fluids.MAGMA.getDefaultState(), 3);
		world.setBlockState(new BlockPos(x + 7, y + 0, z + 17), ExtraPlanets_Fluids.MAGMA.getDefaultState(), 3);
		world.setBlockState(new BlockPos(x + 8, y + 0, z + 17), ExtraPlanets_Fluids.MAGMA.getDefaultState(), 3);
		world.setBlockState(new BlockPos(x + 9, y + 0, z + 17), ExtraPlanets_Fluids.MAGMA.getDefaultState(), 3);
		world.setBlockState(new BlockPos(x + 10, y + 0, z + 17), ExtraPlanets_Fluids.MAGMA.getDefaultState(), 3);
		world.setBlockState(new BlockPos(x + 11, y + 0, z + 17), ExtraPlanets_Fluids.MAGMA.getDefaultState(), 3);
		world.setBlockState(new BlockPos(x + 12, y + 0, z + 17), ExtraPlanets_Fluids.MAGMA.getDefaultState(), 3);
		world.setBlockState(new BlockPos(x + 13, y + 0, z + 17), ExtraPlanets_Fluids.MAGMA.getDefaultState(), 3);
		world.setBlockState(new BlockPos(x + 14, y + 0, z + 17), ExtraPlanets_Fluids.MAGMA.getDefaultState(), 3);
		world.setBlockState(new BlockPos(x + 15, y + 0, z + 17), ExtraPlanets_Fluids.MAGMA.getDefaultState(), 3);
		world.setBlockState(new BlockPos(x + 16, y + 0, z + 17), ExtraPlanets_Fluids.MAGMA.getDefaultState(), 3);
		world.setBlockState(new BlockPos(x + 17, y + 0, z + 17), ExtraPlanets_Fluids.MAGMA.getDefaultState(), 3);
		world.setBlockState(new BlockPos(x + 18, y + 0, z + 17), ExtraPlanets_Fluids.MAGMA.getDefaultState(), 3);
		world.setBlockState(new BlockPos(x + 2, y + 0, z + 18), ExtraPlanets_Blocks.VOLCANIC_ROCK.getDefaultState(), 3);
		world.setBlockState(new BlockPos(x + 3, y + 0, z + 18), ExtraPlanets_Blocks.VOLCANIC_ROCK.getDefaultState(), 3);
		world.setBlockState(new BlockPos(x + 4, y + 0, z + 18), ExtraPlanets_Blocks.VOLCANIC_ROCK.getDefaultState(), 3);
		world.setBlockState(new BlockPos(x + 6, y + 0, z + 18), ExtraPlanets_Blocks.VOLCANIC_ROCK.getDefaultState(), 3);
		world.setBlockState(new BlockPos(x + 17, y + 0, z + 18), ExtraPlanets_Blocks.VOLCANIC_ROCK.getDefaultState(), 3);
		world.setBlockState(new BlockPos(x + 18, y + 0, z + 18), ExtraPlanets_Blocks.VOLCANIC_ROCK.getDefaultState(), 3);
		world.setBlockState(new BlockPos(x + 9, y + 1, z + 4), ExtraPlanets_Blocks.VOLCANIC_ROCK.getDefaultState(), 3);
		world.setBlockState(new BlockPos(x + 10, y + 1, z + 4), ExtraPlanets_Blocks.VOLCANIC_ROCK.getDefaultState(), 3);
		world.setBlockState(new BlockPos(x + 11, y + 1, z + 4), ExtraPlanets_Blocks.VOLCANIC_ROCK.getDefaultState(), 3);
		world.setBlockState(new BlockPos(x + 6, y + 1, z + 5), ExtraPlanets_Blocks.VOLCANIC_ROCK.getDefaultState(), 3);
		world.setBlockState(new BlockPos(x + 7, y + 1, z + 5), ExtraPlanets_Blocks.VOLCANIC_ROCK.getDefaultState(), 3);
		world.setBlockState(new BlockPos(x + 8, y + 1, z + 5), ExtraPlanets_Blocks.VOLCANIC_ROCK.getDefaultState(), 3);
		world.setBlockState(new BlockPos(x + 9, y + 1, z + 5), ExtraPlanets_Blocks.VOLCANIC_ROCK.getDefaultState(), 3);
		world.setBlockState(new BlockPos(x + 10, y + 1, z + 5), ExtraPlanets_Blocks.VOLCANIC_ROCK.getDefaultState(), 3);
		world.setBlockState(new BlockPos(x + 11, y + 1, z + 5), ExtraPlanets_Fluids.MAGMA.getDefaultState(), 3);
		world.setBlockState(new BlockPos(x + 12, y + 1, z + 5), ExtraPlanets_Fluids.MAGMA.getDefaultState(), 3);
		world.setBlockState(new BlockPos(x + 16, y + 1, z + 5), ExtraPlanets_Fluids.MAGMA.getDefaultState(), 3);
		world.setBlockState(new BlockPos(x + 17, y + 1, z + 5), ExtraPlanets_Fluids.MAGMA.getDefaultState(), 3);
		world.setBlockState(new BlockPos(x + 5, y + 1, z + 6), ExtraPlanets_Blocks.VOLCANIC_ROCK.getDefaultState(), 3);
		world.setBlockState(new BlockPos(x + 6, y + 1, z + 6), ExtraPlanets_Blocks.VOLCANIC_ROCK.getDefaultState(), 3);
		world.setBlockState(new BlockPos(x + 7, y + 1, z + 6), ExtraPlanets_Blocks.VOLCANIC_ROCK.getDefaultState(), 3);
		world.setBlockState(new BlockPos(x + 8, y + 1, z + 6), ExtraPlanets_Fluids.MAGMA.getDefaultState(), 3);
		world.setBlockState(new BlockPos(x + 9, y + 1, z + 6), ExtraPlanets_Fluids.MAGMA.getDefaultState(), 3);
		world.setBlockState(new BlockPos(x + 10, y + 1, z + 6), ExtraPlanets_Fluids.MAGMA.getDefaultState(), 3);
		world.setBlockState(new BlockPos(x + 11, y + 1, z + 6), ExtraPlanets_Fluids.MAGMA.getDefaultState(), 3);
		world.setBlockState(new BlockPos(x + 12, y + 1, z + 6), ExtraPlanets_Fluids.MAGMA.getDefaultState(), 3);
		world.setBlockState(new BlockPos(x + 13, y + 1, z + 6), ExtraPlanets_Fluids.MAGMA.getDefaultState(), 3);
		world.setBlockState(new BlockPos(x + 14, y + 1, z + 6), ExtraPlanets_Fluids.MAGMA.getDefaultState(), 3);
		world.setBlockState(new BlockPos(x + 15, y + 1, z + 6), ExtraPlanets_Fluids.MAGMA.getDefaultState(), 3);
		world.setBlockState(new BlockPos(x + 16, y + 1, z + 6), ExtraPlanets_Fluids.MAGMA.getDefaultState(), 3);
		world.setBlockState(new BlockPos(x + 17, y + 1, z + 6), ExtraPlanets_Fluids.MAGMA.getDefaultState(), 3);
		world.setBlockState(new BlockPos(x + 18, y + 1, z + 6), ExtraPlanets_Fluids.MAGMA.getDefaultState(), 3);
		world.setBlockState(new BlockPos(x + 5, y + 1, z + 7), ExtraPlanets_Blocks.VOLCANIC_ROCK.getDefaultState(), 3);
		world.setBlockState(new BlockPos(x + 6, y + 1, z + 7), ExtraPlanets_Fluids.MAGMA.getDefaultState(), 3);
		world.setBlockState(new BlockPos(x + 7, y + 1, z + 7), ExtraPlanets_Fluids.MAGMA.getDefaultState(), 3);
		world.setBlockState(new BlockPos(x + 8, y + 1, z + 7), ExtraPlanets_Fluids.MAGMA.getDefaultState(), 3);
		world.setBlockState(new BlockPos(x + 9, y + 1, z + 7), ExtraPlanets_Fluids.MAGMA.getDefaultState(), 3);
		world.setBlockState(new BlockPos(x + 10, y + 1, z + 7), ExtraPlanets_Fluids.MAGMA.getDefaultState(), 3);
		world.setBlockState(new BlockPos(x + 11, y + 1, z + 7), ExtraPlanets_Fluids.MAGMA.getDefaultState(), 3);
		world.setBlockState(new BlockPos(x + 12, y + 1, z + 7), ExtraPlanets_Fluids.MAGMA.getDefaultState(), 3);
		world.setBlockState(new BlockPos(x + 13, y + 1, z + 7), ExtraPlanets_Blocks.VOLCANIC_ROCK.getDefaultState(), 3);
		world.setBlockState(new BlockPos(x + 14, y + 1, z + 7), ExtraPlanets_Blocks.VOLCANIC_ROCK.getDefaultState(), 3);
		world.setBlockState(new BlockPos(x + 15, y + 1, z + 7), ExtraPlanets_Fluids.MAGMA.getDefaultState(), 3);
		world.setBlockState(new BlockPos(x + 16, y + 1, z + 7), ExtraPlanets_Fluids.MAGMA.getDefaultState(), 3);
		world.setBlockState(new BlockPos(x + 17, y + 1, z + 7), ExtraPlanets_Fluids.MAGMA.getDefaultState(), 3);
		world.setBlockState(new BlockPos(x + 18, y + 1, z + 7), ExtraPlanets_Fluids.MAGMA.getDefaultState(), 3);
		world.setBlockState(new BlockPos(x + 4, y + 1, z + 8), ExtraPlanets_Blocks.VOLCANIC_ROCK.getDefaultState(), 3);
		world.setBlockState(new BlockPos(x + 5, y + 1, z + 8), ExtraPlanets_Blocks.VOLCANIC_ROCK.getDefaultState(), 3);
		world.setBlockState(new BlockPos(x + 6, y + 1, z + 8), ExtraPlanets_Fluids.MAGMA.getDefaultState(), 3);
		world.setBlockState(new BlockPos(x + 7, y + 1, z + 8), ExtraPlanets_Fluids.MAGMA.getDefaultState(), 3);
		world.setBlockState(new BlockPos(x + 8, y + 1, z + 8), ExtraPlanets_Fluids.MAGMA.getDefaultState(), 3);
		world.setBlockState(new BlockPos(x + 9, y + 1, z + 8), ExtraPlanets_Fluids.MAGMA.getDefaultState(), 3);
		world.setBlockState(new BlockPos(x + 10, y + 1, z + 8), ExtraPlanets_Fluids.MAGMA.getDefaultState(), 3);
		world.setBlockState(new BlockPos(x + 11, y + 1, z + 8), ExtraPlanets_Fluids.MAGMA.getDefaultState(), 3);
		world.setBlockState(new BlockPos(x + 12, y + 1, z + 8), ExtraPlanets_Fluids.MAGMA.getDefaultState(), 3);
		world.setBlockState(new BlockPos(x + 13, y + 1, z + 8), ExtraPlanets_Blocks.VOLCANIC_ROCK.getDefaultState(), 3);
		world.setBlockState(new BlockPos(x + 14, y + 1, z + 8), ExtraPlanets_Blocks.VOLCANIC_ROCK.getDefaultState(), 3);
		world.setBlockState(new BlockPos(x + 15, y + 1, z + 8), ExtraPlanets_Blocks.VOLCANIC_ROCK.getDefaultState(), 3);
		world.setBlockState(new BlockPos(x + 16, y + 1, z + 8), ExtraPlanets_Fluids.MAGMA.getDefaultState(), 3);
		world.setBlockState(new BlockPos(x + 17, y + 1, z + 8), ExtraPlanets_Fluids.MAGMA.getDefaultState(), 3);
		world.setBlockState(new BlockPos(x + 18, y + 1, z + 8), ExtraPlanets_Fluids.MAGMA.getDefaultState(), 3);
		world.setBlockState(new BlockPos(x + 3, y + 1, z + 9), ExtraPlanets_Blocks.VOLCANIC_ROCK.getDefaultState(), 3);
		world.setBlockState(new BlockPos(x + 4, y + 1, z + 9), ExtraPlanets_Blocks.VOLCANIC_ROCK.getDefaultState(), 3);
		world.setBlockState(new BlockPos(x + 5, y + 1, z + 9), ExtraPlanets_Fluids.MAGMA.getDefaultState(), 3);
		world.setBlockState(new BlockPos(x + 6, y + 1, z + 9), ExtraPlanets_Fluids.MAGMA.getDefaultState(), 3);
		world.setBlockState(new BlockPos(x + 7, y + 1, z + 9), ExtraPlanets_Fluids.MAGMA.getDefaultState(), 3);
		world.setBlockState(new BlockPos(x + 8, y + 1, z + 9), ExtraPlanets_Fluids.MAGMA.getDefaultState(), 3);
		world.setBlockState(new BlockPos(x + 9, y + 1, z + 9), ExtraPlanets_Fluids.MAGMA.getDefaultState(), 3);
		world.setBlockState(new BlockPos(x + 10, y + 1, z + 9), ExtraPlanets_Fluids.MAGMA.getDefaultState(), 3);
		world.setBlockState(new BlockPos(x + 11, y + 1, z + 9), ExtraPlanets_Fluids.MAGMA.getDefaultState(), 3);
		world.setBlockState(new BlockPos(x + 12, y + 1, z + 9), ExtraPlanets_Fluids.MAGMA.getDefaultState(), 3);
		world.setBlockState(new BlockPos(x + 13, y + 1, z + 9), ExtraPlanets_Fluids.MAGMA.getDefaultState(), 3);
		world.setBlockState(new BlockPos(x + 14, y + 1, z + 9), ExtraPlanets_Fluids.MAGMA.getDefaultState(), 3);
		world.setBlockState(new BlockPos(x + 15, y + 1, z + 9), ExtraPlanets_Blocks.VOLCANIC_ROCK.getDefaultState(), 3);
		world.setBlockState(new BlockPos(x + 16, y + 1, z + 9), ExtraPlanets_Blocks.VOLCANIC_ROCK.getDefaultState(), 3);
		world.setBlockState(new BlockPos(x + 17, y + 1, z + 9), ExtraPlanets_Blocks.VOLCANIC_ROCK.getDefaultState(), 3);
		world.setBlockState(new BlockPos(x + 18, y + 1, z + 9), ExtraPlanets_Fluids.MAGMA.getDefaultState(), 3);
		world.setBlockState(new BlockPos(x + 3, y + 1, z + 10), ExtraPlanets_Blocks.VOLCANIC_ROCK.getDefaultState(), 3);
		world.setBlockState(new BlockPos(x + 4, y + 1, z + 10), ExtraPlanets_Fluids.MAGMA.getDefaultState(), 3);
		world.setBlockState(new BlockPos(x + 5, y + 1, z + 10), ExtraPlanets_Fluids.MAGMA.getDefaultState(), 3);
		world.setBlockState(new BlockPos(x + 6, y + 1, z + 10), ExtraPlanets_Fluids.MAGMA.getDefaultState(), 3);
		world.setBlockState(new BlockPos(x + 7, y + 1, z + 10), ExtraPlanets_Fluids.MAGMA.getDefaultState(), 3);
		world.setBlockState(new BlockPos(x + 8, y + 1, z + 10), ExtraPlanets_Fluids.MAGMA.getDefaultState(), 3);
		world.setBlockState(new BlockPos(x + 9, y + 1, z + 10), ExtraPlanets_Fluids.MAGMA.getDefaultState(), 3);
		world.setBlockState(new BlockPos(x + 10, y + 1, z + 10), ExtraPlanets_Fluids.MAGMA.getDefaultState(), 3);
		world.setBlockState(new BlockPos(x + 11, y + 1, z + 10), ExtraPlanets_Fluids.MAGMA.getDefaultState(), 3);
		world.setBlockState(new BlockPos(x + 12, y + 1, z + 10), ExtraPlanets_Fluids.MAGMA.getDefaultState(), 3);
		world.setBlockState(new BlockPos(x + 13, y + 1, z + 10), ExtraPlanets_Fluids.MAGMA.getDefaultState(), 3);
		world.setBlockState(new BlockPos(x + 14, y + 1, z + 10), ExtraPlanets_Fluids.MAGMA.getDefaultState(), 3);
		world.setBlockState(new BlockPos(x + 15, y + 1, z + 10), ExtraPlanets_Fluids.MAGMA.getDefaultState(), 3);
		world.setBlockState(new BlockPos(x + 16, y + 1, z + 10), ExtraPlanets_Blocks.VOLCANIC_ROCK.getDefaultState(), 3);
		world.setBlockState(new BlockPos(x + 17, y + 1, z + 10), ExtraPlanets_Blocks.VOLCANIC_ROCK.getDefaultState(), 3);
		world.setBlockState(new BlockPos(x + 18, y + 1, z + 10), ExtraPlanets_Blocks.VOLCANIC_ROCK.getDefaultState(), 3);
		world.setBlockState(new BlockPos(x + 2, y + 1, z + 11), ExtraPlanets_Blocks.VOLCANIC_ROCK.getDefaultState(), 3);
		world.setBlockState(new BlockPos(x + 3, y + 1, z + 11), ExtraPlanets_Blocks.VOLCANIC_ROCK.getDefaultState(), 3);
		world.setBlockState(new BlockPos(x + 4, y + 1, z + 11), ExtraPlanets_Fluids.MAGMA.getDefaultState(), 3);
		world.setBlockState(new BlockPos(x + 5, y + 1, z + 11), ExtraPlanets_Fluids.MAGMA.getDefaultState(), 3);
		world.setBlockState(new BlockPos(x + 6, y + 1, z + 11), ExtraPlanets_Fluids.MAGMA.getDefaultState(), 3);
		world.setBlockState(new BlockPos(x + 7, y + 1, z + 11), ExtraPlanets_Fluids.MAGMA.getDefaultState(), 3);
		world.setBlockState(new BlockPos(x + 8, y + 1, z + 11), ExtraPlanets_Fluids.MAGMA.getDefaultState(), 3);
		world.setBlockState(new BlockPos(x + 9, y + 1, z + 11), ExtraPlanets_Fluids.MAGMA.getDefaultState(), 3);
		world.setBlockState(new BlockPos(x + 10, y + 1, z + 11), ExtraPlanets_Fluids.MAGMA.getDefaultState(), 3);
		world.setBlockState(new BlockPos(x + 11, y + 1, z + 11), ExtraPlanets_Fluids.MAGMA.getDefaultState(), 3);
		world.setBlockState(new BlockPos(x + 12, y + 1, z + 11), ExtraPlanets_Fluids.MAGMA.getDefaultState(), 3);
		world.setBlockState(new BlockPos(x + 13, y + 1, z + 11), ExtraPlanets_Fluids.MAGMA.getDefaultState(), 3);
		world.setBlockState(new BlockPos(x + 14, y + 1, z + 11), ExtraPlanets_Fluids.MAGMA.getDefaultState(), 3);
		world.setBlockState(new BlockPos(x + 15, y + 1, z + 11), ExtraPlanets_Fluids.MAGMA.getDefaultState(), 3);
		world.setBlockState(new BlockPos(x + 16, y + 1, z + 11), ExtraPlanets_Fluids.MAGMA.getDefaultState(), 3);
		world.setBlockState(new BlockPos(x + 17, y + 1, z + 11), ExtraPlanets_Fluids.MAGMA.getDefaultState(), 3);
		world.setBlockState(new BlockPos(x + 18, y + 1, z + 11), ExtraPlanets_Blocks.VOLCANIC_ROCK.getDefaultState(), 3);
		world.setBlockState(new BlockPos(x + 2, y + 1, z + 12), ExtraPlanets_Blocks.VOLCANIC_ROCK.getDefaultState(), 3);
		world.setBlockState(new BlockPos(x + 3, y + 1, z + 12), ExtraPlanets_Blocks.VOLCANIC_ROCK.getDefaultState(), 3);
		world.setBlockState(new BlockPos(x + 4, y + 1, z + 12), ExtraPlanets_Fluids.MAGMA.getDefaultState(), 3);
		world.setBlockState(new BlockPos(x + 5, y + 1, z + 12), ExtraPlanets_Fluids.MAGMA.getDefaultState(), 3);
		world.setBlockState(new BlockPos(x + 6, y + 1, z + 12), ExtraPlanets_Fluids.MAGMA.getDefaultState(), 3);
		world.setBlockState(new BlockPos(x + 7, y + 1, z + 12), ExtraPlanets_Fluids.MAGMA.getDefaultState(), 3);
		world.setBlockState(new BlockPos(x + 8, y + 1, z + 12), ExtraPlanets_Fluids.MAGMA.getDefaultState(), 3);
		world.setBlockState(new BlockPos(x + 9, y + 1, z + 12), ExtraPlanets_Fluids.MAGMA.getDefaultState(), 3);
		world.setBlockState(new BlockPos(x + 10, y + 1, z + 12), ExtraPlanets_Fluids.MAGMA.getDefaultState(), 3);
		world.setBlockState(new BlockPos(x + 11, y + 1, z + 12), ExtraPlanets_Fluids.MAGMA.getDefaultState(), 3);
		world.setBlockState(new BlockPos(x + 12, y + 1, z + 12), ExtraPlanets_Fluids.MAGMA.getDefaultState(), 3);
		world.setBlockState(new BlockPos(x + 13, y + 1, z + 12), ExtraPlanets_Fluids.MAGMA.getDefaultState(), 3);
		world.setBlockState(new BlockPos(x + 14, y + 1, z + 12), ExtraPlanets_Fluids.MAGMA.getDefaultState(), 3);
		world.setBlockState(new BlockPos(x + 15, y + 1, z + 12), ExtraPlanets_Fluids.MAGMA.getDefaultState(), 3);
		world.setBlockState(new BlockPos(x + 16, y + 1, z + 12), ExtraPlanets_Fluids.MAGMA.getDefaultState(), 3);
		world.setBlockState(new BlockPos(x + 17, y + 1, z + 12), ExtraPlanets_Fluids.MAGMA.getDefaultState(), 3);
		world.setBlockState(new BlockPos(x + 18, y + 1, z + 12), ExtraPlanets_Fluids.MAGMA.getDefaultState(), 3);
		world.setBlockState(new BlockPos(x + 2, y + 1, z + 13), ExtraPlanets_Blocks.VOLCANIC_ROCK.getDefaultState(), 3);
		world.setBlockState(new BlockPos(x + 3, y + 1, z + 13), ExtraPlanets_Blocks.VOLCANIC_ROCK.getDefaultState(), 3);
		world.setBlockState(new BlockPos(x + 4, y + 1, z + 13), ExtraPlanets_Fluids.MAGMA.getDefaultState(), 3);
		world.setBlockState(new BlockPos(x + 5, y + 1, z + 13), ExtraPlanets_Fluids.MAGMA.getDefaultState(), 3);
		world.setBlockState(new BlockPos(x + 6, y + 1, z + 13), ExtraPlanets_Fluids.MAGMA.getDefaultState(), 3);
		world.setBlockState(new BlockPos(x + 7, y + 1, z + 13), ExtraPlanets_Fluids.MAGMA.getDefaultState(), 3);
		world.setBlockState(new BlockPos(x + 8, y + 1, z + 13), ExtraPlanets_Fluids.MAGMA.getDefaultState(), 3);
		world.setBlockState(new BlockPos(x + 9, y + 1, z + 13), ExtraPlanets_Fluids.MAGMA.getDefaultState(), 3);
		world.setBlockState(new BlockPos(x + 10, y + 1, z + 13), ExtraPlanets_Fluids.MAGMA.getDefaultState(), 3);
		world.setBlockState(new BlockPos(x + 11, y + 1, z + 13), ExtraPlanets_Fluids.MAGMA.getDefaultState(), 3);
		world.setBlockState(new BlockPos(x + 12, y + 1, z + 13), ExtraPlanets_Fluids.MAGMA.getDefaultState(), 3);
		world.setBlockState(new BlockPos(x + 13, y + 1, z + 13), ExtraPlanets_Fluids.MAGMA.getDefaultState(), 3);
		world.setBlockState(new BlockPos(x + 14, y + 1, z + 13), ExtraPlanets_Fluids.MAGMA.getDefaultState(), 3);
		world.setBlockState(new BlockPos(x + 15, y + 1, z + 13), ExtraPlanets_Fluids.MAGMA.getDefaultState(), 3);
		world.setBlockState(new BlockPos(x + 16, y + 1, z + 13), ExtraPlanets_Fluids.MAGMA.getDefaultState(), 3);
		world.setBlockState(new BlockPos(x + 17, y + 1, z + 13), ExtraPlanets_Fluids.MAGMA.getDefaultState(), 3);
		world.setBlockState(new BlockPos(x + 18, y + 1, z + 13), ExtraPlanets_Fluids.MAGMA.getDefaultState(), 3);
		world.setBlockState(new BlockPos(x + 2, y + 1, z + 14), ExtraPlanets_Blocks.VOLCANIC_ROCK.getDefaultState(), 3);
		world.setBlockState(new BlockPos(x + 3, y + 1, z + 14), ExtraPlanets_Blocks.VOLCANIC_ROCK.getDefaultState(), 3);
		world.setBlockState(new BlockPos(x + 4, y + 1, z + 14), ExtraPlanets_Fluids.MAGMA.getDefaultState(), 3);
		world.setBlockState(new BlockPos(x + 5, y + 1, z + 14), ExtraPlanets_Fluids.MAGMA.getDefaultState(), 3);
		world.setBlockState(new BlockPos(x + 6, y + 1, z + 14), ExtraPlanets_Fluids.MAGMA.getDefaultState(), 3);
		world.setBlockState(new BlockPos(x + 7, y + 1, z + 14), ExtraPlanets_Fluids.MAGMA.getDefaultState(), 3);
		world.setBlockState(new BlockPos(x + 8, y + 1, z + 14), ExtraPlanets_Fluids.MAGMA.getDefaultState(), 3);
		world.setBlockState(new BlockPos(x + 9, y + 1, z + 14), ExtraPlanets_Fluids.MAGMA.getDefaultState(), 3);
		world.setBlockState(new BlockPos(x + 10, y + 1, z + 14), ExtraPlanets_Fluids.MAGMA.getDefaultState(), 3);
		world.setBlockState(new BlockPos(x + 11, y + 1, z + 14), ExtraPlanets_Fluids.MAGMA.getDefaultState(), 3);
		world.setBlockState(new BlockPos(x + 12, y + 1, z + 14), ExtraPlanets_Fluids.MAGMA.getDefaultState(), 3);
		world.setBlockState(new BlockPos(x + 13, y + 1, z + 14), ExtraPlanets_Fluids.MAGMA.getDefaultState(), 3);
		world.setBlockState(new BlockPos(x + 14, y + 1, z + 14), ExtraPlanets_Fluids.MAGMA.getDefaultState(), 3);
		world.setBlockState(new BlockPos(x + 15, y + 1, z + 14), ExtraPlanets_Fluids.MAGMA.getDefaultState(), 3);
		world.setBlockState(new BlockPos(x + 16, y + 1, z + 14), ExtraPlanets_Fluids.MAGMA.getDefaultState(), 3);
		world.setBlockState(new BlockPos(x + 17, y + 1, z + 14), ExtraPlanets_Fluids.MAGMA.getDefaultState(), 3);
		world.setBlockState(new BlockPos(x + 18, y + 1, z + 14), ExtraPlanets_Fluids.MAGMA.getDefaultState(), 3);
		world.setBlockState(new BlockPos(x + 3, y + 1, z + 15), ExtraPlanets_Blocks.VOLCANIC_ROCK.getDefaultState(), 3);
		world.setBlockState(new BlockPos(x + 4, y + 1, z + 15), ExtraPlanets_Fluids.MAGMA.getDefaultState(), 3);
		world.setBlockState(new BlockPos(x + 5, y + 1, z + 15), ExtraPlanets_Fluids.MAGMA.getDefaultState(), 3);
		world.setBlockState(new BlockPos(x + 6, y + 1, z + 15), ExtraPlanets_Fluids.MAGMA.getDefaultState(), 3);
		world.setBlockState(new BlockPos(x + 7, y + 1, z + 15), ExtraPlanets_Fluids.MAGMA.getDefaultState(), 3);
		world.setBlockState(new BlockPos(x + 8, y + 1, z + 15), ExtraPlanets_Fluids.MAGMA.getDefaultState(), 3);
		world.setBlockState(new BlockPos(x + 9, y + 1, z + 15), ExtraPlanets_Fluids.MAGMA.getDefaultState(), 3);
		world.setBlockState(new BlockPos(x + 10, y + 1, z + 15), ExtraPlanets_Fluids.MAGMA.getDefaultState(), 3);
		world.setBlockState(new BlockPos(x + 11, y + 1, z + 15), ExtraPlanets_Fluids.MAGMA.getDefaultState(), 3);
		world.setBlockState(new BlockPos(x + 12, y + 1, z + 15), ExtraPlanets_Fluids.MAGMA.getDefaultState(), 3);
		world.setBlockState(new BlockPos(x + 13, y + 1, z + 15), ExtraPlanets_Fluids.MAGMA.getDefaultState(), 3);
		world.setBlockState(new BlockPos(x + 14, y + 1, z + 15), ExtraPlanets_Fluids.MAGMA.getDefaultState(), 3);
		world.setBlockState(new BlockPos(x + 15, y + 1, z + 15), ExtraPlanets_Fluids.MAGMA.getDefaultState(), 3);
		world.setBlockState(new BlockPos(x + 16, y + 1, z + 15), ExtraPlanets_Fluids.MAGMA.getDefaultState(), 3);
		world.setBlockState(new BlockPos(x + 17, y + 1, z + 15), ExtraPlanets_Fluids.MAGMA.getDefaultState(), 3);
		world.setBlockState(new BlockPos(x + 18, y + 1, z + 15), ExtraPlanets_Fluids.MAGMA.getDefaultState(), 3);
		world.setBlockState(new BlockPos(x + 3, y + 1, z + 16), ExtraPlanets_Blocks.VOLCANIC_ROCK.getDefaultState(), 3);
		world.setBlockState(new BlockPos(x + 4, y + 1, z + 16), ExtraPlanets_Blocks.VOLCANIC_ROCK.getDefaultState(), 3);
		world.setBlockState(new BlockPos(x + 5, y + 1, z + 16), ExtraPlanets_Fluids.MAGMA.getDefaultState(), 3);
		world.setBlockState(new BlockPos(x + 6, y + 1, z + 16), ExtraPlanets_Fluids.MAGMA.getDefaultState(), 3);
		world.setBlockState(new BlockPos(x + 7, y + 1, z + 16), ExtraPlanets_Fluids.MAGMA.getDefaultState(), 3);
		world.setBlockState(new BlockPos(x + 8, y + 1, z + 16), ExtraPlanets_Fluids.MAGMA.getDefaultState(), 3);
		world.setBlockState(new BlockPos(x + 9, y + 1, z + 16), ExtraPlanets_Fluids.MAGMA.getDefaultState(), 3);
		world.setBlockState(new BlockPos(x + 10, y + 1, z + 16), ExtraPlanets_Fluids.MAGMA.getDefaultState(), 3);
		world.setBlockState(new BlockPos(x + 11, y + 1, z + 16), ExtraPlanets_Fluids.MAGMA.getDefaultState(), 3);
		world.setBlockState(new BlockPos(x + 12, y + 1, z + 16), ExtraPlanets_Fluids.MAGMA.getDefaultState(), 3);
		world.setBlockState(new BlockPos(x + 13, y + 1, z + 16), ExtraPlanets_Fluids.MAGMA.getDefaultState(), 3);
		world.setBlockState(new BlockPos(x + 14, y + 1, z + 16), ExtraPlanets_Fluids.MAGMA.getDefaultState(), 3);
		world.setBlockState(new BlockPos(x + 15, y + 1, z + 16), ExtraPlanets_Fluids.MAGMA.getDefaultState(), 3);
		world.setBlockState(new BlockPos(x + 16, y + 1, z + 16), ExtraPlanets_Fluids.MAGMA.getDefaultState(), 3);
		world.setBlockState(new BlockPos(x + 17, y + 1, z + 16), ExtraPlanets_Fluids.MAGMA.getDefaultState(), 3);
		world.setBlockState(new BlockPos(x + 18, y + 1, z + 16), ExtraPlanets_Blocks.VOLCANIC_ROCK.getDefaultState(), 3);
		world.setBlockState(new BlockPos(x + 4, y + 1, z + 17), ExtraPlanets_Blocks.VOLCANIC_ROCK.getDefaultState(), 3);
		world.setBlockState(new BlockPos(x + 5, y + 1, z + 17), ExtraPlanets_Fluids.MAGMA.getDefaultState(), 3);
		world.setBlockState(new BlockPos(x + 6, y + 1, z + 17), ExtraPlanets_Fluids.MAGMA.getDefaultState(), 3);
		world.setBlockState(new BlockPos(x + 7, y + 1, z + 17), ExtraPlanets_Fluids.MAGMA.getDefaultState(), 3);
		world.setBlockState(new BlockPos(x + 8, y + 1, z + 17), ExtraPlanets_Fluids.MAGMA.getDefaultState(), 3);
		world.setBlockState(new BlockPos(x + 9, y + 1, z + 17), ExtraPlanets_Fluids.MAGMA.getDefaultState(), 3);
		world.setBlockState(new BlockPos(x + 10, y + 1, z + 17), ExtraPlanets_Fluids.MAGMA.getDefaultState(), 3);
		world.setBlockState(new BlockPos(x + 11, y + 1, z + 17), ExtraPlanets_Fluids.MAGMA.getDefaultState(), 3);
		world.setBlockState(new BlockPos(x + 12, y + 1, z + 17), ExtraPlanets_Fluids.MAGMA.getDefaultState(), 3);
		world.setBlockState(new BlockPos(x + 13, y + 1, z + 17), ExtraPlanets_Fluids.MAGMA.getDefaultState(), 3);
		world.setBlockState(new BlockPos(x + 14, y + 1, z + 17), ExtraPlanets_Fluids.MAGMA.getDefaultState(), 3);
		world.setBlockState(new BlockPos(x + 15, y + 1, z + 17), ExtraPlanets_Fluids.MAGMA.getDefaultState(), 3);
		world.setBlockState(new BlockPos(x + 16, y + 1, z + 17), ExtraPlanets_Blocks.VOLCANIC_ROCK.getDefaultState(), 3);
		world.setBlockState(new BlockPos(x + 17, y + 1, z + 17), ExtraPlanets_Blocks.VOLCANIC_ROCK.getDefaultState(), 3);
		world.setBlockState(new BlockPos(x + 18, y + 1, z + 17), ExtraPlanets_Blocks.VOLCANIC_ROCK.getDefaultState(), 3);
		world.setBlockState(new BlockPos(x + 4, y + 1, z + 18), ExtraPlanets_Blocks.VOLCANIC_ROCK.getDefaultState(), 3);
		world.setBlockState(new BlockPos(x + 5, y + 1, z + 18), ExtraPlanets_Blocks.VOLCANIC_ROCK.getDefaultState(), 3);
		world.setBlockState(new BlockPos(x + 6, y + 1, z + 18), ExtraPlanets_Blocks.VOLCANIC_ROCK.getDefaultState(), 3);
		world.setBlockState(new BlockPos(x + 7, y + 1, z + 18), ExtraPlanets_Fluids.MAGMA.getDefaultState(), 3);
		world.setBlockState(new BlockPos(x + 8, y + 1, z + 18), ExtraPlanets_Fluids.MAGMA.getDefaultState(), 3);
		world.setBlockState(new BlockPos(x + 9, y + 1, z + 18), ExtraPlanets_Fluids.MAGMA.getDefaultState(), 3);
		world.setBlockState(new BlockPos(x + 10, y + 1, z + 18), ExtraPlanets_Fluids.MAGMA.getDefaultState(), 3);
		world.setBlockState(new BlockPos(x + 11, y + 1, z + 18), ExtraPlanets_Fluids.MAGMA.getDefaultState(), 3);
		world.setBlockState(new BlockPos(x + 12, y + 1, z + 18), ExtraPlanets_Fluids.MAGMA.getDefaultState(), 3);
		world.setBlockState(new BlockPos(x + 13, y + 1, z + 18), ExtraPlanets_Fluids.MAGMA.getDefaultState(), 3);
		world.setBlockState(new BlockPos(x + 14, y + 1, z + 18), ExtraPlanets_Blocks.VOLCANIC_ROCK.getDefaultState(), 3);
		world.setBlockState(new BlockPos(x + 15, y + 1, z + 18), ExtraPlanets_Blocks.VOLCANIC_ROCK.getDefaultState(), 3);
		world.setBlockState(new BlockPos(x + 16, y + 1, z + 18), ExtraPlanets_Blocks.VOLCANIC_ROCK.getDefaultState(), 3);
		world.setBlockState(new BlockPos(x + 17, y + 1, z + 18), ExtraPlanets_Fluids.MAGMA.getDefaultState(), 3);
		world.setBlockState(new BlockPos(x + 18, y + 1, z + 18), ExtraPlanets_Fluids.MAGMA.getDefaultState(), 3);
		world.setBlockState(new BlockPos(x + 8, y + 2, z + 6), ExtraPlanets_Blocks.VOLCANIC_ROCK.getDefaultState(), 3);
		world.setBlockState(new BlockPos(x + 9, y + 2, z + 6), ExtraPlanets_Blocks.VOLCANIC_ROCK.getDefaultState(), 3);
		world.setBlockState(new BlockPos(x + 10, y + 2, z + 6), ExtraPlanets_Blocks.VOLCANIC_ROCK.getDefaultState(), 3);
		world.setBlockState(new BlockPos(x + 14, y + 2, z + 6), ExtraPlanets_Fluids.MAGMA.getDefaultState(), 3);
		world.setBlockState(new BlockPos(x + 6, y + 2, z + 7), ExtraPlanets_Blocks.VOLCANIC_ROCK.getDefaultState(), 3);
		world.setBlockState(new BlockPos(x + 7, y + 2, z + 7), ExtraPlanets_Blocks.VOLCANIC_ROCK.getDefaultState(), 3);
		world.setBlockState(new BlockPos(x + 8, y + 2, z + 7), ExtraPlanets_Blocks.VOLCANIC_ROCK.getDefaultState(), 3);
		world.setBlockState(new BlockPos(x + 9, y + 2, z + 7), ExtraPlanets_Blocks.VOLCANIC_ROCK.getDefaultState(), 3);
		world.setBlockState(new BlockPos(x + 10, y + 2, z + 7), ExtraPlanets_Blocks.VOLCANIC_ROCK.getDefaultState(), 3);
		world.setBlockState(new BlockPos(x + 11, y + 2, z + 7), ExtraPlanets_Fluids.MAGMA.getDefaultState(), 3);
		world.setBlockState(new BlockPos(x + 14, y + 2, z + 7), ExtraPlanets_Fluids.MAGMA.getDefaultState(), 3);
		world.setBlockState(new BlockPos(x + 15, y + 2, z + 7), ExtraPlanets_Fluids.MAGMA.getDefaultState(), 3);
		world.setBlockState(new BlockPos(x + 4, y + 2, z + 8), ExtraPlanets_Blocks.VOLCANIC_ROCK.getDefaultState(), 3);
		world.setBlockState(new BlockPos(x + 5, y + 2, z + 8), ExtraPlanets_Blocks.VOLCANIC_ROCK.getDefaultState(), 3);
		world.setBlockState(new BlockPos(x + 6, y + 2, z + 8), ExtraPlanets_Blocks.VOLCANIC_ROCK.getDefaultState(), 3);
		world.setBlockState(new BlockPos(x + 7, y + 2, z + 8), ExtraPlanets_Blocks.VOLCANIC_ROCK.getDefaultState(), 3);
		world.setBlockState(new BlockPos(x + 8, y + 2, z + 8), ExtraPlanets_Blocks.VOLCANIC_ROCK.getDefaultState(), 3);
		world.setBlockState(new BlockPos(x + 9, y + 2, z + 8), ExtraPlanets_Fluids.MAGMA.getDefaultState(), 3);
		world.setBlockState(new BlockPos(x + 10, y + 2, z + 8), ExtraPlanets_Fluids.MAGMA.getDefaultState(), 3);
		world.setBlockState(new BlockPos(x + 11, y + 2, z + 8), ExtraPlanets_Blocks.VOLCANIC_ROCK.getDefaultState(), 3);
		world.setBlockState(new BlockPos(x + 12, y + 2, z + 8), ExtraPlanets_Fluids.MAGMA.getDefaultState(), 3);
		world.setBlockState(new BlockPos(x + 13, y + 2, z + 8), ExtraPlanets_Fluids.MAGMA.getDefaultState(), 3);
		world.setBlockState(new BlockPos(x + 14, y + 2, z + 8), ExtraPlanets_Fluids.MAGMA.getDefaultState(), 3);
		world.setBlockState(new BlockPos(x + 15, y + 2, z + 8), ExtraPlanets_Fluids.MAGMA.getDefaultState(), 3);
		world.setBlockState(new BlockPos(x + 16, y + 2, z + 8), ExtraPlanets_Fluids.MAGMA.getDefaultState(), 3);
		world.setBlockState(new BlockPos(x + 17, y + 2, z + 8), ExtraPlanets_Fluids.MAGMA.getDefaultState(), 3);
		world.setBlockState(new BlockPos(x + 3, y + 2, z + 9), ExtraPlanets_Blocks.VOLCANIC_ROCK.getDefaultState(), 3);
		world.setBlockState(new BlockPos(x + 4, y + 2, z + 9), ExtraPlanets_Blocks.VOLCANIC_ROCK.getDefaultState(), 3);
		world.setBlockState(new BlockPos(x + 5, y + 2, z + 9), ExtraPlanets_Blocks.VOLCANIC_ROCK.getDefaultState(), 3);
		world.setBlockState(new BlockPos(x + 6, y + 2, z + 9), ExtraPlanets_Blocks.VOLCANIC_ROCK.getDefaultState(), 3);
		world.setBlockState(new BlockPos(x + 7, y + 2, z + 9), ExtraPlanets_Fluids.MAGMA.getDefaultState(), 3);
		world.setBlockState(new BlockPos(x + 8, y + 2, z + 9), ExtraPlanets_Fluids.MAGMA.getDefaultState(), 3);
		world.setBlockState(new BlockPos(x + 9, y + 2, z + 9), ExtraPlanets_Fluids.MAGMA.getDefaultState(), 3);
		world.setBlockState(new BlockPos(x + 10, y + 2, z + 9), ExtraPlanets_Fluids.MAGMA.getDefaultState(), 3);
		world.setBlockState(new BlockPos(x + 11, y + 2, z + 9), ExtraPlanets_Blocks.VOLCANIC_ROCK.getDefaultState(), 3);
		world.setBlockState(new BlockPos(x + 12, y + 2, z + 9), ExtraPlanets_Blocks.VOLCANIC_ROCK.getDefaultState(), 3);
		world.setBlockState(new BlockPos(x + 13, y + 2, z + 9), ExtraPlanets_Fluids.MAGMA.getDefaultState(), 3);
		world.setBlockState(new BlockPos(x + 14, y + 2, z + 9), ExtraPlanets_Blocks.VOLCANIC_ROCK.getDefaultState(), 3);
		world.setBlockState(new BlockPos(x + 15, y + 2, z + 9), ExtraPlanets_Fluids.MAGMA.getDefaultState(), 3);
		world.setBlockState(new BlockPos(x + 16, y + 2, z + 9), ExtraPlanets_Fluids.MAGMA.getDefaultState(), 3);
		world.setBlockState(new BlockPos(x + 17, y + 2, z + 9), ExtraPlanets_Fluids.MAGMA.getDefaultState(), 3);
		world.setBlockState(new BlockPos(x + 18, y + 2, z + 9), ExtraPlanets_Fluids.MAGMA.getDefaultState(), 3);
		world.setBlockState(new BlockPos(x + 3, y + 2, z + 10), ExtraPlanets_Blocks.VOLCANIC_ROCK.getDefaultState(), 3);
		world.setBlockState(new BlockPos(x + 4, y + 2, z + 10), ExtraPlanets_Fluids.MAGMA.getDefaultState(), 3);
		world.setBlockState(new BlockPos(x + 5, y + 2, z + 10), ExtraPlanets_Fluids.MAGMA.getDefaultState(), 3);
		world.setBlockState(new BlockPos(x + 6, y + 2, z + 10), ExtraPlanets_Fluids.MAGMA.getDefaultState(), 3);
		world.setBlockState(new BlockPos(x + 7, y + 2, z + 10), ExtraPlanets_Fluids.MAGMA.getDefaultState(), 3);
		world.setBlockState(new BlockPos(x + 8, y + 2, z + 10), ExtraPlanets_Fluids.MAGMA.getDefaultState(), 3);
		world.setBlockState(new BlockPos(x + 9, y + 2, z + 10), ExtraPlanets_Fluids.MAGMA.getDefaultState(), 3);
		world.setBlockState(new BlockPos(x + 10, y + 2, z + 10), ExtraPlanets_Fluids.MAGMA.getDefaultState(), 3);
		world.setBlockState(new BlockPos(x + 11, y + 2, z + 10), ExtraPlanets_Fluids.MAGMA.getDefaultState(), 3);
		world.setBlockState(new BlockPos(x + 12, y + 2, z + 10), ExtraPlanets_Blocks.VOLCANIC_ROCK.getDefaultState(), 3);
		world.setBlockState(new BlockPos(x + 13, y + 2, z + 10), ExtraPlanets_Blocks.VOLCANIC_ROCK.getDefaultState(), 3);
		world.setBlockState(new BlockPos(x + 14, y + 2, z + 10), ExtraPlanets_Blocks.VOLCANIC_ROCK.getDefaultState(), 3);
		world.setBlockState(new BlockPos(x + 15, y + 2, z + 10), ExtraPlanets_Blocks.VOLCANIC_ROCK.getDefaultState(), 3);
		world.setBlockState(new BlockPos(x + 16, y + 2, z + 10), ExtraPlanets_Blocks.VOLCANIC_ROCK.getDefaultState(), 3);
		world.setBlockState(new BlockPos(x + 17, y + 2, z + 10), ExtraPlanets_Blocks.VOLCANIC_ROCK.getDefaultState(), 3);
		world.setBlockState(new BlockPos(x + 18, y + 2, z + 10), ExtraPlanets_Fluids.MAGMA.getDefaultState(), 3);
		world.setBlockState(new BlockPos(x + 3, y + 2, z + 11), ExtraPlanets_Blocks.VOLCANIC_ROCK.getDefaultState(), 3);
		world.setBlockState(new BlockPos(x + 4, y + 2, z + 11), ExtraPlanets_Fluids.MAGMA.getDefaultState(), 3);
		world.setBlockState(new BlockPos(x + 5, y + 2, z + 11), ExtraPlanets_Fluids.MAGMA.getDefaultState(), 3);
		world.setBlockState(new BlockPos(x + 6, y + 2, z + 11), ExtraPlanets_Fluids.MAGMA.getDefaultState(), 3);
		world.setBlockState(new BlockPos(x + 7, y + 2, z + 11), ExtraPlanets_Fluids.MAGMA.getDefaultState(), 3);
		world.setBlockState(new BlockPos(x + 8, y + 2, z + 11), ExtraPlanets_Fluids.MAGMA.getDefaultState(), 3);
		world.setBlockState(new BlockPos(x + 9, y + 2, z + 11), ExtraPlanets_Fluids.MAGMA.getDefaultState(), 3);
		world.setBlockState(new BlockPos(x + 10, y + 2, z + 11), ExtraPlanets_Fluids.MAGMA.getDefaultState(), 3);
		world.setBlockState(new BlockPos(x + 11, y + 2, z + 11), ExtraPlanets_Fluids.MAGMA.getDefaultState(), 3);
		world.setBlockState(new BlockPos(x + 12, y + 2, z + 11), ExtraPlanets_Fluids.MAGMA.getDefaultState(), 3);
		world.setBlockState(new BlockPos(x + 13, y + 2, z + 11), ExtraPlanets_Fluids.MAGMA.getDefaultState(), 3);
		world.setBlockState(new BlockPos(x + 14, y + 2, z + 11), ExtraPlanets_Blocks.VOLCANIC_ROCK.getDefaultState(), 3);
		world.setBlockState(new BlockPos(x + 15, y + 2, z + 11), ExtraPlanets_Blocks.VOLCANIC_ROCK.getDefaultState(), 3);
		world.setBlockState(new BlockPos(x + 16, y + 2, z + 11), ExtraPlanets_Blocks.VOLCANIC_ROCK.getDefaultState(), 3);
		world.setBlockState(new BlockPos(x + 17, y + 2, z + 11), ExtraPlanets_Blocks.VOLCANIC_ROCK.getDefaultState(), 3);
		world.setBlockState(new BlockPos(x + 18, y + 2, z + 11), ExtraPlanets_Fluids.MAGMA.getDefaultState(), 3);
		world.setBlockState(new BlockPos(x + 3, y + 2, z + 12), ExtraPlanets_Blocks.VOLCANIC_ROCK.getDefaultState(), 3);
		world.setBlockState(new BlockPos(x + 4, y + 2, z + 12), ExtraPlanets_Blocks.VOLCANIC_ROCK.getDefaultState(), 3);
		world.setBlockState(new BlockPos(x + 5, y + 2, z + 12), ExtraPlanets_Fluids.MAGMA.getDefaultState(), 3);
		world.setBlockState(new BlockPos(x + 6, y + 2, z + 12), ExtraPlanets_Fluids.MAGMA.getDefaultState(), 3);
		world.setBlockState(new BlockPos(x + 7, y + 2, z + 12), ExtraPlanets_Fluids.MAGMA.getDefaultState(), 3);
		world.setBlockState(new BlockPos(x + 8, y + 2, z + 12), ExtraPlanets_Fluids.MAGMA.getDefaultState(), 3);
		world.setBlockState(new BlockPos(x + 9, y + 2, z + 12), ExtraPlanets_Fluids.MAGMA.getDefaultState(), 3);
		world.setBlockState(new BlockPos(x + 10, y + 2, z + 12), ExtraPlanets_Fluids.MAGMA.getDefaultState(), 3);
		world.setBlockState(new BlockPos(x + 11, y + 2, z + 12), ExtraPlanets_Fluids.MAGMA.getDefaultState(), 3);
		world.setBlockState(new BlockPos(x + 12, y + 2, z + 12), ExtraPlanets_Fluids.MAGMA.getDefaultState(), 3);
		world.setBlockState(new BlockPos(x + 13, y + 2, z + 12), ExtraPlanets_Fluids.MAGMA.getDefaultState(), 3);
		world.setBlockState(new BlockPos(x + 14, y + 2, z + 12), ExtraPlanets_Fluids.MAGMA.getDefaultState(), 3);
		world.setBlockState(new BlockPos(x + 15, y + 2, z + 12), ExtraPlanets_Fluids.MAGMA.getDefaultState(), 3);
		world.setBlockState(new BlockPos(x + 16, y + 2, z + 12), ExtraPlanets_Fluids.MAGMA.getDefaultState(), 3);
		world.setBlockState(new BlockPos(x + 17, y + 2, z + 12), ExtraPlanets_Fluids.MAGMA.getDefaultState(), 3);
		world.setBlockState(new BlockPos(x + 18, y + 2, z + 12), ExtraPlanets_Blocks.VOLCANIC_ROCK.getDefaultState(), 3);
		world.setBlockState(new BlockPos(x + 3, y + 2, z + 13), ExtraPlanets_Blocks.VOLCANIC_ROCK.getDefaultState(), 3);
		world.setBlockState(new BlockPos(x + 4, y + 2, z + 13), ExtraPlanets_Blocks.VOLCANIC_ROCK.getDefaultState(), 3);
		world.setBlockState(new BlockPos(x + 5, y + 2, z + 13), ExtraPlanets_Fluids.MAGMA.getDefaultState(), 3);
		world.setBlockState(new BlockPos(x + 6, y + 2, z + 13), ExtraPlanets_Fluids.MAGMA.getDefaultState(), 3);
		world.setBlockState(new BlockPos(x + 7, y + 2, z + 13), ExtraPlanets_Fluids.MAGMA.getDefaultState(), 3);
		world.setBlockState(new BlockPos(x + 8, y + 2, z + 13), ExtraPlanets_Fluids.MAGMA.getDefaultState(), 3);
		world.setBlockState(new BlockPos(x + 9, y + 2, z + 13), ExtraPlanets_Fluids.MAGMA.getDefaultState(), 3);
		world.setBlockState(new BlockPos(x + 10, y + 2, z + 13), ExtraPlanets_Fluids.MAGMA.getDefaultState(), 3);
		world.setBlockState(new BlockPos(x + 11, y + 2, z + 13), ExtraPlanets_Fluids.MAGMA.getDefaultState(), 3);
		world.setBlockState(new BlockPos(x + 12, y + 2, z + 13), ExtraPlanets_Fluids.MAGMA.getDefaultState(), 3);
		world.setBlockState(new BlockPos(x + 13, y + 2, z + 13), ExtraPlanets_Fluids.MAGMA.getDefaultState(), 3);
		world.setBlockState(new BlockPos(x + 14, y + 2, z + 13), ExtraPlanets_Fluids.MAGMA.getDefaultState(), 3);
		world.setBlockState(new BlockPos(x + 15, y + 2, z + 13), ExtraPlanets_Fluids.MAGMA.getDefaultState(), 3);
		world.setBlockState(new BlockPos(x + 16, y + 2, z + 13), ExtraPlanets_Fluids.MAGMA.getDefaultState(), 3);
		world.setBlockState(new BlockPos(x + 17, y + 2, z + 13), ExtraPlanets_Fluids.MAGMA.getDefaultState(), 3);
		world.setBlockState(new BlockPos(x + 4, y + 2, z + 14), ExtraPlanets_Blocks.VOLCANIC_ROCK.getDefaultState(), 3);
		world.setBlockState(new BlockPos(x + 5, y + 2, z + 14), ExtraPlanets_Fluids.MAGMA.getDefaultState(), 3);
		world.setBlockState(new BlockPos(x + 6, y + 2, z + 14), ExtraPlanets_Fluids.MAGMA.getDefaultState(), 3);
		world.setBlockState(new BlockPos(x + 7, y + 2, z + 14), ExtraPlanets_Fluids.MAGMA.getDefaultState(), 3);
		world.setBlockState(new BlockPos(x + 8, y + 2, z + 14), ExtraPlanets_Fluids.MAGMA.getDefaultState(), 3);
		world.setBlockState(new BlockPos(x + 9, y + 2, z + 14), ExtraPlanets_Fluids.MAGMA.getDefaultState(), 3);
		world.setBlockState(new BlockPos(x + 10, y + 2, z + 14), ExtraPlanets_Fluids.MAGMA.getDefaultState(), 3);
		world.setBlockState(new BlockPos(x + 11, y + 2, z + 14), ExtraPlanets_Fluids.MAGMA.getDefaultState(), 3);
		world.setBlockState(new BlockPos(x + 12, y + 2, z + 14), ExtraPlanets_Fluids.MAGMA.getDefaultState(), 3);
		world.setBlockState(new BlockPos(x + 13, y + 2, z + 14), ExtraPlanets_Fluids.MAGMA.getDefaultState(), 3);
		world.setBlockState(new BlockPos(x + 14, y + 2, z + 14), ExtraPlanets_Fluids.MAGMA.getDefaultState(), 3);
		world.setBlockState(new BlockPos(x + 15, y + 2, z + 14), ExtraPlanets_Fluids.MAGMA.getDefaultState(), 3);
		world.setBlockState(new BlockPos(x + 16, y + 2, z + 14), ExtraPlanets_Fluids.MAGMA.getDefaultState(), 3);
		world.setBlockState(new BlockPos(x + 17, y + 2, z + 14), ExtraPlanets_Fluids.MAGMA.getDefaultState(), 3);
		world.setBlockState(new BlockPos(x + 18, y + 2, z + 14), ExtraPlanets_Fluids.MAGMA.getDefaultState(), 3);
		world.setBlockState(new BlockPos(x + 4, y + 2, z + 15), ExtraPlanets_Blocks.VOLCANIC_ROCK.getDefaultState(), 3);
		world.setBlockState(new BlockPos(x + 5, y + 2, z + 15), ExtraPlanets_Blocks.VOLCANIC_ROCK.getDefaultState(), 3);
		world.setBlockState(new BlockPos(x + 6, y + 2, z + 15), ExtraPlanets_Fluids.MAGMA.getDefaultState(), 3);
		world.setBlockState(new BlockPos(x + 7, y + 2, z + 15), ExtraPlanets_Fluids.MAGMA.getDefaultState(), 3);
		world.setBlockState(new BlockPos(x + 8, y + 2, z + 15), ExtraPlanets_Fluids.MAGMA.getDefaultState(), 3);
		world.setBlockState(new BlockPos(x + 9, y + 2, z + 15), ExtraPlanets_Fluids.MAGMA.getDefaultState(), 3);
		world.setBlockState(new BlockPos(x + 10, y + 2, z + 15), ExtraPlanets_Fluids.MAGMA.getDefaultState(), 3);
		world.setBlockState(new BlockPos(x + 11, y + 2, z + 15), ExtraPlanets_Fluids.MAGMA.getDefaultState(), 3);
		world.setBlockState(new BlockPos(x + 12, y + 2, z + 15), ExtraPlanets_Fluids.MAGMA.getDefaultState(), 3);
		world.setBlockState(new BlockPos(x + 13, y + 2, z + 15), ExtraPlanets_Fluids.MAGMA.getDefaultState(), 3);
		world.setBlockState(new BlockPos(x + 14, y + 2, z + 15), ExtraPlanets_Fluids.MAGMA.getDefaultState(), 3);
		world.setBlockState(new BlockPos(x + 15, y + 2, z + 15), ExtraPlanets_Fluids.MAGMA.getDefaultState(), 3);
		world.setBlockState(new BlockPos(x + 16, y + 2, z + 15), ExtraPlanets_Fluids.MAGMA.getDefaultState(), 3);
		world.setBlockState(new BlockPos(x + 17, y + 2, z + 15), ExtraPlanets_Fluids.MAGMA.getDefaultState(), 3);
		world.setBlockState(new BlockPos(x + 18, y + 2, z + 15), ExtraPlanets_Fluids.MAGMA.getDefaultState(), 3);
		world.setBlockState(new BlockPos(x + 5, y + 2, z + 16), ExtraPlanets_Blocks.VOLCANIC_ROCK.getDefaultState(), 3);
		world.setBlockState(new BlockPos(x + 6, y + 2, z + 16), ExtraPlanets_Fluids.MAGMA.getDefaultState(), 3);
		world.setBlockState(new BlockPos(x + 7, y + 2, z + 16), ExtraPlanets_Fluids.MAGMA.getDefaultState(), 3);
		world.setBlockState(new BlockPos(x + 8, y + 2, z + 16), ExtraPlanets_Fluids.MAGMA.getDefaultState(), 3);
		world.setBlockState(new BlockPos(x + 9, y + 2, z + 16), ExtraPlanets_Fluids.MAGMA.getDefaultState(), 3);
		world.setBlockState(new BlockPos(x + 10, y + 2, z + 16), ExtraPlanets_Fluids.MAGMA.getDefaultState(), 3);
		world.setBlockState(new BlockPos(x + 11, y + 2, z + 16), ExtraPlanets_Fluids.MAGMA.getDefaultState(), 3);
		world.setBlockState(new BlockPos(x + 12, y + 2, z + 16), ExtraPlanets_Fluids.MAGMA.getDefaultState(), 3);
		world.setBlockState(new BlockPos(x + 13, y + 2, z + 16), ExtraPlanets_Fluids.MAGMA.getDefaultState(), 3);
		world.setBlockState(new BlockPos(x + 14, y + 2, z + 16), ExtraPlanets_Fluids.MAGMA.getDefaultState(), 3);
		world.setBlockState(new BlockPos(x + 15, y + 2, z + 16), ExtraPlanets_Fluids.MAGMA.getDefaultState(), 3);
		world.setBlockState(new BlockPos(x + 16, y + 2, z + 16), ExtraPlanets_Fluids.MAGMA.getDefaultState(), 3);
		world.setBlockState(new BlockPos(x + 17, y + 2, z + 16), ExtraPlanets_Fluids.MAGMA.getDefaultState(), 3);
		world.setBlockState(new BlockPos(x + 18, y + 2, z + 16), ExtraPlanets_Blocks.VOLCANIC_ROCK.getDefaultState(), 3);
		world.setBlockState(new BlockPos(x + 5, y + 2, z + 17), ExtraPlanets_Blocks.VOLCANIC_ROCK.getDefaultState(), 3);
		world.setBlockState(new BlockPos(x + 6, y + 2, z + 17), ExtraPlanets_Blocks.VOLCANIC_ROCK.getDefaultState(), 3);
		world.setBlockState(new BlockPos(x + 7, y + 2, z + 17), ExtraPlanets_Blocks.VOLCANIC_ROCK.getDefaultState(), 3);
		world.setBlockState(new BlockPos(x + 8, y + 2, z + 17), ExtraPlanets_Fluids.MAGMA.getDefaultState(), 3);
		world.setBlockState(new BlockPos(x + 9, y + 2, z + 17), ExtraPlanets_Fluids.MAGMA.getDefaultState(), 3);
		world.setBlockState(new BlockPos(x + 10, y + 2, z + 17), ExtraPlanets_Fluids.MAGMA.getDefaultState(), 3);
		world.setBlockState(new BlockPos(x + 11, y + 2, z + 17), ExtraPlanets_Fluids.MAGMA.getDefaultState(), 3);
		world.setBlockState(new BlockPos(x + 12, y + 2, z + 17), ExtraPlanets_Fluids.MAGMA.getDefaultState(), 3);
		world.setBlockState(new BlockPos(x + 13, y + 2, z + 17), ExtraPlanets_Fluids.MAGMA.getDefaultState(), 3);
		world.setBlockState(new BlockPos(x + 14, y + 2, z + 17), ExtraPlanets_Fluids.MAGMA.getDefaultState(), 3);
		world.setBlockState(new BlockPos(x + 15, y + 2, z + 17), ExtraPlanets_Fluids.MAGMA.getDefaultState(), 3);
		world.setBlockState(new BlockPos(x + 16, y + 2, z + 17), ExtraPlanets_Fluids.MAGMA.getDefaultState(), 3);
		world.setBlockState(new BlockPos(x + 17, y + 2, z + 17), ExtraPlanets_Fluids.MAGMA.getDefaultState(), 3);
		world.setBlockState(new BlockPos(x + 18, y + 2, z + 17), ExtraPlanets_Blocks.VOLCANIC_ROCK.getDefaultState(), 3);
		world.setBlockState(new BlockPos(x + 6, y + 2, z + 18), ExtraPlanets_Fluids.MAGMA.getDefaultState(), 3);
		world.setBlockState(new BlockPos(x + 7, y + 2, z + 18), ExtraPlanets_Blocks.VOLCANIC_ROCK.getDefaultState(), 3);
		world.setBlockState(new BlockPos(x + 8, y + 2, z + 18), ExtraPlanets_Blocks.VOLCANIC_ROCK.getDefaultState(), 3);
		world.setBlockState(new BlockPos(x + 9, y + 2, z + 18), ExtraPlanets_Blocks.VOLCANIC_ROCK.getDefaultState(), 3);
		world.setBlockState(new BlockPos(x + 10, y + 2, z + 18), ExtraPlanets_Blocks.VOLCANIC_ROCK.getDefaultState(), 3);
		world.setBlockState(new BlockPos(x + 11, y + 2, z + 18), ExtraPlanets_Blocks.VOLCANIC_ROCK.getDefaultState(), 3);
		world.setBlockState(new BlockPos(x + 12, y + 2, z + 18), ExtraPlanets_Fluids.MAGMA.getDefaultState(), 3);
		world.setBlockState(new BlockPos(x + 13, y + 2, z + 18), ExtraPlanets_Fluids.MAGMA.getDefaultState(), 3);
		world.setBlockState(new BlockPos(x + 14, y + 2, z + 18), ExtraPlanets_Fluids.MAGMA.getDefaultState(), 3);
		world.setBlockState(new BlockPos(x + 15, y + 2, z + 18), ExtraPlanets_Fluids.MAGMA.getDefaultState(), 3);
		world.setBlockState(new BlockPos(x + 16, y + 2, z + 18), ExtraPlanets_Fluids.MAGMA.getDefaultState(), 3);
		world.setBlockState(new BlockPos(x + 17, y + 2, z + 18), ExtraPlanets_Fluids.MAGMA.getDefaultState(), 3);
		world.setBlockState(new BlockPos(x + 18, y + 2, z + 18), ExtraPlanets_Blocks.VOLCANIC_ROCK.getDefaultState(), 3);
		world.setBlockState(new BlockPos(x + 9, y + 3, z + 7), ExtraPlanets_Blocks.VOLCANIC_ROCK.getDefaultState(), 3);
		world.setBlockState(new BlockPos(x + 11, y + 3, z + 7), ExtraPlanets_Fluids.MAGMA.getDefaultState(), 3);
		world.setBlockState(new BlockPos(x + 5, y + 3, z + 8), ExtraPlanets_Blocks.VOLCANIC_ROCK.getDefaultState(), 3);
		world.setBlockState(new BlockPos(x + 6, y + 3, z + 8), ExtraPlanets_Blocks.VOLCANIC_ROCK.getDefaultState(), 3);
		world.setBlockState(new BlockPos(x + 7, y + 3, z + 8), ExtraPlanets_Blocks.VOLCANIC_ROCK.getDefaultState(), 3);
		world.setBlockState(new BlockPos(x + 8, y + 3, z + 8), ExtraPlanets_Blocks.VOLCANIC_ROCK.getDefaultState(), 3);
		world.setBlockState(new BlockPos(x + 9, y + 3, z + 8), ExtraPlanets_Blocks.VOLCANIC_ROCK.getDefaultState(), 3);
		world.setBlockState(new BlockPos(x + 10, y + 3, z + 8), ExtraPlanets_Blocks.VOLCANIC_ROCK.getDefaultState(), 3);
		world.setBlockState(new BlockPos(x + 11, y + 3, z + 8), ExtraPlanets_Fluids.MAGMA.getDefaultState(), 3);
		world.setBlockState(new BlockPos(x + 12, y + 3, z + 8), ExtraPlanets_Fluids.MAGMA.getDefaultState(), 3);
		world.setBlockState(new BlockPos(x + 14, y + 3, z + 8), ExtraPlanets_Fluids.MAGMA.getDefaultState(), 3);
		world.setBlockState(new BlockPos(x + 4, y + 3, z + 9), ExtraPlanets_Blocks.VOLCANIC_ROCK.getDefaultState(), 3);
		world.setBlockState(new BlockPos(x + 5, y + 3, z + 9), ExtraPlanets_Blocks.VOLCANIC_ROCK.getDefaultState(), 3);
		world.setBlockState(new BlockPos(x + 6, y + 3, z + 9), ExtraPlanets_Blocks.VOLCANIC_ROCK.getDefaultState(), 3);
		world.setBlockState(new BlockPos(x + 7, y + 3, z + 9), ExtraPlanets_Blocks.VOLCANIC_ROCK.getDefaultState(), 3);
		world.setBlockState(new BlockPos(x + 8, y + 3, z + 9), ExtraPlanets_Fluids.MAGMA.getDefaultState(), 3);
		world.setBlockState(new BlockPos(x + 9, y + 3, z + 9), ExtraPlanets_Fluids.MAGMA.getDefaultState(), 3);
		world.setBlockState(new BlockPos(x + 10, y + 3, z + 9), ExtraPlanets_Blocks.VOLCANIC_ROCK.getDefaultState(), 3);
		world.setBlockState(new BlockPos(x + 11, y + 3, z + 9), ExtraPlanets_Fluids.MAGMA.getDefaultState(), 3);
		world.setBlockState(new BlockPos(x + 12, y + 3, z + 9), ExtraPlanets_Fluids.MAGMA.getDefaultState(), 3);
		world.setBlockState(new BlockPos(x + 13, y + 3, z + 9), ExtraPlanets_Fluids.MAGMA.getDefaultState(), 3);
		world.setBlockState(new BlockPos(x + 14, y + 3, z + 9), ExtraPlanets_Fluids.MAGMA.getDefaultState(), 3);
		world.setBlockState(new BlockPos(x + 15, y + 3, z + 9), ExtraPlanets_Fluids.MAGMA.getDefaultState(), 3);
		world.setBlockState(new BlockPos(x + 16, y + 3, z + 9), ExtraPlanets_Fluids.MAGMA.getDefaultState(), 3);
		world.setBlockState(new BlockPos(x + 17, y + 3, z + 9), ExtraPlanets_Fluids.MAGMA.getDefaultState(), 3);
		world.setBlockState(new BlockPos(x + 4, y + 3, z + 10), ExtraPlanets_Blocks.VOLCANIC_ROCK.getDefaultState(), 3);
		world.setBlockState(new BlockPos(x + 5, y + 3, z + 10), ExtraPlanets_Blocks.VOLCANIC_ROCK.getDefaultState(), 3);
		world.setBlockState(new BlockPos(x + 6, y + 3, z + 10), ExtraPlanets_Fluids.MAGMA.getDefaultState(), 3);
		world.setBlockState(new BlockPos(x + 7, y + 3, z + 10), ExtraPlanets_Fluids.MAGMA.getDefaultState(), 3);
		world.setBlockState(new BlockPos(x + 8, y + 3, z + 10), ExtraPlanets_Fluids.MAGMA.getDefaultState(), 3);
		world.setBlockState(new BlockPos(x + 9, y + 3, z + 10), ExtraPlanets_Fluids.MAGMA.getDefaultState(), 3);
		world.setBlockState(new BlockPos(x + 10, y + 3, z + 10), ExtraPlanets_Blocks.VOLCANIC_ROCK.getDefaultState(), 3);
		world.setBlockState(new BlockPos(x + 11, y + 3, z + 10), ExtraPlanets_Blocks.VOLCANIC_ROCK.getDefaultState(), 3);
		world.setBlockState(new BlockPos(x + 12, y + 3, z + 10), ExtraPlanets_Fluids.MAGMA.getDefaultState(), 3);
		world.setBlockState(new BlockPos(x + 13, y + 3, z + 10), ExtraPlanets_Fluids.MAGMA.getDefaultState(), 3);
		world.setBlockState(new BlockPos(x + 14, y + 3, z + 10), ExtraPlanets_Fluids.MAGMA.getDefaultState(), 3);
		world.setBlockState(new BlockPos(x + 15, y + 3, z + 10), ExtraPlanets_Fluids.MAGMA.getDefaultState(), 3);
		world.setBlockState(new BlockPos(x + 16, y + 3, z + 10), ExtraPlanets_Fluids.MAGMA.getDefaultState(), 3);
		world.setBlockState(new BlockPos(x + 17, y + 3, z + 10), ExtraPlanets_Fluids.MAGMA.getDefaultState(), 3);
		world.setBlockState(new BlockPos(x + 18, y + 3, z + 10), ExtraPlanets_Fluids.MAGMA.getDefaultState(), 3);
		world.setBlockState(new BlockPos(x + 4, y + 3, z + 11), ExtraPlanets_Blocks.VOLCANIC_ROCK.getDefaultState(), 3);
		world.setBlockState(new BlockPos(x + 5, y + 3, z + 11), ExtraPlanets_Blocks.VOLCANIC_ROCK.getDefaultState(), 3);
		world.setBlockState(new BlockPos(x + 6, y + 3, z + 11), ExtraPlanets_Fluids.MAGMA.getDefaultState(), 3);
		world.setBlockState(new BlockPos(x + 7, y + 3, z + 11), ExtraPlanets_Fluids.MAGMA.getDefaultState(), 3);
		world.setBlockState(new BlockPos(x + 8, y + 3, z + 11), ExtraPlanets_Fluids.MAGMA.getDefaultState(), 3);
		world.setBlockState(new BlockPos(x + 9, y + 3, z + 11), ExtraPlanets_Fluids.MAGMA.getDefaultState(), 3);
		world.setBlockState(new BlockPos(x + 10, y + 3, z + 11), ExtraPlanets_Fluids.MAGMA.getDefaultState(), 3);
		world.setBlockState(new BlockPos(x + 11, y + 3, z + 11), ExtraPlanets_Blocks.VOLCANIC_ROCK.getDefaultState(), 3);
		world.setBlockState(new BlockPos(x + 12, y + 3, z + 11), ExtraPlanets_Blocks.VOLCANIC_ROCK.getDefaultState(), 3);
		world.setBlockState(new BlockPos(x + 13, y + 3, z + 11), ExtraPlanets_Blocks.VOLCANIC_ROCK.getDefaultState(), 3);
		world.setBlockState(new BlockPos(x + 14, y + 3, z + 11), ExtraPlanets_Fluids.MAGMA.getDefaultState(), 3);
		world.setBlockState(new BlockPos(x + 15, y + 3, z + 11), ExtraPlanets_Blocks.VOLCANIC_ROCK.getDefaultState(), 3);
		world.setBlockState(new BlockPos(x + 16, y + 3, z + 11), ExtraPlanets_Fluids.MAGMA.getDefaultState(), 3);
		world.setBlockState(new BlockPos(x + 17, y + 3, z + 11), ExtraPlanets_Fluids.MAGMA.getDefaultState(), 3);
		world.setBlockState(new BlockPos(x + 18, y + 3, z + 11), ExtraPlanets_Fluids.MAGMA.getDefaultState(), 3);
		world.setBlockState(new BlockPos(x + 5, y + 3, z + 12), ExtraPlanets_Blocks.VOLCANIC_ROCK.getDefaultState(), 3);
		world.setBlockState(new BlockPos(x + 6, y + 3, z + 12), ExtraPlanets_Fluids.MAGMA.getDefaultState(), 3);
		world.setBlockState(new BlockPos(x + 7, y + 3, z + 12), ExtraPlanets_Fluids.MAGMA.getDefaultState(), 3);
		world.setBlockState(new BlockPos(x + 8, y + 3, z + 12), ExtraPlanets_Fluids.MAGMA.getDefaultState(), 3);
		world.setBlockState(new BlockPos(x + 9, y + 3, z + 12), ExtraPlanets_Fluids.MAGMA.getDefaultState(), 3);
		world.setBlockState(new BlockPos(x + 10, y + 3, z + 12), ExtraPlanets_Fluids.MAGMA.getDefaultState(), 3);
		world.setBlockState(new BlockPos(x + 11, y + 3, z + 12), ExtraPlanets_Fluids.MAGMA.getDefaultState(), 3);
		world.setBlockState(new BlockPos(x + 12, y + 3, z + 12), ExtraPlanets_Blocks.VOLCANIC_ROCK.getDefaultState(), 3);
		world.setBlockState(new BlockPos(x + 13, y + 3, z + 12), ExtraPlanets_Blocks.VOLCANIC_ROCK.getDefaultState(), 3);
		world.setBlockState(new BlockPos(x + 14, y + 3, z + 12), ExtraPlanets_Blocks.VOLCANIC_ROCK.getDefaultState(), 3);
		world.setBlockState(new BlockPos(x + 15, y + 3, z + 12), ExtraPlanets_Blocks.VOLCANIC_ROCK.getDefaultState(), 3);
		world.setBlockState(new BlockPos(x + 16, y + 3, z + 12), ExtraPlanets_Blocks.VOLCANIC_ROCK.getDefaultState(), 3);
		world.setBlockState(new BlockPos(x + 17, y + 3, z + 12), ExtraPlanets_Blocks.VOLCANIC_ROCK.getDefaultState(), 3);
		world.setBlockState(new BlockPos(x + 18, y + 3, z + 12), ExtraPlanets_Fluids.MAGMA.getDefaultState(), 3);
		world.setBlockState(new BlockPos(x + 5, y + 3, z + 13), ExtraPlanets_Blocks.VOLCANIC_ROCK.getDefaultState(), 3);
		world.setBlockState(new BlockPos(x + 6, y + 3, z + 13), ExtraPlanets_Blocks.VOLCANIC_ROCK.getDefaultState(), 3);
		world.setBlockState(new BlockPos(x + 7, y + 3, z + 13), ExtraPlanets_Fluids.MAGMA.getDefaultState(), 3);
		world.setBlockState(new BlockPos(x + 8, y + 3, z + 13), ExtraPlanets_Fluids.MAGMA.getDefaultState(), 3);
		world.setBlockState(new BlockPos(x + 9, y + 3, z + 13), ExtraPlanets_Fluids.MAGMA.getDefaultState(), 3);
		world.setBlockState(new BlockPos(x + 10, y + 3, z + 13), ExtraPlanets_Fluids.MAGMA.getDefaultState(), 3);
		world.setBlockState(new BlockPos(x + 11, y + 3, z + 13), ExtraPlanets_Fluids.MAGMA.getDefaultState(), 3);
		world.setBlockState(new BlockPos(x + 12, y + 3, z + 13), ExtraPlanets_Fluids.MAGMA.getDefaultState(), 3);
		world.setBlockState(new BlockPos(x + 13, y + 3, z + 13), ExtraPlanets_Blocks.VOLCANIC_ROCK.getDefaultState(), 3);
		world.setBlockState(new BlockPos(x + 14, y + 3, z + 13), ExtraPlanets_Blocks.VOLCANIC_ROCK.getDefaultState(), 3);
		world.setBlockState(new BlockPos(x + 15, y + 3, z + 13), ExtraPlanets_Blocks.VOLCANIC_ROCK.getDefaultState(), 3);
		world.setBlockState(new BlockPos(x + 16, y + 3, z + 13), ExtraPlanets_Blocks.VOLCANIC_ROCK.getDefaultState(), 3);
		world.setBlockState(new BlockPos(x + 17, y + 3, z + 13), ExtraPlanets_Blocks.VOLCANIC_ROCK.getDefaultState(), 3);
		world.setBlockState(new BlockPos(x + 18, y + 3, z + 13), ExtraPlanets_Blocks.VOLCANIC_ROCK.getDefaultState(), 3);
		world.setBlockState(new BlockPos(x + 5, y + 3, z + 14), ExtraPlanets_Blocks.VOLCANIC_ROCK.getDefaultState(), 3);
		world.setBlockState(new BlockPos(x + 6, y + 3, z + 14), ExtraPlanets_Blocks.VOLCANIC_ROCK.getDefaultState(), 3);
		world.setBlockState(new BlockPos(x + 7, y + 3, z + 14), ExtraPlanets_Fluids.MAGMA.getDefaultState(), 3);
		world.setBlockState(new BlockPos(x + 8, y + 3, z + 14), ExtraPlanets_Fluids.MAGMA.getDefaultState(), 3);
		world.setBlockState(new BlockPos(x + 9, y + 3, z + 14), ExtraPlanets_Fluids.MAGMA.getDefaultState(), 3);
		world.setBlockState(new BlockPos(x + 10, y + 3, z + 14), ExtraPlanets_Fluids.MAGMA.getDefaultState(), 3);
		world.setBlockState(new BlockPos(x + 11, y + 3, z + 14), ExtraPlanets_Fluids.MAGMA.getDefaultState(), 3);
		world.setBlockState(new BlockPos(x + 12, y + 3, z + 14), ExtraPlanets_Fluids.MAGMA.getDefaultState(), 3);
		world.setBlockState(new BlockPos(x + 13, y + 3, z + 14), ExtraPlanets_Blocks.VOLCANIC_ROCK.getDefaultState(), 3);
		world.setBlockState(new BlockPos(x + 14, y + 3, z + 14), ExtraPlanets_Blocks.VOLCANIC_ROCK.getDefaultState(), 3);
		world.setBlockState(new BlockPos(x + 15, y + 3, z + 14), ExtraPlanets_Blocks.VOLCANIC_ROCK.getDefaultState(), 3);
		world.setBlockState(new BlockPos(x + 16, y + 3, z + 14), ExtraPlanets_Fluids.MAGMA.getDefaultState(), 3);
		world.setBlockState(new BlockPos(x + 17, y + 3, z + 14), ExtraPlanets_Blocks.VOLCANIC_ROCK.getDefaultState(), 3);
		world.setBlockState(new BlockPos(x + 18, y + 3, z + 14), ExtraPlanets_Blocks.VOLCANIC_ROCK.getDefaultState(), 3);
		world.setBlockState(new BlockPos(x + 5, y + 3, z + 15), ExtraPlanets_Blocks.VOLCANIC_ROCK.getDefaultState(), 3);
		world.setBlockState(new BlockPos(x + 6, y + 3, z + 15), ExtraPlanets_Blocks.VOLCANIC_ROCK.getDefaultState(), 3);
		world.setBlockState(new BlockPos(x + 7, y + 3, z + 15), ExtraPlanets_Blocks.VOLCANIC_ROCK.getDefaultState(), 3);
		world.setBlockState(new BlockPos(x + 8, y + 3, z + 15), ExtraPlanets_Fluids.MAGMA.getDefaultState(), 3);
		world.setBlockState(new BlockPos(x + 9, y + 3, z + 15), ExtraPlanets_Fluids.MAGMA.getDefaultState(), 3);
		world.setBlockState(new BlockPos(x + 10, y + 3, z + 15), ExtraPlanets_Fluids.MAGMA.getDefaultState(), 3);
		world.setBlockState(new BlockPos(x + 11, y + 3, z + 15), ExtraPlanets_Fluids.MAGMA.getDefaultState(), 3);
		world.setBlockState(new BlockPos(x + 12, y + 3, z + 15), ExtraPlanets_Fluids.MAGMA.getDefaultState(), 3);
		world.setBlockState(new BlockPos(x + 13, y + 3, z + 15), ExtraPlanets_Blocks.VOLCANIC_ROCK.getDefaultState(), 3);
		world.setBlockState(new BlockPos(x + 14, y + 3, z + 15), ExtraPlanets_Blocks.VOLCANIC_ROCK.getDefaultState(), 3);
		world.setBlockState(new BlockPos(x + 15, y + 3, z + 15), ExtraPlanets_Blocks.VOLCANIC_ROCK.getDefaultState(), 3);
		world.setBlockState(new BlockPos(x + 16, y + 3, z + 15), ExtraPlanets_Fluids.MAGMA.getDefaultState(), 3);
		world.setBlockState(new BlockPos(x + 17, y + 3, z + 15), ExtraPlanets_Fluids.MAGMA.getDefaultState(), 3);
		world.setBlockState(new BlockPos(x + 18, y + 3, z + 15), ExtraPlanets_Blocks.VOLCANIC_ROCK.getDefaultState(), 3);
		world.setBlockState(new BlockPos(x + 6, y + 3, z + 16), ExtraPlanets_Blocks.VOLCANIC_ROCK.getDefaultState(), 3);
		world.setBlockState(new BlockPos(x + 7, y + 3, z + 16), ExtraPlanets_Blocks.VOLCANIC_ROCK.getDefaultState(), 3);
		world.setBlockState(new BlockPos(x + 8, y + 3, z + 16), ExtraPlanets_Blocks.VOLCANIC_ROCK.getDefaultState(), 3);
		world.setBlockState(new BlockPos(x + 9, y + 3, z + 16), ExtraPlanets_Fluids.MAGMA.getDefaultState(), 3);
		world.setBlockState(new BlockPos(x + 10, y + 3, z + 16), ExtraPlanets_Fluids.MAGMA.getDefaultState(), 3);
		world.setBlockState(new BlockPos(x + 11, y + 3, z + 16), ExtraPlanets_Fluids.MAGMA.getDefaultState(), 3);
		world.setBlockState(new BlockPos(x + 12, y + 3, z + 16), ExtraPlanets_Fluids.MAGMA.getDefaultState(), 3);
		world.setBlockState(new BlockPos(x + 13, y + 3, z + 16), ExtraPlanets_Fluids.MAGMA.getDefaultState(), 3);
		world.setBlockState(new BlockPos(x + 14, y + 3, z + 16), ExtraPlanets_Fluids.MAGMA.getDefaultState(), 3);
		world.setBlockState(new BlockPos(x + 15, y + 3, z + 16), ExtraPlanets_Fluids.MAGMA.getDefaultState(), 3);
		world.setBlockState(new BlockPos(x + 16, y + 3, z + 16), ExtraPlanets_Fluids.MAGMA.getDefaultState(), 3);
		world.setBlockState(new BlockPos(x + 17, y + 3, z + 16), ExtraPlanets_Fluids.MAGMA.getDefaultState(), 3);
		world.setBlockState(new BlockPos(x + 18, y + 3, z + 16), ExtraPlanets_Blocks.VOLCANIC_ROCK.getDefaultState(), 3);
		world.setBlockState(new BlockPos(x + 7, y + 3, z + 17), ExtraPlanets_Blocks.VOLCANIC_ROCK.getDefaultState(), 3);
		world.setBlockState(new BlockPos(x + 8, y + 3, z + 17), ExtraPlanets_Blocks.VOLCANIC_ROCK.getDefaultState(), 3);
		world.setBlockState(new BlockPos(x + 9, y + 3, z + 17), ExtraPlanets_Blocks.VOLCANIC_ROCK.getDefaultState(), 3);
		world.setBlockState(new BlockPos(x + 10, y + 3, z + 17), ExtraPlanets_Fluids.MAGMA.getDefaultState(), 3);
		world.setBlockState(new BlockPos(x + 11, y + 3, z + 17), ExtraPlanets_Fluids.MAGMA.getDefaultState(), 3);
		world.setBlockState(new BlockPos(x + 12, y + 3, z + 17), ExtraPlanets_Fluids.MAGMA.getDefaultState(), 3);
		world.setBlockState(new BlockPos(x + 13, y + 3, z + 17), ExtraPlanets_Fluids.MAGMA.getDefaultState(), 3);
		world.setBlockState(new BlockPos(x + 14, y + 3, z + 17), ExtraPlanets_Fluids.MAGMA.getDefaultState(), 3);
		world.setBlockState(new BlockPos(x + 15, y + 3, z + 17), ExtraPlanets_Fluids.MAGMA.getDefaultState(), 3);
		world.setBlockState(new BlockPos(x + 16, y + 3, z + 17), ExtraPlanets_Fluids.MAGMA.getDefaultState(), 3);
		world.setBlockState(new BlockPos(x + 17, y + 3, z + 17), ExtraPlanets_Blocks.VOLCANIC_ROCK.getDefaultState(), 3);
		world.setBlockState(new BlockPos(x + 18, y + 3, z + 17), ExtraPlanets_Fluids.MAGMA.getDefaultState(), 3);
		world.setBlockState(new BlockPos(x + 6, y + 3, z + 18), ExtraPlanets_Fluids.MAGMA.getDefaultState(), 3);
		world.setBlockState(new BlockPos(x + 7, y + 3, z + 18), ExtraPlanets_Fluids.MAGMA.getDefaultState(), 3);
		world.setBlockState(new BlockPos(x + 8, y + 3, z + 18), ExtraPlanets_Fluids.MAGMA.getDefaultState(), 3);
		world.setBlockState(new BlockPos(x + 9, y + 3, z + 18), ExtraPlanets_Blocks.VOLCANIC_ROCK.getDefaultState(), 3);
		world.setBlockState(new BlockPos(x + 10, y + 3, z + 18), ExtraPlanets_Blocks.VOLCANIC_ROCK.getDefaultState(), 3);
		world.setBlockState(new BlockPos(x + 11, y + 3, z + 18), ExtraPlanets_Fluids.MAGMA.getDefaultState(), 3);
		world.setBlockState(new BlockPos(x + 12, y + 3, z + 18), ExtraPlanets_Fluids.MAGMA.getDefaultState(), 3);
		world.setBlockState(new BlockPos(x + 13, y + 3, z + 18), ExtraPlanets_Blocks.VOLCANIC_ROCK.getDefaultState(), 3);
		world.setBlockState(new BlockPos(x + 14, y + 3, z + 18), ExtraPlanets_Blocks.VOLCANIC_ROCK.getDefaultState(), 3);
		world.setBlockState(new BlockPos(x + 15, y + 3, z + 18), ExtraPlanets_Blocks.VOLCANIC_ROCK.getDefaultState(), 3);
		world.setBlockState(new BlockPos(x + 16, y + 3, z + 18), ExtraPlanets_Blocks.VOLCANIC_ROCK.getDefaultState(), 3);
		world.setBlockState(new BlockPos(x + 17, y + 3, z + 18), ExtraPlanets_Blocks.VOLCANIC_ROCK.getDefaultState(), 3);
		world.setBlockState(new BlockPos(x + 18, y + 3, z + 18), ExtraPlanets_Fluids.MAGMA.getDefaultState(), 3);
		world.setBlockState(new BlockPos(x + 8, y + 4, z + 9), ExtraPlanets_Blocks.VOLCANIC_ROCK.getDefaultState(), 3);
		world.setBlockState(new BlockPos(x + 9, y + 4, z + 9), ExtraPlanets_Blocks.VOLCANIC_ROCK.getDefaultState(), 3);
		world.setBlockState(new BlockPos(x + 11, y + 4, z + 9), ExtraPlanets_Fluids.MAGMA.getDefaultState(), 3);
		world.setBlockState(new BlockPos(x + 6, y + 4, z + 10), ExtraPlanets_Blocks.VOLCANIC_ROCK.getDefaultState(), 3);
		world.setBlockState(new BlockPos(x + 7, y + 4, z + 10), ExtraPlanets_Blocks.VOLCANIC_ROCK.getDefaultState(), 3);
		world.setBlockState(new BlockPos(x + 8, y + 4, z + 10), ExtraPlanets_Blocks.VOLCANIC_ROCK.getDefaultState(), 3);
		world.setBlockState(new BlockPos(x + 9, y + 4, z + 10), ExtraPlanets_Fluids.MAGMA.getDefaultState(), 3);
		world.setBlockState(new BlockPos(x + 10, y + 4, z + 10), ExtraPlanets_Fluids.MAGMA.getDefaultState(), 3);
		world.setBlockState(new BlockPos(x + 11, y + 4, z + 10), ExtraPlanets_Fluids.MAGMA.getDefaultState(), 3);
		world.setBlockState(new BlockPos(x + 12, y + 4, z + 10), ExtraPlanets_Fluids.MAGMA.getDefaultState(), 3);
		world.setBlockState(new BlockPos(x + 13, y + 4, z + 10), ExtraPlanets_Fluids.MAGMA.getDefaultState(), 3);
		world.setBlockState(new BlockPos(x + 15, y + 4, z + 10), ExtraPlanets_Fluids.MAGMA.getDefaultState(), 3);
		world.setBlockState(new BlockPos(x + 6, y + 4, z + 11), ExtraPlanets_Blocks.VOLCANIC_ROCK.getDefaultState(), 3);
		world.setBlockState(new BlockPos(x + 7, y + 4, z + 11), ExtraPlanets_Fluids.MAGMA.getDefaultState(), 3);
		world.setBlockState(new BlockPos(x + 8, y + 4, z + 11), ExtraPlanets_Fluids.MAGMA.getDefaultState(), 3);
		world.setBlockState(new BlockPos(x + 9, y + 4, z + 11), ExtraPlanets_Fluids.MAGMA.getDefaultState(), 3);
		world.setBlockState(new BlockPos(x + 10, y + 4, z + 11), ExtraPlanets_Fluids.MAGMA.getDefaultState(), 3);
		world.setBlockState(new BlockPos(x + 11, y + 4, z + 11), ExtraPlanets_Fluids.MAGMA.getDefaultState(), 3);
		world.setBlockState(new BlockPos(x + 12, y + 4, z + 11), ExtraPlanets_Fluids.MAGMA.getDefaultState(), 3);
		world.setBlockState(new BlockPos(x + 13, y + 4, z + 11), ExtraPlanets_Fluids.MAGMA.getDefaultState(), 3);
		world.setBlockState(new BlockPos(x + 14, y + 4, z + 11), ExtraPlanets_Fluids.MAGMA.getDefaultState(), 3);
		world.setBlockState(new BlockPos(x + 15, y + 4, z + 11), ExtraPlanets_Fluids.MAGMA.getDefaultState(), 3);
		world.setBlockState(new BlockPos(x + 16, y + 4, z + 11), ExtraPlanets_Fluids.MAGMA.getDefaultState(), 3);
		world.setBlockState(new BlockPos(x + 17, y + 4, z + 11), ExtraPlanets_Fluids.MAGMA.getDefaultState(), 3);
		world.setBlockState(new BlockPos(x + 6, y + 4, z + 12), ExtraPlanets_Blocks.VOLCANIC_ROCK.getDefaultState(), 3);
		world.setBlockState(new BlockPos(x + 7, y + 4, z + 12), ExtraPlanets_Blocks.VOLCANIC_ROCK.getDefaultState(), 3);
		world.setBlockState(new BlockPos(x + 8, y + 4, z + 12), ExtraPlanets_Fluids.MAGMA.getDefaultState(), 3);
		world.setBlockState(new BlockPos(x + 9, y + 4, z + 12), ExtraPlanets_Fluids.MAGMA.getDefaultState(), 3);
		world.setBlockState(new BlockPos(x + 10, y + 4, z + 12), ExtraPlanets_Fluids.MAGMA.getDefaultState(), 3);
		world.setBlockState(new BlockPos(x + 11, y + 4, z + 12), ExtraPlanets_Fluids.MAGMA.getDefaultState(), 3);
		world.setBlockState(new BlockPos(x + 12, y + 4, z + 12), ExtraPlanets_Fluids.MAGMA.getDefaultState(), 3);
		world.setBlockState(new BlockPos(x + 13, y + 4, z + 12), ExtraPlanets_Fluids.MAGMA.getDefaultState(), 3);
		world.setBlockState(new BlockPos(x + 14, y + 4, z + 12), ExtraPlanets_Fluids.MAGMA.getDefaultState(), 3);
		world.setBlockState(new BlockPos(x + 15, y + 4, z + 12), ExtraPlanets_Fluids.MAGMA.getDefaultState(), 3);
		world.setBlockState(new BlockPos(x + 16, y + 4, z + 12), ExtraPlanets_Fluids.MAGMA.getDefaultState(), 3);
		world.setBlockState(new BlockPos(x + 17, y + 4, z + 12), ExtraPlanets_Fluids.MAGMA.getDefaultState(), 3);
		world.setBlockState(new BlockPos(x + 18, y + 4, z + 12), ExtraPlanets_Fluids.MAGMA.getDefaultState(), 3);
		world.setBlockState(new BlockPos(x + 6, y + 4, z + 13), ExtraPlanets_Blocks.VOLCANIC_ROCK.getDefaultState(), 3);
		world.setBlockState(new BlockPos(x + 7, y + 4, z + 13), ExtraPlanets_Blocks.VOLCANIC_ROCK.getDefaultState(), 3);
		world.setBlockState(new BlockPos(x + 8, y + 4, z + 13), ExtraPlanets_Fluids.MAGMA.getDefaultState(), 3);
		world.setBlockState(new BlockPos(x + 9, y + 4, z + 13), ExtraPlanets_Fluids.MAGMA.getDefaultState(), 3);
		world.setBlockState(new BlockPos(x + 10, y + 4, z + 13), ExtraPlanets_Fluids.MAGMA.getDefaultState(), 3);
		world.setBlockState(new BlockPos(x + 11, y + 4, z + 13), ExtraPlanets_Fluids.MAGMA.getDefaultState(), 3);
		world.setBlockState(new BlockPos(x + 12, y + 4, z + 13), ExtraPlanets_Fluids.MAGMA.getDefaultState(), 3);
		world.setBlockState(new BlockPos(x + 13, y + 4, z + 13), ExtraPlanets_Fluids.MAGMA.getDefaultState(), 3);
		world.setBlockState(new BlockPos(x + 14, y + 4, z + 13), ExtraPlanets_Fluids.MAGMA.getDefaultState(), 3);
		world.setBlockState(new BlockPos(x + 15, y + 4, z + 13), ExtraPlanets_Fluids.MAGMA.getDefaultState(), 3);
		world.setBlockState(new BlockPos(x + 16, y + 4, z + 13), ExtraPlanets_Blocks.VOLCANIC_ROCK.getDefaultState(), 3);
		world.setBlockState(new BlockPos(x + 17, y + 4, z + 13), ExtraPlanets_Fluids.MAGMA.getDefaultState(), 3);
		world.setBlockState(new BlockPos(x + 7, y + 4, z + 14), ExtraPlanets_Blocks.VOLCANIC_ROCK.getDefaultState(), 3);
		world.setBlockState(new BlockPos(x + 8, y + 4, z + 14), ExtraPlanets_Blocks.VOLCANIC_ROCK.getDefaultState(), 3);
		world.setBlockState(new BlockPos(x + 9, y + 4, z + 14), ExtraPlanets_Fluids.MAGMA.getDefaultState(), 3);
		world.setBlockState(new BlockPos(x + 10, y + 4, z + 14), ExtraPlanets_Fluids.MAGMA.getDefaultState(), 3);
		world.setBlockState(new BlockPos(x + 11, y + 4, z + 14), ExtraPlanets_Fluids.MAGMA.getDefaultState(), 3);
		world.setBlockState(new BlockPos(x + 12, y + 4, z + 14), ExtraPlanets_Fluids.MAGMA.getDefaultState(), 3);
		world.setBlockState(new BlockPos(x + 13, y + 4, z + 14), ExtraPlanets_Fluids.MAGMA.getDefaultState(), 3);
		world.setBlockState(new BlockPos(x + 14, y + 4, z + 14), ExtraPlanets_Fluids.MAGMA.getDefaultState(), 3);
		world.setBlockState(new BlockPos(x + 15, y + 4, z + 14), ExtraPlanets_Fluids.MAGMA.getDefaultState(), 3);
		world.setBlockState(new BlockPos(x + 16, y + 4, z + 14), ExtraPlanets_Blocks.VOLCANIC_ROCK.getDefaultState(), 3);
		world.setBlockState(new BlockPos(x + 17, y + 4, z + 14), ExtraPlanets_Blocks.VOLCANIC_ROCK.getDefaultState(), 3);
		world.setBlockState(new BlockPos(x + 7, y + 4, z + 15), ExtraPlanets_Blocks.VOLCANIC_ROCK.getDefaultState(), 3);
		world.setBlockState(new BlockPos(x + 8, y + 4, z + 15), ExtraPlanets_Blocks.VOLCANIC_ROCK.getDefaultState(), 3);
		world.setBlockState(new BlockPos(x + 9, y + 4, z + 15), ExtraPlanets_Fluids.MAGMA.getDefaultState(), 3);
		world.setBlockState(new BlockPos(x + 10, y + 4, z + 15), ExtraPlanets_Fluids.MAGMA.getDefaultState(), 3);
		world.setBlockState(new BlockPos(x + 11, y + 4, z + 15), ExtraPlanets_Fluids.MAGMA.getDefaultState(), 3);
		world.setBlockState(new BlockPos(x + 12, y + 4, z + 15), ExtraPlanets_Fluids.MAGMA.getDefaultState(), 3);
		world.setBlockState(new BlockPos(x + 13, y + 4, z + 15), ExtraPlanets_Fluids.MAGMA.getDefaultState(), 3);
		world.setBlockState(new BlockPos(x + 14, y + 4, z + 15), ExtraPlanets_Fluids.MAGMA.getDefaultState(), 3);
		world.setBlockState(new BlockPos(x + 15, y + 4, z + 15), ExtraPlanets_Fluids.MAGMA.getDefaultState(), 3);
		world.setBlockState(new BlockPos(x + 16, y + 4, z + 15), ExtraPlanets_Blocks.VOLCANIC_ROCK.getDefaultState(), 3);
		world.setBlockState(new BlockPos(x + 17, y + 4, z + 15), ExtraPlanets_Blocks.VOLCANIC_ROCK.getDefaultState(), 3);
		world.setBlockState(new BlockPos(x + 8, y + 4, z + 16), ExtraPlanets_Blocks.VOLCANIC_ROCK.getDefaultState(), 3);
		world.setBlockState(new BlockPos(x + 9, y + 4, z + 16), ExtraPlanets_Fluids.MAGMA.getDefaultState(), 3);
		world.setBlockState(new BlockPos(x + 10, y + 4, z + 16), ExtraPlanets_Fluids.MAGMA.getDefaultState(), 3);
		world.setBlockState(new BlockPos(x + 11, y + 4, z + 16), ExtraPlanets_Blocks.VOLCANIC_ROCK.getDefaultState(), 3);
		world.setBlockState(new BlockPos(x + 12, y + 4, z + 16), ExtraPlanets_Fluids.MAGMA.getDefaultState(), 3);
		world.setBlockState(new BlockPos(x + 13, y + 4, z + 16), ExtraPlanets_Blocks.VOLCANIC_ROCK.getDefaultState(), 3);
		world.setBlockState(new BlockPos(x + 14, y + 4, z + 16), ExtraPlanets_Blocks.VOLCANIC_ROCK.getDefaultState(), 3);
		world.setBlockState(new BlockPos(x + 15, y + 4, z + 16), ExtraPlanets_Blocks.VOLCANIC_ROCK.getDefaultState(), 3);
		world.setBlockState(new BlockPos(x + 16, y + 4, z + 16), ExtraPlanets_Blocks.VOLCANIC_ROCK.getDefaultState(), 3);
		world.setBlockState(new BlockPos(x + 17, y + 4, z + 16), ExtraPlanets_Blocks.VOLCANIC_ROCK.getDefaultState(), 3);
		world.setBlockState(new BlockPos(x + 8, y + 4, z + 17), ExtraPlanets_Fluids.MAGMA.getDefaultState(), 3);
		world.setBlockState(new BlockPos(x + 9, y + 4, z + 17), ExtraPlanets_Fluids.MAGMA.getDefaultState(), 3);
		world.setBlockState(new BlockPos(x + 10, y + 4, z + 17), ExtraPlanets_Blocks.VOLCANIC_ROCK.getDefaultState(), 3);
		world.setBlockState(new BlockPos(x + 11, y + 4, z + 17), ExtraPlanets_Blocks.VOLCANIC_ROCK.getDefaultState(), 3);
		world.setBlockState(new BlockPos(x + 12, y + 4, z + 17), ExtraPlanets_Blocks.VOLCANIC_ROCK.getDefaultState(), 3);
		world.setBlockState(new BlockPos(x + 13, y + 4, z + 17), ExtraPlanets_Blocks.VOLCANIC_ROCK.getDefaultState(), 3);
		world.setBlockState(new BlockPos(x + 14, y + 4, z + 17), ExtraPlanets_Blocks.VOLCANIC_ROCK.getDefaultState(), 3);
		world.setBlockState(new BlockPos(x + 15, y + 4, z + 17), ExtraPlanets_Blocks.VOLCANIC_ROCK.getDefaultState(), 3);
		world.setBlockState(new BlockPos(x + 16, y + 4, z + 17), ExtraPlanets_Blocks.VOLCANIC_ROCK.getDefaultState(), 3);
		world.setBlockState(new BlockPos(x + 17, y + 4, z + 17), ExtraPlanets_Fluids.MAGMA.getDefaultState(), 3);
		world.setBlockState(new BlockPos(x + 18, y + 4, z + 17), ExtraPlanets_Fluids.MAGMA.getDefaultState(), 3);
		world.setBlockState(new BlockPos(x + 8, y + 4, z + 18), ExtraPlanets_Fluids.MAGMA.getDefaultState(), 3);
		world.setBlockState(new BlockPos(x + 9, y + 4, z + 18), ExtraPlanets_Blocks.VOLCANIC_ROCK.getDefaultState(), 3);
		world.setBlockState(new BlockPos(x + 10, y + 4, z + 18), ExtraPlanets_Blocks.VOLCANIC_ROCK.getDefaultState(), 3);
		world.setBlockState(new BlockPos(x + 11, y + 4, z + 18), ExtraPlanets_Blocks.VOLCANIC_ROCK.getDefaultState(), 3);
